File: exampledata/PXP_N2.csv
Meas. Pts.,Time,Storage Modulus,Loss Modulus,Strain,Angular Frequency,Shear Stress,Shear Rate,Viscosity,Temperature,Speed,Torque,Status
,[s],[Pa],[Pa],[%],[rad/s],[Pa],[1/s],[Pa·s],[°C],[1/min],[µNm],[]
1.00,5,4600.00,1470.00,4.99,30.00,241.00,1.50,******,36.90,******,24.20,WMa
2.00,10,4660.00,2090.00,5.00,30.00,256.00,1.50,******,36.90,******,25.70,
3.00,15,4660.00,2120.00,5.00,30.00,256.00,1.50,******,36.90,******,25.70,
4.00,20,4650.00,2130.00,5.00,30.00,256.00,1.50,******,36.90,******,25.70,
5.00,25,4700.00,2110.00,5.00,30.00,257.00,1.50,******,37.00,******,25.90,
6.00,30,4630.00,2140.00,5.00,30.00,255.00,1.50,******,37.00,******,25.70,
7.00,35,4640.00,2140.00,5.00,30.00,255.00,1.50,******,37.00,******,25.70,
8.00,40,4630.00,2150.00,5.00,30.00,255.00,1.50,******,37.00,******,25.60,
9.00,45,4630.00,2150.00,5.00,30.00,255.00,1.50,******,37.00,******,25.70,
10.00,50,4620.00,2160.00,5.00,30.00,255.00,1.50,******,37.00,******,25.60,
11.00,55,4620.00,2150.00,5.00,30.00,255.00,1.50,******,37.00,******,25.60,
12.00,60,4610.00,2160.00,5.00,30.00,255.00,1.50,******,37.00,******,25.60,
13.00,65,4630.00,2160.00,5.00,30.00,255.00,1.50,******,37.00,******,25.70,
14.00,70,4600.00,2160.00,5.00,30.00,254.00,1.50,******,37.00,******,25.60,
15.00,75,4620.00,2180.00,5.00,30.00,255.00,1.50,******,37.00,******,25.70,
16.00,80,4620.00,2170.00,5.00,30.00,255.00,1.50,******,37.00,******,25.60,
17.00,85,4620.00,2190.00,5.00,30.00,256.00,1.50,******,37.00,******,25.70,
18.00,90,4610.00,2200.00,5.00,30.00,255.00,1.50,******,37.00,******,25.70,
19.00,95,4610.00,2180.00,5.00,30.00,255.00,1.50,******,37.00,******,25.60,
20.00,100,4610.00,2180.00,5.00,30.00,255.00,1.50,******,37.00,******,25.60,
21.00,105,4600.00,2180.00,5.00,30.00,255.00,1.50,******,37.00,******,25.60,
22.00,110,4600.00,2190.00,5.00,30.00,255.00,1.50,******,37.00,******,25.60,
23.00,115,4600.00,2190.00,5.00,30.00,255.00,1.50,******,37.00,******,25.60,
24.00,120,4600.00,2200.00,5.00,30.00,255.00,1.50,******,37.00,******,25.60,
25.00,125,4600.00,2200.00,5.00,30.00,255.00,1.50,******,37.00,******,25.60,
26.00,130,4600.00,2200.00,5.00,30.00,255.00,1.50,******,37.00,******,25.60,
27.00,135,4590.00,2200.00,5.00,30.00,255.00,1.50,******,37.00,******,25.60,
28.00,140,4590.00,2190.00,5.00,30.00,254.00,1.50,******,37.00,******,25.60,
29.00,145,4600.00,2200.00,5.00,30.00,255.00,1.50,******,37.00,******,25.60,
30.00,150,4600.00,2200.00,5.00,30.00,255.00,1.50,******,37.00,******,25.60,
31.00,155,4590.00,2210.00,5.00,30.00,255.00,1.50,******,37.00,******,25.60,
32.00,160,4600.00,2210.00,5.00,30.00,255.00,1.50,******,37.00,******,25.70,
33.00,165,4590.00,2210.00,5.00,30.00,255.00,1.50,******,37.00,******,25.60,
34.00,170,4600.00,2210.00,5.00,30.00,255.00,1.50,******,37.00,******,25.60,
35.00,175,4600.00,2220.00,5.00,30.00,255.00,1.50,******,37.00,******,25.70,
36.00,180,4600.00,2210.00,5.00,30.00,255.00,1.50,******,37.00,******,25.60,
37.00,185,4610.00,2220.00,5.00,30.00,256.00,1.50,******,37.00,******,25.70,
38.00,190,4600.00,2210.00,5.00,30.00,255.00,1.50,******,37.00,******,25.70,
39.00,195,4590.00,2220.00,5.00,30.00,255.00,1.50,******,37.00,******,25.60,
40.00,200,4590.00,2210.00,5.00,30.00,255.00,1.50,******,37.00,******,25.60,
41.00,205,4600.00,2230.00,5.00,30.00,255.00,1.50,******,37.00,******,25.70,
42.00,210,4600.00,2230.00,5.00,30.00,255.00,1.50,******,37.00,******,25.70,
43.00,215,4590.00,2240.00,5.00,30.00,255.00,1.50,******,37.00,******,25.70,
44.00,220,4590.00,2230.00,5.00,30.00,255.00,1.50,******,37.00,******,25.60,
45.00,225,4600.00,2220.00,5.00,30.00,255.00,1.50,******,37.00,******,25.70,
46.00,230,4590.00,2230.00,5.00,30.00,255.00,1.50,******,37.00,******,25.60,
47.00,235,4580.00,2240.00,5.00,30.00,255.00,1.50,******,37.00,******,25.60,
48.00,240,4580.00,2230.00,5.00,30.00,255.00,1.50,******,37.00,******,25.60,
49.00,245,4590.00,2230.00,5.00,30.00,255.00,1.50,******,37.00,******,25.70,
50.00,250,4580.00,2230.00,5.00,30.00,255.00,1.50,******,37.00,******,25.60,
51.00,255,4610.00,2240.00,5.00,30.00,256.00,1.50,******,37.00,******,25.80,
52.00,260,4590.00,2230.00,5.00,30.00,255.00,1.50,******,37.00,******,25.70,
53.00,265,4590.00,2220.00,5.00,30.00,255.00,1.50,******,37.00,******,25.60,
54.00,270,4590.00,2220.00,5.00,30.00,255.00,1.50,******,37.00,******,25.60,
55.00,275,4570.00,2240.00,5.00,30.00,254.00,1.50,******,37.00,******,25.60,
56.00,280,4590.00,2240.00,5.00,30.00,255.00,1.50,******,37.00,******,25.70,
57.00,285,4580.00,2250.00,5.00,30.00,255.00,1.50,******,37.00,******,25.70,
58.00,290,4590.00,2240.00,5.00,30.00,255.00,1.50,******,37.00,******,25.70,
59.00,295,4590.00,2240.00,5.00,30.00,256.00,1.50,******,37.00,******,25.70,
60.00,300,4600.00,2250.00,5.00,30.00,256.00,1.50,******,37.00,******,25.70,
61.00,305,4580.00,2240.00,5.00,30.00,255.00,1.50,******,37.00,******,25.60,
62.00,310,4590.00,2250.00,5.00,30.00,256.00,1.50,******,37.00,******,25.70,
63.00,315,4580.00,2250.00,5.00,30.00,255.00,1.50,******,37.00,******,25.60,
64.00,320,4580.00,2260.00,5.00,30.00,255.00,1.50,******,37.00,******,25.70,
65.00,325,4570.00,2240.00,5.00,30.00,255.00,1.50,******,37.00,******,25.60,
66.00,330,4580.00,2240.00,5.00,30.00,255.00,1.50,******,37.00,******,25.60,
67.00,335,4590.00,2240.00,5.00,30.00,255.00,1.50,******,37.00,******,25.70,
68.00,340,4570.00,2260.00,5.00,30.00,255.00,1.50,******,37.00,******,25.60,
69.00,345,4570.00,2250.00,5.00,30.00,255.00,1.50,******,37.00,******,25.60,
70.00,350,4580.00,2240.00,5.00,30.00,255.00,1.50,******,37.00,******,25.70,
71.00,355,4580.00,2250.00,5.00,30.00,255.00,1.50,******,37.00,******,25.70,
72.00,360,4580.00,2250.00,5.00,30.00,255.00,1.50,******,37.00,******,25.60,
73.00,365,4590.00,2250.00,5.00,30.00,256.00,1.50,******,37.00,******,25.70,
74.00,370,4590.00,2250.00,5.00,30.00,255.00,1.50,******,37.00,******,25.70,
75.00,375,4570.00,2250.00,5.00,30.00,255.00,1.50,******,37.00,******,25.60,
76.00,380,4580.00,2250.00,5.00,30.00,255.00,1.50,******,37.00,******,25.60,
77.00,385,4590.00,2260.00,5.00,30.00,256.00,1.50,******,37.00,******,25.70,
78.00,390,4590.00,2260.00,5.00,30.00,256.00,1.50,******,37.00,******,25.70,
79.00,395,4590.00,2250.00,5.00,30.00,256.00,1.50,******,37.00,******,25.70,
80.00,400,4580.00,2240.00,5.00,30.00,255.00,1.50,******,37.00,******,25.60,
,,,,,,,,,,,,
Interval:,,,2.00,,,,,,,,,
Number of Data Points:,,,31.00,,,,,,,,,
,,,,,,,,,,,,
Time Setting:,,,31 Meas. Pts.,,,,,,,,,
Measuring Profile:,,,,,,,,,,,,
#NAME?,,,Amplitude gamma = 5 %,,,,,,,,,
,,,Angular Frequency omega = 100 ... 0.1 rad/s log; |Slope| = 10 Pt. / dec ,,,,,,,,,
,,,,,,,,,,,,
Meas. Pts.,Time,Storage Modulus,Loss Modulus,Strain,Angular Frequency,Shear Stress,Shear Rate,Viscosity,Temperature,Speed,Torque,Status
,[s],[Pa],[Pa],[%],[rad/s],[Pa],[1/s],[Pa·s],[°C],[1/min],[µNm],[]
1.00,410,4410.00,1470.00,5.00,100.00,232.00,5.00,******,37.00,******,23.40,
2.00,418,5160.00,1380.00,5.00,79.40,267.00,3.97,******,37.00,******,26.90,
3.00,425,5220.00,1590.00,5.00,63.10,273.00,3.15,******,37.00,******,27.40,
4.00,432,5170.00,1760.00,5.00,50.10,273.00,2.51,******,37.00,******,27.50,
5.00,439,5000.00,1990.00,5.00,39.80,269.00,1.99,******,37.00,******,27.00,
6.00,448,4720.00,2210.00,5.00,31.60,260.00,1.58,******,37.00,******,26.20,
7.00,458,4340.00,2410.00,5.00,25.10,248.00,1.26,******,37.00,******,24.90,
8.00,465,3910.00,2550.00,5.00,20.00,233.00,1.00,******,37.00,******,23.50,
9.00,472,3400.00,2640.00,5.00,15.80,215.00,0.79,******,37.00,******,21.60,
10.00,478,2880.00,2640.00,5.00,12.60,196.00,0.63,******,37.00,******,19.70,
11.00,486,2370.00,2570.00,5.00,10.00,175.00,0.50,******,37.00,******,17.60,
12.00,493,1880.00,2420.00,5.00,7.94,153.00,0.40,******,37.00,******,15.40,
13.00,502,1440.00,2230.00,5.00,6.31,133.00,0.32,******,37.00,******,13.40,
14.00,509,1080.00,1980.00,5.00,5.01,113.00,0.25,******,37.00,******,11.30,
15.00,517,785.00,1730.00,5.01,3.98,94.90,0.20,******,37.00,******,9.54,
16.00,527,562.00,1470.00,5.01,3.16,78.80,0.16,******,37.00,******,7.93,
17.00,540,392.00,1230.00,5.01,2.51,64.70,0.13,******,37.00,******,6.51,
18.00,560,272.00,1020.00,5.01,2.00,52.80,0.10,******,37.00,******,5.31,
19.00,586,185.00,834.00,5.01,1.58,42.80,0.08,******,37.00,******,4.30,
20.00,617,127.00,677.00,5.01,1.26,34.50,0.06,******,37.00,******,3.47,
21.00,656,87.30,547.00,5.01,1.00,27.70,0.05,******,37.00,******,2.79,
22.00,693,61.00,440.00,5.01,0.79,22.30,0.04,******,37.00,******,2.24,
23.00,739,42.40,352.00,5.01,0.63,17.80,0.03,******,37.00,******,1.79,
24.00,797,31.20,283.00,5.01,0.50,14.30,0.03,******,37.00,******,1.43,
25.00,869,23.20,227.00,5.01,0.40,11.40,0.02,******,37.00,******,1.15,
26.00,929,17.50,182.00,5.01,0.32,9.14,0.02,******,37.00,******,0.92,
27.00,1010,13.90,145.00,5.01,0.25,7.30,0.01,******,37.00,******,0.73,
28.00,1100,11.60,116.00,5.01,0.20,5.86,0.01,******,37.00,******,0.59,
29.00,1220,9.78,93.40,5.01,0.16,4.70,0.01,******,37.00,******,0.47,
30.00,1450,8.56,75.00,5.01,0.13,3.78,0.01,******,37.00,******,0.38,
31.00,1730,7.63,60.30,5.01,0.10,3.04,0.01,******,37.00,******,0.31,
,,,,,,,,,,,,
Interval:,,,3.00,,,,,,,,,
Number of Data Points:,,,80.00,,,,,,,,,
,,,,,,,,,,,,
Time Setting:,,,80 Meas. Pts.,,,,,,,,,
,,,Meas. Pt. Duration 5 s,,,,,,,,,
Event Control:,,,Standard Mode,,,,,,,,,
"  Terminate test, ...",,,...if M > 75 mNm,,,,,,,,,
Measuring Profile:,,,,,,,,,,,,
#NAME?,,,Amplitude gamma = 5 %,,,,,,,,,
,,,Angular Frequency omega = 30 rad/s,,,,,,,,,
,,,,,,,,,,,,
Meas. Pts.,Time,Storage Modulus,Loss Modulus,Strain,Angular Frequency,Shear Stress,Shear Rate,Viscosity,Temperature,Speed,Torque,Status
,[s],[Pa],[Pa],[%],[rad/s],[Pa],[1/s],[Pa·s],[°C],[1/min],[µNm],[]
1.00,invalid point,,,,,,,,,,,
2.00,1740,,,,,,,,,,,
3.00,1745,,,,,,,,,,,
4.00,1750,,,,,,,,,,,
5.00,1755,,,,,,,,,,,
6.00,1760,,,,,,,,,,,
7.00,1765,,,,,,,,,,,
8.00,1770,,,,,,,,,,,
9.00,1775,,,,,,,,,,,
10.00,1780,,,,,,,,,,,
11.00,1785,,,,,,,,,,,
12.00,1790,,,,,,,,,,,
13.00,1795,,,,,,,,,,,
14.00,1800,,,,,,,,,,,
15.00,1805,,,,,,,,,,,
16.00,1810,,,,,,,,,,,
17.00,1815,,,,,,,,,,,
18.00,1820,,,,,,,,,,,
19.00,1825,,,,,,,,,,,
20.00,1830,4580.00,1970.00,5.17,30.00,258.00,1.55,******,37.00,******,25.90,WMa
21.00,1835,4590.00,2320.00,5.00,30.00,257.00,1.50,******,37.00,******,25.90,
22.00,1840,4610.00,2310.00,5.00,30.00,258.00,1.50,******,37.00,******,25.90,
23.00,1845,4610.00,2320.00,5.00,30.00,258.00,1.50,******,37.00,******,25.90,
24.00,1850,4600.00,2320.00,5.00,30.00,258.00,1.50,******,37.00,******,25.90,
25.00,1855,4610.00,2300.00,5.00,30.00,258.00,1.50,******,37.00,******,25.90,
26.00,1860,4620.00,2310.00,5.00,30.00,258.00,1.50,******,37.00,******,26.00,
27.00,1865,4600.00,2310.00,5.00,30.00,257.00,1.50,******,37.00,******,25.90,
28.00,1870,4600.00,2310.00,5.00,30.00,257.00,1.50,******,37.00,******,25.90,
29.00,1875,4600.00,2310.00,5.00,30.00,257.00,1.50,******,37.00,******,25.90,
30.00,1880,4610.00,2310.00,5.00,30.00,258.00,1.50,******,37.00,******,25.90,
31.00,1885,4610.00,2320.00,5.00,30.00,258.00,1.50,******,37.00,******,25.90,
32.00,1890,4600.00,2310.00,5.00,30.00,257.00,1.50,******,37.00,******,25.90,
33.00,1895,4600.00,2290.00,5.00,30.00,257.00,1.50,******,37.00,******,25.80,
34.00,1900,4600.00,2300.00,5.00,30.00,257.00,1.50,******,37.00,******,25.90,
35.00,1905,4600.00,2320.00,5.00,30.00,258.00,1.50,******,37.00,******,25.90,
36.00,1910,4600.00,2300.00,5.00,30.00,257.00,1.50,******,37.00,******,25.80,
37.00,1915,4600.00,2290.00,5.00,30.00,257.00,1.50,******,37.00,******,25.80,
38.00,1920,4610.00,2300.00,5.00,30.00,258.00,1.50,******,37.00,******,25.90,
39.00,1925,4610.00,2300.00,5.00,30.00,258.00,1.50,******,37.00,******,25.90,
40.00,1930,4590.00,2300.00,5.00,30.00,257.00,1.50,******,37.00,******,25.80,
41.00,1935,4600.00,2310.00,5.00,30.00,258.00,1.50,******,37.00,******,25.90,
42.00,1940,4600.00,2320.00,5.00,30.00,257.00,1.50,******,37.00,******,25.90,
43.00,1945,4600.00,2310.00,5.00,30.00,258.00,1.50,******,37.00,******,25.90,
44.00,1950,4620.00,2310.00,5.00,30.00,258.00,1.50,******,37.00,******,26.00,
45.00,1955,4600.00,2310.00,5.00,30.00,258.00,1.50,******,37.00,******,25.90,
46.00,1960,4590.00,2300.00,5.00,30.00,257.00,1.50,******,37.00,******,25.80,
47.00,1965,4610.00,2300.00,5.00,30.00,258.00,1.50,******,37.00,******,25.90,
48.00,1970,4600.00,2320.00,5.00,30.00,258.00,1.50,******,37.00,******,25.90,
49.00,1975,4610.00,2310.00,5.00,30.00,258.00,1.50,******,37.00,******,25.90,
50.00,1980,4600.00,2310.00,5.00,30.00,257.00,1.50,******,37.00,******,25.90,
51.00,1985,4600.00,2300.00,5.00,30.00,257.00,1.50,******,37.00,******,25.90,
52.00,1990,4610.00,2300.00,5.00,30.00,258.00,1.50,******,37.00,******,25.90,
53.00,1995,4610.00,2310.00,5.00,30.00,258.00,1.50,******,37.00,******,25.90,
54.00,2000,4610.00,2320.00,5.00,30.00,258.00,1.50,******,37.00,******,25.90,
55.00,2005,4610.00,2300.00,5.00,30.00,257.00,1.50,******,37.00,******,25.90,
56.00,2010,4590.00,2310.00,5.00,30.00,257.00,1.50,******,37.00,******,25.80,
57.00,2015,4610.00,2310.00,5.00,30.00,258.00,1.50,******,37.00,******,25.90,
58.00,2020,4610.00,2320.00,5.00,30.00,258.00,1.50,******,37.00,******,26.00,
59.00,2025,4610.00,2320.00,5.00,30.00,258.00,1.50,******,37.00,******,25.90,
60.00,2030,4590.00,2310.00,5.00,30.00,257.00,1.50,******,37.00,******,25.90,
61.00,2035,4610.00,2310.00,5.00,30.00,258.00,1.50,******,37.00,******,25.90,
62.00,2040,4610.00,2300.00,5.00,30.00,258.00,1.50,******,37.00,******,25.90,
63.00,2045,4630.00,2300.00,5.00,30.00,258.00,1.50,******,37.00,******,26.00,
64.00,2050,4610.00,2310.00,5.00,30.00,258.00,1.50,******,37.00,******,25.90,
65.00,2055,4610.00,2300.00,5.00,30.00,258.00,1.50,******,37.00,******,25.90,
66.00,2060,4630.00,2300.00,5.00,30.00,258.00,1.50,******,37.00,******,26.00,
67.00,2065,4620.00,2310.00,5.00,30.00,258.00,1.50,******,37.00,******,26.00,
68.00,2070,4600.00,2300.00,5.00,30.00,257.00,1.50,******,37.00,******,25.90,
69.00,2075,4610.00,2290.00,5.00,30.00,258.00,1.50,******,37.00,******,25.90,
70.00,2080,4610.00,2310.00,5.00,30.00,258.00,1.50,******,37.00,******,25.90,
71.00,2085,4610.00,2310.00,5.00,30.00,258.00,1.50,******,37.00,******,25.90,
72.00,2090,4600.00,2310.00,5.00,30.00,258.00,1.50,******,37.00,******,25.90,
73.00,2095,4600.00,2310.00,5.00,30.00,257.00,1.50,******,37.00,******,25.90,
74.00,2100,4630.00,2310.00,5.00,30.00,258.00,1.50,******,37.00,******,26.00,
75.00,2105,4610.00,2310.00,5.00,30.00,258.00,1.50,******,37.00,******,25.90,
76.00,2110,4610.00,2310.00,5.00,30.00,258.00,1.50,******,37.00,******,25.90,
77.00,2115,4610.00,2310.00,5.00,30.00,258.00,1.50,******,37.00,******,25.90,
78.00,2120,4610.00,2310.00,5.00,30.00,258.00,1.50,******,37.00,******,25.90,
79.00,2125,4600.00,2290.00,5.00,30.00,257.00,1.50,******,37.00,******,25.90,
80.00,2130,4600.00,2310.00,5.00,30.00,258.00,1.50,******,37.00,******,25.90,
,,,,,,,,,,,,
Interval:,,,4.00,,,,,,,,,
Number of Data Points:,,,113.00,,,,,,,,,
,,,,,,,,,,,,
Time Setting:,,,113 Meas. Pts.,,,,,,,,,
,,,Meas. Pt. Duration 5 s,,,,,,,,,
Measuring Profile:,,,,,,,,,,,,
#NAME?,,,Amplitude gamma = 0.1 ... 500 % log; |Slope| = 30.278699 Pt. / dec ,,,,,,,,,
,,,Angular Frequency omega = 30 rad/s,,,,,,,,,
,,,,,,,,,,,,
Meas. Pts.,Time,Storage Modulus,Loss Modulus,Strain,Angular Frequency,Shear Stress,Shear Rate,Viscosity,Temperature,Speed,Torque,Status
,[s],[Pa],[Pa],[%],[rad/s],[Pa],[1/s],[Pa·s],[°C],[1/min],[µNm],[]
1.00,2135,5320.00,2810.00,0.10,30.00,5.99,0.03,******,37.00,******,0.60,WMa
2.00,2140,8050.00,14400.00,0.11,30.00,18.00,0.03,******,37.00,******,1.81,WMa
3.00,2145,4340.00,0.00,0.12,30.00,5.07,0.04,******,37.00,******,0.51,"MV-,WMa"
4.00,2150,6720.00,0.00,0.13,30.00,8.48,0.04,******,37.00,******,0.85,"MV-,WMa"
5.00,2155,17800.00,0.00,0.14,30.00,24.30,0.04,******,37.00,******,2.44,"ME-,WMa"
6.00,2160,28000.00,11300.00,0.15,30.00,45.30,0.05,******,37.00,******,4.55,WMa
7.00,2165,6370.00,4880.00,0.16,30.00,12.90,0.05,******,37.00,******,1.30,WMa
8.00,2170,0.00,12200.00,0.17,30.00,20.80,0.05,******,37.00,******,2.09,"MV-,WMa"
9.00,2175,309.00,5280.00,0.18,30.00,9.56,0.05,******,37.00,******,0.96,WMa
10.00,2180,5510.00,2370.00,0.20,30.00,11.90,0.06,******,37.00,******,1.19,
11.00,2185,3580.00,12500.00,0.22,30.00,27.90,0.06,******,37.00,******,2.80,"ME-,MV-"
12.00,2190,5370.00,2450.00,0.23,30.00,13.60,0.07,******,37.00,******,1.37,
13.00,2195,41000.00,0.00,0.25,30.00,103.00,0.08,******,37.00,******,10.40,"MV-,WMa"
14.00,2200,20600.00,9170.00,0.28,30.00,62.90,0.08,******,37.00,******,6.33,WMa
15.00,2205,0.00,4140.00,0.30,30.00,12.20,0.09,******,37.00,******,1.23,"MV-,WMa"
16.00,2210,5280.00,2310.00,0.31,30.00,18.00,0.09,******,37.00,******,1.81,
17.00,2215,10000.00,356.00,0.34,30.00,34.00,0.10,******,37.00,******,3.42,WMa
18.00,2220,11300.00,5910.00,0.37,30.00,46.60,0.11,******,37.00,******,4.68,WMa
19.00,2225,5300.00,2880.00,0.40,30.00,23.90,0.12,******,37.00,******,2.40,WMa
20.00,2230,447.00,12200.00,0.43,30.00,51.60,0.13,******,37.00,******,5.19,WMa
21.00,2235,0.00,4630.00,0.46,30.00,21.20,0.14,******,37.00,******,2.13,"ME-,WMa"
22.00,2240,4740.00,2300.00,0.49,30.00,26.00,0.15,******,37.00,******,2.62,
23.00,2245,5720.00,6970.00,0.53,30.00,48.20,0.16,******,37.00,******,4.84,WMa
24.00,2250,3800.00,3240.00,0.58,30.00,28.80,0.17,******,37.00,******,2.90,WMa
25.00,2255,6360.00,1720.00,0.62,30.00,40.90,0.19,******,37.00,******,4.11,WMa
26.00,2260,6280.00,3710.00,0.67,30.00,48.90,0.20,******,37.00,******,4.91,WMa
27.00,2265,4240.00,1430.00,0.73,30.00,32.40,0.22,******,37.00,******,3.26,WMa
28.00,2270,2540.00,5410.00,0.78,30.00,46.50,0.23,******,37.00,******,4.68,WMa
29.00,2275,4320.00,2340.00,0.84,30.00,41.40,0.25,******,37.00,******,4.16,
30.00,2280,10300.00,6270.00,0.91,30.00,110.00,0.27,******,37.00,******,11.00,WMa
31.00,2285,4860.00,4730.00,0.98,30.00,66.60,0.30,******,37.00,******,6.70,WMa
32.00,2290,2830.00,4690.00,1.06,30.00,57.90,0.32,******,37.00,******,5.82,WMa
33.00,2295,4540.00,2290.00,1.14,30.00,58.00,0.34,******,37.00,******,5.83,
34.00,2300,352.00,698.00,1.23,30.00,9.61,0.37,******,37.00,******,0.97,"ME-,MV-"
35.00,2305,4680.00,2320.00,1.33,30.00,69.30,0.40,******,37.00,******,6.97,
36.00,2310,6780.00,0.00,1.43,30.00,97.20,0.43,******,37.00,******,9.77,"MV-,WMa"
37.00,2315,8490.00,1630.00,1.55,30.00,134.00,0.46,******,37.00,******,13.50,WMa
38.00,2320,4920.00,2560.00,1.67,30.00,92.70,0.50,******,37.00,******,9.32,WMa
39.00,2325,4490.00,1330.00,1.80,30.00,84.30,0.54,******,37.00,******,8.48,WMa
40.00,2330,6180.00,206.00,1.94,30.00,120.00,0.58,******,37.00,******,12.10,WMa
41.00,2335,3210.00,2530.00,2.10,30.00,85.70,0.63,******,37.00,******,8.62,WMa
42.00,2340,4590.00,2310.00,2.26,30.00,116.00,0.68,******,37.00,******,11.70,
43.00,2345,4690.00,2370.00,2.44,30.00,128.00,0.73,******,37.00,******,12.90,WMa
44.00,2350,4810.00,1980.00,2.64,30.00,137.00,0.79,******,37.00,******,13.80,WMa
45.00,2355,7090.00,2070.00,2.84,30.00,210.00,0.85,******,37.00,******,21.10,WMa
46.00,2360,5310.00,2790.00,3.07,30.00,184.00,0.92,******,37.00,******,18.50,WMa
47.00,2365,4730.00,2680.00,3.31,30.00,180.00,0.99,******,37.00,******,18.10,WMa
48.00,2370,4980.00,1940.00,3.57,30.00,191.00,1.07,******,37.00,******,19.20,WMa
49.00,2375,2410.00,2450.00,3.85,30.00,132.00,1.15,******,37.00,******,13.30,WMa
50.00,2380,4690.00,2300.00,4.15,30.00,217.00,1.25,******,37.00,******,21.80,
51.00,2385,4720.00,2570.00,4.48,30.00,241.00,1.35,******,37.00,******,24.20,WMa
52.00,2390,5380.00,1600.00,4.84,30.00,272.00,1.45,******,37.00,******,27.30,WMa
53.00,2395,3910.00,2240.00,5.23,30.00,236.00,1.57,******,37.00,******,23.70,WMa
54.00,2400,4700.00,2250.00,5.64,30.00,293.00,1.69,******,37.00,******,29.50,WMa
55.00,2405,4660.00,2900.00,6.08,30.00,334.00,1.82,******,37.00,******,33.60,WMa
56.00,2410,4320.00,2560.00,6.56,30.00,329.00,1.97,******,37.00,******,33.10,WMa
57.00,2415,5110.00,2350.00,7.08,30.00,398.00,2.12,******,37.00,******,40.00,WMa
58.00,2420,4290.00,1980.00,7.64,30.00,361.00,2.29,******,37.00,******,36.30,WMa
59.00,2425,4570.00,2120.00,8.24,30.00,415.00,2.47,******,37.00,******,41.70,WMa
60.00,2430,4480.00,2380.00,8.89,30.00,451.00,2.67,******,37.00,******,45.40,WMa
61.00,2435,4530.00,2300.00,9.59,30.00,488.00,2.88,******,37.00,******,49.10,WMa
62.00,2440,4200.00,1830.00,10.40,30.00,474.00,3.11,******,37.00,******,47.70,WMa
63.00,2445,4520.00,2950.00,11.20,30.00,603.00,3.35,******,37.00,******,60.60,WMa
64.00,2450,4600.00,2320.00,12.10,30.00,621.00,3.62,******,37.00,******,62.50,WMa
65.00,2455,3920.00,2230.00,13.00,30.00,586.00,3.90,******,37.00,******,58.90,WMa
66.00,2460,4720.00,2430.00,14.00,30.00,745.00,4.21,******,37.00,******,74.90,WMa
67.00,2465,4610.00,2260.00,15.10,30.00,777.00,4.54,******,37.00,******,78.10,WMa
68.00,2470,4630.00,2280.00,16.30,30.00,842.00,4.90,******,37.00,******,84.70,WMa
69.00,2475,3960.00,2200.00,17.60,30.00,798.00,5.29,******,37.00,******,80.30,WMa
70.00,2480,4710.00,2450.00,19.00,30.00,1010.00,5.71,******,37.00,******,102.00,WMa
71.00,2485,4630.00,2280.00,20.50,30.00,1060.00,6.16,******,37.00,******,106.00,WMa
72.00,2490,3680.00,2800.00,22.10,30.00,1020.00,6.64,******,37.00,******,103.00,WMa
73.00,2495,3600.00,2070.00,23.90,30.00,993.00,7.17,******,37.00,******,99.90,WMa
74.00,2500,4500.00,2180.00,25.80,30.00,1290.00,7.73,******,37.00,******,130.00,WMa
75.00,2505,4570.00,2460.00,27.80,30.00,1440.00,8.34,******,37.00,******,145.00,WMa
76.00,2510,4540.00,2340.00,30.00,30.00,1530.00,9.00,******,37.00,******,154.00,WMa
77.00,2515,4630.00,2310.00,32.40,30.00,1680.00,9.72,******,37.00,******,169.00,WMa
78.00,2520,4680.00,2480.00,34.90,30.00,1850.00,10.50,******,37.00,******,186.00,WMa
79.00,2525,4690.00,1920.00,37.70,30.00,1910.00,11.30,******,37.00,******,192.00,WMa
80.00,2530,4480.00,2350.00,40.70,30.00,2060.00,12.20,******,37.00,******,207.00,WMa
81.00,2535,4360.00,2230.00,43.90,30.00,2150.00,13.20,******,37.00,******,216.00,WMa
82.00,2540,4630.00,2390.00,47.40,30.00,2470.00,14.20,******,37.00,******,248.00,WMa
83.00,2545,4670.00,2000.00,51.10,30.00,2600.00,15.30,******,37.00,******,261.00,WMa
84.00,2550,4510.00,2320.00,55.20,30.00,2800.00,16.50,******,37.00,******,281.00,WMa
85.00,2555,4400.00,2250.00,59.50,30.00,2940.00,17.90,******,37.00,******,296.00,WMa
86.00,2560,4510.00,2260.00,64.20,30.00,3240.00,19.30,******,37.00,******,326.00,WMa
87.00,2565,4380.00,2470.00,69.30,30.00,3480.00,20.80,******,37.00,******,350.00,WMa
88.00,2570,4360.00,2360.00,74.70,30.00,3710.00,22.40,******,37.00,******,373.00,WMa
89.00,2575,4240.00,2290.00,80.60,30.00,3880.00,24.20,******,37.00,******,391.00,WMa
90.00,2580,4300.00,2370.00,87.00,30.00,4270.00,26.10,******,37.00,******,429.00,WMa
91.00,2585,4100.00,2500.00,93.90,30.00,4510.00,28.20,******,37.00,******,453.00,WMa
92.00,2590,4400.00,2210.00,101.00,30.00,4990.00,30.40,******,37.00,******,502.00,WMa
93.00,2595,3530.00,2160.00,109.00,30.00,4530.00,32.80,******,37.00,******,455.00,WMa
94.00,2600,2500.00,1650.00,118.00,30.00,3530.00,35.40,******,37.00,******,354.00,
95.00,2605,1560.00,1100.00,127.00,30.00,2430.00,38.20,******,37.00,******,245.00,
96.00,2610,857.00,681.00,137.00,30.00,1500.00,41.20,******,37.00,******,151.00,
97.00,2615,392.00,397.00,148.00,30.00,826.00,44.40,******,37.00,******,83.10,
98.00,2620,257.00,310.00,160.00,30.00,643.00,47.90,******,37.00,******,64.70,
99.00,2625,154.00,227.00,172.00,30.00,474.00,51.70,******,37.00,******,47.60,
100.00,2630,92.10,183.00,186.00,30.00,381.00,55.80,******,37.00,******,38.30,
101.00,2635,64.40,166.00,201.00,30.00,358.00,60.20,******,37.00,******,36.00,
102.00,2640,32.30,144.00,217.00,30.00,320.00,65.00,******,37.00,******,32.20,
103.00,2645,18.90,121.00,234.00,30.00,286.00,70.10,******,37.00,******,28.80,
104.00,2650,7.71,109.00,252.00,30.00,275.00,75.70,******,37.00,******,27.70,
105.00,2655,0.00,98.90,272.00,30.00,269.00,81.60,******,37.00,******,27.10,"ME-,taD"
106.00,2660,0.00,92.00,294.00,30.00,270.00,88.10,******,37.00,******,27.20,"ME-,taD"
107.00,2665,0.00,104.00,317.00,30.00,331.00,95.00,******,37.00,******,33.30,"ME-,taD"
108.00,2670,0.00,116.00,342.00,30.00,396.00,103.00,******,37.00,******,39.80,"ME-,taD"
109.00,2675,0.00,136.00,369.00,30.00,503.00,111.00,******,37.00,******,50.60,"ME-,taD"
110.00,2680,0.00,154.00,398.00,30.00,612.00,119.00,******,37.00,******,61.50,"ME-,taD"
111.00,2685,0.00,183.00,429.00,30.00,784.00,129.00,******,37.00,******,78.90,"ME-,taD"
112.00,2690,0.00,189.00,463.00,30.00,877.00,139.00,******,37.00,******,88.20,"ME-,taD"
113.00,2695,0.00,185.00,500.00,30.00,924.00,150.00,******,37.00,******,92.90,"ME-,taD"
,,,,,,,,,,,,
Interval:,,,5.00,,,,,,,,,
Number of Data Points:,,,80.00,,,,,,,,,
,,,,,,,,,,,,
Time Setting:,,,80 Meas. Pts.,,,,,,,,,
,,,Meas. Pt. Duration 5 s,,,,,,,,,
Event Control:,,,Standard Mode,,,,,,,,,
"  Terminate test, ...",,,...if M > 75 mNm,,,,,,,,,
Measuring Profile:,,,,,,,,,,,,
#NAME?,,,Amplitude gamma = 5 %,,,,,,,,,
,,,Angular Frequency omega = 30 rad/s,,,,,,,,,
,,,,,,,,,,,,
Meas. Pts.,Time,Storage Modulus,Loss Modulus,Strain,Angular Frequency,Shear Stress,Shear Rate,Viscosity,Temperature,Speed,Torque,Status
,[s],[Pa],[Pa],[%],[rad/s],[Pa],[1/s],[Pa·s],[°C],[1/min],[µNm],[]
1.00,2700,732.00,309.00,5.07,30.00,40.30,1.52,******,37.00,******,4.05,WMa
2.00,2705,902.00,418.00,5.00,30.00,49.70,1.50,******,37.00,******,5.00,
3.00,2710,1310.00,607.00,5.00,30.00,72.10,1.50,******,37.00,******,7.25,
4.00,2715,1580.00,724.00,5.00,30.00,86.80,1.50,******,37.00,******,8.72,
5.00,2720,1870.00,854.00,5.00,30.00,103.00,1.50,******,37.00,******,10.30,
6.00,2725,2140.00,995.00,5.00,30.00,118.00,1.50,******,37.00,******,11.90,
7.00,2730,2380.00,1120.00,5.00,30.00,131.00,1.50,******,37.00,******,13.20,
8.00,2735,2680.00,1270.00,5.00,30.00,148.00,1.50,******,37.00,******,14.90,
9.00,2740,2890.00,1370.00,5.00,30.00,160.00,1.50,******,37.00,******,16.10,
10.00,2745,3100.00,1460.00,5.00,30.00,171.00,1.50,******,37.00,******,17.20,
11.00,2750,3280.00,1560.00,5.00,30.00,182.00,1.50,******,37.00,******,18.30,
12.00,2755,3440.00,1630.00,5.00,30.00,190.00,1.50,******,37.00,******,19.10,
13.00,2760,3650.00,1730.00,5.00,30.00,202.00,1.50,******,37.00,******,20.30,
14.00,2765,3780.00,1800.00,5.00,30.00,209.00,1.50,******,37.00,******,21.10,
15.00,2770,3930.00,1850.00,5.00,30.00,217.00,1.50,******,37.00,******,21.90,
16.00,2775,4050.00,1930.00,5.00,30.00,224.00,1.50,******,37.00,******,22.60,
17.00,2780,4150.00,1980.00,5.00,30.00,230.00,1.50,******,37.00,******,23.10,
18.00,2785,4270.00,2040.00,5.00,30.00,237.00,1.50,******,37.00,******,23.80,
19.00,2790,4340.00,2070.00,5.00,30.00,240.00,1.50,******,37.00,******,24.20,
20.00,2795,4400.00,2100.00,5.00,30.00,244.00,1.50,******,37.00,******,24.50,
21.00,2800,4470.00,2130.00,5.00,30.00,248.00,1.50,******,37.00,******,24.90,
22.00,2805,4500.00,2150.00,5.00,30.00,249.00,1.50,******,37.00,******,25.10,
23.00,2810,4540.00,2160.00,5.00,30.00,252.00,1.50,******,37.00,******,25.30,
24.00,2815,4580.00,2180.00,5.00,30.00,254.00,1.50,******,37.00,******,25.50,
25.00,2820,4590.00,2190.00,5.00,30.00,254.00,1.50,******,37.00,******,25.60,
26.00,2825,4610.00,2210.00,5.00,30.00,256.00,1.50,******,37.00,******,25.70,
27.00,2830,4620.00,2200.00,5.00,30.00,256.00,1.50,******,37.00,******,25.70,
28.00,2835,4630.00,2200.00,5.00,30.00,256.00,1.50,******,37.00,******,25.80,
29.00,2840,4650.00,2210.00,5.00,30.00,258.00,1.50,******,37.00,******,25.90,
30.00,2845,4650.00,2230.00,5.00,30.00,258.00,1.50,******,37.00,******,25.90,
31.00,2850,4670.00,2230.00,5.00,30.00,259.00,1.50,******,37.00,******,26.00,
32.00,2855,4680.00,2240.00,5.00,30.00,259.00,1.50,******,37.00,******,26.10,
33.00,2860,4690.00,2240.00,5.00,30.00,260.00,1.50,******,37.00,******,26.10,
34.00,2865,4710.00,2240.00,5.00,30.00,261.00,1.50,******,37.00,******,26.20,
35.00,2870,4710.00,2250.00,5.00,30.00,261.00,1.50,******,37.00,******,26.20,
36.00,2875,4720.00,2250.00,5.00,30.00,261.00,1.50,******,37.00,******,26.30,
37.00,2880,4720.00,2250.00,5.00,30.00,261.00,1.50,******,37.00,******,26.30,
38.00,2885,4730.00,2260.00,5.00,30.00,262.00,1.50,******,37.00,******,26.30,
39.00,2890,4740.00,2260.00,5.00,30.00,262.00,1.50,******,37.00,******,26.40,
40.00,2895,4740.00,2260.00,5.00,30.00,262.00,1.50,******,37.00,******,26.40,
41.00,2900,4740.00,2260.00,5.00,30.00,263.00,1.50,******,37.00,******,26.40,
42.00,2905,4750.00,2260.00,5.00,30.00,263.00,1.50,******,37.00,******,26.40,
43.00,2910,4750.00,2270.00,5.00,30.00,263.00,1.50,******,37.00,******,26.40,
44.00,2915,4740.00,2270.00,5.00,30.00,263.00,1.50,******,37.00,******,26.40,
45.00,2920,4750.00,2270.00,5.00,30.00,263.00,1.50,******,37.00,******,26.50,
46.00,2925,4770.00,2280.00,5.00,30.00,265.00,1.50,******,37.00,******,26.60,
47.00,2930,4770.00,2270.00,5.00,30.00,264.00,1.50,******,37.00,******,26.60,
48.00,2935,4760.00,2270.00,5.00,30.00,264.00,1.50,******,37.00,******,26.50,
49.00,2940,4770.00,2280.00,5.00,30.00,264.00,1.50,******,37.00,******,26.60,
50.00,2945,4770.00,2280.00,5.00,30.00,264.00,1.50,******,37.00,******,26.60,
51.00,2950,4770.00,2280.00,5.00,30.00,264.00,1.50,******,37.00,******,26.60,
52.00,2955,4780.00,2280.00,5.00,30.00,265.00,1.50,******,37.00,******,26.70,
53.00,2960,4780.00,2270.00,5.00,30.00,265.00,1.50,******,37.00,******,26.60,
54.00,2965,4790.00,2280.00,5.00,30.00,265.00,1.50,******,37.00,******,26.70,
55.00,2970,4790.00,2280.00,5.00,30.00,265.00,1.50,******,37.00,******,26.70,
56.00,2975,4790.00,2280.00,5.00,30.00,265.00,1.50,******,37.00,******,26.70,
57.00,2980,4790.00,2300.00,5.00,30.00,265.00,1.50,******,37.00,******,26.70,
58.00,2985,4810.00,2290.00,5.00,30.00,266.00,1.50,******,37.00,******,26.80,
59.00,2990,4820.00,2290.00,5.00,30.00,267.00,1.50,******,37.00,******,26.80,
60.00,2995,4800.00,2290.00,5.00,30.00,266.00,1.50,******,37.00,******,26.70,
61.00,3000,4790.00,2290.00,5.00,30.00,266.00,1.50,******,37.00,******,26.70,
62.00,3005,4800.00,2290.00,5.00,30.00,266.00,1.50,******,37.00,******,26.70,
63.00,3010,4810.00,2300.00,5.00,30.00,266.00,1.50,******,37.00,******,26.80,
64.00,3015,4810.00,2300.00,5.00,30.00,267.00,1.50,******,37.00,******,26.80,
65.00,3020,4800.00,2300.00,5.00,30.00,266.00,1.50,******,37.00,******,26.80,
66.00,3025,4800.00,2270.00,5.00,30.00,265.00,1.50,******,37.00,******,26.70,
67.00,3030,4810.00,2280.00,5.00,30.00,266.00,1.50,******,37.00,******,26.80,
68.00,3035,4810.00,2300.00,5.00,30.00,266.00,1.50,******,37.00,******,26.80,
69.00,3040,4810.00,2300.00,5.00,30.00,266.00,1.50,******,37.00,******,26.80,
70.00,3045,4840.00,2310.00,5.00,30.00,268.00,1.50,******,37.00,******,27.00,
71.00,3050,4820.00,2300.00,5.00,30.00,267.00,1.50,******,37.00,******,26.80,
72.00,3055,4820.00,2300.00,5.00,30.00,267.00,1.50,******,37.00,******,26.80,
73.00,3060,4820.00,2300.00,5.00,30.00,267.00,1.50,******,37.00,******,26.90,
74.00,3065,4820.00,2310.00,5.00,30.00,267.00,1.50,******,37.00,******,26.90,
75.00,3070,4820.00,2310.00,5.00,30.00,267.00,1.50,******,37.00,******,26.90,
76.00,3075,4810.00,2300.00,5.00,30.00,267.00,1.50,******,37.00,******,26.80,
77.00,3080,4820.00,2300.00,5.00,30.00,267.00,1.50,******,37.00,******,26.90,
78.00,3085,4830.00,2300.00,5.00,30.00,267.00,1.50,******,37.00,******,26.90,
79.00,3090,4830.00,2300.00,5.00,30.00,268.00,1.50,******,37.00,******,26.90,
80.00,3095,4840.00,2320.00,5.00,30.00,268.00,1.50,******,37.00,******,27.00,
,,,,,,,,,,,,
Interval:,,,6.00,,,,,,,,,
Number of Data Points:,,,600.00,,,,,,,,,
,,,,,,,,,,,,
Time Setting:,,,600 Meas. Pts.,,,,,,,,,
,,,Meas. Pt. Duration 3 s,,,,,,,,,
Event Control:,,,Standard Mode,,,,,,,,,
"  Terminate test, ...",,,...if M > 200 mNm,,,,,,,,,
Measuring Profile:,,,,,,,,,,,,
#NAME?,,,Amplitude gamma = 5 %,,,,,,,,,
,,,Angular Frequency omega = 30 rad/s,,,,,,,,,
,,,,,,,,,,,,
Meas. Pts.,Time,Storage Modulus,Loss Modulus,Strain,Angular Frequency,Shear Stress,Shear Rate,Viscosity,Temperature,Speed,Torque,Status
,[s],[Pa],[Pa],[%],[rad/s],[Pa],[1/s],[Pa·s],[°C],[1/min],[µNm],[]
1.00,3098,4900.00,2320.00,5.04,30.00,273.00,1.51,******,37.00,******,27.40,WMa
2.00,3101,4870.00,2300.00,5.00,30.00,269.00,1.50,******,37.00,******,27.10,WMa
3.00,3104,4880.00,2300.00,5.00,30.00,270.00,1.50,******,37.00,******,27.10,WMa
4.00,3107,4870.00,2310.00,5.00,30.00,269.00,1.50,******,37.00,******,27.10,
5.00,3110,4870.00,2300.00,5.00,30.00,269.00,1.50,******,37.00,******,27.10,
6.00,3113,4880.00,2310.00,5.00,30.00,270.00,1.50,******,37.00,******,27.10,
7.00,3116,4880.00,2310.00,5.00,30.00,270.00,1.50,******,37.00,******,27.10,
8.00,3119,4880.00,2300.00,5.00,30.00,270.00,1.50,******,37.00,******,27.10,
9.00,3122,4870.00,2300.00,5.00,30.00,269.00,1.50,******,37.00,******,27.10,
10.00,3125,4910.00,2320.00,5.00,30.00,272.00,1.50,******,37.00,******,27.30,
11.00,3128,4900.00,2310.00,5.00,30.00,271.00,1.50,******,37.00,******,27.30,
12.00,3131,4880.00,2290.00,5.00,30.00,269.00,1.50,******,37.00,******,27.10,
13.00,3134,4890.00,2300.00,5.00,30.00,270.00,1.50,******,37.00,******,27.20,
14.00,3137,4880.00,2310.00,5.00,30.00,270.00,1.50,******,37.00,******,27.10,
15.00,3140,4880.00,2310.00,5.00,30.00,270.00,1.50,******,37.00,******,27.10,
16.00,3143,4890.00,2300.00,5.00,30.00,270.00,1.50,******,37.00,******,27.20,
17.00,3146,4900.00,2310.00,5.00,30.00,271.00,1.50,******,37.00,******,27.20,
18.00,3149,4870.00,2300.00,5.00,30.00,270.00,1.50,******,37.00,******,27.10,
19.00,3152,4890.00,2310.00,5.00,30.00,270.00,1.50,******,37.00,******,27.20,
20.00,3155,4910.00,2330.00,5.00,30.00,272.00,1.50,******,37.00,******,27.30,
21.00,3158,4900.00,2340.00,5.00,30.00,271.00,1.50,******,37.00,******,27.30,
22.00,3161,4880.00,2300.00,5.00,30.00,269.00,1.50,******,37.00,******,27.10,
23.00,3164,4870.00,2300.00,5.00,30.00,269.00,1.50,******,37.00,******,27.10,
24.00,3167,4880.00,2310.00,5.00,30.00,270.00,1.50,******,37.00,******,27.20,
25.00,3170,4870.00,2320.00,5.00,30.00,269.00,1.50,******,37.00,******,27.10,
26.00,3173,4900.00,2310.00,5.00,30.00,271.00,1.50,******,37.00,******,27.20,
27.00,3176,4880.00,2290.00,5.00,30.00,269.00,1.50,******,37.00,******,27.10,
28.00,3179,4890.00,2310.00,5.00,30.00,270.00,1.50,******,37.00,******,27.20,
29.00,3182,4890.00,2310.00,5.00,30.00,270.00,1.50,******,37.00,******,27.20,
30.00,3185,4890.00,2310.00,5.00,30.00,270.00,1.50,******,37.00,******,27.20,
31.00,3188,4870.00,2320.00,5.00,30.00,270.00,1.50,******,37.00,******,27.10,
32.00,3191,4900.00,2330.00,5.00,30.00,271.00,1.50,******,37.00,******,27.30,
33.00,3194,4890.00,2340.00,5.00,30.00,271.00,1.50,******,37.00,******,27.30,
34.00,3197,4890.00,2300.00,5.00,30.00,270.00,1.50,******,37.00,******,27.20,
35.00,3200,4890.00,2330.00,5.00,30.00,271.00,1.50,******,37.00,******,27.20,
36.00,3203,4890.00,2320.00,5.00,30.00,271.00,1.50,******,37.00,******,27.20,
37.00,3206,4880.00,2310.00,5.00,30.00,270.00,1.50,******,37.00,******,27.10,
38.00,3209,4890.00,2310.00,5.00,30.00,271.00,1.50,******,37.00,******,27.20,
39.00,3212,4900.00,2280.00,5.00,30.00,270.00,1.50,******,37.00,******,27.20,
40.00,3215,4910.00,2320.00,5.00,30.00,272.00,1.50,******,37.00,******,27.30,
41.00,3218,4890.00,2300.00,5.00,30.00,270.00,1.50,******,37.00,******,27.20,
42.00,3221,4890.00,2310.00,5.00,30.00,270.00,1.50,******,37.00,******,27.20,
43.00,3224,4890.00,2320.00,5.00,30.00,271.00,1.50,******,37.00,******,27.20,
44.00,3227,4900.00,2320.00,5.00,30.00,271.00,1.50,******,37.00,******,27.30,
45.00,3230,4890.00,2330.00,5.00,30.00,271.00,1.50,******,37.00,******,27.20,
46.00,3233,4890.00,2310.00,5.00,30.00,271.00,1.50,******,37.00,******,27.20,
47.00,3236,4920.00,2300.00,5.00,30.00,272.00,1.50,******,37.00,******,27.30,
48.00,3239,4900.00,2310.00,5.00,30.00,271.00,1.50,******,37.00,******,27.20,
49.00,3242,4870.00,2310.00,5.00,30.00,270.00,1.50,******,37.00,******,27.10,
50.00,3245,4870.00,2320.00,5.00,30.00,270.00,1.50,******,37.00,******,27.10,
51.00,3248,4910.00,2330.00,5.00,30.00,272.00,1.50,******,37.00,******,27.30,
52.00,3251,4900.00,2320.00,5.00,30.00,271.00,1.50,******,37.00,******,27.20,
53.00,3254,4900.00,2310.00,5.00,30.00,271.00,1.50,******,37.00,******,27.20,
54.00,3257,4900.00,2310.00,5.00,30.00,271.00,1.50,******,37.00,******,27.20,
55.00,3260,4890.00,2330.00,5.00,30.00,271.00,1.50,******,37.00,******,27.20,
56.00,3263,4880.00,2320.00,5.00,30.00,270.00,1.50,******,37.00,******,27.20,
57.00,3266,4930.00,2290.00,5.00,30.00,272.00,1.50,******,37.00,******,27.30,
58.00,3269,4910.00,2300.00,5.00,30.00,271.00,1.50,******,37.00,******,27.30,
59.00,3272,4900.00,2320.00,5.00,30.00,271.00,1.50,******,37.00,******,27.20,
60.00,3275,4870.00,2280.00,5.00,30.00,269.00,1.50,******,37.00,******,27.00,
61.00,3278,4890.00,2310.00,5.00,30.00,271.00,1.50,******,37.00,******,27.20,
62.00,3281,4920.00,2320.00,5.00,30.00,272.00,1.50,******,37.00,******,27.40,
63.00,3284,4910.00,2340.00,5.00,30.00,272.00,1.50,******,37.00,******,27.30,
64.00,3287,4890.00,2340.00,5.00,30.00,271.00,1.50,******,37.00,******,27.30,
65.00,3290,4900.00,2310.00,5.00,30.00,271.00,1.50,******,37.00,******,27.20,
66.00,3293,4900.00,2310.00,5.00,30.00,271.00,1.50,******,37.00,******,27.30,
67.00,3296,4880.00,2320.00,5.00,30.00,270.00,1.50,******,37.00,******,27.20,
68.00,3299,4890.00,2310.00,5.00,30.00,271.00,1.50,******,37.00,******,27.20,
69.00,3302,4880.00,2330.00,5.00,30.00,270.00,1.50,******,37.00,******,27.20,
70.00,3305,4900.00,2320.00,5.00,30.00,271.00,1.50,******,37.00,******,27.30,
71.00,3308,4920.00,2330.00,5.00,30.00,272.00,1.50,******,37.00,******,27.40,
72.00,3311,4910.00,2340.00,5.00,30.00,272.00,1.50,******,37.00,******,27.30,
73.00,3314,4900.00,2310.00,5.00,30.00,271.00,1.50,******,37.00,******,27.20,
74.00,3317,4890.00,2300.00,5.00,30.00,270.00,1.50,******,37.00,******,27.20,
75.00,3320,4900.00,2340.00,5.00,30.00,271.00,1.50,******,37.00,******,27.30,
76.00,3323,4900.00,2320.00,5.00,30.00,271.00,1.50,******,37.00,******,27.20,
77.00,3326,4900.00,2330.00,5.00,30.00,271.00,1.50,******,37.00,******,27.30,
78.00,3329,4910.00,2290.00,5.00,30.00,271.00,1.50,******,37.00,******,27.20,
79.00,3332,4910.00,2320.00,5.00,30.00,271.00,1.50,******,37.00,******,27.30,
80.00,3335,4900.00,2320.00,5.00,30.00,271.00,1.50,******,37.00,******,27.30,
81.00,3338,4880.00,2320.00,5.00,30.00,270.00,1.50,******,37.00,******,27.20,
82.00,3341,4900.00,2320.00,5.00,30.00,271.00,1.50,******,37.00,******,27.30,
83.00,3344,4910.00,2320.00,5.00,30.00,272.00,1.50,******,37.00,******,27.30,
84.00,3347,4920.00,2320.00,5.00,30.00,272.00,1.50,******,37.00,******,27.30,
85.00,3350,4910.00,2320.00,5.00,30.00,272.00,1.50,******,37.00,******,27.30,
86.00,3353,4920.00,2320.00,5.00,30.00,272.00,1.50,******,37.00,******,27.40,
87.00,3356,4910.00,2310.00,5.00,30.00,271.00,1.50,******,37.00,******,27.30,
88.00,3359,4940.00,2310.00,5.00,30.00,273.00,1.50,******,37.00,******,27.40,
89.00,3362,4900.00,2330.00,5.00,30.00,271.00,1.50,******,37.00,******,27.30,
90.00,3365,4920.00,2330.00,5.00,30.00,272.00,1.50,******,37.00,******,27.40,
91.00,3368,4920.00,2310.00,5.00,30.00,272.00,1.50,******,37.00,******,27.30,
92.00,3371,4910.00,2330.00,5.00,30.00,272.00,1.50,******,37.00,******,27.30,
93.00,3374,4900.00,2320.00,5.00,30.00,271.00,1.50,******,37.00,******,27.30,
94.00,3377,4940.00,2320.00,5.00,30.00,273.00,1.50,******,37.00,******,27.40,
95.00,3380,4910.00,2330.00,5.00,30.00,272.00,1.50,******,37.00,******,27.30,
96.00,3383,4900.00,2330.00,5.00,30.00,271.00,1.50,******,37.00,******,27.30,
97.00,3386,4920.00,2310.00,5.00,30.00,272.00,1.50,******,37.00,******,27.30,
98.00,3389,4920.00,2340.00,5.00,30.00,272.00,1.50,******,37.00,******,27.40,
99.00,3392,4900.00,2340.00,5.00,30.00,271.00,1.50,******,37.00,******,27.30,
100.00,3395,4900.00,2320.00,5.00,30.00,271.00,1.50,******,37.00,******,27.20,
101.00,3398,4900.00,2330.00,5.00,30.00,271.00,1.50,******,37.00,******,27.30,
102.00,3401,4910.00,2320.00,5.00,30.00,272.00,1.50,******,37.00,******,27.30,
103.00,3404,4920.00,2310.00,5.00,30.00,272.00,1.50,******,37.00,******,27.30,
104.00,3407,4910.00,2300.00,5.00,30.00,271.00,1.50,******,37.00,******,27.30,
105.00,3410,4930.00,2340.00,5.00,30.00,273.00,1.50,******,37.00,******,27.40,
106.00,3413,4900.00,2350.00,5.00,30.00,271.00,1.50,******,37.00,******,27.30,
107.00,3416,4900.00,2330.00,5.00,30.00,271.00,1.50,******,37.00,******,27.30,
[...]
396.00,11723,5130.00,2440.00,5.00,30.00,284.00,1.50,******,37.00,******,28.60,WMa
397.00,11726,5140.00,2440.00,5.00,30.00,285.00,1.50,******,37.00,******,28.60,WMa
398.00,11729,5120.00,2450.00,5.00,30.00,284.00,1.50,******,37.00,******,28.50,WMa
399.00,11732,5120.00,2440.00,5.00,30.00,283.00,1.50,******,37.00,******,28.50,WMa
400.00,11735,5100.00,2430.00,5.00,30.00,282.00,1.50,******,37.00,******,28.40,WMa
401.00,11738,5130.00,2430.00,5.00,30.00,284.00,1.50,******,37.00,******,28.60,WMa
402.00,11741,5140.00,2430.00,5.00,30.00,284.00,1.50,******,37.00,******,28.60,WMa
403.00,11744,5120.00,2420.00,5.00,30.00,283.00,1.50,******,37.00,******,28.50,WMa
404.00,11747,5150.00,2450.00,5.00,30.00,285.00,1.50,******,37.00,******,28.70,WMa
405.00,11750,5130.00,2450.00,5.00,30.00,284.00,1.50,******,37.00,******,28.60,WMa
406.00,11753,5110.00,2450.00,5.00,30.00,283.00,1.50,******,37.00,******,28.50,WMa
407.00,11756,5110.00,2460.00,5.00,30.00,284.00,1.50,******,37.00,******,28.50,WMa
408.00,11759,5130.00,2440.00,5.00,30.00,284.00,1.50,******,37.00,******,28.60,WMa
409.00,11762,5130.00,2430.00,5.00,30.00,284.00,1.50,******,37.00,******,28.60,WMa
410.00,11765,5130.00,2430.00,5.00,30.00,284.00,1.50,******,37.00,******,28.50,WMa
411.00,11768,5130.00,2430.00,5.00,30.00,284.00,1.50,******,37.00,******,28.50,WMa
412.00,11771,5140.00,2450.00,5.00,30.00,285.00,1.50,******,37.00,******,28.60,WMa
413.00,11774,5140.00,2450.00,5.00,30.00,285.00,1.50,******,37.00,******,28.60,WMa
414.00,11777,5140.00,2430.00,5.00,30.00,284.00,1.50,******,37.00,******,28.60,WMa
415.00,11780,5140.00,2450.00,5.00,30.00,284.00,1.50,******,37.00,******,28.60,WMa
416.00,11783,5140.00,2450.00,5.00,30.00,284.00,1.50,******,37.00,******,28.60,WMa
417.00,11786,5140.00,2440.00,5.00,30.00,284.00,1.50,******,37.00,******,28.60,WMa
418.00,11789,5150.00,2460.00,5.00,30.00,285.00,1.50,******,37.00,******,28.70,WMa
419.00,11792,5150.00,2450.00,5.00,30.00,285.00,1.50,******,37.00,******,28.70,WMa
420.00,11795,5140.00,2440.00,5.00,30.00,285.00,1.50,******,37.00,******,28.60,WMa
421.00,11798,5130.00,2450.00,5.00,30.00,284.00,1.50,******,37.00,******,28.60,WMa
422.00,11801,5150.00,2410.00,5.00,30.00,285.00,1.50,******,37.00,******,28.60,WMa
423.00,11804,5130.00,2460.00,5.00,30.00,284.00,1.50,******,37.00,******,28.60,WMa
424.00,11807,5120.00,2460.00,5.00,30.00,284.00,1.50,******,37.00,******,28.50,WMa
425.00,11810,5110.00,2430.00,5.00,30.00,283.00,1.50,******,37.00,******,28.50,WMa
426.00,11813,5150.00,2440.00,5.00,30.00,285.00,1.50,******,37.00,******,28.70,WMa
427.00,11816,5180.00,2450.00,5.00,30.00,286.00,1.50,******,37.00,******,28.80,WMa
428.00,11819,5110.00,2460.00,5.00,30.00,284.00,1.50,******,37.00,******,28.50,WMa
429.00,11822,5140.00,2450.00,5.00,30.00,284.00,1.50,******,37.00,******,28.60,WMa
430.00,11825,5130.00,2430.00,5.00,30.00,284.00,1.50,******,37.00,******,28.50,WMa
431.00,11828,5140.00,2450.00,5.00,30.00,285.00,1.50,******,37.00,******,28.60,WMa
432.00,11831,5120.00,2430.00,5.00,30.00,283.00,1.50,******,37.00,******,28.50,WMa
433.00,11834,5150.00,2440.00,5.00,30.00,285.00,1.50,******,37.00,******,28.70,WMa
434.00,11837,5130.00,2440.00,5.00,30.00,284.00,1.50,******,37.00,******,28.60,WMa
435.00,11840,5120.00,2460.00,5.00,30.00,284.00,1.50,******,37.00,******,28.50,WMa
436.00,11843,5100.00,2450.00,5.00,30.00,283.00,1.50,******,37.00,******,28.50,WMa
437.00,11846,5140.00,2420.00,5.00,30.00,284.00,1.50,******,37.00,******,28.60,WMa
438.00,11849,5130.00,2440.00,5.00,30.00,284.00,1.50,******,37.00,******,28.60,WMa
439.00,11852,5130.00,2440.00,5.00,30.00,284.00,1.50,******,37.00,******,28.60,WMa
440.00,11855,5130.00,2440.00,5.00,30.00,284.00,1.50,******,37.00,******,28.60,WMa
441.00,11858,5170.00,2440.00,5.00,30.00,286.00,1.50,******,37.00,******,28.70,WMa
442.00,11861,5120.00,2450.00,5.00,30.00,284.00,1.50,******,37.00,******,28.50,WMa
443.00,11864,5130.00,2450.00,5.00,30.00,284.00,1.50,******,37.00,******,28.60,WMa
444.00,11867,5130.00,2470.00,5.00,30.00,285.00,1.50,******,37.00,******,28.60,WMa
445.00,11870,5130.00,2430.00,5.00,30.00,284.00,1.50,******,37.00,******,28.50,WMa
446.00,11873,5160.00,2460.00,5.00,30.00,286.00,1.50,******,37.00,******,28.70,WMa
447.00,11876,5140.00,2440.00,5.00,30.00,285.00,1.50,******,37.00,******,28.60,WMa
448.00,11879,5150.00,2440.00,5.00,30.00,285.00,1.50,******,37.00,******,28.70,WMa
449.00,11882,5160.00,2430.00,5.00,30.00,286.00,1.50,******,37.00,******,28.70,WMa
450.00,11885,5130.00,2460.00,5.00,30.00,284.00,1.50,******,37.00,******,28.60,WMa
451.00,11888,5140.00,2450.00,5.00,30.00,285.00,1.50,******,37.00,******,28.60,WMa
452.00,11891,5140.00,2430.00,5.00,30.00,284.00,1.50,******,37.00,******,28.60,WMa
453.00,11894,5160.00,2420.00,5.00,30.00,285.00,1.50,******,37.00,******,28.60,WMa
454.00,11897,5130.00,2450.00,5.00,30.00,284.00,1.50,******,37.00,******,28.60,WMa
455.00,11900,5120.00,2440.00,5.00,30.00,284.00,1.50,******,37.00,******,28.50,WMa
456.00,11903,5160.00,2440.00,5.00,30.00,285.00,1.50,******,37.00,******,28.70,WMa
457.00,11906,5150.00,2440.00,5.00,30.00,285.00,1.50,******,37.00,******,28.60,WMa
458.00,11909,5140.00,2430.00,5.00,30.00,284.00,1.50,******,37.00,******,28.60,WMa
459.00,11912,5150.00,2450.00,5.00,30.00,285.00,1.50,******,37.00,******,28.60,WMa
460.00,11915,5140.00,2450.00,5.00,30.00,285.00,1.50,******,37.00,******,28.60,WMa
461.00,11918,5130.00,2430.00,5.00,30.00,284.00,1.50,******,37.00,******,28.50,WMa
462.00,11921,5130.00,2440.00,5.00,30.00,284.00,1.50,******,37.00,******,28.60,WMa
463.00,11924,5150.00,2440.00,5.00,30.00,285.00,1.50,******,37.00,******,28.60,WMa
464.00,11927,5140.00,2450.00,5.00,30.00,285.00,1.50,******,37.00,******,28.60,WMa
465.00,11930,5120.00,2440.00,5.00,30.00,283.00,1.50,******,37.00,******,28.50,WMa
466.00,11933,5130.00,2430.00,5.00,30.00,284.00,1.50,******,37.00,******,28.60,WMa
467.00,11936,5140.00,2430.00,5.00,30.00,284.00,1.50,******,37.00,******,28.60,WMa
468.00,11939,5140.00,2440.00,5.00,30.00,284.00,1.50,******,37.00,******,28.60,WMa
469.00,11942,5160.00,2450.00,5.00,30.00,286.00,1.50,******,37.00,******,28.70,WMa
470.00,11945,5140.00,2450.00,5.00,30.00,284.00,1.50,******,37.00,******,28.60,WMa
471.00,11948,5140.00,2450.00,5.00,30.00,285.00,1.50,******,37.00,******,28.60,WMa
472.00,11951,5130.00,2480.00,5.00,30.00,285.00,1.50,******,37.00,******,28.60,WMa
473.00,11954,5140.00,2420.00,5.00,30.00,284.00,1.50,******,37.00,******,28.60,WMa
474.00,11957,5150.00,2440.00,5.00,30.00,285.00,1.50,******,37.00,******,28.60,WMa
475.00,11960,5160.00,2460.00,5.00,30.00,286.00,1.50,******,37.00,******,28.70,WMa
476.00,11963,5130.00,2440.00,5.00,30.00,284.00,1.50,******,37.00,******,28.50,WMa
477.00,11966,5150.00,2460.00,5.00,30.00,286.00,1.50,******,37.00,******,28.70,WMa
478.00,11969,5160.00,2440.00,5.00,30.00,285.00,1.50,******,37.00,******,28.70,WMa
479.00,11972,5150.00,2450.00,5.00,30.00,285.00,1.50,******,37.00,******,28.60,WMa
480.00,11975,5140.00,2460.00,5.00,30.00,285.00,1.50,******,37.00,******,28.60,WMa
481.00,11978,5150.00,2440.00,5.00,30.00,285.00,1.50,******,37.00,******,28.60,WMa
482.00,11981,5160.00,2460.00,5.00,30.00,286.00,1.50,******,37.00,******,28.80,"MV-,WMa"
483.00,11984,5170.00,2440.00,5.00,30.00,286.00,1.50,******,37.00,******,28.80,WMa
484.00,11987,5160.00,2450.00,5.00,30.00,286.00,1.50,******,37.00,******,28.70,WMa
485.00,11990,5140.00,2450.00,5.00,30.00,284.00,1.50,******,37.00,******,28.60,WMa
486.00,11993,5140.00,2450.00,5.00,30.00,285.00,1.50,******,37.00,******,28.60,WMa
487.00,11996,5150.00,2440.00,5.00,30.00,285.00,1.50,******,37.00,******,28.60,WMa
488.00,11999,5140.00,2430.00,5.00,30.00,284.00,1.50,******,37.00,******,28.60,WMa
489.00,12002,5160.00,2430.00,5.00,30.00,285.00,1.50,******,37.00,******,28.70,WMa
490.00,12005,5140.00,2450.00,5.00,30.00,284.00,1.50,******,37.00,******,28.60,WMa
491.00,12008,5120.00,2450.00,5.00,30.00,284.00,1.50,******,37.00,******,28.50,WMa
492.00,12011,5150.00,2440.00,5.00,30.00,285.00,1.50,******,37.00,******,28.70,WMa
493.00,12014,5140.00,2430.00,5.00,30.00,284.00,1.50,******,37.00,******,28.60,WMa
494.00,12017,5150.00,2440.00,5.00,30.00,285.00,1.50,******,37.00,******,28.60,WMa
495.00,12020,5140.00,2430.00,5.00,30.00,284.00,1.50,******,37.00,******,28.60,WMa
496.00,12023,5140.00,2430.00,5.00,30.00,284.00,1.50,******,37.00,******,28.60,"MV-,WMa"
497.00,12026,5160.00,2460.00,5.00,30.00,286.00,1.50,******,37.00,******,28.80,WMa
498.00,12029,5150.00,2450.00,5.00,30.00,285.00,1.50,******,37.00,******,28.70,WMa
499.00,12032,5150.00,2440.00,5.00,30.00,285.00,1.50,******,37.00,******,28.60,WMa
500.00,12035,5160.00,2440.00,5.00,30.00,285.00,1.50,******,37.00,******,28.70,WMa
501.00,12038,5150.00,2450.00,5.00,30.00,285.00,1.50,******,37.00,******,28.70,WMa
502.00,12041,5150.00,2480.00,5.00,30.00,286.00,1.50,******,37.00,******,28.70,WMa
503.00,12044,5140.00,2440.00,5.00,30.00,285.00,1.50,******,37.00,******,28.60,WMa
504.00,12047,5150.00,2440.00,5.00,30.00,285.00,1.50,******,37.00,******,28.60,WMa
505.00,12050,5140.00,2440.00,5.00,30.00,285.00,1.50,******,37.00,******,28.60,WMa
506.00,12053,5120.00,2450.00,5.00,30.00,284.00,1.50,******,37.00,******,28.50,WMa
507.00,12056,5150.00,2440.00,5.00,30.00,285.00,1.50,******,37.00,******,28.70,WMa
508.00,12059,5140.00,2450.00,5.00,30.00,285.00,1.50,******,37.00,******,28.60,WMa
509.00,12062,5140.00,2450.00,5.00,30.00,285.00,1.50,******,37.00,******,28.60,WMa
510.00,12065,5140.00,2430.00,5.00,30.00,284.00,1.50,******,37.00,******,28.60,WMa
511.00,12068,5150.00,2450.00,5.00,30.00,285.00,1.50,******,37.00,******,28.70,WMa
512.00,12071,5140.00,2440.00,5.00,30.00,284.00,1.50,******,37.00,******,28.60,WMa
513.00,12074,5140.00,2450.00,5.00,30.00,285.00,1.50,******,37.00,******,28.60,WMa
514.00,12077,5150.00,2440.00,5.00,30.00,285.00,1.50,******,37.00,******,28.70,WMa
515.00,12080,5150.00,2460.00,5.00,30.00,285.00,1.50,******,37.00,******,28.70,WMa
516.00,12083,5150.00,2470.00,5.00,30.00,286.00,1.50,******,37.00,******,28.70,WMa
517.00,12086,5120.00,2410.00,5.00,30.00,283.00,1.50,******,37.00,******,28.50,WMa
518.00,12089,5140.00,2450.00,5.00,30.00,285.00,1.50,******,37.00,******,28.60,WMa
519.00,12092,5160.00,2450.00,5.00,30.00,286.00,1.50,******,37.00,******,28.70,WMa
520.00,12095,5160.00,2440.00,5.00,30.00,285.00,1.50,******,37.00,******,28.70,WMa
521.00,12098,5140.00,2450.00,5.00,30.00,285.00,1.50,******,37.00,******,28.60,WMa
522.00,12101,5150.00,2420.00,5.00,30.00,285.00,1.50,******,37.00,******,28.60,WMa
523.00,12104,5150.00,2430.00,5.00,30.00,285.00,1.50,******,37.00,******,28.60,WMa
524.00,12107,5160.00,2460.00,5.00,30.00,286.00,1.50,******,37.00,******,28.70,WMa
525.00,12110,5140.00,2440.00,5.00,30.00,284.00,1.50,******,37.00,******,28.60,WMa
526.00,12113,5140.00,2440.00,5.00,30.00,285.00,1.50,******,37.00,******,28.60,WMa
527.00,12116,5150.00,2450.00,5.00,30.00,285.00,1.50,******,37.00,******,28.70,WMa
528.00,12119,5130.00,2460.00,5.00,30.00,284.00,1.50,******,37.00,******,28.60,WMa
529.00,12122,5160.00,2420.00,5.00,30.00,285.00,1.50,******,37.00,******,28.70,WMa
530.00,12125,5130.00,2460.00,5.00,30.00,284.00,1.50,******,37.00,******,28.60,WMa
531.00,12128,5150.00,2460.00,5.00,30.00,285.00,1.50,******,37.00,******,28.70,"MV-,WMa"
532.00,12131,5160.00,2450.00,5.00,30.00,286.00,1.50,******,37.00,******,28.70,WMa
533.00,12134,5130.00,2440.00,5.00,30.00,284.00,1.50,******,37.00,******,28.60,WMa
534.00,12137,5140.00,2450.00,5.00,30.00,285.00,1.50,******,37.00,******,28.60,WMa
535.00,12140,5170.00,2430.00,5.00,30.00,286.00,1.50,******,37.00,******,28.70,WMa
536.00,12143,5140.00,2450.00,5.00,30.00,285.00,1.50,******,37.00,******,28.60,WMa
537.00,12146,5150.00,2460.00,5.00,30.00,285.00,1.50,******,37.00,******,28.70,WMa
538.00,12149,5150.00,2470.00,5.00,30.00,286.00,1.50,******,37.00,******,28.70,WMa
539.00,12152,5150.00,2450.00,5.00,30.00,285.00,1.50,******,37.00,******,28.70,WMa
540.00,12155,5140.00,2440.00,5.00,30.00,284.00,1.50,******,37.00,******,28.60,WMa
541.00,12158,5140.00,2450.00,5.00,30.00,285.00,1.50,******,37.00,******,28.60,WMa
542.00,12161,5140.00,2450.00,5.00,30.00,285.00,1.50,******,37.00,******,28.60,WMa
543.00,12164,5150.00,2450.00,5.00,30.00,285.00,1.50,******,37.00,******,28.60,WMa
544.00,12167,5150.00,2440.00,5.00,30.00,285.00,1.50,******,37.00,******,28.60,WMa
545.00,12170,5140.00,2430.00,5.00,30.00,284.00,1.50,******,37.00,******,28.60,WMa
546.00,12173,5170.00,2460.00,5.00,30.00,286.00,1.50,******,37.00,******,28.80,WMa
547.00,12176,5150.00,2440.00,5.00,30.00,285.00,1.50,******,37.00,******,28.60,WMa
548.00,12179,5140.00,2450.00,5.00,30.00,285.00,1.50,******,37.00,******,28.60,WMa
549.00,12182,5130.00,2450.00,5.00,30.00,284.00,1.50,******,37.00,******,28.60,WMa
550.00,12185,5140.00,2460.00,5.00,30.00,285.00,1.50,******,37.00,******,28.60,WMa
551.00,12188,5160.00,2420.00,5.00,30.00,285.00,1.50,******,37.00,******,28.60,WMa
552.00,12191,5150.00,2440.00,5.00,30.00,285.00,1.50,******,37.00,******,28.70,WMa
553.00,12194,5140.00,2440.00,5.00,30.00,284.00,1.50,******,37.00,******,28.60,WMa
554.00,12197,5150.00,2450.00,5.00,30.00,285.00,1.50,******,37.00,******,28.70,WMa
555.00,12200,5130.00,2440.00,5.00,30.00,284.00,1.50,******,37.00,******,28.50,WMa
556.00,12203,5170.00,2440.00,5.00,30.00,286.00,1.50,******,37.00,******,28.80,WMa
557.00,12206,5140.00,2470.00,5.00,30.00,285.00,1.50,******,37.00,******,28.60,WMa
558.00,12209,5150.00,2440.00,5.00,30.00,285.00,1.50,******,37.00,******,28.60,WMa
559.00,12212,5140.00,2410.00,5.00,30.00,284.00,1.50,******,37.00,******,28.60,WMa
560.00,12215,5160.00,2450.00,5.00,30.00,286.00,1.50,******,37.00,******,28.70,WMa
561.00,12218,5150.00,2450.00,5.00,30.00,285.00,1.50,******,37.00,******,28.70,WMa
562.00,12221,5120.00,2440.00,5.00,30.00,284.00,1.50,******,37.00,******,28.50,WMa
563.00,12224,5140.00,2450.00,5.00,30.00,285.00,1.50,******,37.00,******,28.60,WMa
564.00,12227,5150.00,2450.00,5.00,30.00,285.00,1.50,******,37.00,******,28.70,WMa
565.00,12230,5160.00,2420.00,5.00,30.00,285.00,1.50,******,37.00,******,28.70,WMa
566.00,12233,5150.00,2430.00,5.00,30.00,285.00,1.50,******,37.00,******,28.60,WMa
567.00,12236,5150.00,2450.00,5.00,30.00,285.00,1.50,******,37.00,******,28.70,WMa
568.00,12239,5180.00,2470.00,5.00,30.00,287.00,1.50,******,37.00,******,28.80,WMa
569.00,12242,5130.00,2440.00,5.00,30.00,284.00,1.50,******,37.00,******,28.50,WMa
570.00,12245,5160.00,2450.00,5.00,30.00,286.00,1.50,******,37.00,******,28.70,WMa
571.00,12248,5140.00,2450.00,5.00,30.00,285.00,1.50,******,37.00,******,28.60,WMa
572.00,12251,5150.00,2450.00,5.00,30.00,285.00,1.50,******,37.00,******,28.70,WMa
573.00,12254,5140.00,2450.00,5.00,30.00,285.00,1.50,******,37.00,******,28.60,WMa
574.00,12257,5140.00,2440.00,5.00,30.00,285.00,1.50,******,37.00,******,28.60,WMa
575.00,12260,5140.00,2440.00,5.00,30.00,285.00,1.50,******,37.00,******,28.60,WMa
576.00,12263,5170.00,2450.00,5.00,30.00,286.00,1.50,******,37.00,******,28.80,WMa
577.00,12266,5130.00,2450.00,5.00,30.00,284.00,1.50,******,37.00,******,28.60,WMa
578.00,12269,5150.00,2440.00,5.00,30.00,285.00,1.50,******,37.00,******,28.70,WMa
579.00,12272,5140.00,2460.00,5.00,30.00,285.00,1.50,******,37.00,******,28.70,WMa
580.00,12275,5150.00,2430.00,5.00,30.00,285.00,1.50,******,37.00,******,28.60,WMa
581.00,12278,5150.00,2440.00,5.00,30.00,285.00,1.50,******,37.00,******,28.70,WMa
582.00,12281,5150.00,2450.00,5.00,30.00,285.00,1.50,******,37.00,******,28.70,WMa
583.00,12284,5160.00,2460.00,5.00,30.00,286.00,1.50,******,37.00,******,28.70,WMa
584.00,12287,5140.00,2450.00,5.00,30.00,285.00,1.50,******,37.00,******,28.60,WMa
585.00,12290,5140.00,2460.00,5.00,30.00,285.00,1.50,******,37.00,******,28.60,WMa
586.00,12293,5160.00,2430.00,5.00,30.00,285.00,1.50,******,37.00,******,28.70,WMa
587.00,12296,5150.00,2450.00,5.00,30.00,285.00,1.50,******,37.00,******,28.70,WMa
588.00,12299,5160.00,2450.00,5.00,30.00,285.00,1.50,******,37.00,******,28.70,WMa
589.00,12302,5150.00,2450.00,5.00,30.00,285.00,1.50,******,37.00,******,28.70,WMa
590.00,12305,5150.00,2460.00,5.00,30.00,285.00,1.50,******,37.00,******,28.70,WMa
591.00,12308,5160.00,2450.00,5.00,30.00,286.00,1.50,******,37.00,******,28.70,WMa
592.00,12311,5170.00,2450.00,5.00,30.00,286.00,1.50,******,37.00,******,28.80,WMa
593.00,12314,5160.00,2450.00,5.00,30.00,285.00,1.50,******,37.00,******,28.70,WMa
594.00,12317,5130.00,2480.00,5.00,30.00,285.00,1.50,******,37.00,******,28.60,WMa
595.00,12320,5150.00,2460.00,5.00,30.00,285.00,1.50,******,37.00,******,28.70,WMa
596.00,12323,5150.00,2430.00,5.00,30.00,285.00,1.50,******,37.00,******,28.60,WMa
597.00,12326,5170.00,2450.00,5.00,30.00,286.00,1.50,******,37.00,******,28.80,WMa
598.00,12329,5140.00,2450.00,5.00,30.00,285.00,1.50,******,37.00,******,28.60,WMa
599.00,12332,5160.00,2460.00,5.00,30.00,286.00,1.50,******,37.00,******,28.70,WMa
600.00,12335,5150.00,2440.00,5.00,30.00,285.00,1.50,******,37.00,******,28.70,WMa
,,,,,,,,,,,,
Interval:,,,15.00,,,,,,,,,
Number of Data Points:,,,28.00,,,,,,,,,
,,,,,,,,,,,,
Time Setting:,,,28 Meas. Pts.,,,,,,,,,
,,,Meas. Pt. Duration 6.4285714 s,,,,,,,,,
Event Control:,,,Standard Mode,,,,,,,,,
"  Terminate test, ...",,,...if d(gamma)/dt > 1000 1/s,,,,,,,,,
"  Terminate test, ...",,,...if M > 200 mNm,,,,,,,,,
"  Terminate test, ...",,,...if FN < -50 N or > 50 N,,,,,,,,,
Measuring Profile:,,,,,,,,,,,,
  Shear Rate,,,d(gamma)/dt = 0.1 ... 50 1/s log; |Slope| = 10.003816 Pt. / dec ,,,,,,,,,
,,,,,,,,,,,,
Meas. Pts.,Time,Storage Modulus,Loss Modulus,Strain,Angular Frequency,Shear Stress,Shear Rate,Viscosity,Temperature,Speed,Torque,Status
,[s],[Pa],[Pa],[%],[rad/s],[Pa],[1/s],[Pa·s],[°C],[1/min],[µNm],[]
1.00,12300,******,******,48.40,******,62.90,0.10,629.00,37.00,0.12,6.32,Dy_auto
2.00,12300,******,******,125.00,******,80.70,0.13,642.00,37.00,0.15,8.12,Dy_auto
3.00,12400,******,******,222.00,******,102.00,0.16,644.00,37.00,0.19,10.30,Dy_auto
4.00,12400,******,******,343.00,******,126.00,0.20,633.00,37.00,0.24,12.70,Dy_auto
5.00,12400,******,******,496.00,******,156.00,0.25,622.00,37.00,0.30,15.70,Dy_auto
6.00,12400,******,******,689.00,******,192.00,0.32,609.00,37.00,0.38,19.40,Dy_auto
7.00,12400,******,******,931.00,******,237.00,0.40,595.00,37.00,0.48,23.80,Dy_auto
8.00,12400,******,******,1240.00,******,292.00,0.50,584.00,37.00,0.60,29.40,Dy_auto
9.00,12400,******,******,1620.00,******,364.00,0.63,577.00,37.00,0.75,36.50,Dy_auto
10.00,12400,******,******,2100.00,******,452.00,0.79,569.00,37.00,0.95,45.40,Dy_auto
11.00,12400,******,******,2710.00,******,563.00,1.00,564.00,37.00,1.19,56.60,Dy_auto
12.00,12400,******,******,3480.00,******,699.00,1.26,556.00,37.00,1.50,70.30,Dy_auto
13.00,12400,******,******,4440.00,******,873.00,1.58,552.00,37.00,1.89,87.80,Dy_auto
14.00,12400,******,******,5660.00,******,1090.00,1.99,548.00,37.00,2.38,110.00,Dy_auto
15.00,12400,******,******,7190.00,******,1360.00,2.51,541.00,37.00,2.99,137.00,Dy_auto
16.00,12400,******,******,9110.00,******,1690.00,3.16,534.00,37.00,3.77,170.00,Dy_auto
17.00,12400,******,******,11500.00,******,2100.00,3.98,528.00,37.00,4.74,211.00,Dy_auto
18.00,12500,******,******,14600.00,******,2600.00,5.00,520.00,37.00,5.97,262.00,Dy_auto
19.00,12500,******,******,18400.00,******,3220.00,6.30,511.00,37.00,7.52,323.00,Dy_auto
20.00,12500,******,******,23300.00,******,3890.00,7.93,491.00,37.00,9.46,391.00,Dy_auto
21.00,12500,******,******,29300.00,******,4040.00,9.98,405.00,37.00,11.90,407.00,Dy_auto
22.00,12500,******,******,37000.00,******,4450.00,12.60,354.00,37.00,15.00,448.00,Dy_auto
23.00,12500,******,******,46600.00,******,1720.00,15.80,109.00,37.00,18.90,173.00,Dy_auto
24.00,12500,******,******,58800.00,******,1100.00,19.90,55.40,37.00,23.80,111.00,Dy_auto
25.00,12500,******,******,74100.00,******,522.00,25.10,20.80,37.00,29.90,52.50,Dy_auto
26.00,12500,******,******,93300.00,******,292.00,31.60,9.24,37.00,37.70,29.30,Dy_auto
27.00,12500,******,******,117000.00,******,183.00,39.70,4.60,37.00,47.40,18.40,Dy_auto
28.00,12500,******,******,148000.00,******,216.00,50.00,4.33,37.00,59.70,21.80,Dy_auto