File: exampledata/PXP_N4.csv
Meas. Pts.,Time,Storage Modulus,Loss Modulus,Strain,Angular Frequency,Shear Stress,Shear Rate,Viscosity,Temperature,Speed,Torque,Status
,[s],[Pa],[Pa],[%],[rad/s],[Pa],[1/s],[Pa·s],[°C],[1/min],[µNm],[]
1.00,5,5320.00,1940.00,4.99,30.00,282.00,1.50,******,36.90,******,28.40,WMa
2.00,10,5360.00,1910.00,5.00,30.00,285.00,1.50,******,36.90,******,28.60,
3.00,15,5410.00,1930.00,5.00,30.00,287.00,1.50,******,36.90,******,28.90,
4.00,20,5460.00,1960.00,5.00,30.00,290.00,1.50,******,36.90,******,29.20,
5.00,25,5470.00,1980.00,5.00,30.00,291.00,1.50,******,37.00,******,29.30,
6.00,30,5500.00,1980.00,5.00,30.00,292.00,1.50,******,37.00,******,29.40,
7.00,35,5520.00,2000.00,5.00,30.00,294.00,1.50,******,37.00,******,29.50,
8.00,40,5530.00,2010.00,5.00,30.00,294.00,1.50,******,37.00,******,29.60,
9.00,45,5550.00,2010.00,5.00,30.00,295.00,1.50,******,37.00,******,29.70,
10.00,50,5560.00,2020.00,5.00,30.00,296.00,1.50,******,37.00,******,29.70,
11.00,55,5560.00,2020.00,5.00,30.00,296.00,1.50,******,37.00,******,29.80,
12.00,60,5580.00,2040.00,5.00,30.00,297.00,1.50,******,37.00,******,29.90,
13.00,65,5590.00,2050.00,5.00,30.00,297.00,1.50,******,37.00,******,29.90,
14.00,70,5590.00,2050.00,5.00,30.00,298.00,1.50,******,37.00,******,30.00,
15.00,75,5590.00,2070.00,5.00,30.00,298.00,1.50,******,37.00,******,30.00,
16.00,80,5590.00,2080.00,5.00,30.00,298.00,1.50,******,37.00,******,30.00,
17.00,85,5610.00,2070.00,5.00,30.00,299.00,1.50,******,37.00,******,30.10,
18.00,90,5620.00,2100.00,5.00,30.00,300.00,1.50,******,37.00,******,30.10,
19.00,95,5610.00,2090.00,5.00,30.00,299.00,1.50,******,37.00,******,30.10,
20.00,100,5630.00,2080.00,5.00,30.00,300.00,1.50,******,37.00,******,30.20,
21.00,105,5630.00,2080.00,5.00,30.00,300.00,1.50,******,37.00,******,30.20,
22.00,110,5620.00,2100.00,5.00,30.00,300.00,1.50,******,37.00,******,30.20,
23.00,115,5650.00,2100.00,5.00,30.00,301.00,1.50,******,37.00,******,30.30,
24.00,120,5650.00,2120.00,5.00,30.00,302.00,1.50,******,37.00,******,30.40,
25.00,125,5650.00,2110.00,5.00,30.00,302.00,1.50,******,37.00,******,30.30,
26.00,130,5650.00,2120.00,5.00,30.00,302.00,1.50,******,37.00,******,30.40,
27.00,135,5640.00,2110.00,5.00,30.00,301.00,1.50,******,37.00,******,30.30,
28.00,140,5660.00,2100.00,5.00,30.00,302.00,1.50,******,37.00,******,30.40,
29.00,145,5650.00,2140.00,5.00,30.00,302.00,1.50,******,37.00,******,30.40,
30.00,150,5670.00,2120.00,5.00,30.00,303.00,1.50,******,37.00,******,30.40,
31.00,155,5660.00,2130.00,5.00,30.00,303.00,1.50,******,37.00,******,30.40,
32.00,160,5660.00,2130.00,5.00,30.00,302.00,1.50,******,37.00,******,30.40,
33.00,165,5660.00,2130.00,5.00,30.00,303.00,1.50,******,37.00,******,30.40,
34.00,170,5670.00,2140.00,5.00,30.00,303.00,1.50,******,37.00,******,30.50,
35.00,175,5680.00,2130.00,5.00,30.00,303.00,1.50,******,37.00,******,30.50,
36.00,180,5680.00,2140.00,5.00,30.00,303.00,1.50,******,37.00,******,30.50,
37.00,185,5680.00,2150.00,5.00,30.00,304.00,1.50,******,37.00,******,30.50,
38.00,190,5680.00,2160.00,5.00,30.00,304.00,1.50,******,37.00,******,30.50,
39.00,195,5690.00,2140.00,5.00,30.00,304.00,1.50,******,37.00,******,30.50,
40.00,200,5680.00,2150.00,5.00,30.00,304.00,1.50,******,37.00,******,30.50,
41.00,205,5690.00,2140.00,5.00,30.00,304.00,1.50,******,37.00,******,30.50,
42.00,210,5690.00,2150.00,5.00,30.00,304.00,1.50,******,37.00,******,30.60,
43.00,215,5670.00,2160.00,5.00,30.00,304.00,1.50,******,37.00,******,30.50,
44.00,220,5690.00,2150.00,5.00,30.00,304.00,1.50,******,37.00,******,30.60,
45.00,225,5700.00,2160.00,5.00,30.00,305.00,1.50,******,37.00,******,30.60,
46.00,230,5690.00,2170.00,5.00,30.00,304.00,1.50,******,37.00,******,30.60,
47.00,235,5700.00,2170.00,5.00,30.00,305.00,1.50,******,37.00,******,30.60,
48.00,240,5700.00,2160.00,5.00,30.00,305.00,1.50,******,37.00,******,30.60,
49.00,245,5700.00,2170.00,5.00,30.00,305.00,1.50,******,37.00,******,30.60,
50.00,250,5700.00,2170.00,5.00,30.00,305.00,1.50,******,37.00,******,30.70,
51.00,255,5700.00,2160.00,5.00,30.00,305.00,1.50,******,37.00,******,30.60,
52.00,260,5710.00,2160.00,5.00,30.00,305.00,1.50,******,37.00,******,30.70,
53.00,265,5720.00,2170.00,5.00,30.00,306.00,1.50,******,37.00,******,30.80,
54.00,270,5710.00,2180.00,5.00,30.00,306.00,1.50,******,37.00,******,30.70,
55.00,275,5710.00,2180.00,5.00,30.00,305.00,1.50,******,37.00,******,30.70,
56.00,280,5720.00,2180.00,5.00,30.00,306.00,1.50,******,37.00,******,30.80,
57.00,285,5730.00,2180.00,5.00,30.00,307.00,1.50,******,37.00,******,30.80,
58.00,290,5710.00,2170.00,5.00,30.00,306.00,1.50,******,37.00,******,30.70,
59.00,295,5720.00,2180.00,5.00,30.00,306.00,1.50,******,37.00,******,30.80,
60.00,300,5710.00,2180.00,5.00,30.00,306.00,1.50,******,37.00,******,30.70,
61.00,305,5720.00,2180.00,5.00,30.00,306.00,1.50,******,37.00,******,30.80,
62.00,310,5730.00,2180.00,5.00,30.00,307.00,1.50,******,37.00,******,30.80,
63.00,315,5710.00,2200.00,5.00,30.00,306.00,1.50,******,37.00,******,30.80,
64.00,320,5730.00,2190.00,5.00,30.00,307.00,1.50,******,37.00,******,30.80,
65.00,325,5730.00,2190.00,5.00,30.00,307.00,1.50,******,37.00,******,30.80,
66.00,330,5730.00,2190.00,5.00,30.00,307.00,1.50,******,37.00,******,30.90,
67.00,335,5720.00,2200.00,5.00,30.00,307.00,1.50,******,37.00,******,30.80,
68.00,340,5730.00,2200.00,5.00,30.00,307.00,1.50,******,37.00,******,30.90,
69.00,345,5730.00,2200.00,5.00,30.00,307.00,1.50,******,37.00,******,30.90,
70.00,350,5730.00,2200.00,5.00,30.00,307.00,1.50,******,37.00,******,30.80,
71.00,355,5730.00,2190.00,5.00,30.00,307.00,1.50,******,37.00,******,30.80,
72.00,360,5740.00,2190.00,5.00,30.00,307.00,1.50,******,37.00,******,30.90,
73.00,365,5740.00,2190.00,5.00,30.00,307.00,1.50,******,37.00,******,30.90,
74.00,370,5750.00,2200.00,5.00,30.00,308.00,1.50,******,37.00,******,30.90,
75.00,375,5750.00,2220.00,5.00,30.00,308.00,1.50,******,37.00,******,31.00,
76.00,380,5740.00,2200.00,5.00,30.00,307.00,1.50,******,37.00,******,30.90,
77.00,385,5740.00,2200.00,5.00,30.00,307.00,1.50,******,37.00,******,30.90,
78.00,390,5750.00,2200.00,5.00,30.00,308.00,1.50,******,37.00,******,30.90,
79.00,395,5740.00,2200.00,5.00,30.00,308.00,1.50,******,37.00,******,30.90,
80.00,400,5720.00,2210.00,5.00,30.00,306.00,1.50,******,37.00,******,30.80,
,,,,,,,,,,,,
Interval:,,,2.00,,,,,,,,,
Number of Data Points:,,,31.00,,,,,,,,,
,,,,,,,,,,,,
Time Setting:,,,31 Meas. Pts.,,,,,,,,,
Measuring Profile:,,,,,,,,,,,,
#NAME?,,,Amplitude gamma = 5 %,,,,,,,,,
,,,Angular Frequency omega = 100 ... 0.1 rad/s log; |Slope| = 10 Pt. / dec ,,,,,,,,,
,,,,,,,,,,,,
Meas. Pts.,Time,Storage Modulus,Loss Modulus,Strain,Angular Frequency,Shear Stress,Shear Rate,Viscosity,Temperature,Speed,Torque,Status
,[s],[Pa],[Pa],[%],[rad/s],[Pa],[1/s],[Pa·s],[°C],[1/min],[µNm],[]
1.00,410,6080.00,1490.00,5.00,100.00,313.00,5.00,******,37.00,******,31.50,
2.00,418,6240.00,1260.00,5.00,79.40,318.00,3.97,******,37.00,******,32.00,
3.00,425,6340.00,1430.00,5.00,63.10,325.00,3.16,******,37.00,******,32.70,
4.00,432,6240.00,1710.00,5.00,50.10,323.00,2.51,******,37.00,******,32.50,
5.00,439,6090.00,1900.00,5.00,39.80,319.00,1.99,******,37.00,******,32.10,
6.00,448,5840.00,2150.00,5.00,31.60,311.00,1.58,******,37.00,******,31.30,
7.00,458,5500.00,2390.00,5.00,25.10,300.00,1.26,******,37.00,******,30.10,
8.00,465,5090.00,2610.00,5.00,20.00,286.00,1.00,******,37.00,******,28.80,
9.00,472,4600.00,2780.00,5.00,15.80,269.00,0.79,******,37.00,******,27.00,
10.00,478,4060.00,2890.00,5.00,12.60,249.00,0.63,******,37.00,******,25.00,
11.00,486,3500.00,2920.00,5.00,10.00,228.00,0.50,******,37.00,******,22.90,
12.00,493,2930.00,2870.00,5.00,7.94,205.00,0.40,******,37.00,******,20.60,
13.00,502,2380.00,2750.00,5.00,6.31,182.00,0.32,******,37.00,******,18.30,
14.00,509,1880.00,2560.00,5.00,5.01,159.00,0.25,******,37.00,******,16.00,
15.00,517,1450.00,2320.00,5.01,3.98,137.00,0.20,******,37.00,******,13.80,
16.00,527,1080.00,2060.00,5.01,3.16,116.00,0.16,******,37.00,******,11.70,
17.00,540,793.00,1780.00,5.01,2.51,97.80,0.13,******,37.00,******,9.83,
18.00,560,567.00,1520.00,5.01,2.00,81.10,0.10,******,37.00,******,8.16,
19.00,586,398.00,1270.00,5.01,1.58,66.70,0.08,******,37.00,******,6.70,
20.00,617,277.00,1050.00,5.01,1.26,54.40,0.06,******,37.00,******,5.47,
21.00,656,191.00,859.00,5.01,1.00,44.10,0.05,******,37.00,******,4.43,
22.00,693,132.00,698.00,5.02,0.79,35.60,0.04,******,37.00,******,3.58,
23.00,739,92.40,564.00,5.02,0.63,28.70,0.03,******,37.00,******,2.88,
24.00,797,65.10,455.00,5.02,0.50,23.00,0.03,******,37.00,******,2.32,
25.00,869,47.00,366.00,5.02,0.40,18.50,0.02,******,37.00,******,1.86,
26.00,929,35.00,294.00,5.01,0.32,14.80,0.02,******,37.00,******,1.49,
27.00,1010,26.70,236.00,5.01,0.25,11.90,0.01,******,37.00,******,1.20,
28.00,1100,20.70,189.00,5.01,0.20,9.55,0.01,******,37.00,******,0.96,
29.00,1220,17.20,152.00,5.01,0.16,7.68,0.01,******,37.00,******,0.77,
30.00,1450,14.50,123.00,5.01,0.13,6.20,0.01,******,37.00,******,0.62,
31.00,1730,12.60,99.20,5.01,0.10,5.01,0.01,******,37.00,******,0.50,
,,,,,,,,,,,,
Interval:,,,3.00,,,,,,,,,
Number of Data Points:,,,80.00,,,,,,,,,
,,,,,,,,,,,,
Time Setting:,,,80 Meas. Pts.,,,,,,,,,
,,,Meas. Pt. Duration 5 s,,,,,,,,,
Event Control:,,,Standard Mode,,,,,,,,,
"  Terminate test, ...",,,...if M > 75 mNm,,,,,,,,,
Measuring Profile:,,,,,,,,,,,,
#NAME?,,,Amplitude gamma = 5 %,,,,,,,,,
,,,Angular Frequency omega = 30 rad/s,,,,,,,,,
,,,,,,,,,,,,
Meas. Pts.,Time,Storage Modulus,Loss Modulus,Strain,Angular Frequency,Shear Stress,Shear Rate,Viscosity,Temperature,Speed,Torque,Status
,[s],[Pa],[Pa],[%],[rad/s],[Pa],[1/s],[Pa·s],[°C],[1/min],[µNm],[]
1.00,invalid point,,,,,,,,,,,
2.00,1740,,,,,,,,,,,
3.00,1745,,,,,,,,,,,
4.00,1750,,,,,,,,,,,
5.00,1755,,,,,,,,,,,
6.00,1760,,,,,,,,,,,
7.00,1765,,,,,,,,,,,
8.00,1770,,,,,,,,,,,
9.00,1775,,,,,,,,,,,
10.00,1780,,,,,,,,,,,
11.00,1785,,,,,,,,,,,
12.00,1790,,,,,,,,,,,
13.00,1795,,,,,,,,,,,
14.00,1800,,,,,,,,,,,
15.00,1805,,,,,,,,,,,
16.00,1810,,,,,,,,,,,
17.00,1815,,,,,,,,,,,
18.00,1820,,,,,,,,,,,
19.00,1825,,,,,,,,,,,
20.00,1830,5960.00,2690.00,5.17,30.00,338.00,1.55,******,37.00,******,34.00,WMa
21.00,1835,5930.00,2270.00,5.00,30.00,318.00,1.50,******,37.00,******,31.90,
22.00,1840,5920.00,2290.00,5.00,30.00,317.00,1.50,******,37.00,******,31.90,
23.00,1845,5920.00,2270.00,5.00,30.00,317.00,1.50,******,37.00,******,31.90,
24.00,1850,5930.00,2270.00,5.00,30.00,318.00,1.50,******,37.00,******,31.90,
25.00,1855,5940.00,2280.00,5.00,30.00,318.00,1.50,******,37.00,******,32.00,
26.00,1860,5930.00,2280.00,5.00,30.00,318.00,1.50,******,37.00,******,31.90,
27.00,1865,5930.00,2290.00,5.00,30.00,318.00,1.50,******,37.00,******,31.90,
28.00,1870,5940.00,2280.00,5.00,30.00,318.00,1.50,******,37.00,******,32.00,
29.00,1875,5930.00,2290.00,5.00,30.00,318.00,1.50,******,37.00,******,32.00,
30.00,1880,5940.00,2300.00,5.00,30.00,318.00,1.50,******,37.00,******,32.00,
31.00,1885,5930.00,2280.00,5.00,30.00,318.00,1.50,******,37.00,******,31.90,
32.00,1890,5940.00,2290.00,5.00,30.00,318.00,1.50,******,37.00,******,32.00,
33.00,1895,5950.00,2300.00,5.00,30.00,319.00,1.50,******,37.00,******,32.10,
34.00,1900,5930.00,2290.00,5.00,30.00,318.00,1.50,******,37.00,******,32.00,
35.00,1905,5920.00,2300.00,5.00,30.00,318.00,1.50,******,37.00,******,31.90,
36.00,1910,5940.00,2300.00,5.00,30.00,318.00,1.50,******,37.00,******,32.00,
37.00,1915,5930.00,2290.00,5.00,30.00,318.00,1.50,******,37.00,******,32.00,
38.00,1920,5930.00,2290.00,5.00,30.00,318.00,1.50,******,37.00,******,32.00,
39.00,1925,5920.00,2290.00,5.00,30.00,318.00,1.50,******,37.00,******,31.90,
40.00,1930,5930.00,2290.00,5.00,30.00,318.00,1.50,******,37.00,******,32.00,
41.00,1935,5920.00,2300.00,5.00,30.00,318.00,1.50,******,37.00,******,31.90,
42.00,1940,5940.00,2300.00,5.00,30.00,318.00,1.50,******,37.00,******,32.00,
43.00,1945,5940.00,2310.00,5.00,30.00,318.00,1.50,******,37.00,******,32.00,
44.00,1950,5930.00,2290.00,5.00,30.00,318.00,1.50,******,37.00,******,32.00,
45.00,1955,5920.00,2300.00,5.00,30.00,318.00,1.50,******,37.00,******,31.90,
46.00,1960,5930.00,2290.00,5.00,30.00,318.00,1.50,******,37.00,******,32.00,
47.00,1965,5930.00,2280.00,5.00,30.00,318.00,1.50,******,37.00,******,32.00,
48.00,1970,5940.00,2290.00,5.00,30.00,318.00,1.50,******,37.00,******,32.00,
49.00,1975,5940.00,2290.00,5.00,30.00,318.00,1.50,******,37.00,******,32.00,
50.00,1980,5930.00,2300.00,5.00,30.00,318.00,1.50,******,37.00,******,32.00,
51.00,1985,5930.00,2310.00,5.00,30.00,318.00,1.50,******,37.00,******,32.00,
52.00,1990,5920.00,2300.00,5.00,30.00,317.00,1.50,******,37.00,******,31.90,
53.00,1995,5930.00,2290.00,5.00,30.00,318.00,1.50,******,37.00,******,32.00,
54.00,2000,5930.00,2300.00,5.00,30.00,318.00,1.50,******,37.00,******,32.00,
55.00,2005,5940.00,2280.00,5.00,30.00,318.00,1.50,******,37.00,******,32.00,
56.00,2010,5940.00,2290.00,5.00,30.00,318.00,1.50,******,37.00,******,32.00,
57.00,2015,5940.00,2300.00,5.00,30.00,318.00,1.50,******,37.00,******,32.00,
58.00,2020,5940.00,2290.00,5.00,30.00,318.00,1.50,******,37.00,******,32.00,
59.00,2025,5940.00,2290.00,5.00,30.00,319.00,1.50,******,37.00,******,32.00,
60.00,2030,5940.00,2310.00,5.00,30.00,319.00,1.50,******,37.00,******,32.10,
61.00,2035,5940.00,2290.00,5.00,30.00,318.00,1.50,******,37.00,******,32.00,
62.00,2040,5940.00,2300.00,5.00,30.00,319.00,1.50,******,37.00,******,32.00,
63.00,2045,5930.00,2300.00,5.00,30.00,318.00,1.50,******,37.00,******,32.00,
64.00,2050,5930.00,2280.00,5.00,30.00,318.00,1.50,******,37.00,******,32.00,
65.00,2055,5940.00,2300.00,5.00,30.00,319.00,1.50,******,37.00,******,32.00,
66.00,2060,5930.00,2300.00,5.00,30.00,318.00,1.50,******,37.00,******,32.00,
67.00,2065,5950.00,2300.00,5.00,30.00,319.00,1.50,******,37.00,******,32.10,
68.00,2070,5940.00,2310.00,5.00,30.00,319.00,1.50,******,37.00,******,32.10,
69.00,2075,5950.00,2300.00,5.00,30.00,319.00,1.50,******,37.00,******,32.10,
70.00,2080,5940.00,2300.00,5.00,30.00,319.00,1.50,******,37.00,******,32.00,
71.00,2085,5950.00,2290.00,5.00,30.00,319.00,1.50,******,37.00,******,32.10,
72.00,2090,5950.00,2290.00,5.00,30.00,319.00,1.50,******,37.00,******,32.10,
73.00,2095,5930.00,2300.00,5.00,30.00,318.00,1.50,******,37.00,******,32.00,
74.00,2100,5940.00,2300.00,5.00,30.00,319.00,1.50,******,37.00,******,32.00,
75.00,2105,5950.00,2300.00,5.00,30.00,319.00,1.50,******,37.00,******,32.10,
76.00,2110,5950.00,2290.00,5.00,30.00,319.00,1.50,******,37.00,******,32.10,
77.00,2115,5930.00,2280.00,5.00,30.00,318.00,1.50,******,37.00,******,31.90,
78.00,2120,5950.00,2300.00,5.00,30.00,319.00,1.50,******,37.00,******,32.10,
79.00,2125,5940.00,2300.00,5.00,30.00,319.00,1.50,******,37.00,******,32.00,
80.00,2130,5950.00,2300.00,5.00,30.00,319.00,1.50,******,37.00,******,32.00,
,,,,,,,,,,,,
Interval:,,,4.00,,,,,,,,,
Number of Data Points:,,,113.00,,,,,,,,,
,,,,,,,,,,,,
Time Setting:,,,113 Meas. Pts.,,,,,,,,,
,,,Meas. Pt. Duration 5 s,,,,,,,,,
Measuring Profile:,,,,,,,,,,,,
#NAME?,,,Amplitude gamma = 0.1 ... 500 % log; |Slope| = 30.278699 Pt. / dec ,,,,,,,,,
,,,Angular Frequency omega = 30 rad/s,,,,,,,,,
,,,,,,,,,,,,
Meas. Pts.,Time,Storage Modulus,Loss Modulus,Strain,Angular Frequency,Shear Stress,Shear Rate,Viscosity,Temperature,Speed,Torque,Status
,[s],[Pa],[Pa],[%],[rad/s],[Pa],[1/s],[Pa·s],[°C],[1/min],[µNm],[]
1.00,2135,3860.00,11900.00,0.10,30.00,12.70,0.03,******,37.00,******,1.28,WMa
2.00,2140,4300.00,2220.00,0.11,30.00,5.22,0.03,******,37.00,******,0.53,
3.00,2145,6210.00,0.00,0.12,30.00,7.25,0.04,******,37.00,******,0.73,"MV-,WMa"
4.00,2150,26500.00,0.00,0.13,30.00,33.30,0.04,******,37.00,******,3.35,"MV-,WMa"
5.00,2155,1820.00,1660.00,0.14,30.00,3.43,0.04,******,37.00,******,0.35,WMa
6.00,2160,4190.00,2130.00,0.15,30.00,6.92,0.04,******,37.00,******,0.70,
7.00,2165,0.00,19300.00,0.16,30.00,30.60,0.05,******,37.00,******,3.07,"ME-,WMa"
8.00,2170,0.00,7600.00,0.17,30.00,12.90,0.05,******,37.00,******,1.29,"ME-,WMa"
9.00,2175,21900.00,7550.00,0.18,30.00,42.60,0.06,******,37.00,******,4.29,"ME-,MV-"
10.00,2180,11100.00,25500.00,0.20,30.00,56.10,0.06,******,37.00,******,5.64,WMa
11.00,2185,4670.00,2360.00,0.21,30.00,11.20,0.06,******,37.00,******,1.13,
12.00,2190,9420.00,337.00,0.23,30.00,21.90,0.07,******,37.00,******,2.20,WMa
13.00,2195,6190.00,2750.00,0.25,30.00,17.00,0.08,******,37.00,******,1.71,WMa
14.00,2200,0.00,6370.00,0.27,30.00,17.20,0.08,******,37.00,******,1.73,"MV-,WMa"
15.00,2205,5240.00,2410.00,0.29,30.00,16.70,0.09,******,37.00,******,1.68,
16.00,2210,10900.00,632.00,0.31,30.00,34.20,0.09,******,37.00,******,3.43,WMa
17.00,2215,0.00,444.00,0.34,30.00,1.52,0.10,******,37.00,******,0.15,"MV-,WMa"
18.00,2220,5510.00,2310.00,0.37,30.00,21.80,0.11,******,37.00,******,2.19,
19.00,2225,5500.00,2540.00,0.40,30.00,24.00,0.12,******,37.00,******,2.41,WMa
20.00,2230,8320.00,1500.00,0.43,30.00,36.10,0.13,******,37.00,******,3.63,WMa
21.00,2235,7020.00,2900.00,0.46,30.00,35.00,0.14,******,37.00,******,3.52,WMa
22.00,2240,0.00,7170.00,0.50,30.00,35.60,0.15,******,37.00,******,3.58,"MV-,WMa"
23.00,2245,6430.00,2230.00,0.53,30.00,36.20,0.16,******,37.00,******,3.64,
24.00,2250,6470.00,2360.00,0.58,30.00,39.80,0.17,******,37.00,******,4.01,WMa
25.00,2255,7530.00,2740.00,0.62,30.00,49.90,0.19,******,37.00,******,5.02,WMa
26.00,2260,5860.00,167.00,0.67,30.00,39.40,0.20,******,37.00,******,3.96,WMa
27.00,2265,3130.00,6680.00,0.73,30.00,53.50,0.22,******,37.00,******,5.38,WMa
28.00,2270,6480.00,2290.00,0.78,30.00,53.60,0.23,******,37.00,******,5.39,
29.00,2275,0.00,1260.00,0.84,30.00,10.60,0.25,******,37.00,******,1.06,"MV-,WMa"
30.00,2280,6360.00,2270.00,0.91,30.00,61.30,0.27,******,37.00,******,6.16,
31.00,2285,5550.00,3420.00,0.98,30.00,64.00,0.29,******,37.00,******,6.43,WMa
32.00,2290,8880.00,1710.00,1.06,30.00,95.80,0.32,******,37.00,******,9.63,WMa
33.00,2295,1920.00,0.00,1.14,30.00,21.90,0.34,******,37.00,******,2.20,"MV-,WMa"
34.00,2300,5460.00,0.00,1.23,30.00,67.20,0.37,******,37.00,******,6.76,"MV-,WMa"
35.00,2305,7280.00,305.00,1.33,30.00,96.90,0.40,******,37.00,******,9.74,WMa
36.00,2310,5410.00,2430.00,1.43,30.00,84.90,0.43,******,37.00,******,8.54,WMa
37.00,2315,5820.00,2140.00,1.55,30.00,96.00,0.47,******,37.00,******,9.65,WMa
38.00,2320,5630.00,0.00,1.67,30.00,93.90,0.50,******,37.00,******,9.44,"MV-,WMa"
39.00,2325,2770.00,5870.00,1.80,30.00,117.00,0.54,******,37.00,******,11.80,WMa
40.00,2330,6010.00,2290.00,1.94,30.00,125.00,0.58,******,37.00,******,12.60,
41.00,2335,5120.00,1640.00,2.10,30.00,113.00,0.63,******,37.00,******,11.30,WMa
42.00,2340,5790.00,262.00,2.26,30.00,131.00,0.68,******,37.00,******,13.20,WMa
43.00,2345,5370.00,3010.00,2.44,30.00,150.00,0.73,******,37.00,******,15.10,WMa
44.00,2350,6460.00,2280.00,2.63,30.00,181.00,0.79,******,37.00,******,18.20,WMa
45.00,2355,5200.00,1510.00,2.84,30.00,154.00,0.85,******,37.00,******,15.50,WMa
46.00,2360,6080.00,2980.00,3.07,30.00,208.00,0.92,******,37.00,******,20.90,WMa
47.00,2365,6830.00,1440.00,3.31,30.00,231.00,0.99,******,37.00,******,23.20,WMa
48.00,2370,5800.00,2290.00,3.57,30.00,223.00,1.07,******,37.00,******,22.40,WMa
49.00,2375,7660.00,4190.00,3.85,30.00,336.00,1.16,******,37.00,******,33.80,WMa
50.00,2380,5920.00,3180.00,4.16,30.00,279.00,1.25,******,37.00,******,28.10,WMa
51.00,2385,5690.00,2580.00,4.49,30.00,280.00,1.35,******,37.00,******,28.20,WMa
52.00,2390,5970.00,2340.00,4.84,30.00,310.00,1.45,******,37.00,******,31.20,WMa
53.00,2395,5610.00,1870.00,5.22,30.00,309.00,1.57,******,37.00,******,31.10,WMa
54.00,2400,6050.00,1730.00,5.64,30.00,354.00,1.69,******,37.00,******,35.60,WMa
55.00,2405,4910.00,3210.00,6.08,30.00,357.00,1.82,******,37.00,******,35.90,WMa
56.00,2410,5780.00,2290.00,6.56,30.00,407.00,1.97,******,37.00,******,41.00,WMa
57.00,2415,6660.00,3120.00,7.08,30.00,521.00,2.12,******,37.00,******,52.40,WMa
58.00,2420,6010.00,1880.00,7.64,30.00,481.00,2.29,******,37.00,******,48.40,WMa
59.00,2425,6490.00,1880.00,8.24,30.00,557.00,2.47,******,37.00,******,56.00,WMa
60.00,2430,6010.00,2310.00,8.90,30.00,573.00,2.67,******,37.00,******,57.60,WMa
61.00,2435,6030.00,2420.00,9.60,30.00,623.00,2.88,******,37.00,******,62.70,WMa
62.00,2440,5900.00,2720.00,10.40,30.00,673.00,3.11,******,37.00,******,67.70,WMa
63.00,2445,5870.00,2390.00,11.20,30.00,709.00,3.35,******,37.00,******,71.30,WMa
64.00,2450,5980.00,2300.00,12.10,30.00,773.00,3.62,******,37.00,******,77.70,WMa
65.00,2455,6030.00,2320.00,13.00,30.00,841.00,3.90,******,37.00,******,84.50,WMa
66.00,2460,6020.00,2100.00,14.00,30.00,895.00,4.21,******,37.00,******,90.00,WMa
67.00,2465,5960.00,2310.00,15.10,30.00,968.00,4.54,******,37.00,******,97.30,WMa
68.00,2470,6120.00,2350.00,16.30,30.00,1070.00,4.90,******,37.00,******,108.00,WMa
69.00,2475,5890.00,2160.00,17.60,30.00,1110.00,5.29,******,37.00,******,111.00,WMa
70.00,2480,5990.00,2260.00,19.00,30.00,1220.00,5.71,******,37.00,******,123.00,WMa
71.00,2485,6040.00,2270.00,20.50,30.00,1320.00,6.16,******,37.00,******,133.00,WMa
72.00,2490,6450.00,2440.00,22.20,30.00,1530.00,6.65,******,37.00,******,154.00,WMa
73.00,2495,6060.00,2530.00,23.90,30.00,1570.00,7.17,******,37.00,******,158.00,WMa
74.00,2500,5950.00,2320.00,25.80,30.00,1650.00,7.74,******,37.00,******,166.00,WMa
75.00,2505,5470.00,2550.00,27.80,30.00,1680.00,8.35,******,37.00,******,169.00,WMa
76.00,2510,5970.00,2310.00,30.00,30.00,1920.00,9.01,******,37.00,******,193.00,WMa
77.00,2515,6020.00,2430.00,32.40,30.00,2100.00,9.72,******,37.00,******,211.00,WMa
78.00,2520,6010.00,2190.00,35.00,30.00,2230.00,10.50,******,37.00,******,225.00,WMa
79.00,2525,6020.00,2260.00,37.70,30.00,2420.00,11.30,******,37.00,******,244.00,WMa
80.00,2530,5580.00,2150.00,40.70,30.00,2430.00,12.20,******,37.00,******,245.00,WMa
81.00,2535,5990.00,2420.00,43.90,30.00,2840.00,13.20,******,37.00,******,285.00,WMa
82.00,2540,5940.00,2270.00,47.40,30.00,3010.00,14.20,******,37.00,******,303.00,WMa
83.00,2545,5860.00,2340.00,51.10,30.00,3230.00,15.30,******,37.00,******,324.00,WMa
84.00,2550,6360.00,2540.00,55.20,30.00,3780.00,16.60,******,37.00,******,380.00,WMa
85.00,2555,5850.00,2060.00,59.50,30.00,3690.00,17.90,******,37.00,******,371.00,WMa
86.00,2560,5800.00,2450.00,64.20,30.00,4050.00,19.30,******,37.00,******,407.00,WMa
87.00,2565,5940.00,2280.00,69.30,30.00,4410.00,20.80,******,37.00,******,443.00,WMa
88.00,2570,6330.00,2750.00,74.80,30.00,5160.00,22.40,******,37.00,******,519.00,WMa
89.00,2575,5440.00,2120.00,80.70,30.00,4710.00,24.20,******,37.00,******,474.00,WMa
90.00,2580,4950.00,2760.00,87.00,30.00,4930.00,26.10,******,37.00,******,496.00,WMa
91.00,2585,4650.00,2350.00,93.90,30.00,4890.00,28.20,******,37.00,******,492.00,WMa
92.00,2590,3650.00,1800.00,101.00,30.00,4130.00,30.40,******,37.00,******,415.00,WMa
93.00,2595,2410.00,1230.00,109.00,30.00,2950.00,32.80,******,37.00,******,297.00,WMa
94.00,2600,1220.00,738.00,118.00,30.00,1680.00,35.40,******,37.00,******,169.00,
95.00,2605,616.00,480.00,127.00,30.00,993.00,38.20,******,37.00,******,99.90,
96.00,2610,360.00,356.00,137.00,30.00,694.00,41.20,******,37.00,******,69.80,
97.00,2615,199.00,263.00,148.00,30.00,488.00,44.40,******,37.00,******,49.10,
98.00,2620,81.10,207.00,160.00,30.00,356.00,47.90,******,37.00,******,35.80,
99.00,2625,14.60,178.00,172.00,30.00,309.00,51.70,******,37.00,******,31.00,
100.00,2630,0.00,164.00,186.00,30.00,305.00,55.80,******,37.00,******,30.60,"ME-,taD"
101.00,2635,0.00,179.00,201.00,30.00,359.00,60.20,******,37.00,******,36.10,"ME-,taD"
102.00,2640,0.00,218.00,217.00,30.00,473.00,65.00,******,37.00,******,47.60,"ME-,taD"
103.00,2645,0.00,213.00,234.00,30.00,499.00,70.10,******,37.00,******,50.20,"ME-,taD"
104.00,2650,0.00,205.00,252.00,30.00,517.00,75.70,******,37.00,******,52.00,"ME-,taD"
105.00,2655,0.00,194.00,272.00,30.00,527.00,81.60,******,37.00,******,53.00,"ME-,taD"
106.00,2660,0.00,192.00,294.00,30.00,565.00,88.10,******,37.00,******,56.80,"ME-,taD"
107.00,2665,0.00,181.00,317.00,30.00,573.00,95.00,******,37.00,******,57.60,"ME-,taD"
108.00,2670,0.00,170.00,342.00,30.00,581.00,103.00,******,37.00,******,58.40,"ME-,taD"
109.00,2675,0.00,138.00,369.00,30.00,510.00,111.00,******,37.00,******,51.30,"ME-,taD"
110.00,2680,0.00,129.00,398.00,30.00,512.00,119.00,******,37.00,******,51.50,"ME-,taD"
111.00,2685,0.00,128.00,429.00,30.00,551.00,129.00,******,37.00,******,55.40,"ME-,taD"
112.00,2690,0.00,122.00,463.00,30.00,564.00,139.00,******,37.00,******,56.70,"ME-,taD"
113.00,2695,0.00,131.00,500.00,30.00,655.00,150.00,******,37.00,******,65.80,"ME-,taD"
,,,,,,,,,,,,
Interval:,,,5.00,,,,,,,,,
Number of Data Points:,,,80.00,,,,,,,,,
,,,,,,,,,,,,
Time Setting:,,,80 Meas. Pts.,,,,,,,,,
,,,Meas. Pt. Duration 5 s,,,,,,,,,
Event Control:,,,Standard Mode,,,,,,,,,
"  Terminate test, ...",,,...if M > 75 mNm,,,,,,,,,
Measuring Profile:,,,,,,,,,,,,
#NAME?,,,Amplitude gamma = 5 %,,,,,,,,,
,,,Angular Frequency omega = 30 rad/s,,,,,,,,,
,,,,,,,,,,,,
Meas. Pts.,Time,Storage Modulus,Loss Modulus,Strain,Angular Frequency,Shear Stress,Shear Rate,Viscosity,Temperature,Speed,Torque,Status
,[s],[Pa],[Pa],[%],[rad/s],[Pa],[1/s],[Pa·s],[°C],[1/min],[µNm],[]
1.00,2700,144.00,238.00,5.05,30.00,14.00,1.51,******,37.00,******,1.41,WMa
2.00,2705,186.00,120.00,5.00,30.00,11.10,1.50,******,37.00,******,1.11,
3.00,2710,326.00,221.00,5.00,30.00,19.70,1.50,******,37.00,******,1.98,
4.00,2715,502.00,267.00,5.00,30.00,28.40,1.50,******,37.00,******,2.86,
5.00,2720,698.00,373.00,5.00,30.00,39.60,1.50,******,37.00,******,3.98,
6.00,2725,916.00,436.00,5.00,30.00,50.70,1.50,******,37.00,******,5.10,
7.00,2730,1060.00,504.00,5.00,30.00,58.60,1.50,******,37.00,******,5.90,
8.00,2735,1320.00,595.00,5.00,30.00,72.20,1.50,******,37.00,******,7.26,
9.00,2740,1520.00,683.00,5.00,30.00,83.40,1.50,******,37.00,******,8.38,
10.00,2745,1760.00,765.00,5.00,30.00,96.10,1.50,******,37.00,******,9.66,
11.00,2750,2020.00,866.00,5.00,30.00,110.00,1.50,******,37.00,******,11.00,
12.00,2755,2250.00,946.00,5.00,30.00,122.00,1.50,******,37.00,******,12.30,
13.00,2760,2540.00,1070.00,5.00,30.00,138.00,1.50,******,37.00,******,13.90,
14.00,2765,2770.00,1140.00,5.00,30.00,150.00,1.50,******,37.00,******,15.00,
15.00,2770,2980.00,1230.00,5.00,30.00,161.00,1.50,******,37.00,******,16.20,
16.00,2775,3210.00,1310.00,5.00,30.00,173.00,1.50,******,37.00,******,17.40,
17.00,2780,3470.00,1410.00,5.00,30.00,187.00,1.50,******,37.00,******,18.80,
18.00,2785,3700.00,1480.00,5.00,30.00,199.00,1.50,******,37.00,******,20.00,
19.00,2790,3920.00,1570.00,5.00,30.00,211.00,1.50,******,37.00,******,21.20,
20.00,2795,4110.00,1640.00,5.00,30.00,222.00,1.50,******,37.00,******,22.30,
21.00,2800,4300.00,1710.00,5.00,30.00,231.00,1.50,******,37.00,******,23.30,
22.00,2805,4530.00,1790.00,5.00,30.00,243.00,1.50,******,37.00,******,24.50,
23.00,2810,4640.00,1820.00,5.00,30.00,249.00,1.50,******,37.00,******,25.10,
24.00,2815,4760.00,1870.00,5.00,30.00,256.00,1.50,******,37.00,******,25.70,
25.00,2820,4880.00,1910.00,5.00,30.00,262.00,1.50,******,37.00,******,26.30,
26.00,2825,4960.00,1950.00,5.00,30.00,267.00,1.50,******,37.00,******,26.80,
27.00,2830,5040.00,1990.00,5.00,30.00,271.00,1.50,******,37.00,******,27.30,
28.00,2835,5120.00,2010.00,5.00,30.00,275.00,1.50,******,37.00,******,27.60,
29.00,2840,5180.00,2020.00,5.00,30.00,278.00,1.50,******,37.00,******,27.90,
30.00,2845,5250.00,2060.00,5.00,30.00,282.00,1.50,******,37.00,******,28.40,
31.00,2850,5310.00,2090.00,5.00,30.00,285.00,1.50,******,37.00,******,28.70,
32.00,2855,5360.00,2090.00,5.00,30.00,287.00,1.50,******,37.00,******,28.90,
33.00,2860,5420.00,2110.00,5.00,30.00,291.00,1.50,******,37.00,******,29.20,
34.00,2865,5460.00,2150.00,5.00,30.00,293.00,1.50,******,37.00,******,29.50,
35.00,2870,5500.00,2150.00,5.00,30.00,295.00,1.50,******,37.00,******,29.70,
36.00,2875,5570.00,2170.00,5.00,30.00,299.00,1.50,******,37.00,******,30.00,
37.00,2880,5610.00,2190.00,5.00,30.00,301.00,1.50,******,37.00,******,30.30,
38.00,2885,5640.00,2210.00,5.00,30.00,303.00,1.50,******,37.00,******,30.50,
39.00,2890,5690.00,2220.00,5.00,30.00,305.00,1.50,******,37.00,******,30.70,
40.00,2895,5730.00,2240.00,5.00,30.00,307.00,1.50,******,37.00,******,30.90,
41.00,2900,5760.00,2240.00,5.00,30.00,309.00,1.50,******,37.00,******,31.10,
42.00,2905,5780.00,2260.00,5.00,30.00,310.00,1.50,******,37.00,******,31.20,
43.00,2910,5810.00,2260.00,5.00,30.00,312.00,1.50,******,37.00,******,31.30,
44.00,2915,5820.00,2280.00,5.00,30.00,312.00,1.50,******,37.00,******,31.40,
45.00,2920,5860.00,2270.00,5.00,30.00,314.00,1.50,******,37.00,******,31.60,
46.00,2925,5850.00,2270.00,5.00,30.00,314.00,1.50,******,37.00,******,31.60,
47.00,2930,5860.00,2290.00,5.00,30.00,315.00,1.50,******,37.00,******,31.60,
48.00,2935,5860.00,2290.00,5.00,30.00,314.00,1.50,******,37.00,******,31.60,
49.00,2940,5900.00,2300.00,5.00,30.00,317.00,1.50,******,37.00,******,31.80,
50.00,2945,5900.00,2290.00,5.00,30.00,317.00,1.50,******,37.00,******,31.80,
51.00,2950,5890.00,2290.00,5.00,30.00,316.00,1.50,******,37.00,******,31.80,
52.00,2955,5900.00,2290.00,5.00,30.00,317.00,1.50,******,37.00,******,31.80,
53.00,2960,5920.00,2300.00,5.00,30.00,317.00,1.50,******,37.00,******,31.90,
54.00,2965,5920.00,2300.00,5.00,30.00,318.00,1.50,******,37.00,******,31.90,
55.00,2970,5930.00,2300.00,5.00,30.00,318.00,1.50,******,37.00,******,32.00,
56.00,2975,5930.00,2310.00,5.00,30.00,318.00,1.50,******,37.00,******,32.00,
57.00,2980,5940.00,2310.00,5.00,30.00,319.00,1.50,******,37.00,******,32.00,
58.00,2985,5920.00,2300.00,5.00,30.00,318.00,1.50,******,37.00,******,31.90,
59.00,2990,5950.00,2320.00,5.00,30.00,319.00,1.50,******,37.00,******,32.10,
60.00,2995,5940.00,2310.00,5.00,30.00,319.00,1.50,******,37.00,******,32.10,
61.00,3000,5960.00,2310.00,5.00,30.00,319.00,1.50,******,37.00,******,32.10,
62.00,3005,5960.00,2310.00,5.00,30.00,319.00,1.50,******,37.00,******,32.10,
63.00,3010,5970.00,2300.00,5.00,30.00,320.00,1.50,******,37.00,******,32.20,
64.00,3015,5980.00,2310.00,5.00,30.00,321.00,1.50,******,37.00,******,32.20,
65.00,3020,5970.00,2310.00,5.00,30.00,320.00,1.50,******,37.00,******,32.20,
66.00,3025,5970.00,2330.00,5.00,30.00,320.00,1.50,******,37.00,******,32.20,
67.00,3030,5980.00,2330.00,5.00,30.00,321.00,1.50,******,37.00,******,32.20,
68.00,3035,5990.00,2330.00,5.00,30.00,322.00,1.50,******,37.00,******,32.30,
69.00,3040,5980.00,2330.00,5.00,30.00,321.00,1.50,******,37.00,******,32.30,
70.00,3045,5990.00,2330.00,5.00,30.00,321.00,1.50,******,37.00,******,32.30,
71.00,3050,5990.00,2340.00,5.00,30.00,322.00,1.50,******,37.00,******,32.30,
72.00,3055,6000.00,2320.00,5.00,30.00,322.00,1.50,******,37.00,******,32.40,
73.00,3060,6000.00,2320.00,5.00,30.00,322.00,1.50,******,37.00,******,32.40,
74.00,3065,6000.00,2330.00,5.00,30.00,322.00,1.50,******,37.00,******,32.40,
75.00,3070,6010.00,2320.00,5.00,30.00,322.00,1.50,******,37.00,******,32.40,
76.00,3075,6010.00,2330.00,5.00,30.00,322.00,1.50,******,37.00,******,32.40,
77.00,3080,5990.00,2330.00,5.00,30.00,321.00,1.50,******,37.00,******,32.30,
78.00,3085,6020.00,2340.00,5.00,30.00,323.00,1.50,******,37.00,******,32.50,
79.00,3090,6010.00,2340.00,5.00,30.00,323.00,1.50,******,37.00,******,32.40,
80.00,3095,6010.00,2330.00,5.00,30.00,322.00,1.50,******,37.00,******,32.40,
,,,,,,,,,,,,
Interval:,,,6.00,,,,,,,,,
Number of Data Points:,,,600.00,,,,,,,,,
,,,,,,,,,,,,
Time Setting:,,,600 Meas. Pts.,,,,,,,,,
,,,Meas. Pt. Duration 3 s,,,,,,,,,
Event Control:,,,Standard Mode,,,,,,,,,
"  Terminate test, ...",,,...if M > 200 mNm,,,,,,,,,
Measuring Profile:,,,,,,,,,,,,
#NAME?,,,Amplitude gamma = 5 %,,,,,,,,,
,,,Angular Frequency omega = 30 rad/s,,,,,,,,,
,,,,,,,,,,,,
Meas. Pts.,Time,Storage Modulus,Loss Modulus,Strain,Angular Frequency,Shear Stress,Shear Rate,Viscosity,Temperature,Speed,Torque,Status
,[s],[Pa],[Pa],[%],[rad/s],[Pa],[1/s],[Pa·s],[°C],[1/min],[µNm],[]
1.00,3098,6030.00,2350.00,5.05,30.00,327.00,1.52,******,37.00,******,32.90,WMa
2.00,3101,6030.00,2320.00,5.00,30.00,323.00,1.50,******,37.00,******,32.50,
3.00,3104,6040.00,2340.00,5.00,30.00,324.00,1.50,******,37.00,******,32.60,
4.00,3107,6050.00,2350.00,5.00,30.00,324.00,1.50,******,37.00,******,32.60,
5.00,3110,6030.00,2350.00,5.00,30.00,324.00,1.50,******,37.00,******,32.60,
6.00,3113,6030.00,2350.00,5.00,30.00,324.00,1.50,******,37.00,******,32.50,
7.00,3116,6040.00,2340.00,5.00,30.00,324.00,1.50,******,37.00,******,32.60,
8.00,3119,6040.00,2350.00,5.00,30.00,324.00,1.50,******,37.00,******,32.60,
9.00,3122,6040.00,2340.00,5.00,30.00,324.00,1.50,******,37.00,******,32.60,
10.00,3125,6070.00,2370.00,5.00,30.00,326.00,1.50,******,37.00,******,32.80,
11.00,3128,6040.00,2320.00,5.00,30.00,323.00,1.50,******,37.00,******,32.50,
12.00,3131,6050.00,2340.00,5.00,30.00,324.00,1.50,******,37.00,******,32.60,
13.00,3134,6040.00,2310.00,5.00,30.00,323.00,1.50,******,37.00,******,32.50,
14.00,3137,6050.00,2360.00,5.00,30.00,324.00,1.50,******,37.00,******,32.60,
15.00,3140,6050.00,2340.00,5.00,30.00,324.00,1.50,******,37.00,******,32.60,
16.00,3143,6040.00,2310.00,5.00,30.00,323.00,1.50,******,37.00,******,32.50,
17.00,3146,6040.00,2360.00,5.00,30.00,324.00,1.50,******,37.00,******,32.60,
18.00,3149,6050.00,2350.00,5.00,30.00,325.00,1.50,******,37.00,******,32.60,
19.00,3152,6050.00,2330.00,5.00,30.00,324.00,1.50,******,37.00,******,32.60,
20.00,3155,6050.00,2360.00,5.00,30.00,325.00,1.50,******,37.00,******,32.70,
21.00,3158,6070.00,2370.00,5.00,30.00,326.00,1.50,******,37.00,******,32.80,
22.00,3161,6080.00,2360.00,5.00,30.00,326.00,1.50,******,37.00,******,32.80,
23.00,3164,6060.00,2320.00,5.00,30.00,325.00,1.50,******,37.00,******,32.60,
24.00,3167,6060.00,2340.00,5.00,30.00,325.00,1.50,******,37.00,******,32.70,
25.00,3170,6060.00,2350.00,5.00,30.00,325.00,1.50,******,37.00,******,32.70,
26.00,3173,6050.00,2370.00,5.00,30.00,325.00,1.50,******,37.00,******,32.70,
27.00,3176,6060.00,2340.00,5.00,30.00,325.00,1.50,******,37.00,******,32.70,
28.00,3179,6080.00,2340.00,5.00,30.00,326.00,1.50,******,37.00,******,32.80,
29.00,3182,6070.00,2350.00,5.00,30.00,325.00,1.50,******,37.00,******,32.70,
30.00,3185,6090.00,2350.00,5.00,30.00,326.00,1.50,******,37.00,******,32.80,
31.00,3188,6060.00,2350.00,5.00,30.00,325.00,1.50,******,37.00,******,32.70,
32.00,3191,6090.00,2350.00,5.00,30.00,326.00,1.50,******,37.00,******,32.80,
33.00,3194,6070.00,2350.00,5.00,30.00,325.00,1.50,******,37.00,******,32.70,
34.00,3197,6070.00,2340.00,5.00,30.00,326.00,1.50,******,37.00,******,32.70,
35.00,3200,6070.00,2350.00,5.00,30.00,326.00,1.50,******,37.00,******,32.70,
36.00,3203,6080.00,2350.00,5.00,30.00,326.00,1.50,******,37.00,******,32.70,
37.00,3206,6070.00,2320.00,5.00,30.00,325.00,1.50,******,37.00,******,32.70,
38.00,3209,6050.00,2360.00,5.00,30.00,324.00,1.50,******,37.00,******,32.60,
39.00,3212,6070.00,2340.00,5.00,30.00,325.00,1.50,******,37.00,******,32.70,
40.00,3215,6060.00,2350.00,5.00,30.00,325.00,1.50,******,37.00,******,32.70,
41.00,3218,6100.00,2340.00,5.00,30.00,327.00,1.50,******,37.00,******,32.90,
42.00,3221,6090.00,2360.00,5.00,30.00,327.00,1.50,******,37.00,******,32.80,
43.00,3224,6070.00,2370.00,5.00,30.00,326.00,1.50,******,37.00,******,32.80,
44.00,3227,6080.00,2380.00,5.00,30.00,326.00,1.50,******,37.00,******,32.80,
45.00,3230,6090.00,2370.00,5.00,30.00,327.00,1.50,******,37.00,******,32.90,
46.00,3233,6070.00,2360.00,5.00,30.00,325.00,1.50,******,37.00,******,32.70,
47.00,3236,6120.00,2370.00,5.00,30.00,328.00,1.50,******,37.00,******,33.00,
48.00,3239,6100.00,2350.00,5.00,30.00,327.00,1.50,******,37.00,******,32.90,
49.00,3242,6090.00,2350.00,5.00,30.00,326.00,1.50,******,37.00,******,32.80,
50.00,3245,6070.00,2340.00,5.00,30.00,325.00,1.50,******,37.00,******,32.70,
51.00,3248,6090.00,2380.00,5.00,30.00,327.00,1.50,******,37.00,******,32.90,
52.00,3251,6080.00,2350.00,5.00,30.00,326.00,1.50,******,37.00,******,32.80,
53.00,3254,6070.00,2350.00,5.00,30.00,326.00,1.50,******,37.00,******,32.70,
54.00,3257,6080.00,2360.00,5.00,30.00,326.00,1.50,******,37.00,******,32.80,
55.00,3260,6100.00,2360.00,5.00,30.00,327.00,1.50,******,37.00,******,32.90,
56.00,3263,6100.00,2360.00,5.00,30.00,327.00,1.50,******,37.00,******,32.90,
57.00,3266,6100.00,2330.00,5.00,30.00,327.00,1.50,******,37.00,******,32.90,
58.00,3269,6050.00,2350.00,5.00,30.00,325.00,1.50,******,37.00,******,32.60,
59.00,3272,6080.00,2350.00,5.00,30.00,326.00,1.50,******,37.00,******,32.80,
60.00,3275,6100.00,2360.00,5.00,30.00,327.00,1.50,******,37.00,******,32.90,
61.00,3278,6060.00,2360.00,5.00,30.00,325.00,1.50,******,37.00,******,32.70,
62.00,3281,6100.00,2410.00,5.00,30.00,328.00,1.50,******,37.00,******,32.90,
63.00,3284,6070.00,2370.00,5.00,30.00,326.00,1.50,******,37.00,******,32.80,
64.00,3287,6100.00,2350.00,5.00,30.00,327.00,1.50,******,37.00,******,32.90,
65.00,3290,6100.00,2380.00,5.00,30.00,327.00,1.50,******,37.00,******,32.90,
66.00,3293,6110.00,2360.00,5.00,30.00,328.00,1.50,******,37.00,******,32.90,
67.00,3296,6090.00,2370.00,5.00,30.00,327.00,1.50,******,37.00,******,32.90,
68.00,3299,6110.00,2360.00,5.00,30.00,327.00,1.50,******,37.00,******,32.90,
69.00,3302,6110.00,2370.00,5.00,30.00,328.00,1.50,******,37.00,******,33.00,
70.00,3305,6100.00,2360.00,5.00,30.00,327.00,1.50,******,37.00,******,32.90,
71.00,3308,6100.00,2370.00,5.00,30.00,327.00,1.50,******,37.00,******,32.90,
72.00,3311,6100.00,2360.00,5.00,30.00,327.00,1.50,******,37.00,******,32.90,
73.00,3314,6090.00,2340.00,5.00,30.00,327.00,1.50,******,37.00,******,32.80,
74.00,3317,6090.00,2370.00,5.00,30.00,327.00,1.50,******,37.00,******,32.90,
75.00,3320,6060.00,2350.00,5.00,30.00,325.00,1.50,******,37.00,******,32.70,
76.00,3323,6080.00,2370.00,5.00,30.00,326.00,1.50,******,37.00,******,32.80,
77.00,3326,6090.00,2380.00,5.00,30.00,327.00,1.50,******,37.00,******,32.90,
78.00,3329,6110.00,2370.00,5.00,30.00,328.00,1.50,******,37.00,******,32.90,
79.00,3332,6100.00,2390.00,5.00,30.00,328.00,1.50,******,37.00,******,32.90,
80.00,3335,6100.00,2350.00,5.00,30.00,327.00,1.50,******,37.00,******,32.90,
81.00,3338,6110.00,2360.00,5.00,30.00,327.00,1.50,******,37.00,******,32.90,
82.00,3341,6130.00,2340.00,5.00,30.00,328.00,1.50,******,37.00,******,33.00,
83.00,3344,6130.00,2370.00,5.00,30.00,329.00,1.50,******,37.00,******,33.10,
84.00,3347,6140.00,2340.00,5.00,30.00,329.00,1.50,******,37.00,******,33.10,
85.00,3350,6120.00,2340.00,5.00,30.00,328.00,1.50,******,37.00,******,33.00,
86.00,3353,6080.00,2360.00,5.00,30.00,326.00,1.50,******,37.00,******,32.80,
87.00,3356,6130.00,2400.00,5.00,30.00,329.00,1.50,******,37.00,******,33.10,
88.00,3359,6100.00,2360.00,5.00,30.00,327.00,1.50,******,37.00,******,32.80,
89.00,3362,6140.00,2370.00,5.00,30.00,329.00,1.50,******,37.00,******,33.10,
90.00,3365,6130.00,2330.00,5.00,30.00,328.00,1.50,******,37.00,******,33.00,
91.00,3368,6100.00,2380.00,5.00,30.00,327.00,1.50,******,37.00,******,32.90,
92.00,3371,6130.00,2330.00,5.00,30.00,328.00,1.50,******,37.00,******,33.00,
93.00,3374,6120.00,2380.00,5.00,30.00,328.00,1.50,******,37.00,******,33.00,
94.00,3377,6130.00,2370.00,5.00,30.00,328.00,1.50,******,37.00,******,33.00,
95.00,3380,6100.00,2360.00,5.00,30.00,327.00,1.50,******,37.00,******,32.90,
96.00,3383,6090.00,2360.00,5.00,30.00,327.00,1.50,******,37.00,******,32.80,
97.00,3386,6080.00,2370.00,5.00,30.00,326.00,1.50,******,37.00,******,32.80,
98.00,3389,6130.00,2390.00,5.00,30.00,329.00,1.50,******,37.00,******,33.10,
99.00,3392,6110.00,2350.00,5.00,30.00,327.00,1.50,******,37.00,******,32.90,
100.00,3395,6120.00,2370.00,5.00,30.00,328.00,1.50,******,37.00,******,33.00,
101.00,3398,6140.00,2370.00,5.00,30.00,329.00,1.50,******,37.00,******,33.10,
102.00,3401,6130.00,2370.00,5.00,30.00,329.00,1.50,******,37.00,******,33.00,
103.00,3404,6120.00,2380.00,5.00,30.00,328.00,1.50,******,37.00,******,33.00,
104.00,3407,6130.00,2360.00,5.00,30.00,328.00,1.50,******,37.00,******,33.00,
105.00,3410,6120.00,2370.00,5.00,30.00,328.00,1.50,******,37.00,******,33.00,
106.00,3413,6130.00,2390.00,5.00,30.00,329.00,1.50,******,37.00,******,33.10,
107.00,3416,6090.00,2350.00,5.00,30.00,326.00,1.50,******,37.00,******,32.80,
[...]
388.00,11699,6600.00,2590.00,5.00,30.00,355.00,1.50,******,37.00,******,35.70,
389.00,11702,6590.00,2600.00,5.00,30.00,354.00,1.50,******,37.00,******,35.60,
390.00,11705,6610.00,2590.00,5.00,30.00,355.00,1.50,******,37.00,******,35.70,
391.00,11708,6600.00,2610.00,5.00,30.00,355.00,1.50,******,37.00,******,35.70,
392.00,11711,6630.00,2610.00,5.00,30.00,357.00,1.50,******,37.00,******,35.80,
393.00,11714,6600.00,2600.00,5.00,30.00,355.00,1.50,******,37.00,******,35.70,
394.00,11717,6580.00,2580.00,5.00,30.00,354.00,1.50,******,37.00,******,35.50,
395.00,11720,6610.00,2580.00,5.00,30.00,355.00,1.50,******,37.00,******,35.70,
396.00,11723,6590.00,2600.00,5.00,30.00,354.00,1.50,******,37.00,******,35.60,
397.00,11726,6590.00,2600.00,5.00,30.00,354.00,1.50,******,37.00,******,35.60,
398.00,11729,6600.00,2610.00,5.00,30.00,355.00,1.50,******,37.00,******,35.70,
399.00,11732,6610.00,2620.00,5.00,30.00,356.00,1.50,******,37.00,******,35.80,
400.00,11735,6600.00,2580.00,5.00,30.00,354.00,1.50,******,37.00,******,35.60,
401.00,11738,6610.00,2600.00,5.00,30.00,355.00,1.50,******,37.00,******,35.70,
402.00,11741,6600.00,2590.00,5.00,30.00,355.00,1.50,******,37.00,******,35.70,
403.00,11744,6600.00,2620.00,5.00,30.00,355.00,1.50,******,37.00,******,35.70,
404.00,11747,6580.00,2610.00,5.00,30.00,354.00,1.50,******,37.00,******,35.60,
405.00,11750,6600.00,2620.00,5.00,30.00,355.00,1.50,******,37.00,******,35.70,
406.00,11753,6610.00,2600.00,5.00,30.00,355.00,1.50,******,37.00,******,35.70,
407.00,11756,6620.00,2600.00,5.00,30.00,355.00,1.50,******,37.00,******,35.70,
408.00,11759,6620.00,2610.00,5.00,30.00,356.00,1.50,******,37.00,******,35.80,
409.00,11762,6610.00,2600.00,5.00,30.00,355.00,1.50,******,37.00,******,35.70,
410.00,11765,6580.00,2610.00,5.00,30.00,354.00,1.50,******,37.00,******,35.60,
411.00,11768,6610.00,2610.00,5.00,30.00,355.00,1.50,******,37.00,******,35.70,
412.00,11771,6610.00,2600.00,5.00,30.00,355.00,1.50,******,37.00,******,35.70,
413.00,11774,6620.00,2630.00,5.00,30.00,356.00,1.50,******,37.00,******,35.80,
414.00,11777,6620.00,2620.00,5.00,30.00,356.00,1.50,******,37.00,******,35.80,
415.00,11780,6600.00,2600.00,5.00,30.00,355.00,1.50,******,37.00,******,35.70,
416.00,11783,6610.00,2600.00,5.00,30.00,355.00,1.50,******,37.00,******,35.70,
417.00,11786,6620.00,2600.00,5.00,30.00,356.00,1.50,******,37.00,******,35.80,
418.00,11789,6610.00,2600.00,5.00,30.00,355.00,1.50,******,37.00,******,35.70,
419.00,11792,6610.00,2600.00,5.00,30.00,355.00,1.50,******,37.00,******,35.70,
420.00,11795,6620.00,2610.00,5.00,30.00,356.00,1.50,******,37.00,******,35.80,
421.00,11798,6640.00,2610.00,5.00,30.00,357.00,1.50,******,37.00,******,35.90,
422.00,11801,6600.00,2590.00,5.00,30.00,355.00,1.50,******,37.00,******,35.70,
423.00,11804,6600.00,2640.00,5.00,30.00,355.00,1.50,******,37.00,******,35.70,
424.00,11807,6600.00,2610.00,5.00,30.00,355.00,1.50,******,37.00,******,35.70,
425.00,11810,6620.00,2560.00,5.00,30.00,355.00,1.50,******,37.00,******,35.70,
426.00,11813,6610.00,2590.00,5.00,30.00,355.00,1.50,******,37.00,******,35.70,
427.00,11816,6630.00,2600.00,5.00,30.00,356.00,1.50,******,37.00,******,35.80,
428.00,11819,6640.00,2620.00,5.00,30.00,357.00,1.50,******,37.00,******,35.90,
429.00,11822,6620.00,2600.00,5.00,30.00,355.00,1.50,******,37.00,******,35.70,
430.00,11825,6660.00,2590.00,5.00,30.00,357.00,1.50,******,37.00,******,35.90,
431.00,11828,6620.00,2610.00,5.00,30.00,356.00,1.50,******,37.00,******,35.80,
432.00,11831,6630.00,2570.00,5.00,30.00,355.00,1.50,******,37.00,******,35.70,
433.00,11834,6610.00,2570.00,5.00,30.00,355.00,1.50,******,37.00,******,35.70,
434.00,11837,6580.00,2570.00,5.00,30.00,353.00,1.50,******,37.00,******,35.50,
435.00,11840,6590.00,2640.00,5.00,30.00,355.00,1.50,******,37.00,******,35.70,
436.00,11843,6610.00,2600.00,5.00,30.00,355.00,1.50,******,37.00,******,35.70,
437.00,11846,6610.00,2620.00,5.00,30.00,355.00,1.50,******,37.00,******,35.70,
438.00,11849,6610.00,2640.00,5.00,30.00,356.00,1.50,******,37.00,******,35.80,
439.00,11852,6630.00,2600.00,5.00,30.00,356.00,1.50,******,37.00,******,35.80,
440.00,11855,6630.00,2630.00,5.00,30.00,357.00,1.50,******,37.00,******,35.90,
441.00,11858,6620.00,2600.00,5.00,30.00,356.00,1.50,******,37.00,******,35.70,
442.00,11861,6600.00,2600.00,5.00,30.00,354.00,1.50,******,37.00,******,35.60,
443.00,11864,6630.00,2610.00,5.00,30.00,356.00,1.50,******,37.00,******,35.80,
444.00,11867,6610.00,2620.00,5.00,30.00,356.00,1.50,******,37.00,******,35.80,
445.00,11870,6630.00,2580.00,5.00,30.00,356.00,1.50,******,37.00,******,35.80,
446.00,11873,6630.00,2610.00,5.00,30.00,356.00,1.50,******,37.00,******,35.80,
447.00,11876,6640.00,2590.00,5.00,30.00,357.00,1.50,******,37.00,******,35.90,
448.00,11879,6620.00,2610.00,5.00,30.00,356.00,1.50,******,37.00,******,35.80,
449.00,11882,6610.00,2610.00,5.00,30.00,355.00,1.50,******,37.00,******,35.70,
450.00,11885,6640.00,2590.00,5.00,30.00,357.00,1.50,******,37.00,******,35.90,
451.00,11888,6600.00,2590.00,5.00,30.00,354.00,1.50,******,37.00,******,35.60,
452.00,11891,6630.00,2610.00,5.00,30.00,356.00,1.50,******,37.00,******,35.80,
453.00,11894,6620.00,2580.00,5.00,30.00,355.00,1.50,******,37.00,******,35.70,
454.00,11897,6630.00,2600.00,5.00,30.00,356.00,1.50,******,37.00,******,35.80,
455.00,11900,6620.00,2610.00,5.00,30.00,356.00,1.50,******,37.00,******,35.80,
456.00,11903,6640.00,2600.00,5.00,30.00,357.00,1.50,******,37.00,******,35.80,
457.00,11906,6630.00,2610.00,5.00,30.00,356.00,1.50,******,37.00,******,35.80,
458.00,11909,6620.00,2610.00,5.00,30.00,356.00,1.50,******,37.00,******,35.80,
459.00,11912,6640.00,2600.00,5.00,30.00,356.00,1.50,******,37.00,******,35.80,
460.00,11915,6620.00,2590.00,5.00,30.00,355.00,1.50,******,37.00,******,35.70,
461.00,11918,6650.00,2610.00,5.00,30.00,357.00,1.50,******,37.00,******,35.90,
462.00,11921,6640.00,2600.00,5.00,30.00,357.00,1.50,******,37.00,******,35.90,
463.00,11924,6630.00,2620.00,5.00,30.00,356.00,1.50,******,37.00,******,35.80,
464.00,11927,6640.00,2590.00,5.00,30.00,356.00,1.50,******,37.00,******,35.80,
465.00,11930,6630.00,2590.00,5.00,30.00,356.00,1.50,******,37.00,******,35.80,
466.00,11933,6620.00,2610.00,5.00,30.00,356.00,1.50,******,37.00,******,35.80,
467.00,11936,6620.00,2620.00,5.00,30.00,356.00,1.50,******,37.00,******,35.80,
468.00,11939,6590.00,2590.00,5.00,30.00,354.00,1.50,******,37.00,******,35.60,
469.00,11942,6640.00,2600.00,5.00,30.00,356.00,1.50,******,37.00,******,35.80,
470.00,11945,6630.00,2610.00,5.00,30.00,356.00,1.50,******,37.00,******,35.80,
471.00,11948,6660.00,2630.00,5.00,30.00,358.00,1.50,******,37.00,******,36.00,
472.00,11951,6630.00,2630.00,5.00,30.00,357.00,1.50,******,37.00,******,35.90,
473.00,11954,6620.00,2590.00,5.00,30.00,356.00,1.50,******,37.00,******,35.80,
474.00,11957,6630.00,2610.00,5.00,30.00,356.00,1.50,******,37.00,******,35.80,
475.00,11960,6640.00,2600.00,5.00,30.00,356.00,1.50,******,37.00,******,35.80,
476.00,11963,6630.00,2610.00,5.00,30.00,356.00,1.50,******,37.00,******,35.80,
477.00,11966,6660.00,2570.00,5.00,30.00,357.00,1.50,******,37.00,******,35.90,
478.00,11969,6630.00,2600.00,5.00,30.00,356.00,1.50,******,37.00,******,35.80,
479.00,11972,6630.00,2610.00,5.00,30.00,356.00,1.50,******,37.00,******,35.80,
480.00,11975,6640.00,2620.00,5.00,30.00,357.00,1.50,******,37.00,******,35.90,
481.00,11978,6630.00,2600.00,5.00,30.00,356.00,1.50,******,37.00,******,35.80,
482.00,11981,6640.00,2610.00,5.00,30.00,357.00,1.50,******,37.00,******,35.90,
483.00,11984,6640.00,2650.00,5.00,30.00,357.00,1.50,******,37.00,******,35.90,
484.00,11987,6630.00,2620.00,5.00,30.00,356.00,1.50,******,37.00,******,35.80,
485.00,11990,6640.00,2600.00,5.00,30.00,356.00,1.50,******,37.00,******,35.80,
486.00,11993,6630.00,2590.00,5.00,30.00,356.00,1.50,******,37.00,******,35.80,
487.00,11996,6640.00,2590.00,5.00,30.00,357.00,1.50,******,37.00,******,35.90,
488.00,11999,6640.00,2610.00,5.00,30.00,357.00,1.50,******,37.00,******,35.90,
489.00,12002,6650.00,2600.00,5.00,30.00,357.00,1.50,******,37.00,******,35.90,
490.00,12005,6610.00,2640.00,5.00,30.00,356.00,1.50,******,37.00,******,35.80,
491.00,12008,6640.00,2610.00,5.00,30.00,357.00,1.50,******,37.00,******,35.80,
492.00,12011,6640.00,2580.00,5.00,30.00,356.00,1.50,******,37.00,******,35.80,
493.00,12014,6630.00,2600.00,5.00,30.00,356.00,1.50,******,37.00,******,35.80,
494.00,12017,6650.00,2620.00,5.00,30.00,358.00,1.50,******,37.00,******,36.00,
495.00,12020,6630.00,2630.00,5.00,30.00,357.00,1.50,******,37.00,******,35.90,
496.00,12023,6630.00,2620.00,5.00,30.00,357.00,1.50,******,37.00,******,35.90,
497.00,12026,6640.00,2590.00,5.00,30.00,357.00,1.50,******,37.00,******,35.90,
498.00,12029,6640.00,2610.00,5.00,30.00,357.00,1.50,******,37.00,******,35.90,
499.00,12032,6640.00,2610.00,5.00,30.00,357.00,1.50,******,37.00,******,35.90,
500.00,12035,6650.00,2610.00,5.00,30.00,357.00,1.50,******,37.00,******,35.90,
501.00,12038,6630.00,2600.00,5.00,30.00,356.00,1.50,******,37.00,******,35.80,
502.00,12041,6650.00,2610.00,5.00,30.00,357.00,1.50,******,37.00,******,35.90,
503.00,12044,6660.00,2650.00,5.00,30.00,358.00,1.50,******,37.00,******,36.00,
504.00,12047,6630.00,2630.00,5.00,30.00,356.00,1.50,******,37.00,******,35.80,
505.00,12050,6640.00,2600.00,5.00,30.00,357.00,1.50,******,37.00,******,35.90,
506.00,12053,6650.00,2600.00,5.00,30.00,357.00,1.50,******,37.00,******,35.90,
507.00,12056,6660.00,2600.00,5.00,30.00,357.00,1.50,******,37.00,******,35.90,
508.00,12059,6650.00,2610.00,5.00,30.00,357.00,1.50,******,37.00,******,35.90,
509.00,12062,6670.00,2600.00,5.00,30.00,358.00,1.50,******,37.00,******,36.00,
510.00,12065,6640.00,2600.00,5.00,30.00,357.00,1.50,******,37.00,******,35.90,
511.00,12068,6630.00,2600.00,5.00,30.00,356.00,1.50,******,37.00,******,35.80,
512.00,12071,6640.00,2590.00,5.00,30.00,357.00,1.50,******,37.00,******,35.90,
513.00,12074,6640.00,2600.00,5.00,30.00,357.00,1.50,******,37.00,******,35.90,
514.00,12077,6650.00,2610.00,5.00,30.00,357.00,1.50,******,37.00,******,35.90,
515.00,12080,6650.00,2620.00,5.00,30.00,357.00,1.50,******,37.00,******,35.90,
516.00,12083,6640.00,2620.00,5.00,30.00,357.00,1.50,******,37.00,******,35.90,
517.00,12086,6650.00,2610.00,5.00,30.00,357.00,1.50,******,37.00,******,35.90,
518.00,12089,6650.00,2630.00,5.00,30.00,357.00,1.50,******,37.00,******,35.90,
519.00,12092,6640.00,2600.00,5.00,30.00,356.00,1.50,******,37.00,******,35.80,
520.00,12095,6670.00,2630.00,5.00,30.00,359.00,1.50,******,37.00,******,36.10,
521.00,12098,6670.00,2610.00,5.00,30.00,358.00,1.50,******,37.00,******,36.00,
522.00,12101,6640.00,2610.00,5.00,30.00,357.00,1.50,******,37.00,******,35.90,
523.00,12104,6660.00,2630.00,5.00,30.00,358.00,1.50,******,37.00,******,36.00,
524.00,12107,6640.00,2620.00,5.00,30.00,357.00,1.50,******,37.00,******,35.90,
525.00,12110,6640.00,2590.00,5.00,30.00,357.00,1.50,******,37.00,******,35.80,
526.00,12113,6650.00,2610.00,5.00,30.00,357.00,1.50,******,37.00,******,35.90,
527.00,12116,6650.00,2620.00,5.00,30.00,357.00,1.50,******,37.00,******,35.90,
528.00,12119,6630.00,2610.00,5.00,30.00,356.00,1.50,******,37.00,******,35.80,
529.00,12122,6670.00,2610.00,5.00,30.00,358.00,1.50,******,37.00,******,36.00,
530.00,12125,6650.00,2630.00,5.00,30.00,357.00,1.50,******,37.00,******,35.90,
531.00,12128,6650.00,2610.00,5.00,30.00,357.00,1.50,******,37.00,******,35.90,
532.00,12131,6660.00,2610.00,5.00,30.00,357.00,1.50,******,37.00,******,35.90,
533.00,12134,6640.00,2600.00,5.00,30.00,356.00,1.50,******,37.00,******,35.80,
534.00,12137,6670.00,2620.00,5.00,30.00,358.00,1.50,******,37.00,******,36.00,
535.00,12140,6660.00,2590.00,5.00,30.00,357.00,1.50,******,37.00,******,35.90,
536.00,12143,6650.00,2620.00,5.00,30.00,357.00,1.50,******,37.00,******,35.90,
537.00,12146,6650.00,2630.00,5.00,30.00,357.00,1.50,******,37.00,******,35.90,
538.00,12149,6660.00,2620.00,5.00,30.00,358.00,1.50,******,37.00,******,36.00,
539.00,12152,6670.00,2610.00,5.00,30.00,358.00,1.50,******,37.00,******,36.00,
540.00,12155,6680.00,2620.00,5.00,30.00,359.00,1.50,******,37.00,******,36.10,
541.00,12158,6670.00,2600.00,5.00,30.00,358.00,1.50,******,37.00,******,36.00,
542.00,12161,6630.00,2610.00,5.00,30.00,356.00,1.50,******,37.00,******,35.80,
543.00,12164,6670.00,2630.00,5.00,30.00,358.00,1.50,******,37.00,******,36.00,
544.00,12167,6650.00,2610.00,5.00,30.00,357.00,1.50,******,37.00,******,35.90,
545.00,12170,6650.00,2600.00,5.00,30.00,357.00,1.50,******,37.00,******,35.90,
546.00,12173,6670.00,2630.00,5.00,30.00,358.00,1.50,******,37.00,******,36.00,
547.00,12176,6700.00,2590.00,5.00,30.00,359.00,1.50,******,37.00,******,36.10,
548.00,12179,6640.00,2620.00,5.00,30.00,357.00,1.50,******,37.00,******,35.90,
549.00,12182,6660.00,2620.00,5.00,30.00,358.00,1.50,******,37.00,******,36.00,
550.00,12185,6660.00,2610.00,5.00,30.00,358.00,1.50,******,37.00,******,36.00,
551.00,12188,6670.00,2610.00,5.00,30.00,358.00,1.50,******,37.00,******,36.00,
552.00,12191,6670.00,2620.00,5.00,30.00,358.00,1.50,******,37.00,******,36.00,
553.00,12194,6640.00,2600.00,5.00,30.00,357.00,1.50,******,37.00,******,35.90,
554.00,12197,6650.00,2620.00,5.00,30.00,357.00,1.50,******,37.00,******,35.90,
555.00,12200,6660.00,2630.00,5.00,30.00,358.00,1.50,******,37.00,******,36.00,
556.00,12203,6650.00,2620.00,5.00,30.00,357.00,1.50,******,37.00,******,35.90,
557.00,12206,6640.00,2650.00,5.00,30.00,357.00,1.50,******,37.00,******,35.90,
558.00,12209,6660.00,2610.00,5.00,30.00,358.00,1.50,******,37.00,******,36.00,
559.00,12212,6650.00,2620.00,5.00,30.00,357.00,1.50,******,37.00,******,35.90,
560.00,12215,6660.00,2620.00,5.00,30.00,358.00,1.50,******,37.00,******,36.00,
561.00,12218,6660.00,2620.00,5.00,30.00,358.00,1.50,******,37.00,******,36.00,
562.00,12221,6660.00,2590.00,5.00,30.00,357.00,1.50,******,37.00,******,35.90,
563.00,12224,6660.00,2610.00,5.00,30.00,358.00,1.50,******,37.00,******,36.00,
564.00,12227,6670.00,2600.00,5.00,30.00,358.00,1.50,******,37.00,******,36.00,
565.00,12230,6660.00,2610.00,5.00,30.00,358.00,1.50,******,37.00,******,36.00,
566.00,12233,6650.00,2620.00,5.00,30.00,357.00,1.50,******,37.00,******,35.90,
567.00,12236,6650.00,2600.00,5.00,30.00,357.00,1.50,******,37.00,******,35.90,
568.00,12239,6660.00,2620.00,5.00,30.00,358.00,1.50,******,37.00,******,36.00,
569.00,12242,6670.00,2610.00,5.00,30.00,358.00,1.50,******,37.00,******,36.00,
570.00,12245,6660.00,2610.00,5.00,30.00,358.00,1.50,******,37.00,******,35.90,
571.00,12248,6660.00,2630.00,5.00,30.00,358.00,1.50,******,37.00,******,36.00,
572.00,12251,6660.00,2610.00,5.00,30.00,358.00,1.50,******,37.00,******,36.00,
573.00,12254,6650.00,2600.00,5.00,30.00,357.00,1.50,******,37.00,******,35.90,
574.00,12257,6670.00,2600.00,5.00,30.00,358.00,1.50,******,37.00,******,36.00,
575.00,12260,6660.00,2620.00,5.00,30.00,358.00,1.50,******,37.00,******,36.00,
576.00,12263,6670.00,2620.00,5.00,30.00,358.00,1.50,******,37.00,******,36.00,
577.00,12266,6670.00,2620.00,5.00,30.00,358.00,1.50,******,37.00,******,36.00,
578.00,12269,6650.00,2620.00,5.00,30.00,357.00,1.50,******,37.00,******,35.90,
579.00,12272,6660.00,2610.00,5.00,30.00,358.00,1.50,******,37.00,******,35.90,
580.00,12275,6680.00,2630.00,5.00,30.00,359.00,1.50,******,37.00,******,36.10,
581.00,12278,6700.00,2620.00,5.00,30.00,360.00,1.50,******,37.00,******,36.20,
582.00,12281,6670.00,2620.00,5.00,30.00,359.00,1.50,******,37.00,******,36.00,
583.00,12284,6660.00,2620.00,5.00,30.00,358.00,1.50,******,37.00,******,36.00,
584.00,12287,6680.00,2600.00,5.00,30.00,358.00,1.50,******,37.00,******,36.00,
585.00,12290,6660.00,2610.00,5.00,30.00,358.00,1.50,******,37.00,******,36.00,
586.00,12293,6680.00,2610.00,5.00,30.00,358.00,1.50,******,37.00,******,36.00,
587.00,12296,6660.00,2610.00,5.00,30.00,358.00,1.50,******,37.00,******,36.00,
588.00,12299,6660.00,2620.00,5.00,30.00,358.00,1.50,******,37.00,******,36.00,
589.00,12302,6650.00,2620.00,5.00,30.00,357.00,1.50,******,37.00,******,35.90,
590.00,12305,6670.00,2620.00,5.00,30.00,358.00,1.50,******,37.00,******,36.00,
591.00,12308,6660.00,2640.00,5.00,30.00,358.00,1.50,******,37.00,******,36.00,
592.00,12311,6670.00,2630.00,5.00,30.00,359.00,1.50,******,37.00,******,36.10,
593.00,12314,6670.00,2620.00,5.00,30.00,358.00,1.50,******,37.00,******,36.00,
594.00,12317,6680.00,2600.00,5.00,30.00,358.00,1.50,******,37.00,******,36.00,
595.00,12320,6640.00,2630.00,5.00,30.00,357.00,1.50,******,37.00,******,35.90,
596.00,12323,6690.00,2620.00,5.00,30.00,359.00,1.50,******,37.00,******,36.10,
597.00,12326,6680.00,2600.00,5.00,30.00,358.00,1.50,******,37.00,******,36.00,
598.00,12329,6650.00,2600.00,5.00,30.00,357.00,1.50,******,37.00,******,35.90,
599.00,12332,6680.00,2630.00,5.00,30.00,359.00,1.50,******,37.00,******,36.10,
600.00,12335,6670.00,2620.00,5.00,30.00,358.00,1.50,******,37.00,******,36.00,
,,,,,,,,,,,,
Interval:,,,15.00,,,,,,,,,
Number of Data Points:,,,28.00,,,,,,,,,
,,,,,,,,,,,,
Time Setting:,,,28 Meas. Pts.,,,,,,,,,
,,,Meas. Pt. Duration 6.4285714 s,,,,,,,,,
Event Control:,,,Standard Mode,,,,,,,,,
"  Terminate test, ...",,,...if d(gamma)/dt > 1000 1/s,,,,,,,,,
"  Terminate test, ...",,,...if M > 200 mNm,,,,,,,,,
"  Terminate test, ...",,,...if FN < -50 N or > 50 N,,,,,,,,,
Measuring Profile:,,,,,,,,,,,,
  Shear Rate,,,d(gamma)/dt = 0.1 ... 50 1/s log; |Slope| = 10.003816 Pt. / dec ,,,,,,,,,
,,,,,,,,,,,,
Meas. Pts.,Time,Storage Modulus,Loss Modulus,Strain,Angular Frequency,Shear Stress,Shear Rate,Viscosity,Temperature,Speed,Torque,Status
,[s],[Pa],[Pa],[%],[rad/s],[Pa],[1/s],[Pa·s],[°C],[1/min],[µNm],[]
1.00,12300,******,******,48.50,******,111.00,0.10,1110.00,37.00,0.12,11.10,Dy_auto
2.00,12300,******,******,125.00,******,141.00,0.13,1120.00,37.00,0.15,14.20,Dy_auto
3.00,12400,******,******,222.00,******,178.00,0.16,1120.00,37.00,0.19,17.90,Dy_auto
4.00,12400,******,******,343.00,******,221.00,0.20,1110.00,37.00,0.24,22.30,Dy_auto
5.00,12400,******,******,496.00,******,274.00,0.25,1090.00,37.00,0.30,27.50,Dy_auto
6.00,12400,******,******,689.00,******,340.00,0.32,1070.00,37.00,0.38,34.20,Dy_auto
7.00,12400,******,******,931.00,******,421.00,0.40,1060.00,37.00,0.48,42.30,Dy_auto
8.00,12400,******,******,1240.00,******,524.00,0.50,1050.00,37.00,0.60,52.70,Dy_auto
9.00,12400,******,******,1620.00,******,652.00,0.63,1030.00,37.00,0.75,65.60,Dy_auto
10.00,12400,******,******,2100.00,******,809.00,0.79,1020.00,37.00,0.95,81.40,Dy_auto
11.00,12400,******,******,2710.00,******,1000.00,1.00,1010.00,37.00,1.19,101.00,Dy_auto
12.00,12400,******,******,3480.00,******,1250.00,1.26,990.00,37.00,1.50,125.00,Dy_auto
13.00,12400,******,******,4440.00,******,1550.00,1.58,978.00,37.00,1.89,156.00,Dy_auto
14.00,12400,******,******,5660.00,******,1910.00,1.99,959.00,37.00,2.38,192.00,Dy_auto
15.00,12400,******,******,7190.00,******,2350.00,2.51,935.00,37.00,2.99,236.00,Dy_auto
16.00,12400,******,******,9110.00,******,2920.00,3.16,924.00,37.00,3.77,293.00,Dy_auto
17.00,12400,******,******,11500.00,******,3670.00,3.98,923.00,37.00,4.74,369.00,Dy_auto
18.00,12500,******,******,14600.00,******,4510.00,5.00,901.00,37.00,5.97,453.00,Dy_auto
19.00,12500,******,******,18400.00,******,5340.00,6.30,848.00,37.00,7.52,537.00,Dy_auto
20.00,12500,******,******,23300.00,******,4370.00,7.93,551.00,37.00,9.47,439.00,Dy_auto
21.00,12500,******,******,29300.00,******,2610.00,9.99,261.00,37.00,11.90,262.00,Dy_auto
22.00,12500,******,******,37000.00,******,1660.00,12.60,132.00,37.00,15.00,167.00,Dy_auto
23.00,12500,******,******,46600.00,******,950.00,15.80,60.10,37.00,18.90,95.50,Dy_auto
24.00,12500,******,******,58800.00,******,668.00,19.90,33.60,37.00,23.80,67.20,Dy_auto
25.00,12500,******,******,74100.00,******,490.00,25.10,19.50,37.00,29.90,49.20,Dy_auto
26.00,12500,******,******,93300.00,******,263.00,31.60,8.33,37.00,37.70,26.40,Dy_auto
27.00,12500,******,******,117000.00,******,128.00,39.70,3.23,37.00,47.40,12.90,Dy_auto
28.00,12500,******,******,148000.00,******,59.30,50.00,1.19,37.00,59.70,5.96,Dy_auto