File: exampledata/PXP_N1.csv
Meas. Pts.,Time,Storage Modulus,Loss Modulus,Strain,Angular Frequency,Shear Stress,Shear Rate,Viscosity,Temperature,Speed,Torque,Status
,[s],[Pa],[Pa],[%],[rad/s],[Pa],[1/s],[Pa·s],[°C],[1/min],[µNm],[]
1.00,5,3020.00,2330.00,4.99,30.00,190.00,1.50,******,37.00,******,19.10,WMa
2.00,10,3130.00,1630.00,5.00,30.00,176.00,1.50,******,37.00,******,17.70,
3.00,15,3230.00,1690.00,5.00,30.00,182.00,1.50,******,37.00,******,18.30,
4.00,20,3350.00,1750.00,5.00,30.00,189.00,1.50,******,37.00,******,19.00,
5.00,25,3490.00,1850.00,5.00,30.00,198.00,1.50,******,37.00,******,19.90,
6.00,30,3640.00,1920.00,5.00,30.00,206.00,1.50,******,37.00,******,20.70,
7.00,35,3830.00,2020.00,5.00,30.00,216.00,1.50,******,37.00,******,21.80,
8.00,40,3950.00,2090.00,5.00,30.00,224.00,1.50,******,37.00,******,22.50,
9.00,45,4070.00,2170.00,5.00,30.00,230.00,1.50,******,37.00,******,23.20,
10.00,50,4150.00,2210.00,5.00,30.00,235.00,1.50,******,37.00,******,23.60,
11.00,55,4240.00,2270.00,5.00,30.00,241.00,1.50,******,37.00,******,24.20,
12.00,60,4340.00,2340.00,5.00,30.00,247.00,1.50,******,37.00,******,24.80,
13.00,65,4420.00,2370.00,5.00,30.00,251.00,1.50,******,37.00,******,25.20,
14.00,70,4490.00,2430.00,5.00,30.00,255.00,1.50,******,37.00,******,25.70,
15.00,75,4560.00,2470.00,5.00,30.00,259.00,1.50,******,37.00,******,26.00,
16.00,80,4640.00,2520.00,5.00,30.00,264.00,1.50,******,37.00,******,26.50,
17.00,85,4690.00,2550.00,5.00,30.00,267.00,1.50,******,37.00,******,26.80,
18.00,90,4740.00,2580.00,5.00,30.00,270.00,1.50,******,37.00,******,27.10,
19.00,95,4760.00,2600.00,5.00,30.00,271.00,1.50,******,37.00,******,27.30,
20.00,100,4820.00,2630.00,5.00,30.00,275.00,1.50,******,37.00,******,27.60,
21.00,105,4860.00,2660.00,5.00,30.00,277.00,1.50,******,37.00,******,27.80,
22.00,110,4920.00,2700.00,5.00,30.00,281.00,1.50,******,37.00,******,28.20,
23.00,115,4950.00,2720.00,5.00,30.00,283.00,1.50,******,37.00,******,28.40,
24.00,120,4990.00,2740.00,5.00,30.00,284.00,1.50,******,37.00,******,28.60,
25.00,125,5000.00,2760.00,5.00,30.00,286.00,1.50,******,37.00,******,28.70,
26.00,130,5030.00,2810.00,5.00,30.00,288.00,1.50,******,37.00,******,28.90,
27.00,135,5070.00,2790.00,5.00,30.00,289.00,1.50,******,37.00,******,29.10,
28.00,140,5100.00,2820.00,5.00,30.00,291.00,1.50,******,37.00,******,29.30,
29.00,145,5090.00,2830.00,5.00,30.00,291.00,1.50,******,37.00,******,29.30,
30.00,150,5110.00,2840.00,5.00,30.00,292.00,1.50,******,37.00,******,29.40,
31.00,155,5110.00,2830.00,5.00,30.00,292.00,1.50,******,37.00,******,29.40,
32.00,160,5120.00,2860.00,5.00,30.00,293.00,1.50,******,37.00,******,29.50,
33.00,165,5130.00,2860.00,5.00,30.00,293.00,1.50,******,37.00,******,29.50,
34.00,170,5150.00,2860.00,5.00,30.00,295.00,1.50,******,37.00,******,29.60,
35.00,175,5150.00,2870.00,5.00,30.00,295.00,1.50,******,37.00,******,29.60,
36.00,180,5170.00,2870.00,5.00,30.00,296.00,1.50,******,37.00,******,29.70,
37.00,185,5170.00,2890.00,5.00,30.00,296.00,1.50,******,37.00,******,29.80,
38.00,190,5160.00,2880.00,5.00,30.00,296.00,1.50,******,37.00,******,29.70,
39.00,195,5160.00,2900.00,5.00,30.00,296.00,1.50,******,37.00,******,29.80,
40.00,200,5170.00,2900.00,5.00,30.00,297.00,1.50,******,37.00,******,29.80,
41.00,205,5180.00,2900.00,5.00,30.00,297.00,1.50,******,37.00,******,29.90,
42.00,210,5180.00,2900.00,5.00,30.00,297.00,1.50,******,37.00,******,29.90,
43.00,215,5190.00,2900.00,5.00,30.00,297.00,1.50,******,37.00,******,29.90,
44.00,220,5180.00,2910.00,5.00,30.00,297.00,1.50,******,37.00,******,29.90,
45.00,225,5210.00,2900.00,5.00,30.00,298.00,1.50,******,37.00,******,30.00,
46.00,230,5180.00,2910.00,5.00,30.00,297.00,1.50,******,37.00,******,29.90,
47.00,235,5190.00,2920.00,5.00,30.00,298.00,1.50,******,37.00,******,29.90,
48.00,240,5190.00,2920.00,5.00,30.00,298.00,1.50,******,37.00,******,30.00,
49.00,245,5200.00,2920.00,5.00,30.00,298.00,1.50,******,37.00,******,30.00,
50.00,250,5180.00,2890.00,5.00,30.00,297.00,1.50,******,37.00,******,29.80,
51.00,255,5190.00,2940.00,5.00,30.00,298.00,1.50,******,37.00,******,30.00,
52.00,260,5210.00,2930.00,5.00,30.00,299.00,1.50,******,37.00,******,30.00,
53.00,265,5210.00,2940.00,5.00,30.00,299.00,1.50,******,37.00,******,30.10,
54.00,270,5210.00,2930.00,5.00,30.00,299.00,1.50,******,37.00,******,30.10,
55.00,275,5210.00,2940.00,5.00,30.00,299.00,1.50,******,37.00,******,30.10,
56.00,280,5200.00,2930.00,5.00,30.00,298.00,1.50,******,37.00,******,30.00,
57.00,285,5200.00,2940.00,5.00,30.00,299.00,1.50,******,37.00,******,30.00,
58.00,290,5200.00,2940.00,5.00,30.00,299.00,1.50,******,37.00,******,30.00,
59.00,295,5200.00,2940.00,5.00,30.00,299.00,1.50,******,37.00,******,30.00,
60.00,300,5200.00,2950.00,5.00,30.00,299.00,1.50,******,37.00,******,30.10,
61.00,305,5220.00,2930.00,5.00,30.00,300.00,1.50,******,37.00,******,30.10,
62.00,310,5210.00,2940.00,5.00,30.00,299.00,1.50,******,37.00,******,30.10,
63.00,315,5220.00,2940.00,5.00,30.00,299.00,1.50,******,37.00,******,30.10,
64.00,320,5210.00,2940.00,5.00,30.00,299.00,1.50,******,37.00,******,30.10,
65.00,325,5220.00,2940.00,5.00,30.00,300.00,1.50,******,37.00,******,30.10,
66.00,330,5210.00,2940.00,5.00,30.00,299.00,1.50,******,37.00,******,30.10,
67.00,335,5210.00,2950.00,5.00,30.00,299.00,1.50,******,37.00,******,30.10,
68.00,340,5210.00,2950.00,5.00,30.00,299.00,1.50,******,37.00,******,30.10,
69.00,345,5210.00,2960.00,5.00,30.00,300.00,1.50,******,37.00,******,30.10,
70.00,350,5210.00,2950.00,5.00,30.00,300.00,1.50,******,37.00,******,30.10,
71.00,355,5230.00,2950.00,5.00,30.00,300.00,1.50,******,37.00,******,30.20,
72.00,360,5220.00,2950.00,5.00,30.00,300.00,1.50,******,37.00,******,30.10,
73.00,365,5210.00,2960.00,5.00,30.00,300.00,1.50,******,37.00,******,30.10,
74.00,370,5230.00,2970.00,5.00,30.00,301.00,1.50,******,37.00,******,30.20,
75.00,375,5210.00,2950.00,5.00,30.00,300.00,1.50,******,37.00,******,30.10,
76.00,380,5210.00,2960.00,5.00,30.00,300.00,1.50,******,37.00,******,30.10,
77.00,385,5210.00,2950.00,5.00,30.00,299.00,1.50,******,37.00,******,30.10,
78.00,390,5210.00,2960.00,5.00,30.00,300.00,1.50,******,37.00,******,30.10,
79.00,395,5230.00,2950.00,5.00,30.00,300.00,1.50,******,37.00,******,30.20,
80.00,400,5220.00,2960.00,5.00,30.00,300.00,1.50,******,37.00,******,30.20,
,,,,,,,,,,,,
Interval:,,,2.00,,,,,,,,,
Number of Data Points:,,,31.00,,,,,,,,,
,,,,,,,,,,,,
Time Setting:,,,31 Meas. Pts.,,,,,,,,,
Measuring Profile:,,,,,,,,,,,,
#NAME?,,,Amplitude gamma = 5 %,,,,,,,,,
,,,Angular Frequency omega = 100 ... 0.1 rad/s log; |Slope| = 10 Pt. / dec ,,,,,,,,,
,,,,,,,,,,,,
Meas. Pts.,Time,Storage Modulus,Loss Modulus,Strain,Angular Frequency,Shear Stress,Shear Rate,Viscosity,Temperature,Speed,Torque,Status
,[s],[Pa],[Pa],[%],[rad/s],[Pa],[1/s],[Pa·s],[°C],[1/min],[µNm],[]
1.00,410,8180.00,2420.00,5.00,100.00,426.00,5.00,******,37.00,******,42.90,
2.00,418,7590.00,2130.00,5.00,79.40,394.00,3.97,******,37.00,******,39.60,
3.00,425,7010.00,2410.00,5.00,63.10,370.00,3.15,******,37.00,******,37.20,
4.00,432,6440.00,2540.00,5.00,50.10,346.00,2.51,******,37.00,******,34.80,
5.00,439,5920.00,2750.00,5.00,39.80,326.00,1.99,******,37.00,******,32.80,
6.00,448,5360.00,2940.00,5.00,31.60,306.00,1.58,******,37.00,******,30.70,
7.00,458,4780.00,3060.00,5.00,25.10,284.00,1.26,******,37.00,******,28.50,
8.00,465,4170.00,3130.00,5.00,20.00,260.00,1.00,******,37.00,******,26.20,
9.00,472,3540.00,3120.00,5.00,15.80,236.00,0.79,******,37.00,******,23.70,
10.00,478,2930.00,3040.00,5.00,12.60,211.00,0.63,******,37.00,******,21.20,
11.00,486,2370.00,2880.00,5.00,10.00,186.00,0.50,******,37.00,******,18.70,
12.00,493,1860.00,2660.00,5.00,7.94,162.00,0.40,******,37.00,******,16.30,
13.00,502,1420.00,2390.00,5.00,6.31,139.00,0.32,******,37.00,******,14.00,
14.00,509,1050.00,2110.00,5.00,5.01,118.00,0.25,******,37.00,******,11.80,
15.00,517,766.00,1810.00,5.01,3.98,98.30,0.20,******,37.00,******,9.89,
16.00,527,545.00,1530.00,5.01,3.16,81.50,0.16,******,37.00,******,8.19,
17.00,540,381.00,1280.00,5.01,2.51,66.80,0.13,******,37.00,******,6.72,
18.00,560,264.00,1050.00,5.01,2.00,54.40,0.10,******,37.00,******,5.47,
19.00,586,182.00,861.00,5.01,1.58,44.10,0.08,******,37.00,******,4.43,
20.00,617,125.00,699.00,5.01,1.26,35.60,0.06,******,37.00,******,3.57,
21.00,656,87.00,565.00,5.01,1.00,28.60,0.05,******,37.00,******,2.88,
22.00,693,60.50,455.00,5.01,0.79,23.00,0.04,******,37.00,******,2.31,
23.00,739,43.20,366.00,5.01,0.63,18.50,0.03,******,37.00,******,1.86,
24.00,797,31.20,294.00,5.01,0.50,14.80,0.03,******,37.00,******,1.49,
25.00,869,23.00,235.00,5.01,0.40,11.80,0.02,******,37.00,******,1.19,
26.00,929,17.50,189.00,5.01,0.32,9.52,0.02,******,37.00,******,0.96,
27.00,1010,13.80,152.00,5.01,0.25,7.63,0.01,******,37.00,******,0.77,
28.00,1100,11.10,122.00,5.01,0.20,6.12,0.01,******,37.00,******,0.62,
29.00,1220,9.20,97.90,5.01,0.16,4.93,0.01,******,37.00,******,0.50,
30.00,1450,7.82,78.70,5.01,0.13,3.96,0.01,******,37.00,******,0.40,
31.00,1730,6.96,63.60,5.01,0.10,3.20,0.01,******,37.00,******,0.32,
,,,,,,,,,,,,
Interval:,,,3.00,,,,,,,,,
Number of Data Points:,,,80.00,,,,,,,,,
,,,,,,,,,,,,
Time Setting:,,,80 Meas. Pts.,,,,,,,,,
,,,Meas. Pt. Duration 5 s,,,,,,,,,
Event Control:,,,Standard Mode,,,,,,,,,
"  Terminate test, ...",,,...if M > 75 mNm,,,,,,,,,
Measuring Profile:,,,,,,,,,,,,
#NAME?,,,Amplitude gamma = 5 %,,,,,,,,,
,,,Angular Frequency omega = 30 rad/s,,,,,,,,,
,,,,,,,,,,,,
Meas. Pts.,Time,Storage Modulus,Loss Modulus,Strain,Angular Frequency,Shear Stress,Shear Rate,Viscosity,Temperature,Speed,Torque,Status
,[s],[Pa],[Pa],[%],[rad/s],[Pa],[1/s],[Pa·s],[°C],[1/min],[µNm],[]
1.00,invalid point,,,,,,,,,,,
2.00,1740,,,,,,,,,,,
3.00,1745,,,,,,,,,,,
4.00,1750,,,,,,,,,,,
5.00,1755,,,,,,,,,,,
6.00,1760,,,,,,,,,,,
7.00,1765,,,,,,,,,,,
8.00,1770,,,,,,,,,,,
9.00,1775,,,,,,,,,,,
10.00,1780,,,,,,,,,,,
11.00,1785,,,,,,,,,,,
12.00,1790,,,,,,,,,,,
13.00,1795,,,,,,,,,,,
14.00,1800,,,,,,,,,,,
15.00,1805,,,,,,,,,,,
16.00,1810,,,,,,,,,,,
17.00,1815,,,,,,,,,,,
18.00,1820,,,,,,,,,,,
19.00,1825,,,,,,,,,,,
20.00,1830,5230.00,1870.00,5.17,30.00,288.00,1.55,******,37.00,******,28.90,WMa
21.00,1835,5300.00,3040.00,5.00,30.00,305.00,1.50,******,37.00,******,30.70,
22.00,1840,5300.00,3040.00,5.00,30.00,306.00,1.50,******,37.00,******,30.70,
23.00,1845,5300.00,3010.00,5.00,30.00,305.00,1.50,******,37.00,******,30.70,
24.00,1850,5300.00,3040.00,5.00,30.00,305.00,1.50,******,37.00,******,30.70,
25.00,1855,5300.00,3030.00,5.00,30.00,305.00,1.50,******,37.00,******,30.70,
26.00,1860,5290.00,3030.00,5.00,30.00,305.00,1.50,******,37.00,******,30.60,
27.00,1865,5300.00,3040.00,5.00,30.00,305.00,1.50,******,37.00,******,30.70,
28.00,1870,5310.00,3030.00,5.00,30.00,306.00,1.50,******,37.00,******,30.70,
29.00,1875,5300.00,3030.00,5.00,30.00,305.00,1.50,******,37.00,******,30.70,
30.00,1880,5300.00,3020.00,5.00,30.00,305.00,1.50,******,37.00,******,30.70,
31.00,1885,5290.00,3020.00,5.00,30.00,305.00,1.50,******,37.00,******,30.60,
32.00,1890,5310.00,3040.00,5.00,30.00,306.00,1.50,******,37.00,******,30.70,
33.00,1895,5300.00,3040.00,5.00,30.00,305.00,1.50,******,37.00,******,30.70,
34.00,1900,5300.00,3030.00,5.00,30.00,306.00,1.50,******,37.00,******,30.70,
35.00,1905,5290.00,3030.00,5.00,30.00,305.00,1.50,******,37.00,******,30.70,
36.00,1910,5290.00,3050.00,5.00,30.00,305.00,1.50,******,37.00,******,30.70,
37.00,1915,5300.00,3030.00,5.00,30.00,305.00,1.50,******,37.00,******,30.70,
38.00,1920,5300.00,3030.00,5.00,30.00,305.00,1.50,******,37.00,******,30.70,
39.00,1925,5300.00,3030.00,5.00,30.00,305.00,1.50,******,37.00,******,30.70,
40.00,1930,5300.00,3030.00,5.00,30.00,305.00,1.50,******,37.00,******,30.70,
41.00,1935,5300.00,3030.00,5.00,30.00,305.00,1.50,******,37.00,******,30.70,
42.00,1940,5300.00,3050.00,5.00,30.00,306.00,1.50,******,37.00,******,30.70,
43.00,1945,5310.00,3030.00,5.00,30.00,305.00,1.50,******,37.00,******,30.70,
44.00,1950,5310.00,3040.00,5.00,30.00,306.00,1.50,******,37.00,******,30.70,
45.00,1955,5300.00,3040.00,5.00,30.00,306.00,1.50,******,37.00,******,30.70,
46.00,1960,5300.00,3040.00,5.00,30.00,305.00,1.50,******,37.00,******,30.70,
47.00,1965,5300.00,3040.00,5.00,30.00,306.00,1.50,******,37.00,******,30.70,
48.00,1970,5300.00,3040.00,5.00,30.00,305.00,1.50,******,37.00,******,30.70,
49.00,1975,5310.00,3020.00,5.00,30.00,306.00,1.50,******,37.00,******,30.70,
50.00,1980,5310.00,3040.00,5.00,30.00,306.00,1.50,******,37.00,******,30.70,
51.00,1985,5300.00,3040.00,5.00,30.00,305.00,1.50,******,37.00,******,30.70,
52.00,1990,5310.00,3030.00,5.00,30.00,306.00,1.50,******,37.00,******,30.70,
53.00,1995,5290.00,3030.00,5.00,30.00,305.00,1.50,******,37.00,******,30.70,
54.00,2000,5300.00,3030.00,5.00,30.00,305.00,1.50,******,37.00,******,30.70,
55.00,2005,5310.00,3030.00,5.00,30.00,306.00,1.50,******,37.00,******,30.70,
56.00,2010,5300.00,3040.00,5.00,30.00,305.00,1.50,******,37.00,******,30.70,
57.00,2015,5290.00,3000.00,5.00,30.00,304.00,1.50,******,37.00,******,30.60,
58.00,2020,5310.00,3030.00,5.00,30.00,306.00,1.50,******,37.00,******,30.70,
59.00,2025,5300.00,3040.00,5.00,30.00,306.00,1.50,******,37.00,******,30.70,
60.00,2030,5300.00,3030.00,5.00,30.00,305.00,1.50,******,37.00,******,30.70,
61.00,2035,5310.00,3030.00,5.00,30.00,306.00,1.50,******,37.00,******,30.70,
62.00,2040,5280.00,3030.00,5.00,30.00,304.00,1.50,******,37.00,******,30.60,
63.00,2045,5310.00,3040.00,5.00,30.00,306.00,1.50,******,37.00,******,30.70,
64.00,2050,5300.00,3040.00,5.00,30.00,306.00,1.50,******,37.00,******,30.70,
65.00,2055,5300.00,3030.00,5.00,30.00,305.00,1.50,******,37.00,******,30.70,
66.00,2060,5300.00,3040.00,5.00,30.00,306.00,1.50,******,37.00,******,30.70,
67.00,2065,5310.00,3020.00,5.00,30.00,305.00,1.50,******,37.00,******,30.70,
68.00,2070,5300.00,3040.00,5.00,30.00,305.00,1.50,******,37.00,******,30.70,
69.00,2075,5300.00,3040.00,5.00,30.00,306.00,1.50,******,37.00,******,30.70,
70.00,2080,5310.00,3030.00,5.00,30.00,306.00,1.50,******,37.00,******,30.70,
71.00,2085,5290.00,3040.00,5.00,30.00,305.00,1.50,******,37.00,******,30.70,
72.00,2090,5300.00,3030.00,5.00,30.00,306.00,1.50,******,37.00,******,30.70,
73.00,2095,5310.00,3030.00,5.00,30.00,306.00,1.50,******,37.00,******,30.80,
74.00,2100,5280.00,3030.00,5.00,30.00,304.00,1.50,******,37.00,******,30.60,
75.00,2105,5300.00,3040.00,5.00,30.00,306.00,1.50,******,37.00,******,30.70,
76.00,2110,5300.00,3040.00,5.00,30.00,306.00,1.50,******,37.00,******,30.70,
77.00,2115,5290.00,3050.00,5.00,30.00,305.00,1.50,******,37.00,******,30.70,
78.00,2120,5300.00,3040.00,5.00,30.00,305.00,1.50,******,37.00,******,30.70,
79.00,2125,5310.00,3030.00,5.00,30.00,306.00,1.50,******,37.00,******,30.70,
80.00,2130,5290.00,3040.00,5.00,30.00,305.00,1.50,******,37.00,******,30.70,
,,,,,,,,,,,,
Interval:,,,4.00,,,,,,,,,
Number of Data Points:,,,113.00,,,,,,,,,
,,,,,,,,,,,,
Time Setting:,,,113 Meas. Pts.,,,,,,,,,
,,,Meas. Pt. Duration 5 s,,,,,,,,,
Measuring Profile:,,,,,,,,,,,,
#NAME?,,,Amplitude gamma = 0.1 ... 500 % log; |Slope| = 30.278699 Pt. / dec ,,,,,,,,,
,,,Angular Frequency omega = 30 rad/s,,,,,,,,,
,,,,,,,,,,,,
Meas. Pts.,Time,Storage Modulus,Loss Modulus,Strain,Angular Frequency,Shear Stress,Shear Rate,Viscosity,Temperature,Speed,Torque,Status
,[s],[Pa],[Pa],[%],[rad/s],[Pa],[1/s],[Pa·s],[°C],[1/min],[µNm],[]
1.00,2135,0.00,10500.00,0.10,30.00,10.60,0.03,******,37.00,******,1.06,"MV-,WMa"
2.00,2140,0.00,51900.00,0.11,30.00,55.70,0.03,******,37.00,******,5.60,"MV-,WMa"
3.00,2145,26300.00,2610.00,0.11,30.00,30.10,0.03,******,37.00,******,3.02,WMa
4.00,2150,10100.00,9010.00,0.13,30.00,17.50,0.04,******,37.00,******,1.76,"ME-,MV-"
5.00,2155,4280.00,932.00,0.14,30.00,5.95,0.04,******,37.00,******,0.60,WMa
6.00,2160,0.00,10100.00,0.15,30.00,14.80,0.04,******,37.00,******,1.49,"ME-,WMa"
7.00,2165,22900.00,2620.00,0.16,30.00,36.50,0.05,******,37.00,******,3.67,WMa
8.00,2170,0.00,1820.00,0.18,30.00,3.18,0.05,******,37.00,******,0.32,"MV-,WMa"
9.00,2175,4480.00,3340.00,0.18,30.00,10.20,0.05,******,37.00,******,1.03,
10.00,2180,4160.00,3240.00,0.20,30.00,10.50,0.06,******,37.00,******,1.05,
11.00,2185,4700.00,3120.00,0.21,30.00,12.10,0.06,******,37.00,******,1.21,
12.00,2190,1010.00,3040.00,0.23,30.00,7.41,0.07,******,37.00,******,0.75,"ME-,MV-"
13.00,2195,4930.00,2850.00,0.25,30.00,14.20,0.07,******,37.00,******,1.43,
14.00,2200,5460.00,2740.00,0.27,30.00,16.50,0.08,******,37.00,******,1.66,WMa
15.00,2205,5550.00,2230.00,0.29,30.00,17.60,0.09,******,37.00,******,1.77,WMa
16.00,2210,5070.00,2780.00,0.32,30.00,18.30,0.09,******,37.00,******,1.84,WMa
17.00,2215,4850.00,0.00,0.34,30.00,16.40,0.10,******,37.00,******,1.65,"MV-,WMa"
18.00,2220,0.00,10000.00,0.37,30.00,36.70,0.11,******,37.00,******,3.69,"ME-,WMa"
19.00,2225,6120.00,3930.00,0.39,30.00,28.20,0.12,******,37.00,******,2.84,WMa
20.00,2230,10500.00,11300.00,0.42,30.00,65.50,0.13,******,37.00,******,6.59,WMa
21.00,2235,4830.00,7230.00,0.46,30.00,40.00,0.14,******,37.00,******,4.02,WMa
22.00,2240,5080.00,3100.00,0.49,30.00,29.40,0.15,******,37.00,******,2.96,
23.00,2245,10200.00,3300.00,0.54,30.00,57.60,0.16,******,37.00,******,5.79,WMa
24.00,2250,7640.00,6640.00,0.58,30.00,58.50,0.17,******,37.00,******,5.88,WMa
25.00,2255,2590.00,10500.00,0.62,30.00,67.20,0.19,******,37.00,******,6.75,WMa
26.00,2260,5120.00,3080.00,0.67,30.00,39.90,0.20,******,37.00,******,4.01,
27.00,2265,2340.00,3140.00,0.72,30.00,28.10,0.22,******,37.00,******,2.82,WMa
28.00,2270,5170.00,3050.00,0.78,30.00,46.80,0.23,******,37.00,******,4.71,
29.00,2275,5340.00,2740.00,0.84,30.00,50.60,0.25,******,37.00,******,5.08,WMa
30.00,2280,5210.00,3300.00,0.91,30.00,56.10,0.27,******,37.00,******,5.64,WMa
31.00,2285,3710.00,2270.00,0.98,30.00,42.80,0.30,******,37.00,******,4.30,WMa
32.00,2290,5120.00,2660.00,1.06,30.00,61.00,0.32,******,37.00,******,6.14,WMa
33.00,2295,5700.00,1690.00,1.14,30.00,67.80,0.34,******,37.00,******,6.82,WMa
34.00,2300,4080.00,3490.00,1.23,30.00,66.20,0.37,******,37.00,******,6.66,WMa
35.00,2305,5410.00,3080.00,1.33,30.00,82.60,0.40,******,37.00,******,8.30,
36.00,2310,5600.00,3520.00,1.43,30.00,94.70,0.43,******,37.00,******,9.52,WMa
37.00,2315,4830.00,4630.00,1.55,30.00,103.00,0.46,******,37.00,******,10.40,WMa
38.00,2320,3860.00,3860.00,1.67,30.00,91.00,0.50,******,37.00,******,9.15,WMa
39.00,2325,5400.00,3060.00,1.80,30.00,112.00,0.54,******,37.00,******,11.20,
40.00,2330,5430.00,3230.00,1.94,30.00,123.00,0.58,******,37.00,******,12.30,WMa
41.00,2335,5230.00,3740.00,2.10,30.00,135.00,0.63,******,37.00,******,13.50,WMa
42.00,2340,6230.00,2570.00,2.26,30.00,152.00,0.68,******,37.00,******,15.30,WMa
43.00,2345,5740.00,3180.00,2.44,30.00,160.00,0.73,******,37.00,******,16.10,WMa
44.00,2350,4830.00,1870.00,2.63,30.00,136.00,0.79,******,37.00,******,13.70,WMa
45.00,2355,5310.00,3150.00,2.84,30.00,175.00,0.85,******,37.00,******,17.60,WMa
46.00,2360,5080.00,3150.00,3.07,30.00,183.00,0.92,******,37.00,******,18.40,WMa
47.00,2365,5810.00,3310.00,3.31,30.00,221.00,0.99,******,37.00,******,22.20,WMa
48.00,2370,4930.00,2020.00,3.57,30.00,190.00,1.07,******,37.00,******,19.10,WMa
49.00,2375,5260.00,3170.00,3.85,30.00,237.00,1.16,******,37.00,******,23.80,WMa
50.00,2380,3520.00,3580.00,4.16,30.00,209.00,1.25,******,37.00,******,21.00,WMa
51.00,2385,5320.00,3040.00,4.48,30.00,274.00,1.34,******,37.00,******,27.60,
52.00,2390,5120.00,2330.00,4.84,30.00,272.00,1.45,******,37.00,******,27.40,WMa
53.00,2395,5870.00,2190.00,5.22,30.00,327.00,1.57,******,37.00,******,32.90,WMa
54.00,2400,4500.00,3290.00,5.63,30.00,314.00,1.69,******,37.00,******,31.60,WMa
55.00,2405,4990.00,2880.00,6.08,30.00,350.00,1.82,******,37.00,******,35.20,WMa
56.00,2410,5300.00,2900.00,6.56,30.00,396.00,1.97,******,37.00,******,39.80,WMa
57.00,2415,5110.00,3440.00,7.07,30.00,436.00,2.12,******,37.00,******,43.80,WMa
58.00,2420,6120.00,2860.00,7.63,30.00,515.00,2.29,******,37.00,******,51.80,WMa
59.00,2425,6480.00,3770.00,8.24,30.00,618.00,2.47,******,37.00,******,62.10,WMa
60.00,2430,5240.00,2650.00,8.89,30.00,522.00,2.67,******,37.00,******,52.50,WMa
61.00,2435,5000.00,3410.00,9.60,30.00,581.00,2.88,******,37.00,******,58.40,WMa
62.00,2440,4830.00,3110.00,10.40,30.00,595.00,3.11,******,37.00,******,59.80,WMa
63.00,2445,4500.00,2510.00,11.20,30.00,576.00,3.35,******,37.00,******,57.90,WMa
64.00,2450,5370.00,3450.00,12.00,30.00,770.00,3.61,******,37.00,******,77.40,WMa
65.00,2455,5500.00,2790.00,13.00,30.00,802.00,3.90,******,37.00,******,80.70,WMa
66.00,2460,6090.00,2940.00,14.00,30.00,948.00,4.21,******,37.00,******,95.30,WMa
67.00,2465,5920.00,3510.00,15.10,30.00,1040.00,4.54,******,37.00,******,105.00,WMa
68.00,2470,5250.00,2960.00,16.30,30.00,985.00,4.90,******,37.00,******,99.00,WMa
69.00,2475,5290.00,3020.00,17.60,30.00,1070.00,5.29,******,37.00,******,108.00,WMa
70.00,2480,4390.00,3120.00,19.00,30.00,1020.00,5.71,******,37.00,******,103.00,WMa
71.00,2485,4650.00,2550.00,20.50,30.00,1090.00,6.15,******,37.00,******,109.00,WMa
72.00,2490,5260.00,3000.00,22.10,30.00,1340.00,6.64,******,37.00,******,135.00,WMa
73.00,2495,5730.00,2470.00,23.90,30.00,1490.00,7.17,******,37.00,******,150.00,WMa
74.00,2500,5330.00,3020.00,25.80,30.00,1580.00,7.74,******,37.00,******,159.00,WMa
75.00,2505,5350.00,3140.00,27.80,30.00,1730.00,8.35,******,37.00,******,174.00,WMa
76.00,2510,5200.00,3110.00,30.00,30.00,1820.00,9.00,******,37.00,******,183.00,WMa
77.00,2515,5490.00,2720.00,32.40,30.00,1980.00,9.72,******,37.00,******,199.00,WMa
78.00,2520,5250.00,3020.00,34.90,30.00,2120.00,10.50,******,37.00,******,213.00,WMa
79.00,2525,5200.00,3050.00,37.70,30.00,2270.00,11.30,******,37.00,******,229.00,WMa
80.00,2530,5160.00,3170.00,40.70,30.00,2460.00,12.20,******,37.00,******,248.00,WMa
81.00,2535,5870.00,2320.00,43.90,30.00,2770.00,13.20,******,37.00,******,279.00,WMa
82.00,2540,6360.00,3110.00,47.40,30.00,3350.00,14.20,******,37.00,******,337.00,WMa
83.00,2545,4880.00,2690.00,51.10,30.00,2850.00,15.30,******,37.00,******,287.00,WMa
84.00,2550,5160.00,2840.00,55.10,30.00,3250.00,16.50,******,37.00,******,327.00,WMa
85.00,2555,4700.00,3310.00,59.50,30.00,3420.00,17.90,******,37.00,******,344.00,WMa
86.00,2560,4000.00,2820.00,64.20,30.00,3140.00,19.30,******,37.00,******,316.00,WMa
87.00,2565,5070.00,3010.00,69.20,30.00,4080.00,20.80,******,37.00,******,410.00,
88.00,2570,5070.00,2890.00,74.80,30.00,4360.00,22.40,******,37.00,******,438.00,WMa
89.00,2575,5280.00,2750.00,80.70,30.00,4800.00,24.20,******,37.00,******,483.00,WMa
90.00,2580,5880.00,3180.00,87.00,30.00,5820.00,26.10,******,37.00,******,585.00,WMa
91.00,2585,5060.00,3370.00,93.90,30.00,5710.00,28.20,******,37.00,******,574.00,WMa
92.00,2590,4630.00,2650.00,101.00,30.00,5410.00,30.40,******,37.00,******,544.00,WMa
93.00,2595,3460.00,2880.00,109.00,30.00,4930.00,32.80,******,37.00,******,495.00,WMa
94.00,2600,2980.00,1890.00,118.00,30.00,4160.00,35.40,******,37.00,******,418.00,
95.00,2605,2200.00,1470.00,127.00,30.00,3370.00,38.20,******,37.00,******,338.00,
96.00,2610,1490.00,1070.00,137.00,30.00,2520.00,41.20,******,37.00,******,254.00,
97.00,2615,603.00,533.00,148.00,30.00,1190.00,44.40,******,37.00,******,120.00,
98.00,2620,159.00,253.00,160.00,30.00,477.00,47.90,******,37.00,******,48.00,
99.00,2625,40.70,192.00,172.00,30.00,338.00,51.70,******,37.00,******,34.00,
100.00,2630,0.00,153.00,186.00,30.00,285.00,55.80,******,37.00,******,28.60,"ME-,taD"
101.00,2635,0.00,144.00,201.00,30.00,289.00,60.20,******,37.00,******,29.10,"ME-,taD"
102.00,2640,0.00,152.00,217.00,30.00,329.00,65.00,******,37.00,******,33.10,"ME-,taD"
103.00,2645,0.00,165.00,234.00,30.00,386.00,70.10,******,37.00,******,38.80,"ME-,taD"
104.00,2650,0.00,178.00,252.00,30.00,448.00,75.70,******,37.00,******,45.00,"ME-,taD"
105.00,2655,0.00,190.00,272.00,30.00,518.00,81.60,******,37.00,******,52.00,"ME-,taD"
106.00,2660,0.00,173.00,294.00,30.00,507.00,88.10,******,37.00,******,50.90,"ME-,taD"
107.00,2665,0.00,142.00,317.00,30.00,451.00,95.10,******,37.00,******,45.30,"ME-,taD"
108.00,2670,0.00,123.00,342.00,30.00,422.00,103.00,******,37.00,******,42.40,"ME-,taD"
109.00,2675,0.00,101.00,369.00,30.00,371.00,111.00,******,37.00,******,37.30,"ME-,taD"
110.00,2680,0.00,69.10,398.00,30.00,275.00,119.00,******,37.00,******,27.70,"ME-,taD"
111.00,2685,0.00,49.80,429.00,30.00,214.00,129.00,******,37.00,******,21.50,"ME-,taD"
112.00,2690,0.00,52.70,463.00,30.00,244.00,139.00,******,37.00,******,24.60,"ME-,taD"
113.00,2695,0.00,63.00,500.00,30.00,315.00,150.00,******,37.00,******,31.70,"ME-,taD"
,,,,,,,,,,,,
Interval:,,,5.00,,,,,,,,,
Number of Data Points:,,,80.00,,,,,,,,,
,,,,,,,,,,,,
Time Setting:,,,80 Meas. Pts.,,,,,,,,,
,,,Meas. Pt. Duration 5 s,,,,,,,,,
Event Control:,,,Standard Mode,,,,,,,,,
"  Terminate test, ...",,,...if M > 75 mNm,,,,,,,,,
Measuring Profile:,,,,,,,,,,,,
#NAME?,,,Amplitude gamma = 5 %,,,,,,,,,
,,,Angular Frequency omega = 30 rad/s,,,,,,,,,
,,,,,,,,,,,,
Meas. Pts.,Time,Storage Modulus,Loss Modulus,Strain,Angular Frequency,Shear Stress,Shear Rate,Viscosity,Temperature,Speed,Torque,Status
,[s],[Pa],[Pa],[%],[rad/s],[Pa],[1/s],[Pa·s],[°C],[1/min],[µNm],[]
1.00,2700,0.00,260.00,4.95,30.00,12.90,1.49,******,37.00,******,1.29,"MV-,WMa"
2.00,2705,46.80,48.90,5.00,30.00,3.39,1.50,******,37.00,******,0.34,
3.00,2710,64.40,82.40,5.00,30.00,5.23,1.50,******,37.00,******,0.53,
4.00,2715,88.80,129.00,5.00,30.00,7.82,1.50,******,37.00,******,0.79,
5.00,2720,258.00,198.00,5.00,30.00,16.20,1.50,******,37.00,******,1.63,
6.00,2725,430.00,315.00,5.00,30.00,26.60,1.50,******,37.00,******,2.68,
7.00,2730,635.00,437.00,5.00,30.00,38.50,1.50,******,37.00,******,3.88,
8.00,2735,928.00,604.00,5.00,30.00,55.30,1.50,******,37.00,******,5.56,
9.00,2740,1200.00,756.00,5.00,30.00,71.10,1.50,******,37.00,******,7.15,
10.00,2745,1470.00,876.00,5.00,30.00,85.40,1.50,******,37.00,******,8.58,
11.00,2750,1760.00,1070.00,5.00,30.00,103.00,1.50,******,37.00,******,10.40,
12.00,2755,2230.00,1340.00,5.00,30.00,130.00,1.50,******,37.00,******,13.10,
13.00,2760,2630.00,1540.00,5.00,30.00,153.00,1.50,******,37.00,******,15.30,
14.00,2765,2960.00,1750.00,5.00,30.00,172.00,1.50,******,37.00,******,17.30,
15.00,2770,3240.00,1910.00,5.00,30.00,188.00,1.50,******,37.00,******,18.90,
16.00,2775,3480.00,2040.00,5.00,30.00,202.00,1.50,******,37.00,******,20.30,
17.00,2780,3760.00,2200.00,5.00,30.00,218.00,1.50,******,37.00,******,21.90,
18.00,2785,3910.00,2290.00,5.00,30.00,226.00,1.50,******,37.00,******,22.80,
19.00,2790,4070.00,2380.00,5.00,30.00,236.00,1.50,******,37.00,******,23.70,
20.00,2795,4210.00,2450.00,5.00,30.00,243.00,1.50,******,37.00,******,24.50,
21.00,2800,4330.00,2540.00,5.00,30.00,251.00,1.50,******,37.00,******,25.20,
22.00,2805,4420.00,2590.00,5.00,30.00,256.00,1.50,******,37.00,******,25.80,
23.00,2810,4500.00,2640.00,5.00,30.00,261.00,1.50,******,37.00,******,26.20,
24.00,2815,4570.00,2690.00,5.00,30.00,265.00,1.50,******,37.00,******,26.70,
25.00,2820,4620.00,2690.00,5.00,30.00,267.00,1.50,******,37.00,******,26.90,
26.00,2825,4670.00,2740.00,5.00,30.00,271.00,1.50,******,37.00,******,27.20,
27.00,2830,4730.00,2780.00,5.00,30.00,274.00,1.50,******,37.00,******,27.60,
28.00,2835,4780.00,2780.00,5.00,30.00,277.00,1.50,******,37.00,******,27.80,
29.00,2840,4800.00,2820.00,5.00,30.00,279.00,1.50,******,37.00,******,28.00,
30.00,2845,4850.00,2840.00,5.00,30.00,281.00,1.50,******,37.00,******,28.30,
31.00,2850,4870.00,2850.00,5.00,30.00,282.00,1.50,******,37.00,******,28.40,
32.00,2855,4890.00,2860.00,5.00,30.00,283.00,1.50,******,37.00,******,28.50,
33.00,2860,4900.00,2870.00,5.00,30.00,284.00,1.50,******,37.00,******,28.50,
34.00,2865,4910.00,2890.00,5.00,30.00,285.00,1.50,******,37.00,******,28.60,
35.00,2870,4940.00,2900.00,5.00,30.00,286.00,1.50,******,37.00,******,28.80,
36.00,2875,4930.00,2870.00,5.00,30.00,285.00,1.50,******,37.00,******,28.70,
37.00,2880,4940.00,2900.00,5.00,30.00,286.00,1.50,******,37.00,******,28.80,
38.00,2885,4960.00,2900.00,5.00,30.00,287.00,1.50,******,37.00,******,28.90,
39.00,2890,4950.00,2900.00,5.00,30.00,287.00,1.50,******,37.00,******,28.90,
40.00,2895,4950.00,2910.00,5.00,30.00,287.00,1.50,******,37.00,******,28.90,
41.00,2900,4980.00,2910.00,5.00,30.00,288.00,1.50,******,37.00,******,29.00,
42.00,2905,4980.00,2910.00,5.00,30.00,288.00,1.50,******,37.00,******,29.00,
43.00,2910,4980.00,2920.00,5.00,30.00,289.00,1.50,******,37.00,******,29.00,
44.00,2915,4990.00,2930.00,5.00,30.00,290.00,1.50,******,37.00,******,29.10,
45.00,2920,4990.00,2910.00,5.00,30.00,289.00,1.50,******,37.00,******,29.00,
46.00,2925,4990.00,2920.00,5.00,30.00,289.00,1.50,******,37.00,******,29.10,
47.00,2930,5000.00,2930.00,5.00,30.00,290.00,1.50,******,37.00,******,29.10,
48.00,2935,5000.00,2930.00,5.00,30.00,290.00,1.50,******,37.00,******,29.10,
49.00,2940,4990.00,2930.00,5.00,30.00,290.00,1.50,******,37.00,******,29.10,
50.00,2945,5020.00,2940.00,5.00,30.00,291.00,1.50,******,37.00,******,29.30,
51.00,2950,5010.00,2930.00,5.00,30.00,290.00,1.50,******,37.00,******,29.20,
52.00,2955,5030.00,2920.00,5.00,30.00,291.00,1.50,******,37.00,******,29.20,
53.00,2960,5010.00,2930.00,5.00,30.00,290.00,1.50,******,37.00,******,29.20,
54.00,2965,5020.00,2940.00,5.00,30.00,291.00,1.50,******,37.00,******,29.20,
55.00,2970,5040.00,2930.00,5.00,30.00,292.00,1.50,******,37.00,******,29.30,
56.00,2975,5020.00,2940.00,5.00,30.00,291.00,1.50,******,37.00,******,29.20,
57.00,2980,5030.00,2950.00,5.00,30.00,292.00,1.50,******,37.00,******,29.30,
58.00,2985,5040.00,2940.00,5.00,30.00,292.00,1.50,******,37.00,******,29.30,
59.00,2990,5020.00,2940.00,5.00,30.00,291.00,1.50,******,37.00,******,29.30,
60.00,2995,5030.00,2940.00,5.00,30.00,292.00,1.50,******,37.00,******,29.30,
61.00,3000,5050.00,2940.00,5.00,30.00,292.00,1.50,******,37.00,******,29.40,
62.00,3005,5040.00,2950.00,5.00,30.00,292.00,1.50,******,37.00,******,29.40,
63.00,3010,5030.00,2950.00,5.00,30.00,292.00,1.50,******,37.00,******,29.30,
64.00,3015,5050.00,2950.00,5.00,30.00,293.00,1.50,******,37.00,******,29.40,
65.00,3020,5040.00,2950.00,5.00,30.00,292.00,1.50,******,37.00,******,29.30,
66.00,3025,5050.00,2960.00,5.00,30.00,293.00,1.50,******,37.00,******,29.40,
67.00,3030,5050.00,2950.00,5.00,30.00,293.00,1.50,******,37.00,******,29.40,
68.00,3035,5050.00,2960.00,5.00,30.00,293.00,1.50,******,37.00,******,29.40,
69.00,3040,5060.00,2950.00,5.00,30.00,293.00,1.50,******,37.00,******,29.40,
70.00,3045,5040.00,2960.00,5.00,30.00,292.00,1.50,******,37.00,******,29.40,
71.00,3050,5040.00,2950.00,5.00,30.00,292.00,1.50,******,37.00,******,29.40,
72.00,3055,5050.00,2950.00,5.00,30.00,293.00,1.50,******,37.00,******,29.40,
73.00,3060,5040.00,2950.00,5.00,30.00,292.00,1.50,******,37.00,******,29.40,
74.00,3065,5060.00,2970.00,5.00,30.00,293.00,1.50,******,37.00,******,29.50,
75.00,3070,5060.00,2950.00,5.00,30.00,293.00,1.50,******,37.00,******,29.40,
76.00,3075,5050.00,2960.00,5.00,30.00,293.00,1.50,******,37.00,******,29.40,
77.00,3080,5060.00,2960.00,5.00,30.00,293.00,1.50,******,37.00,******,29.50,
78.00,3085,5070.00,2940.00,5.00,30.00,293.00,1.50,******,37.00,******,29.50,
79.00,3090,5060.00,2960.00,5.00,30.00,293.00,1.50,******,37.00,******,29.50,
80.00,3095,5060.00,2970.00,5.00,30.00,293.00,1.50,******,37.00,******,29.50,
,,,,,,,,,,,,
Interval:,,,6.00,,,,,,,,,
Number of Data Points:,,,600.00,,,,,,,,,
,,,,,,,,,,,,
Time Setting:,,,600 Meas. Pts.,,,,,,,,,
,,,Meas. Pt. Duration 3 s,,,,,,,,,
Event Control:,,,Standard Mode,,,,,,,,,
"  Terminate test, ...",,,...if M > 200 mNm,,,,,,,,,
Measuring Profile:,,,,,,,,,,,,
#NAME?,,,Amplitude gamma = 5 %,,,,,,,,,
,,,Angular Frequency omega = 30 rad/s,,,,,,,,,
,,,,,,,,,,,,
Meas. Pts.,Time,Storage Modulus,Loss Modulus,Strain,Angular Frequency,Shear Stress,Shear Rate,Viscosity,Temperature,Speed,Torque,Status
,[s],[Pa],[Pa],[%],[rad/s],[Pa],[1/s],[Pa·s],[°C],[1/min],[µNm],[]
1.00,3098,5170.00,2970.00,5.01,30.00,298.00,1.50,******,37.00,******,30.00,WMa
2.00,3101,5180.00,2970.00,5.00,30.00,298.00,1.50,******,37.00,******,30.00,WMa
3.00,3104,5140.00,2970.00,5.00,30.00,297.00,1.50,******,37.00,******,29.80,WMa
4.00,3107,5120.00,2970.00,5.00,30.00,296.00,1.50,******,37.00,******,29.80,WMa
5.00,3110,5160.00,2960.00,5.00,30.00,297.00,1.50,******,37.00,******,29.90,WMa
6.00,3113,5160.00,2970.00,5.00,30.00,298.00,1.50,******,37.00,******,29.90,
7.00,3116,5170.00,2960.00,5.00,30.00,298.00,1.50,******,37.00,******,30.00,
8.00,3119,5150.00,2980.00,5.00,30.00,298.00,1.50,******,37.00,******,29.90,
9.00,3122,5180.00,2950.00,5.00,30.00,298.00,1.50,******,37.00,******,30.00,
10.00,3125,5150.00,2950.00,5.00,30.00,297.00,1.50,******,37.00,******,29.90,
11.00,3128,5170.00,2980.00,5.00,30.00,298.00,1.50,******,37.00,******,30.00,
12.00,3131,5170.00,2970.00,5.00,30.00,298.00,1.50,******,37.00,******,29.90,
13.00,3134,5170.00,2970.00,5.00,30.00,298.00,1.50,******,37.00,******,30.00,
14.00,3137,5150.00,2970.00,5.00,30.00,297.00,1.50,******,37.00,******,29.90,
15.00,3140,5200.00,2960.00,5.00,30.00,299.00,1.50,******,37.00,******,30.10,
16.00,3143,5160.00,2970.00,5.00,30.00,298.00,1.50,******,37.00,******,29.90,
17.00,3146,5180.00,2950.00,5.00,30.00,298.00,1.50,******,37.00,******,30.00,
18.00,3149,5170.00,2980.00,5.00,30.00,298.00,1.50,******,37.00,******,30.00,
19.00,3152,5170.00,2970.00,5.00,30.00,298.00,1.50,******,37.00,******,30.00,
20.00,3155,5160.00,2960.00,5.00,30.00,298.00,1.50,******,37.00,******,29.90,
21.00,3158,5170.00,2970.00,5.00,30.00,298.00,1.50,******,37.00,******,30.00,
22.00,3161,5180.00,2960.00,5.00,30.00,298.00,1.50,******,37.00,******,30.00,
23.00,3164,5170.00,2980.00,5.00,30.00,298.00,1.50,******,37.00,******,30.00,
24.00,3167,5190.00,2970.00,5.00,30.00,299.00,1.50,******,37.00,******,30.10,
25.00,3170,5160.00,2980.00,5.00,30.00,298.00,1.50,******,37.00,******,30.00,
26.00,3173,5180.00,2950.00,5.00,30.00,298.00,1.50,******,37.00,******,30.00,
27.00,3176,5150.00,2960.00,5.00,30.00,297.00,1.50,******,37.00,******,29.80,
28.00,3179,5170.00,2970.00,5.00,30.00,298.00,1.50,******,37.00,******,30.00,
29.00,3182,5180.00,2970.00,5.00,30.00,298.00,1.50,******,37.00,******,30.00,
30.00,3185,5170.00,2970.00,5.00,30.00,298.00,1.50,******,37.00,******,30.00,
31.00,3188,5170.00,2970.00,5.00,30.00,298.00,1.50,******,37.00,******,30.00,
32.00,3191,5160.00,2980.00,5.00,30.00,298.00,1.50,******,37.00,******,29.90,
33.00,3194,5180.00,2970.00,5.00,30.00,299.00,1.50,******,37.00,******,30.00,
34.00,3197,5180.00,2960.00,5.00,30.00,298.00,1.50,******,37.00,******,30.00,
35.00,3200,5180.00,2960.00,5.00,30.00,298.00,1.50,******,37.00,******,30.00,
36.00,3203,5190.00,2970.00,5.00,30.00,299.00,1.50,******,37.00,******,30.00,
37.00,3206,5190.00,2970.00,5.00,30.00,299.00,1.50,******,37.00,******,30.00,
38.00,3209,5170.00,2960.00,5.00,30.00,298.00,1.50,******,37.00,******,30.00,
39.00,3212,5180.00,2970.00,5.00,30.00,299.00,1.50,******,37.00,******,30.00,
40.00,3215,5190.00,2940.00,5.00,30.00,298.00,1.50,******,37.00,******,30.00,
41.00,3218,5190.00,2970.00,5.00,30.00,299.00,1.50,******,37.00,******,30.10,
42.00,3221,5170.00,2980.00,5.00,30.00,298.00,1.50,******,37.00,******,30.00,
43.00,3224,5180.00,2970.00,5.00,30.00,299.00,1.50,******,37.00,******,30.00,
44.00,3227,5180.00,2960.00,5.00,30.00,299.00,1.50,******,37.00,******,30.00,
45.00,3230,5190.00,2990.00,5.00,30.00,299.00,1.50,******,37.00,******,30.10,
46.00,3233,5180.00,2970.00,5.00,30.00,299.00,1.50,******,37.00,******,30.00,
47.00,3236,5180.00,2980.00,5.00,30.00,299.00,1.50,******,37.00,******,30.10,
48.00,3239,5190.00,2960.00,5.00,30.00,299.00,1.50,******,37.00,******,30.00,
49.00,3242,5170.00,2970.00,5.00,30.00,298.00,1.50,******,37.00,******,30.00,
50.00,3245,5190.00,2970.00,5.00,30.00,299.00,1.50,******,37.00,******,30.10,
51.00,3248,5180.00,2970.00,5.00,30.00,299.00,1.50,******,37.00,******,30.00,
52.00,3251,5200.00,2980.00,5.00,30.00,299.00,1.50,******,37.00,******,30.10,
53.00,3254,5190.00,2980.00,5.00,30.00,299.00,1.50,******,37.00,******,30.10,WMa
54.00,3257,5180.00,2970.00,5.00,30.00,299.00,1.50,******,37.00,******,30.00,
55.00,3260,5200.00,2990.00,5.00,30.00,300.00,1.50,******,37.00,******,30.20,
56.00,3263,5190.00,2980.00,5.00,30.00,300.00,1.50,******,37.00,******,30.10,
57.00,3266,5190.00,2970.00,5.00,30.00,299.00,1.50,******,37.00,******,30.00,
58.00,3269,5200.00,2960.00,5.00,30.00,299.00,1.50,******,37.00,******,30.10,
59.00,3272,5190.00,2960.00,5.00,30.00,299.00,1.50,******,37.00,******,30.10,
60.00,3275,5190.00,2980.00,5.00,30.00,299.00,1.50,******,37.00,******,30.10,
61.00,3278,5180.00,2970.00,5.00,30.00,298.00,1.50,******,37.00,******,30.00,
62.00,3281,5190.00,2980.00,5.00,30.00,299.00,1.50,******,37.00,******,30.10,
63.00,3284,5170.00,2960.00,5.00,30.00,298.00,1.50,******,37.00,******,30.00,
64.00,3287,5210.00,2980.00,5.00,30.00,300.00,1.50,******,37.00,******,30.20,
65.00,3290,5190.00,2970.00,5.00,30.00,299.00,1.50,******,37.00,******,30.00,
66.00,3293,5170.00,2990.00,5.00,30.00,299.00,1.50,******,37.00,******,30.00,
67.00,3296,5190.00,2970.00,5.00,30.00,299.00,1.50,******,37.00,******,30.10,
68.00,3299,5190.00,2970.00,5.00,30.00,299.00,1.50,******,37.00,******,30.10,
69.00,3302,5200.00,2980.00,5.00,30.00,300.00,1.50,******,37.00,******,30.10,
70.00,3305,5180.00,2980.00,5.00,30.00,299.00,1.50,******,37.00,******,30.10,
71.00,3308,5190.00,2980.00,5.00,30.00,299.00,1.50,******,37.00,******,30.10,
72.00,3311,5170.00,2970.00,5.00,30.00,298.00,1.50,******,37.00,******,30.00,
73.00,3314,5210.00,2980.00,5.00,30.00,300.00,1.50,******,37.00,******,30.20,
74.00,3317,5190.00,2970.00,5.00,30.00,299.00,1.50,******,37.00,******,30.10,
75.00,3320,5190.00,2990.00,5.00,30.00,299.00,1.50,******,37.00,******,30.10,
76.00,3323,5200.00,2940.00,5.00,30.00,299.00,1.50,******,37.00,******,30.10,
77.00,3326,5190.00,2980.00,5.00,30.00,299.00,1.50,******,37.00,******,30.10,
78.00,3329,5210.00,2980.00,5.00,30.00,300.00,1.50,******,37.00,******,30.20,
79.00,3332,5190.00,2970.00,5.00,30.00,299.00,1.50,******,37.00,******,30.10,
80.00,3335,5180.00,2980.00,5.00,30.00,299.00,1.50,******,37.00,******,30.10,
81.00,3338,5190.00,2970.00,5.00,30.00,299.00,1.50,******,37.00,******,30.10,
82.00,3341,5190.00,2980.00,5.00,30.00,299.00,1.50,******,37.00,******,30.10,
83.00,3344,5190.00,2980.00,5.00,30.00,299.00,1.50,******,37.00,******,30.10,
84.00,3347,5190.00,3000.00,5.00,30.00,299.00,1.50,******,37.00,******,30.10,
85.00,3350,5190.00,2970.00,5.00,30.00,299.00,1.50,******,37.00,******,30.10,
86.00,3353,5200.00,2980.00,5.00,30.00,300.00,1.50,******,37.00,******,30.10,
87.00,3356,5200.00,2980.00,5.00,30.00,300.00,1.50,******,37.00,******,30.10,
88.00,3359,5190.00,2990.00,5.00,30.00,300.00,1.50,******,37.00,******,30.10,
89.00,3362,5200.00,2980.00,5.00,30.00,300.00,1.50,******,37.00,******,30.10,
90.00,3365,5190.00,2970.00,5.00,30.00,299.00,1.50,******,37.00,******,30.10,
91.00,3368,5200.00,2980.00,5.00,30.00,300.00,1.50,******,37.00,******,30.10,
92.00,3371,5190.00,2990.00,5.00,30.00,300.00,1.50,******,37.00,******,30.10,
93.00,3374,5190.00,2970.00,5.00,30.00,299.00,1.50,******,37.00,******,30.10,
94.00,3377,5190.00,2990.00,5.00,30.00,300.00,1.50,******,37.00,******,30.10,
95.00,3380,5190.00,2980.00,5.00,30.00,299.00,1.50,******,37.00,******,30.10,
96.00,3383,5200.00,2990.00,5.00,30.00,300.00,1.50,******,37.00,******,30.10,
97.00,3386,5210.00,2980.00,5.00,30.00,300.00,1.50,******,37.00,******,30.20,
98.00,3389,5190.00,2980.00,5.00,30.00,299.00,1.50,******,37.00,******,30.10,
99.00,3392,5200.00,2990.00,5.00,30.00,300.00,1.50,******,37.00,******,30.20,
100.00,3395,5200.00,2970.00,5.00,30.00,300.00,1.50,******,37.00,******,30.10,
101.00,3398,5200.00,2970.00,5.00,30.00,299.00,1.50,******,37.00,******,30.10,
102.00,3401,5190.00,2970.00,5.00,30.00,299.00,1.50,******,37.00,******,30.10,
103.00,3404,5180.00,2980.00,5.00,30.00,299.00,1.50,******,37.00,******,30.10,
104.00,3407,5200.00,2990.00,5.00,30.00,300.00,1.50,******,37.00,******,30.20,
105.00,3410,5180.00,2970.00,5.00,30.00,299.00,1.50,******,37.00,******,30.00,
106.00,3413,5220.00,2980.00,5.00,30.00,301.00,1.50,******,37.00,******,30.20,
107.00,3416,5200.00,2960.00,5.00,30.00,299.00,1.50,******,37.00,******,30.10,
[...]
388.00,11699,5220.00,3050.00,5.00,30.00,302.00,1.50,******,37.00,******,30.40,
389.00,11702,5240.00,3060.00,5.00,30.00,304.00,1.50,******,37.00,******,30.50,
390.00,11705,5200.00,3070.00,5.00,30.00,302.00,1.50,******,37.00,******,30.40,
391.00,11708,5220.00,3040.00,5.00,30.00,302.00,1.50,******,37.00,******,30.40,
392.00,11711,5220.00,3060.00,5.00,30.00,303.00,1.50,******,37.00,******,30.40,
393.00,11714,5200.00,3040.00,5.00,30.00,301.00,1.50,******,37.00,******,30.30,
394.00,11717,5220.00,3060.00,5.00,30.00,303.00,1.50,******,37.00,******,30.50,
395.00,11720,5230.00,3060.00,5.00,30.00,303.00,1.50,******,37.00,******,30.50,
396.00,11723,5200.00,3040.00,5.00,30.00,301.00,1.50,******,37.00,******,30.30,
397.00,11726,5220.00,3040.00,5.00,30.00,302.00,1.50,******,37.00,******,30.40,
398.00,11729,5210.00,3050.00,5.00,30.00,302.00,1.50,******,37.00,******,30.30,
399.00,11732,5210.00,3060.00,5.00,30.00,302.00,1.50,******,37.00,******,30.40,
400.00,11735,5190.00,3070.00,5.00,30.00,301.00,1.50,******,37.00,******,30.30,
401.00,11738,5200.00,3050.00,5.00,30.00,301.00,1.50,******,37.00,******,30.30,
402.00,11741,5220.00,3060.00,5.00,30.00,303.00,1.50,******,37.00,******,30.40,
403.00,11744,5230.00,3050.00,5.00,30.00,303.00,1.50,******,37.00,******,30.40,
404.00,11747,5220.00,3070.00,5.00,30.00,303.00,1.50,******,37.00,******,30.40,
405.00,11750,5210.00,3060.00,5.00,30.00,302.00,1.50,******,37.00,******,30.40,
406.00,11753,5230.00,3070.00,5.00,30.00,303.00,1.50,******,37.00,******,30.50,
407.00,11756,5230.00,3070.00,5.00,30.00,303.00,1.50,******,37.00,******,30.50,
408.00,11759,5220.00,3020.00,5.00,30.00,302.00,1.50,******,37.00,******,30.40,
409.00,11762,5220.00,3050.00,5.00,30.00,302.00,1.50,******,37.00,******,30.40,
410.00,11765,5220.00,3040.00,5.00,30.00,302.00,1.50,******,37.00,******,30.40,
411.00,11768,5220.00,3060.00,5.00,30.00,302.00,1.50,******,37.00,******,30.40,
412.00,11771,5200.00,3060.00,5.00,30.00,302.00,1.50,******,37.00,******,30.30,
413.00,11774,5200.00,3050.00,5.00,30.00,302.00,1.50,******,37.00,******,30.30,
414.00,11777,5220.00,3060.00,5.00,30.00,303.00,1.50,******,37.00,******,30.40,
415.00,11780,5230.00,3060.00,5.00,30.00,303.00,1.50,******,37.00,******,30.40,
416.00,11783,5220.00,3060.00,5.00,30.00,303.00,1.50,******,37.00,******,30.40,
417.00,11786,5220.00,3050.00,5.00,30.00,302.00,1.50,******,37.00,******,30.40,
418.00,11789,5230.00,3110.00,5.00,30.00,304.00,1.50,******,37.00,******,30.60,
419.00,11792,5220.00,3050.00,5.00,30.00,302.00,1.50,******,37.00,******,30.40,
420.00,11795,5220.00,3060.00,5.00,30.00,303.00,1.50,******,37.00,******,30.40,
421.00,11798,5210.00,3070.00,5.00,30.00,302.00,1.50,******,37.00,******,30.40,
422.00,11801,5230.00,3050.00,5.00,30.00,303.00,1.50,******,37.00,******,30.40,
423.00,11804,5210.00,3080.00,5.00,30.00,303.00,1.50,******,37.00,******,30.40,
424.00,11807,5190.00,3060.00,5.00,30.00,301.00,1.50,******,37.00,******,30.30,
425.00,11810,5210.00,3060.00,5.00,30.00,302.00,1.50,******,37.00,******,30.40,
426.00,11813,5230.00,3070.00,5.00,30.00,303.00,1.50,******,37.00,******,30.50,
427.00,11816,5210.00,3070.00,5.00,30.00,302.00,1.50,******,37.00,******,30.40,
428.00,11819,5220.00,3050.00,5.00,30.00,302.00,1.50,******,37.00,******,30.40,
429.00,11822,5220.00,3060.00,5.00,30.00,302.00,1.50,******,37.00,******,30.40,
430.00,11825,5210.00,3060.00,5.00,30.00,302.00,1.50,******,37.00,******,30.40,
431.00,11828,5210.00,3060.00,5.00,30.00,302.00,1.50,******,37.00,******,30.40,
432.00,11831,5210.00,3060.00,5.00,30.00,302.00,1.50,******,37.00,******,30.40,
433.00,11834,5210.00,3060.00,5.00,30.00,302.00,1.50,******,37.00,******,30.40,
434.00,11837,5200.00,3080.00,5.00,30.00,302.00,1.50,******,37.00,******,30.40,
435.00,11840,5210.00,3080.00,5.00,30.00,303.00,1.50,******,37.00,******,30.40,
436.00,11843,5220.00,3060.00,5.00,30.00,302.00,1.50,******,37.00,******,30.40,
437.00,11846,5220.00,3060.00,5.00,30.00,303.00,1.50,******,37.00,******,30.40,
438.00,11849,5200.00,3060.00,5.00,30.00,302.00,1.50,******,37.00,******,30.30,
439.00,11852,5220.00,3060.00,5.00,30.00,302.00,1.50,******,37.00,******,30.40,
440.00,11855,5220.00,3070.00,5.00,30.00,303.00,1.50,******,37.00,******,30.40,
441.00,11858,5210.00,3060.00,5.00,30.00,302.00,1.50,******,37.00,******,30.40,
442.00,11861,5210.00,3060.00,5.00,30.00,302.00,1.50,******,37.00,******,30.40,
443.00,11864,5210.00,3070.00,5.00,30.00,302.00,1.50,******,37.00,******,30.40,
444.00,11867,5200.00,3050.00,5.00,30.00,302.00,1.50,******,37.00,******,30.30,
445.00,11870,5200.00,3060.00,5.00,30.00,302.00,1.50,******,37.00,******,30.30,
446.00,11873,5210.00,3060.00,5.00,30.00,302.00,1.50,******,37.00,******,30.40,
447.00,11876,5220.00,3050.00,5.00,30.00,302.00,1.50,******,37.00,******,30.40,
448.00,11879,5200.00,3100.00,5.00,30.00,303.00,1.50,******,37.00,******,30.40,
449.00,11882,5220.00,3080.00,5.00,30.00,303.00,1.50,******,37.00,******,30.50,
450.00,11885,5210.00,3050.00,5.00,30.00,302.00,1.50,******,37.00,******,30.30,
451.00,11888,5230.00,3060.00,5.00,30.00,303.00,1.50,******,37.00,******,30.50,
452.00,11891,5240.00,3070.00,5.00,30.00,304.00,1.50,******,37.00,******,30.50,
453.00,11894,5210.00,3070.00,5.00,30.00,302.00,1.50,******,37.00,******,30.40,
454.00,11897,5220.00,3060.00,5.00,30.00,302.00,1.50,******,37.00,******,30.40,
455.00,11900,5210.00,3050.00,5.00,30.00,302.00,1.50,******,37.00,******,30.40,
456.00,11903,5210.00,3060.00,5.00,30.00,302.00,1.50,******,37.00,******,30.40,
457.00,11906,5210.00,3050.00,5.00,30.00,302.00,1.50,******,37.00,******,30.30,
458.00,11909,5210.00,3070.00,5.00,30.00,303.00,1.50,******,37.00,******,30.40,
459.00,11912,5210.00,3090.00,5.00,30.00,303.00,1.50,******,37.00,******,30.40,
460.00,11915,5190.00,3090.00,5.00,30.00,302.00,1.50,******,37.00,******,30.40,
461.00,11918,5220.00,3060.00,5.00,30.00,303.00,1.50,******,37.00,******,30.40,
462.00,11921,5210.00,3070.00,5.00,30.00,302.00,1.50,******,37.00,******,30.40,
463.00,11924,5210.00,3070.00,5.00,30.00,302.00,1.50,******,37.00,******,30.40,
464.00,11927,5230.00,3070.00,5.00,30.00,303.00,1.50,******,37.00,******,30.50,
465.00,11930,5160.00,3060.00,5.00,30.00,300.00,1.50,******,37.00,******,30.20,
466.00,11933,5210.00,3060.00,5.00,30.00,302.00,1.50,******,37.00,******,30.40,
467.00,11936,5200.00,3060.00,5.00,30.00,302.00,1.50,******,37.00,******,30.30,
468.00,11939,5210.00,3080.00,5.00,30.00,303.00,1.50,******,37.00,******,30.40,
469.00,11942,5230.00,3080.00,5.00,30.00,304.00,1.50,******,37.00,******,30.50,
470.00,11945,5220.00,3070.00,5.00,30.00,303.00,1.50,******,37.00,******,30.50,
471.00,11948,5220.00,3070.00,5.00,30.00,303.00,1.50,******,37.00,******,30.40,
472.00,11951,5220.00,3070.00,5.00,30.00,303.00,1.50,******,37.00,******,30.40,
473.00,11954,5230.00,3050.00,5.00,30.00,303.00,1.50,******,37.00,******,30.50,
474.00,11957,5220.00,3050.00,5.00,30.00,303.00,1.50,******,37.00,******,30.40,
475.00,11960,5210.00,3060.00,5.00,30.00,302.00,1.50,******,37.00,******,30.40,
476.00,11963,5200.00,3050.00,5.00,30.00,302.00,1.50,******,37.00,******,30.30,
477.00,11966,5200.00,3050.00,5.00,30.00,301.00,1.50,******,37.00,******,30.30,
478.00,11969,5220.00,3060.00,5.00,30.00,302.00,1.50,******,37.00,******,30.40,
479.00,11972,5220.00,3100.00,5.00,30.00,304.00,1.50,******,37.00,******,30.50,
480.00,11975,5220.00,3070.00,5.00,30.00,303.00,1.50,******,37.00,******,30.40,
481.00,11978,5210.00,3060.00,5.00,30.00,302.00,1.50,******,37.00,******,30.40,
482.00,11981,5200.00,3050.00,5.00,30.00,302.00,1.50,******,37.00,******,30.30,
483.00,11984,5210.00,3060.00,5.00,30.00,302.00,1.50,******,37.00,******,30.40,
484.00,11987,5220.00,3070.00,5.00,30.00,303.00,1.50,******,37.00,******,30.50,
485.00,11990,5210.00,3070.00,5.00,30.00,302.00,1.50,******,37.00,******,30.40,
486.00,11993,5200.00,3060.00,5.00,30.00,302.00,1.50,******,37.00,******,30.30,
487.00,11996,5230.00,3080.00,5.00,30.00,303.00,1.50,******,37.00,******,30.50,
488.00,11999,5220.00,3080.00,5.00,30.00,303.00,1.50,******,37.00,******,30.50,
489.00,12002,5220.00,3070.00,5.00,30.00,303.00,1.50,******,37.00,******,30.50,
490.00,12005,5210.00,3070.00,5.00,30.00,302.00,1.50,******,37.00,******,30.40,
491.00,12008,5220.00,3070.00,5.00,30.00,303.00,1.50,******,37.00,******,30.40,
492.00,12011,5220.00,3070.00,5.00,30.00,303.00,1.50,******,37.00,******,30.50,
493.00,12014,5220.00,3050.00,5.00,30.00,302.00,1.50,******,37.00,******,30.40,
494.00,12017,5170.00,3060.00,5.00,30.00,300.00,1.50,******,37.00,******,30.20,
495.00,12020,5210.00,3050.00,5.00,30.00,302.00,1.50,******,37.00,******,30.40,
496.00,12023,5250.00,3070.00,5.00,30.00,304.00,1.50,******,37.00,******,30.60,
497.00,12026,5240.00,3060.00,5.00,30.00,304.00,1.50,******,37.00,******,30.50,
498.00,12029,5210.00,3060.00,5.00,30.00,302.00,1.50,******,37.00,******,30.40,
499.00,12032,5220.00,3050.00,5.00,30.00,302.00,1.50,******,37.00,******,30.40,
500.00,12035,5220.00,3030.00,5.00,30.00,302.00,1.50,******,37.00,******,30.30,
501.00,12038,5210.00,3050.00,5.00,30.00,302.00,1.50,******,37.00,******,30.40,
502.00,12041,5200.00,3070.00,5.00,30.00,302.00,1.50,******,37.00,******,30.40,
503.00,12044,5210.00,3070.00,5.00,30.00,302.00,1.50,******,37.00,******,30.40,
504.00,12047,5200.00,3070.00,5.00,30.00,302.00,1.50,******,37.00,******,30.40,
505.00,12050,5220.00,3070.00,5.00,30.00,303.00,1.50,******,37.00,******,30.40,
506.00,12053,5240.00,3080.00,5.00,30.00,304.00,1.50,******,37.00,******,30.60,
507.00,12056,5220.00,3090.00,5.00,30.00,304.00,1.50,******,37.00,******,30.50,
508.00,12059,5210.00,3070.00,5.00,30.00,302.00,1.50,******,37.00,******,30.40,
509.00,12062,5220.00,3070.00,5.00,30.00,303.00,1.50,******,37.00,******,30.40,
510.00,12065,5210.00,3080.00,5.00,30.00,302.00,1.50,******,37.00,******,30.40,
511.00,12068,5210.00,3070.00,5.00,30.00,303.00,1.50,******,37.00,******,30.40,
512.00,12071,5220.00,3070.00,5.00,30.00,303.00,1.50,******,37.00,******,30.40,
513.00,12074,5210.00,3060.00,5.00,30.00,302.00,1.50,******,37.00,******,30.40,
514.00,12077,5240.00,3070.00,5.00,30.00,303.00,1.50,******,37.00,******,30.50,
515.00,12080,5220.00,3060.00,5.00,30.00,303.00,1.50,******,37.00,******,30.40,
516.00,12083,5180.00,3060.00,5.00,30.00,301.00,1.50,******,37.00,******,30.20,
517.00,12086,5200.00,3070.00,5.00,30.00,302.00,1.50,******,37.00,******,30.30,
518.00,12089,5220.00,3080.00,5.00,30.00,303.00,1.50,******,37.00,******,30.50,
519.00,12092,5220.00,3070.00,5.00,30.00,303.00,1.50,******,37.00,******,30.40,
520.00,12095,5200.00,3050.00,5.00,30.00,301.00,1.50,******,37.00,******,30.30,
521.00,12098,5200.00,3050.00,5.00,30.00,301.00,1.50,******,37.00,******,30.30,
522.00,12101,5210.00,3090.00,5.00,30.00,303.00,1.50,******,37.00,******,30.40,
523.00,12104,5210.00,3070.00,5.00,30.00,302.00,1.50,******,37.00,******,30.40,
524.00,12107,5220.00,3070.00,5.00,30.00,303.00,1.50,******,37.00,******,30.40,
525.00,12110,5230.00,3040.00,5.00,30.00,302.00,1.50,******,37.00,******,30.40,
526.00,12113,5230.00,3070.00,5.00,30.00,303.00,1.50,******,37.00,******,30.50,
527.00,12116,5240.00,3080.00,5.00,30.00,304.00,1.50,******,37.00,******,30.50,
528.00,12119,5190.00,3050.00,5.00,30.00,301.00,1.50,******,37.00,******,30.30,
529.00,12122,5230.00,3070.00,5.00,30.00,303.00,1.50,******,37.00,******,30.50,
530.00,12125,5220.00,3080.00,5.00,30.00,303.00,1.50,******,37.00,******,30.50,
531.00,12128,5220.00,3050.00,5.00,30.00,303.00,1.50,******,37.00,******,30.40,
532.00,12131,5220.00,3070.00,5.00,30.00,303.00,1.50,******,37.00,******,30.40,
533.00,12134,5200.00,3050.00,5.00,30.00,301.00,1.50,******,37.00,******,30.30,
534.00,12137,5210.00,3080.00,5.00,30.00,302.00,1.50,******,37.00,******,30.40,
535.00,12140,5220.00,3060.00,5.00,30.00,302.00,1.50,******,37.00,******,30.40,
536.00,12143,5200.00,3090.00,5.00,30.00,302.00,1.50,******,37.00,******,30.40,
537.00,12146,5210.00,3080.00,5.00,30.00,303.00,1.50,******,37.00,******,30.40,
538.00,12149,5220.00,3060.00,5.00,30.00,303.00,1.50,******,37.00,******,30.40,
539.00,12152,5230.00,3080.00,5.00,30.00,304.00,1.50,******,37.00,******,30.50,
540.00,12155,5220.00,3060.00,5.00,30.00,303.00,1.50,******,37.00,******,30.40,
541.00,12158,5220.00,3070.00,5.00,30.00,303.00,1.50,******,37.00,******,30.50,
542.00,12161,5210.00,3060.00,5.00,30.00,302.00,1.50,******,37.00,******,30.40,
543.00,12164,5250.00,3050.00,5.00,30.00,304.00,1.50,******,37.00,******,30.50,
544.00,12167,5220.00,3060.00,5.00,30.00,302.00,1.50,******,37.00,******,30.40,
545.00,12170,5220.00,3080.00,5.00,30.00,303.00,1.50,******,37.00,******,30.50,
546.00,12173,5220.00,3060.00,5.00,30.00,303.00,1.50,******,37.00,******,30.40,
547.00,12176,5240.00,3080.00,5.00,30.00,304.00,1.50,******,37.00,******,30.60,
548.00,12179,5220.00,3060.00,5.00,30.00,303.00,1.50,******,37.00,******,30.40,
549.00,12182,5220.00,3080.00,5.00,30.00,303.00,1.50,******,37.00,******,30.50,
550.00,12185,5220.00,3050.00,5.00,30.00,302.00,1.50,******,37.00,******,30.40,
551.00,12188,5210.00,3060.00,5.00,30.00,302.00,1.50,******,37.00,******,30.40,
552.00,12191,5220.00,3080.00,5.00,30.00,303.00,1.50,******,37.00,******,30.50,
553.00,12194,5210.00,3070.00,5.00,30.00,302.00,1.50,******,37.00,******,30.40,
554.00,12197,5220.00,3060.00,5.00,30.00,303.00,1.50,******,37.00,******,30.40,
555.00,12200,5230.00,3060.00,5.00,30.00,303.00,1.50,******,37.00,******,30.50,
556.00,12203,5230.00,3050.00,5.00,30.00,303.00,1.50,******,37.00,******,30.50,
557.00,12206,5200.00,3050.00,5.00,30.00,301.00,1.50,******,37.00,******,30.30,
558.00,12209,5220.00,3070.00,5.00,30.00,303.00,1.50,******,37.00,******,30.50,
559.00,12212,5210.00,3060.00,5.00,30.00,302.00,1.50,******,37.00,******,30.40,
560.00,12215,5250.00,3070.00,5.00,30.00,304.00,1.50,******,37.00,******,30.60,
561.00,12218,5210.00,3080.00,5.00,30.00,303.00,1.50,******,37.00,******,30.40,
562.00,12221,5210.00,3070.00,5.00,30.00,302.00,1.50,******,37.00,******,30.40,
563.00,12224,5230.00,3050.00,5.00,30.00,303.00,1.50,******,37.00,******,30.40,
564.00,12227,5220.00,3050.00,5.00,30.00,302.00,1.50,******,37.00,******,30.40,
565.00,12230,5180.00,3080.00,5.00,30.00,301.00,1.50,******,37.00,******,30.30,
566.00,12233,5190.00,3050.00,5.00,30.00,301.00,1.50,******,37.00,******,30.30,
567.00,12236,5220.00,3060.00,5.00,30.00,303.00,1.50,******,37.00,******,30.40,
568.00,12239,5230.00,3060.00,5.00,30.00,303.00,1.50,******,37.00,******,30.50,
569.00,12242,5230.00,3080.00,5.00,30.00,303.00,1.50,******,37.00,******,30.50,
570.00,12245,5210.00,3080.00,5.00,30.00,303.00,1.50,******,37.00,******,30.40,
571.00,12248,5220.00,3070.00,5.00,30.00,303.00,1.50,******,37.00,******,30.40,
572.00,12251,5230.00,3080.00,5.00,30.00,303.00,1.50,******,37.00,******,30.50,
573.00,12254,5220.00,3070.00,5.00,30.00,303.00,1.50,******,37.00,******,30.40,
574.00,12257,5190.00,3080.00,5.00,30.00,301.00,1.50,******,37.00,******,30.30,
575.00,12260,5230.00,3060.00,5.00,30.00,303.00,1.50,******,37.00,******,30.40,
576.00,12263,5220.00,3080.00,5.00,30.00,303.00,1.50,******,37.00,******,30.50,
577.00,12266,5210.00,3060.00,5.00,30.00,302.00,1.50,******,37.00,******,30.40,
578.00,12269,5220.00,3070.00,5.00,30.00,303.00,1.50,******,37.00,******,30.50,
579.00,12272,5200.00,3060.00,5.00,30.00,302.00,1.50,******,37.00,******,30.30,
580.00,12275,5220.00,3060.00,5.00,30.00,303.00,1.50,******,37.00,******,30.40,
581.00,12278,5220.00,3090.00,5.00,30.00,303.00,1.50,******,37.00,******,30.50,
582.00,12281,5230.00,3060.00,5.00,30.00,303.00,1.50,******,37.00,******,30.50,
583.00,12284,5220.00,3060.00,5.00,30.00,302.00,1.50,******,37.00,******,30.40,
584.00,12287,5210.00,3060.00,5.00,30.00,302.00,1.50,******,37.00,******,30.40,
585.00,12290,5210.00,3080.00,5.00,30.00,302.00,1.50,******,37.00,******,30.40,
586.00,12293,5190.00,3070.00,5.00,30.00,301.00,1.50,******,37.00,******,30.30,
587.00,12296,5200.00,3080.00,5.00,30.00,302.00,1.50,******,37.00,******,30.40,
588.00,12299,5210.00,3080.00,5.00,30.00,302.00,1.50,******,37.00,******,30.40,
589.00,12302,5250.00,3080.00,5.00,30.00,304.00,1.50,******,37.00,******,30.60,
590.00,12305,5230.00,3100.00,5.00,30.00,304.00,1.50,******,37.00,******,30.60,
591.00,12308,5210.00,3060.00,5.00,30.00,302.00,1.50,******,37.00,******,30.40,
592.00,12311,5200.00,3070.00,5.00,30.00,302.00,1.50,******,37.00,******,30.40,
593.00,12314,5210.00,3090.00,5.00,30.00,303.00,1.50,******,37.00,******,30.50,
594.00,12317,5200.00,3090.00,5.00,30.00,302.00,1.50,******,37.00,******,30.40,
595.00,12320,5230.00,3050.00,5.00,30.00,303.00,1.50,******,37.00,******,30.40,
596.00,12323,5220.00,3060.00,5.00,30.00,303.00,1.50,******,37.00,******,30.40,
597.00,12326,5200.00,3070.00,5.00,30.00,302.00,1.50,******,37.00,******,30.30,
598.00,12329,5210.00,3060.00,5.00,30.00,302.00,1.50,******,37.00,******,30.40,
599.00,12332,5220.00,3070.00,5.00,30.00,303.00,1.50,******,37.00,******,30.50,
600.00,12335,5210.00,3070.00,5.00,30.00,302.00,1.50,******,37.00,******,30.40,
,,,,,,,,,,,,
Interval:,,,15.00,,,,,,,,,
Number of Data Points:,,,28.00,,,,,,,,,
,,,,,,,,,,,,
Time Setting:,,,28 Meas. Pts.,,,,,,,,,
,,,Meas. Pt. Duration 6.4285714 s,,,,,,,,,
Event Control:,,,Standard Mode,,,,,,,,,
"  Terminate test, ...",,,...if d(gamma)/dt > 1000 1/s,,,,,,,,,
"  Terminate test, ...",,,...if M > 200 mNm,,,,,,,,,
"  Terminate test, ...",,,...if FN < -50 N or > 50 N,,,,,,,,,
Measuring Profile:,,,,,,,,,,,,
  Shear Rate,,,d(gamma)/dt = 0.1 ... 50 1/s log; |Slope| = 10.003816 Pt. / dec ,,,,,,,,,
,,,,,,,,,,,,
Meas. Pts.,Time,Storage Modulus,Loss Modulus,Strain,Angular Frequency,Shear Stress,Shear Rate,Viscosity,Temperature,Speed,Torque,Status
,[s],[Pa],[Pa],[%],[rad/s],[Pa],[1/s],[Pa·s],[°C],[1/min],[µNm],[]
1.00,12300,******,******,47.70,******,62.00,0.10,620.00,37.00,0.12,6.24,Dy_auto
2.00,12300,******,******,124.00,******,80.40,0.13,639.00,37.00,0.15,8.09,Dy_auto
3.00,12400,******,******,221.00,******,102.00,0.16,642.00,37.00,0.19,10.20,Dy_auto
4.00,12400,******,******,342.00,******,127.00,0.20,637.00,37.00,0.24,12.80,Dy_auto
5.00,12400,******,******,495.00,******,157.00,0.25,625.00,37.00,0.30,15.80,Dy_auto
6.00,12400,******,******,688.00,******,194.00,0.32,613.00,37.00,0.38,19.50,Dy_auto
7.00,12400,******,******,931.00,******,239.00,0.40,600.00,37.00,0.48,24.00,Dy_auto
8.00,12400,******,******,1240.00,******,296.00,0.50,591.00,37.00,0.60,29.80,Dy_auto
9.00,12400,******,******,1620.00,******,367.00,0.63,583.00,37.00,0.75,36.90,Dy_auto
10.00,12400,******,******,2100.00,******,456.00,0.79,575.00,37.00,0.95,45.90,Dy_auto
11.00,12400,******,******,2710.00,******,566.00,1.00,566.00,37.00,1.19,56.90,Dy_auto
12.00,12400,******,******,3480.00,******,702.00,1.26,558.00,37.00,1.50,70.60,Dy_auto
13.00,12400,******,******,4440.00,******,877.00,1.58,554.00,37.00,1.89,88.20,Dy_auto
14.00,12400,******,******,5660.00,******,1100.00,1.99,550.00,37.00,2.38,110.00,Dy_auto
15.00,12400,******,******,7190.00,******,1360.00,2.51,543.00,37.00,2.99,137.00,Dy_auto
16.00,12400,******,******,9110.00,******,1690.00,3.16,535.00,37.00,3.77,170.00,Dy_auto
17.00,12400,******,******,11500.00,******,2100.00,3.98,528.00,37.00,4.74,211.00,Dy_auto
18.00,12500,******,******,14600.00,******,2600.00,5.00,520.00,37.00,5.97,262.00,Dy_auto
19.00,12500,******,******,18400.00,******,3230.00,6.30,513.00,37.00,7.52,325.00,Dy_auto
20.00,12500,******,******,23300.00,******,3960.00,7.93,500.00,37.00,9.46,398.00,Dy_auto
21.00,12500,******,******,29300.00,******,4810.00,9.98,482.00,37.00,11.90,484.00,Dy_auto
22.00,12500,******,******,37000.00,******,5610.00,12.60,447.00,37.00,15.00,564.00,Dy_auto
23.00,12500,******,******,46600.00,******,4080.00,15.80,258.00,37.00,18.90,410.00,Dy_auto
24.00,12500,******,******,58800.00,******,1290.00,19.90,64.90,37.00,23.80,130.00,Dy_auto
25.00,12500,******,******,74100.00,******,689.00,25.10,27.50,37.00,29.90,69.20,Dy_auto
26.00,12500,******,******,93300.00,******,501.00,31.60,15.90,37.00,37.70,50.30,Dy_auto
27.00,12500,******,******,117000.00,******,129.00,39.70,3.24,37.00,47.40,13.00,Dy_auto
28.00,12500,******,******,148000.00,******,99.20,50.00,1.98,37.00,59.70,9.97,Dy_auto