File: exampledata/PXP_N3.csv
Meas. Pts.,Time,Storage Modulus,Loss Modulus,Strain,Angular Frequency,Shear Stress,Shear Rate,Viscosity,Temperature,Speed,Torque,Status
,[s],[Pa],[Pa],[%],[rad/s],[Pa],[1/s],[Pa·s],[°C],[1/min],[µNm],[]
1.00,5,3950.00,3260.00,4.98,30.00,255.00,1.50,******,37.00,******,25.70,WMa
2.00,10,3870.00,2460.00,5.00,30.00,229.00,1.50,******,37.00,******,23.00,
3.00,15,3860.00,2480.00,5.00,30.00,229.00,1.50,******,37.00,******,23.10,
4.00,20,3850.00,2450.00,5.00,30.00,228.00,1.50,******,37.00,******,22.90,
5.00,25,3860.00,2480.00,5.00,30.00,229.00,1.50,******,37.00,******,23.00,
6.00,30,3850.00,2480.00,5.00,30.00,229.00,1.50,******,37.00,******,23.00,
7.00,35,3830.00,2480.00,5.00,30.00,228.00,1.50,******,37.00,******,22.90,
8.00,40,3850.00,2470.00,5.00,30.00,229.00,1.50,******,37.00,******,23.00,
9.00,45,3830.00,2480.00,5.00,30.00,228.00,1.50,******,37.00,******,22.90,
10.00,50,3830.00,2490.00,5.00,30.00,229.00,1.50,******,37.00,******,23.00,
11.00,55,3820.00,2490.00,5.00,30.00,228.00,1.50,******,37.00,******,22.90,
12.00,60,3810.00,2490.00,5.00,30.00,228.00,1.50,******,37.00,******,22.90,
13.00,65,3810.00,2470.00,5.00,30.00,227.00,1.50,******,37.00,******,22.80,
14.00,70,3800.00,2500.00,5.00,30.00,227.00,1.50,******,37.00,******,22.80,
15.00,75,3810.00,2490.00,5.00,30.00,228.00,1.50,******,37.00,******,22.90,
16.00,80,3790.00,2500.00,5.00,30.00,227.00,1.50,******,37.00,******,22.80,
17.00,85,3800.00,2490.00,5.00,30.00,227.00,1.50,******,37.00,******,22.80,
18.00,90,3800.00,2500.00,5.00,30.00,227.00,1.50,******,37.00,******,22.90,
19.00,95,3800.00,2490.00,5.00,30.00,227.00,1.50,******,37.00,******,22.80,
20.00,100,3780.00,2510.00,5.00,30.00,227.00,1.50,******,37.00,******,22.80,
21.00,105,3800.00,2510.00,5.00,30.00,228.00,1.50,******,37.00,******,22.90,
22.00,110,3780.00,2490.00,5.00,30.00,226.00,1.50,******,37.00,******,22.80,
23.00,115,3780.00,2510.00,5.00,30.00,227.00,1.50,******,37.00,******,22.80,
24.00,120,3780.00,2490.00,5.00,30.00,227.00,1.50,******,37.00,******,22.80,
25.00,125,3770.00,2500.00,5.00,30.00,226.00,1.50,******,37.00,******,22.70,
26.00,130,3780.00,2500.00,5.00,30.00,227.00,1.50,******,37.00,******,22.80,
27.00,135,3780.00,2500.00,5.00,30.00,227.00,1.50,******,37.00,******,22.80,
28.00,140,3780.00,2500.00,5.00,30.00,227.00,1.50,******,37.00,******,22.80,
29.00,145,3770.00,2500.00,5.00,30.00,226.00,1.50,******,37.00,******,22.80,
30.00,150,3780.00,2510.00,5.00,30.00,227.00,1.50,******,37.00,******,22.80,
31.00,155,3760.00,2490.00,5.00,30.00,226.00,1.50,******,37.00,******,22.70,
32.00,160,3770.00,2490.00,5.00,30.00,226.00,1.50,******,37.00,******,22.70,
33.00,165,3760.00,2510.00,5.00,30.00,226.00,1.50,******,37.00,******,22.70,
34.00,170,3790.00,2520.00,5.00,30.00,227.00,1.50,******,37.00,******,22.90,
35.00,175,3760.00,2510.00,5.00,30.00,226.00,1.50,******,37.00,******,22.70,
36.00,180,3760.00,2510.00,5.00,30.00,226.00,1.50,******,37.00,******,22.70,
37.00,185,3770.00,2520.00,5.00,30.00,227.00,1.50,******,37.00,******,22.80,
38.00,190,3760.00,2530.00,5.00,30.00,226.00,1.50,******,37.00,******,22.80,
39.00,195,3770.00,2510.00,5.00,30.00,226.00,1.50,******,37.00,******,22.70,
40.00,200,3770.00,2520.00,5.00,30.00,227.00,1.50,******,37.00,******,22.80,
41.00,205,3750.00,2510.00,5.00,30.00,226.00,1.50,******,37.00,******,22.70,
42.00,210,3740.00,2520.00,5.00,30.00,225.00,1.50,******,37.00,******,22.70,
43.00,215,3770.00,2500.00,5.00,30.00,226.00,1.50,******,37.00,******,22.70,
44.00,220,3750.00,2510.00,5.00,30.00,226.00,1.50,******,37.00,******,22.70,
45.00,225,3760.00,2510.00,5.00,30.00,226.00,1.50,******,37.00,******,22.70,
46.00,230,3750.00,2510.00,5.00,30.00,225.00,1.50,******,37.00,******,22.70,
47.00,235,3760.00,2520.00,5.00,30.00,226.00,1.50,******,37.00,******,22.80,
48.00,240,3760.00,2500.00,5.00,30.00,226.00,1.50,******,37.00,******,22.70,
49.00,245,3760.00,2520.00,5.00,30.00,226.00,1.50,******,37.00,******,22.80,
50.00,250,3750.00,2500.00,5.00,30.00,225.00,1.50,******,37.00,******,22.70,
51.00,255,3760.00,2510.00,5.00,30.00,226.00,1.50,******,37.00,******,22.70,
52.00,260,3740.00,2520.00,5.00,30.00,226.00,1.50,******,37.00,******,22.70,
53.00,265,3740.00,2510.00,5.00,30.00,225.00,1.50,******,37.00,******,22.60,
54.00,270,3730.00,2520.00,5.00,30.00,225.00,1.50,******,37.00,******,22.60,
55.00,275,3760.00,2520.00,5.00,30.00,226.00,1.50,******,37.00,******,22.70,
56.00,280,3750.00,2520.00,5.00,30.00,226.00,1.50,******,37.00,******,22.70,
57.00,285,3740.00,2520.00,5.00,30.00,226.00,1.50,******,37.00,******,22.70,
58.00,290,3750.00,2520.00,5.00,30.00,226.00,1.50,******,37.00,******,22.70,
59.00,295,3750.00,2520.00,5.00,30.00,226.00,1.50,******,37.00,******,22.70,
60.00,300,3740.00,2520.00,5.00,30.00,226.00,1.50,******,37.00,******,22.70,
61.00,305,3750.00,2520.00,5.00,30.00,226.00,1.50,******,37.00,******,22.70,
62.00,310,3750.00,2520.00,5.00,30.00,226.00,1.50,******,37.00,******,22.70,
63.00,315,3740.00,2520.00,5.00,30.00,226.00,1.50,******,37.00,******,22.70,
64.00,320,3730.00,2530.00,5.00,30.00,225.00,1.50,******,37.00,******,22.60,
65.00,325,3740.00,2520.00,5.00,30.00,225.00,1.50,******,37.00,******,22.70,
66.00,330,3740.00,2530.00,5.00,30.00,226.00,1.50,******,37.00,******,22.70,
67.00,335,3730.00,2530.00,5.00,30.00,225.00,1.50,******,37.00,******,22.60,
68.00,340,3740.00,2530.00,5.00,30.00,226.00,1.50,******,37.00,******,22.70,
69.00,345,3740.00,2530.00,5.00,30.00,226.00,1.50,******,37.00,******,22.70,
70.00,350,3730.00,2530.00,5.00,30.00,225.00,1.50,******,37.00,******,22.70,
71.00,355,3750.00,2530.00,5.00,30.00,226.00,1.50,******,37.00,******,22.70,
72.00,360,3740.00,2530.00,5.00,30.00,226.00,1.50,******,37.00,******,22.70,
73.00,365,3700.00,2530.00,5.00,30.00,224.00,1.50,******,37.00,******,22.50,
74.00,370,3730.00,2530.00,5.00,30.00,225.00,1.50,******,37.00,******,22.70,
75.00,375,3740.00,2530.00,5.00,30.00,226.00,1.50,******,37.00,******,22.70,
76.00,380,3740.00,2520.00,5.00,30.00,225.00,1.50,******,37.00,******,22.70,
77.00,385,3740.00,2530.00,5.00,30.00,226.00,1.50,******,37.00,******,22.70,
78.00,390,3740.00,2520.00,5.00,30.00,225.00,1.50,******,37.00,******,22.70,
79.00,395,3730.00,2520.00,5.00,30.00,225.00,1.50,******,37.00,******,22.60,
80.00,400,3730.00,2530.00,5.00,30.00,225.00,1.50,******,37.00,******,22.70,
,,,,,,,,,,,,
Interval:,,,2.00,,,,,,,,,
Number of Data Points:,,,31.00,,,,,,,,,
,,,,,,,,,,,,
Time Setting:,,,31 Meas. Pts.,,,,,,,,,
Measuring Profile:,,,,,,,,,,,,
#NAME?,,,Amplitude gamma = 5 %,,,,,,,,,
,,,Angular Frequency omega = 100 ... 0.1 rad/s log; |Slope| = 10 Pt. / dec ,,,,,,,,,
,,,,,,,,,,,,
Meas. Pts.,Time,Storage Modulus,Loss Modulus,Strain,Angular Frequency,Shear Stress,Shear Rate,Viscosity,Temperature,Speed,Torque,Status
,[s],[Pa],[Pa],[%],[rad/s],[Pa],[1/s],[Pa·s],[°C],[1/min],[µNm],[]
1.00,410,4020.00,2050.00,5.00,100.00,226.00,5.00,******,37.00,******,22.70,
2.00,418,4540.00,1890.00,5.00,79.40,246.00,3.97,******,37.00,******,24.70,
3.00,425,4530.00,2150.00,5.00,63.10,251.00,3.15,******,37.00,******,25.20,
4.00,432,4500.00,2250.00,5.00,50.10,252.00,2.51,******,37.00,******,25.30,
5.00,439,4220.00,2410.00,5.00,39.80,243.00,1.99,******,37.00,******,24.40,
6.00,448,3870.00,2510.00,5.00,31.60,231.00,1.58,******,37.00,******,23.20,
7.00,458,3470.00,2560.00,5.00,25.10,216.00,1.26,******,37.00,******,21.70,
8.00,465,3020.00,2560.00,5.00,20.00,198.00,1.00,******,37.00,******,19.90,
9.00,472,2570.00,2500.00,5.00,15.80,179.00,0.79,******,37.00,******,18.00,
10.00,478,2140.00,2390.00,5.00,12.60,160.00,0.63,******,37.00,******,16.10,
11.00,486,1730.00,2230.00,5.00,10.00,141.00,0.50,******,37.00,******,14.20,
12.00,493,1360.00,2040.00,5.00,7.94,123.00,0.40,******,37.00,******,12.30,
13.00,502,1050.00,1830.00,5.00,6.31,105.00,0.32,******,37.00,******,10.60,
14.00,509,779.00,1600.00,5.00,5.01,89.00,0.25,******,37.00,******,8.95,
15.00,517,571.00,1380.00,5.00,3.98,74.70,0.20,******,37.00,******,7.52,
16.00,527,406.00,1170.00,5.01,3.16,61.80,0.16,******,37.00,******,6.21,
17.00,540,288.00,975.00,5.01,2.51,50.90,0.13,******,37.00,******,5.12,
18.00,560,200.00,803.00,5.01,2.00,41.40,0.10,******,37.00,******,4.17,
19.00,586,140.00,656.00,5.01,1.58,33.60,0.08,******,37.00,******,3.37,
20.00,617,96.80,531.00,5.01,1.26,27.00,0.06,******,37.00,******,2.72,
21.00,656,68.10,429.00,5.01,1.00,21.70,0.05,******,37.00,******,2.19,
22.00,693,47.90,345.00,5.01,0.79,17.50,0.04,******,37.00,******,1.76,
23.00,739,35.90,277.00,5.01,0.63,14.00,0.03,******,37.00,******,1.41,
24.00,797,26.10,222.00,5.01,0.50,11.20,0.03,******,37.00,******,1.13,
25.00,869,19.90,179.00,5.01,0.40,8.99,0.02,******,37.00,******,0.90,
26.00,929,15.70,143.00,5.01,0.32,7.20,0.02,******,37.00,******,0.72,
27.00,1010,12.70,115.00,5.01,0.25,5.79,0.01,******,37.00,******,0.58,
28.00,1100,10.70,92.50,5.01,0.20,4.66,0.01,******,37.00,******,0.47,
29.00,1220,9.10,74.50,5.00,0.16,3.76,0.01,******,37.00,******,0.38,
30.00,1450,7.90,60.00,5.00,0.13,3.03,0.01,******,37.00,******,0.30,
31.00,1730,7.04,48.60,5.00,0.10,2.46,0.01,******,37.00,******,0.25,
,,,,,,,,,,,,
Interval:,,,3.00,,,,,,,,,
Number of Data Points:,,,80.00,,,,,,,,,
,,,,,,,,,,,,
Time Setting:,,,80 Meas. Pts.,,,,,,,,,
,,,Meas. Pt. Duration 5 s,,,,,,,,,
Event Control:,,,Standard Mode,,,,,,,,,
"  Terminate test, ...",,,...if M > 75 mNm,,,,,,,,,
Measuring Profile:,,,,,,,,,,,,
#NAME?,,,Amplitude gamma = 5 %,,,,,,,,,
,,,Angular Frequency omega = 30 rad/s,,,,,,,,,
,,,,,,,,,,,,
Meas. Pts.,Time,Storage Modulus,Loss Modulus,Strain,Angular Frequency,Shear Stress,Shear Rate,Viscosity,Temperature,Speed,Torque,Status
,[s],[Pa],[Pa],[%],[rad/s],[Pa],[1/s],[Pa·s],[°C],[1/min],[µNm],[]
1.00,invalid point,,,,,,,,,,,
2.00,1740,,,,,,,,,,,
3.00,1745,,,,,,,,,,,
4.00,1750,,,,,,,,,,,
5.00,1755,,,,,,,,,,,
6.00,1760,,,,,,,,,,,
7.00,1765,,,,,,,,,,,
8.00,1770,,,,,,,,,,,
9.00,1775,,,,,,,,,,,
10.00,1780,,,,,,,,,,,
11.00,1785,,,,,,,,,,,
12.00,1790,,,,,,,,,,,
13.00,1795,,,,,,,,,,,
14.00,1800,,,,,,,,,,,
15.00,1805,,,,,,,,,,,
16.00,1810,,,,,,,,,,,
17.00,1815,,,,,,,,,,,
18.00,1820,,,,,,,,,,,
19.00,1825,,,,,,,,,,,
20.00,1830,3680.00,2030.00,5.17,30.00,217.00,1.55,******,37.00,******,21.90,WMa
21.00,1835,3680.00,2560.00,5.00,30.00,224.00,1.50,******,37.00,******,22.50,
22.00,1840,3690.00,2570.00,5.00,30.00,225.00,1.50,******,37.00,******,22.60,
23.00,1845,3680.00,2550.00,5.00,30.00,224.00,1.50,******,37.00,******,22.50,
24.00,1850,3680.00,2550.00,5.00,30.00,224.00,1.50,******,37.00,******,22.50,
25.00,1855,3680.00,2550.00,5.00,30.00,224.00,1.50,******,37.00,******,22.50,
26.00,1860,3690.00,2550.00,5.00,30.00,224.00,1.50,******,37.00,******,22.60,
27.00,1865,3660.00,2560.00,5.00,30.00,223.00,1.50,******,37.00,******,22.50,
28.00,1870,3680.00,2550.00,5.00,30.00,224.00,1.50,******,37.00,******,22.50,
29.00,1875,3680.00,2550.00,5.00,30.00,224.00,1.50,******,37.00,******,22.50,
30.00,1880,3690.00,2540.00,5.00,30.00,224.00,1.50,******,37.00,******,22.50,
31.00,1885,3680.00,2560.00,5.00,30.00,224.00,1.50,******,37.00,******,22.50,
32.00,1890,3680.00,2570.00,5.00,30.00,224.00,1.50,******,37.00,******,22.60,
33.00,1895,3680.00,2550.00,5.00,30.00,224.00,1.50,******,37.00,******,22.50,
34.00,1900,3680.00,2550.00,5.00,30.00,224.00,1.50,******,37.00,******,22.50,
35.00,1905,3670.00,2550.00,5.00,30.00,223.00,1.50,******,37.00,******,22.50,
36.00,1910,3690.00,2550.00,5.00,30.00,224.00,1.50,******,37.00,******,22.50,
37.00,1915,3690.00,2550.00,5.00,30.00,224.00,1.50,******,37.00,******,22.50,
38.00,1920,3680.00,2540.00,5.00,30.00,223.00,1.50,******,37.00,******,22.50,
39.00,1925,3680.00,2550.00,5.00,30.00,224.00,1.50,******,37.00,******,22.50,
40.00,1930,3680.00,2550.00,5.00,30.00,224.00,1.50,******,37.00,******,22.50,
41.00,1935,3680.00,2560.00,5.00,30.00,224.00,1.50,******,37.00,******,22.60,
42.00,1940,3690.00,2540.00,5.00,30.00,224.00,1.50,******,37.00,******,22.50,
43.00,1945,3670.00,2550.00,5.00,30.00,224.00,1.50,******,37.00,******,22.50,
44.00,1950,3680.00,2550.00,5.00,30.00,224.00,1.50,******,37.00,******,22.50,
45.00,1955,3680.00,2550.00,5.00,30.00,224.00,1.50,******,37.00,******,22.50,
46.00,1960,3690.00,2550.00,5.00,30.00,224.00,1.50,******,37.00,******,22.50,
47.00,1965,3670.00,2540.00,5.00,30.00,223.00,1.50,******,37.00,******,22.50,
48.00,1970,3680.00,2530.00,5.00,30.00,224.00,1.50,******,37.00,******,22.50,
49.00,1975,3680.00,2540.00,5.00,30.00,224.00,1.50,******,37.00,******,22.50,
50.00,1980,3670.00,2530.00,5.00,30.00,223.00,1.50,******,37.00,******,22.40,
51.00,1985,3680.00,2540.00,5.00,30.00,224.00,1.50,******,37.00,******,22.50,
52.00,1990,3680.00,2550.00,5.00,30.00,224.00,1.50,******,37.00,******,22.50,
53.00,1995,3670.00,2550.00,5.00,30.00,224.00,1.50,******,37.00,******,22.50,
54.00,2000,3680.00,2540.00,5.00,30.00,224.00,1.50,******,37.00,******,22.50,
55.00,2005,3680.00,2550.00,5.00,30.00,224.00,1.50,******,37.00,******,22.50,
56.00,2010,3690.00,2560.00,5.00,30.00,225.00,1.50,******,37.00,******,22.60,
57.00,2015,3680.00,2560.00,5.00,30.00,224.00,1.50,******,37.00,******,22.60,
58.00,2020,3670.00,2550.00,5.00,30.00,224.00,1.50,******,37.00,******,22.50,
59.00,2025,3680.00,2560.00,5.00,30.00,224.00,1.50,******,37.00,******,22.50,
60.00,2030,3680.00,2550.00,5.00,30.00,224.00,1.50,******,37.00,******,22.50,
61.00,2035,3670.00,2550.00,5.00,30.00,223.00,1.50,******,37.00,******,22.50,
62.00,2040,3680.00,2550.00,5.00,30.00,224.00,1.50,******,37.00,******,22.50,
63.00,2045,3680.00,2550.00,5.00,30.00,224.00,1.50,******,37.00,******,22.50,
64.00,2050,3660.00,2560.00,5.00,30.00,223.00,1.50,******,37.00,******,22.50,
65.00,2055,3700.00,2560.00,5.00,30.00,225.00,1.50,******,37.00,******,22.60,
66.00,2060,3680.00,2540.00,5.00,30.00,224.00,1.50,******,37.00,******,22.50,
67.00,2065,3680.00,2560.00,5.00,30.00,224.00,1.50,******,37.00,******,22.50,
68.00,2070,3680.00,2560.00,5.00,30.00,224.00,1.50,******,37.00,******,22.60,
69.00,2075,3680.00,2550.00,5.00,30.00,224.00,1.50,******,37.00,******,22.50,
70.00,2080,3680.00,2550.00,5.00,30.00,224.00,1.50,******,37.00,******,22.50,
71.00,2085,3680.00,2560.00,5.00,30.00,224.00,1.50,******,37.00,******,22.50,
72.00,2090,3680.00,2560.00,5.00,30.00,224.00,1.50,******,37.00,******,22.50,
73.00,2095,3680.00,2550.00,5.00,30.00,224.00,1.50,******,37.00,******,22.50,
74.00,2100,3680.00,2550.00,5.00,30.00,224.00,1.50,******,37.00,******,22.50,
75.00,2105,3680.00,2560.00,5.00,30.00,224.00,1.50,******,37.00,******,22.50,
76.00,2110,3680.00,2560.00,5.00,30.00,224.00,1.50,******,37.00,******,22.50,
77.00,2115,3680.00,2550.00,5.00,30.00,224.00,1.50,******,37.00,******,22.50,
78.00,2120,3680.00,2550.00,5.00,30.00,224.00,1.50,******,37.00,******,22.50,
79.00,2125,3680.00,2550.00,5.00,30.00,224.00,1.50,******,37.00,******,22.50,
80.00,2130,3710.00,2550.00,5.00,30.00,225.00,1.50,******,37.00,******,22.60,
,,,,,,,,,,,,
Interval:,,,4.00,,,,,,,,,
Number of Data Points:,,,113.00,,,,,,,,,
,,,,,,,,,,,,
Time Setting:,,,113 Meas. Pts.,,,,,,,,,
,,,Meas. Pt. Duration 5 s,,,,,,,,,
Measuring Profile:,,,,,,,,,,,,
#NAME?,,,Amplitude gamma = 0.1 ... 500 % log; |Slope| = 30.278699 Pt. / dec ,,,,,,,,,
,,,Angular Frequency omega = 30 rad/s,,,,,,,,,
,,,,,,,,,,,,
Meas. Pts.,Time,Storage Modulus,Loss Modulus,Strain,Angular Frequency,Shear Stress,Shear Rate,Viscosity,Temperature,Speed,Torque,Status
,[s],[Pa],[Pa],[%],[rad/s],[Pa],[1/s],[Pa·s],[°C],[1/min],[µNm],[]
1.00,2135,8660.00,46800.00,0.10,30.00,47.70,0.03,******,37.00,******,4.80,"ME-,MV-"
2.00,2140,6890.00,2290.00,0.11,30.00,7.87,0.03,******,37.00,******,0.79,
3.00,2145,27600.00,0.00,0.12,30.00,32.50,0.04,******,37.00,******,3.27,"ME-,WMa"
4.00,2150,12100.00,8110.00,0.13,30.00,18.80,0.04,******,37.00,******,1.89,"ME-,MV-"
5.00,2155,0.00,7710.00,0.14,30.00,10.50,0.04,******,37.00,******,1.06,"MV-,WMa"
6.00,2160,0.00,19500.00,0.15,30.00,28.40,0.04,******,37.00,******,2.86,"ME-,WMa"
7.00,2165,16500.00,1480.00,0.16,30.00,25.60,0.05,******,37.00,******,2.57,WMa
8.00,2170,12100.00,8130.00,0.17,30.00,25.20,0.05,******,37.00,******,2.53,WMa
9.00,2175,4410.00,27200.00,0.19,30.00,51.00,0.06,******,37.00,******,5.13,WMa
10.00,2180,11100.00,0.00,0.20,30.00,21.90,0.06,******,37.00,******,2.20,"MV-,WMa"
11.00,2185,26700.00,0.00,0.22,30.00,57.90,0.07,******,37.00,******,5.82,"ME-,WMa"
12.00,2190,13200.00,10100.00,0.24,30.00,39.40,0.07,******,37.00,******,3.96,WMa
13.00,2195,5270.00,11500.00,0.25,30.00,31.80,0.08,******,37.00,******,3.20,WMa
14.00,2200,5550.00,2470.00,0.27,30.00,16.40,0.08,******,37.00,******,1.65,
15.00,2205,5240.00,2710.00,0.29,30.00,17.10,0.09,******,37.00,******,1.72,WMa
16.00,2210,1430.00,3190.00,0.32,30.00,11.00,0.09,******,37.00,******,1.11,"ME-,MV-"
17.00,2215,5160.00,2440.00,0.34,30.00,19.30,0.10,******,37.00,******,1.94,
18.00,2220,8650.00,0.00,0.37,30.00,31.80,0.11,******,37.00,******,3.19,"MV-,WMa"
19.00,2225,27100.00,3930.00,0.40,30.00,109.00,0.12,******,37.00,******,10.90,WMa
20.00,2230,1560.00,0.00,0.44,30.00,6.79,0.13,******,37.00,******,0.68,"MV-,WMa"
21.00,2235,4490.00,2440.00,0.46,30.00,23.40,0.14,******,37.00,******,2.35,
22.00,2240,3860.00,2910.00,0.50,30.00,24.00,0.15,******,37.00,******,2.41,WMa
23.00,2245,4210.00,2640.00,0.53,30.00,26.50,0.16,******,37.00,******,2.67,
24.00,2250,4020.00,2650.00,0.58,30.00,27.70,0.17,******,37.00,******,2.78,
25.00,2255,4710.00,2450.00,0.63,30.00,33.20,0.19,******,37.00,******,3.34,
26.00,2260,0.00,7610.00,0.67,30.00,51.00,0.20,******,37.00,******,5.13,"ME-,WMa"
27.00,2265,6720.00,2990.00,0.72,30.00,53.00,0.22,******,37.00,******,5.33,WMa
28.00,2270,2520.00,1250.00,0.78,30.00,21.90,0.23,******,37.00,******,2.20,WMa
29.00,2275,3730.00,2560.00,0.84,30.00,38.10,0.25,******,37.00,******,3.83,
30.00,2280,3760.00,2530.00,0.91,30.00,41.10,0.27,******,37.00,******,4.14,
31.00,2285,3680.00,2510.00,0.98,30.00,43.60,0.29,******,37.00,******,4.38,
32.00,2290,3730.00,2540.00,1.06,30.00,47.70,0.32,******,37.00,******,4.79,
33.00,2295,3670.00,2640.00,1.14,30.00,51.50,0.34,******,37.00,******,5.17,
34.00,2300,3770.00,2560.00,1.23,30.00,56.00,0.37,******,37.00,******,5.64,
35.00,2305,3770.00,2560.00,1.33,30.00,60.50,0.40,******,37.00,******,6.08,
36.00,2310,3760.00,2500.00,1.43,30.00,64.70,0.43,******,37.00,******,6.50,
37.00,2315,3680.00,2570.00,1.54,30.00,69.30,0.46,******,37.00,******,6.97,
38.00,2320,3620.00,2580.00,1.67,30.00,74.10,0.50,******,37.00,******,7.45,
39.00,2325,3580.00,2580.00,1.80,30.00,79.40,0.54,******,37.00,******,7.98,
40.00,2330,3590.00,2580.00,1.94,30.00,85.90,0.58,******,37.00,******,8.63,
41.00,2335,3700.00,2530.00,2.10,30.00,94.00,0.63,******,37.00,******,9.45,
42.00,2340,3760.00,2560.00,2.26,30.00,103.00,0.68,******,37.00,******,10.30,
43.00,2345,3780.00,2540.00,2.44,30.00,111.00,0.73,******,37.00,******,11.20,
44.00,2350,3730.00,2560.00,2.63,30.00,119.00,0.79,******,37.00,******,12.00,
45.00,2355,3750.00,2570.00,2.84,30.00,129.00,0.85,******,37.00,******,13.00,
46.00,2360,3750.00,2550.00,3.06,30.00,139.00,0.92,******,37.00,******,14.00,
47.00,2365,3810.00,2580.00,3.31,30.00,152.00,0.99,******,37.00,******,15.30,
48.00,2370,3790.00,2540.00,3.57,30.00,163.00,1.07,******,37.00,******,16.40,
49.00,2375,3740.00,2570.00,3.85,30.00,174.00,1.15,******,37.00,******,17.50,
50.00,2380,3770.00,2550.00,4.15,30.00,189.00,1.25,******,37.00,******,19.00,
51.00,2385,3830.00,2560.00,4.48,30.00,206.00,1.34,******,37.00,******,20.70,
52.00,2390,3810.00,2540.00,4.84,30.00,221.00,1.45,******,37.00,******,22.20,
53.00,2395,3820.00,2550.00,5.22,30.00,240.00,1.57,******,37.00,******,24.10,
54.00,2400,3750.00,2550.00,5.63,30.00,255.00,1.69,******,37.00,******,25.70,
55.00,2405,3720.00,2560.00,6.07,30.00,274.00,1.82,******,37.00,******,27.60,
56.00,2410,3740.00,2560.00,6.55,30.00,297.00,1.97,******,37.00,******,29.80,
57.00,2415,3720.00,2550.00,7.07,30.00,319.00,2.12,******,37.00,******,32.10,
58.00,2420,3710.00,2560.00,7.63,30.00,344.00,2.29,******,37.00,******,34.60,
59.00,2425,3710.00,2560.00,8.23,30.00,371.00,2.47,******,37.00,******,37.30,
60.00,2430,3710.00,2560.00,8.88,30.00,400.00,2.67,******,37.00,******,40.20,
61.00,2435,3710.00,2550.00,9.59,30.00,432.00,2.88,******,37.00,******,43.40,
62.00,2440,3710.00,2550.00,10.30,30.00,466.00,3.10,******,37.00,******,46.90,
63.00,2445,3750.00,2570.00,11.20,30.00,507.00,3.35,******,37.00,******,50.90,
64.00,2450,3750.00,2550.00,12.00,30.00,547.00,3.61,******,37.00,******,55.00,
65.00,2455,3780.00,2550.00,13.00,30.00,592.00,3.90,******,37.00,******,59.50,
66.00,2460,3720.00,2550.00,14.00,30.00,633.00,4.21,******,37.00,******,63.70,
67.00,2465,3710.00,2550.00,15.10,30.00,682.00,4.54,******,37.00,******,68.50,
68.00,2470,3710.00,2550.00,16.30,30.00,735.00,4.90,******,37.00,******,73.90,
69.00,2475,3710.00,2550.00,17.60,30.00,793.00,5.28,******,37.00,******,79.80,
70.00,2480,3720.00,2550.00,19.00,30.00,857.00,5.70,******,37.00,******,86.20,
71.00,2485,3750.00,2550.00,20.50,30.00,931.00,6.15,******,37.00,******,93.60,
72.00,2490,3720.00,2550.00,22.10,30.00,998.00,6.64,******,37.00,******,100.00,
73.00,2495,3700.00,2550.00,23.90,30.00,1070.00,7.16,******,37.00,******,108.00,
74.00,2500,3710.00,2550.00,25.80,30.00,1160.00,7.73,******,37.00,******,117.00,
75.00,2505,3730.00,2550.00,27.80,30.00,1260.00,8.34,******,37.00,******,126.00,
76.00,2510,3720.00,2540.00,30.00,30.00,1350.00,9.00,******,37.00,******,136.00,
77.00,2515,3700.00,2540.00,32.40,30.00,1450.00,9.71,******,37.00,******,146.00,
78.00,2520,3710.00,2540.00,34.90,30.00,1570.00,10.50,******,37.00,******,158.00,
79.00,2525,3720.00,2540.00,37.70,30.00,1700.00,11.30,******,37.00,******,171.00,
80.00,2530,3710.00,2540.00,40.70,30.00,1830.00,12.20,******,37.00,******,184.00,
81.00,2535,3720.00,2540.00,43.90,30.00,1980.00,13.20,******,37.00,******,199.00,
82.00,2540,3720.00,2540.00,47.30,30.00,2130.00,14.20,******,37.00,******,214.00,
83.00,2545,3630.00,2560.00,51.10,30.00,2270.00,15.30,******,37.00,******,228.00,
84.00,2550,3630.00,2550.00,55.10,30.00,2450.00,16.50,******,37.00,******,246.00,
85.00,2555,3620.00,2550.00,59.50,30.00,2640.00,17.80,******,37.00,******,265.00,
86.00,2560,3630.00,2550.00,64.20,30.00,2850.00,19.30,******,37.00,******,286.00,
87.00,2565,3610.00,2550.00,69.20,30.00,3060.00,20.80,******,37.00,******,307.00,
88.00,2570,3610.00,2550.00,74.70,30.00,3300.00,22.40,******,37.00,******,332.00,
89.00,2575,3610.00,2540.00,80.60,30.00,3560.00,24.20,******,37.00,******,358.00,
90.00,2580,3590.00,2530.00,87.00,30.00,3820.00,26.10,******,37.00,******,384.00,
91.00,2585,3560.00,2520.00,93.90,30.00,4090.00,28.20,******,37.00,******,411.00,
92.00,2590,3540.00,2510.00,101.00,30.00,4390.00,30.40,******,37.00,******,442.00,
93.00,2595,3420.00,2470.00,109.00,30.00,4610.00,32.80,******,37.00,******,464.00,
94.00,2600,3190.00,2340.00,118.00,30.00,4660.00,35.40,******,37.00,******,468.00,
95.00,2605,2850.00,2140.00,127.00,30.00,4540.00,38.20,******,37.00,******,456.00,
96.00,2610,2280.00,1760.00,137.00,30.00,3950.00,41.20,******,37.00,******,397.00,
97.00,2615,1310.00,1060.00,148.00,30.00,2500.00,44.50,******,37.00,******,251.00,
98.00,2620,498.00,487.00,160.00,30.00,1110.00,48.00,******,37.00,******,112.00,
99.00,2625,192.00,274.00,172.00,30.00,577.00,51.70,******,37.00,******,58.00,
100.00,2630,66.50,193.00,186.00,30.00,380.00,55.80,******,37.00,******,38.20,
101.00,2635,15.90,151.00,201.00,30.00,305.00,60.20,******,37.00,******,30.70,
102.00,2640,0.00,119.00,217.00,30.00,258.00,65.00,******,37.00,******,25.90,"ME-,taD"
103.00,2645,0.00,110.00,234.00,30.00,256.00,70.10,******,37.00,******,25.70,"ME-,taD"
104.00,2650,0.00,99.60,252.00,30.00,251.00,75.70,******,37.00,******,25.30,"ME-,taD"
105.00,2655,0.00,95.30,272.00,30.00,259.00,81.60,******,37.00,******,26.10,"ME-,taD"
106.00,2660,0.00,111.00,294.00,30.00,325.00,88.10,******,37.00,******,32.60,"ME-,taD"
107.00,2665,0.00,129.00,317.00,30.00,408.00,95.10,******,37.00,******,41.00,"ME-,taD"
108.00,2670,0.00,145.00,342.00,30.00,497.00,103.00,******,37.00,******,50.00,"ME-,taD"
109.00,2675,0.00,154.00,369.00,30.00,567.00,111.00,******,37.00,******,57.00,"ME-,taD"
110.00,2680,0.00,163.00,398.00,30.00,647.00,119.00,******,37.00,******,65.10,"ME-,taD"
111.00,2685,0.00,179.00,429.00,30.00,768.00,129.00,******,37.00,******,77.20,"ME-,taD"
112.00,2690,0.00,172.00,463.00,30.00,798.00,139.00,******,37.00,******,80.30,"ME-,taD"
113.00,2695,0.00,169.00,500.00,30.00,846.00,150.00,******,37.00,******,85.10,"ME-,taD"
,,,,,,,,,,,,
Interval:,,,5.00,,,,,,,,,
Number of Data Points:,,,80.00,,,,,,,,,
,,,,,,,,,,,,
Time Setting:,,,80 Meas. Pts.,,,,,,,,,
,,,Meas. Pt. Duration 5 s,,,,,,,,,
Event Control:,,,Standard Mode,,,,,,,,,
"  Terminate test, ...",,,...if M > 75 mNm,,,,,,,,,
Measuring Profile:,,,,,,,,,,,,
#NAME?,,,Amplitude gamma = 5 %,,,,,,,,,
,,,Angular Frequency omega = 30 rad/s,,,,,,,,,
,,,,,,,,,,,,
Meas. Pts.,Time,Storage Modulus,Loss Modulus,Strain,Angular Frequency,Shear Stress,Shear Rate,Viscosity,Temperature,Speed,Torque,Status
,[s],[Pa],[Pa],[%],[rad/s],[Pa],[1/s],[Pa·s],[°C],[1/min],[µNm],[]
1.00,2700,0.00,1430.00,4.96,30.00,70.70,1.49,******,37.00,******,7.11,"ME-,WMa"
2.00,2705,0.00,201.00,5.00,30.00,10.00,1.50,******,37.00,******,1.01,"ME-,taD"
3.00,2710,0.00,151.00,5.00,30.00,7.55,1.50,******,37.00,******,0.76,"ME-,taD"
4.00,2715,8.20,177.00,5.00,30.00,8.85,1.50,******,37.00,******,0.89,ME-
5.00,2720,152.00,283.00,5.00,30.00,16.10,1.50,******,37.00,******,1.61,
6.00,2725,300.00,395.00,5.00,30.00,24.80,1.50,******,37.00,******,2.49,
7.00,2730,502.00,508.00,5.00,30.00,35.70,1.50,******,37.00,******,3.59,
8.00,2735,753.00,666.00,5.00,30.00,50.30,1.50,******,37.00,******,5.05,
9.00,2740,901.00,779.00,5.00,30.00,59.50,1.50,******,37.00,******,5.99,
10.00,2745,1080.00,885.00,5.00,30.00,69.80,1.50,******,37.00,******,7.02,
11.00,2750,1320.00,1030.00,5.00,30.00,83.70,1.50,******,37.00,******,8.42,
12.00,2755,1600.00,1230.00,5.00,30.00,101.00,1.50,******,37.00,******,10.10,
13.00,2760,1810.00,1380.00,5.00,30.00,114.00,1.50,******,37.00,******,11.40,
14.00,2765,2000.00,1480.00,5.00,30.00,125.00,1.50,******,37.00,******,12.50,
15.00,2770,2220.00,1610.00,5.00,30.00,137.00,1.50,******,37.00,******,13.80,
16.00,2775,2340.00,1710.00,5.00,30.00,145.00,1.50,******,37.00,******,14.60,
17.00,2780,2540.00,1840.00,5.00,30.00,157.00,1.50,******,37.00,******,15.80,
18.00,2785,2650.00,1910.00,5.00,30.00,163.00,1.50,******,37.00,******,16.40,
19.00,2790,2770.00,1990.00,5.00,30.00,171.00,1.50,******,37.00,******,17.10,
20.00,2795,2870.00,2050.00,5.00,30.00,176.00,1.50,******,37.00,******,17.70,
21.00,2800,2960.00,2100.00,5.00,30.00,182.00,1.50,******,37.00,******,18.30,
22.00,2805,3070.00,2150.00,5.00,30.00,187.00,1.50,******,37.00,******,18.80,
23.00,2810,3140.00,2220.00,5.00,30.00,192.00,1.50,******,37.00,******,19.40,
24.00,2815,3220.00,2270.00,5.00,30.00,197.00,1.50,******,37.00,******,19.80,
25.00,2820,3290.00,2320.00,5.00,30.00,201.00,1.50,******,37.00,******,20.30,
26.00,2825,3360.00,2370.00,5.00,30.00,206.00,1.50,******,37.00,******,20.70,
27.00,2830,3420.00,2400.00,5.00,30.00,209.00,1.50,******,37.00,******,21.00,
28.00,2835,3460.00,2430.00,5.00,30.00,211.00,1.50,******,37.00,******,21.20,
29.00,2840,3500.00,2450.00,5.00,30.00,214.00,1.50,******,37.00,******,21.50,
30.00,2845,3510.00,2470.00,5.00,30.00,215.00,1.50,******,37.00,******,21.60,
31.00,2850,3560.00,2500.00,5.00,30.00,217.00,1.50,******,37.00,******,21.90,
32.00,2855,3560.00,2490.00,5.00,30.00,217.00,1.50,******,37.00,******,21.90,
33.00,2860,3570.00,2500.00,5.00,30.00,218.00,1.50,******,37.00,******,21.90,
34.00,2865,3560.00,2500.00,5.00,30.00,218.00,1.50,******,37.00,******,21.90,
35.00,2870,3590.00,2510.00,5.00,30.00,219.00,1.50,******,37.00,******,22.00,
36.00,2875,3580.00,2520.00,5.00,30.00,219.00,1.50,******,37.00,******,22.00,
37.00,2880,3610.00,2520.00,5.00,30.00,220.00,1.50,******,37.00,******,22.10,
38.00,2885,3600.00,2500.00,5.00,30.00,219.00,1.50,******,37.00,******,22.10,
39.00,2890,3610.00,2520.00,5.00,30.00,220.00,1.50,******,37.00,******,22.20,
40.00,2895,3620.00,2540.00,5.00,30.00,221.00,1.50,******,37.00,******,22.20,
41.00,2900,3620.00,2520.00,5.00,30.00,221.00,1.50,******,37.00,******,22.20,
42.00,2905,3630.00,2530.00,5.00,30.00,221.00,1.50,******,37.00,******,22.20,
43.00,2910,3640.00,2530.00,5.00,30.00,222.00,1.50,******,37.00,******,22.30,
44.00,2915,3630.00,2530.00,5.00,30.00,221.00,1.50,******,37.00,******,22.30,
45.00,2920,3630.00,2540.00,5.00,30.00,222.00,1.50,******,37.00,******,22.30,
46.00,2925,3640.00,2530.00,5.00,30.00,222.00,1.50,******,37.00,******,22.30,
47.00,2930,3650.00,2560.00,5.00,30.00,223.00,1.50,******,37.00,******,22.40,
48.00,2935,3650.00,2530.00,5.00,30.00,222.00,1.50,******,37.00,******,22.30,
49.00,2940,3640.00,2540.00,5.00,30.00,222.00,1.50,******,37.00,******,22.30,
50.00,2945,3650.00,2540.00,5.00,30.00,222.00,1.50,******,37.00,******,22.40,
51.00,2950,3650.00,2540.00,5.00,30.00,222.00,1.50,******,37.00,******,22.40,
52.00,2955,3650.00,2550.00,5.00,30.00,223.00,1.50,******,37.00,******,22.40,
53.00,2960,3650.00,2560.00,5.00,30.00,223.00,1.50,******,37.00,******,22.40,
54.00,2965,3630.00,2560.00,5.00,30.00,222.00,1.50,******,37.00,******,22.30,
55.00,2970,3650.00,2550.00,5.00,30.00,223.00,1.50,******,37.00,******,22.40,
56.00,2975,3650.00,2540.00,5.00,30.00,222.00,1.50,******,37.00,******,22.40,
57.00,2980,3650.00,2550.00,5.00,30.00,223.00,1.50,******,37.00,******,22.40,
58.00,2985,3650.00,2560.00,5.00,30.00,223.00,1.50,******,37.00,******,22.40,
59.00,2990,3660.00,2550.00,5.00,30.00,223.00,1.50,******,37.00,******,22.40,
60.00,2995,3660.00,2540.00,5.00,30.00,223.00,1.50,******,37.00,******,22.40,
61.00,3000,3660.00,2560.00,5.00,30.00,223.00,1.50,******,37.00,******,22.40,
62.00,3005,3670.00,2560.00,5.00,30.00,224.00,1.50,******,37.00,******,22.50,
63.00,3010,3660.00,2560.00,5.00,30.00,223.00,1.50,******,37.00,******,22.50,
64.00,3015,3670.00,2560.00,5.00,30.00,224.00,1.50,******,37.00,******,22.50,
65.00,3020,3660.00,2550.00,5.00,30.00,223.00,1.50,******,37.00,******,22.40,
66.00,3025,3660.00,2560.00,5.00,30.00,223.00,1.50,******,37.00,******,22.50,
67.00,3030,3680.00,2560.00,5.00,30.00,224.00,1.50,******,37.00,******,22.50,
68.00,3035,3670.00,2560.00,5.00,30.00,224.00,1.50,******,37.00,******,22.50,
69.00,3040,3670.00,2550.00,5.00,30.00,224.00,1.50,******,37.00,******,22.50,
70.00,3045,3670.00,2550.00,5.00,30.00,223.00,1.50,******,37.00,******,22.50,
71.00,3050,3660.00,2560.00,5.00,30.00,223.00,1.50,******,37.00,******,22.50,
72.00,3055,3670.00,2550.00,5.00,30.00,223.00,1.50,******,37.00,******,22.40,
73.00,3060,3650.00,2560.00,5.00,30.00,223.00,1.50,******,37.00,******,22.40,
74.00,3065,3670.00,2560.00,5.00,30.00,224.00,1.50,******,37.00,******,22.50,
75.00,3070,3670.00,2560.00,5.00,30.00,224.00,1.50,******,37.00,******,22.50,
76.00,3075,3660.00,2580.00,5.00,30.00,224.00,1.50,******,37.00,******,22.50,
77.00,3080,3690.00,2560.00,5.00,30.00,224.00,1.50,******,37.00,******,22.60,
78.00,3085,3680.00,2550.00,5.00,30.00,224.00,1.50,******,37.00,******,22.50,
79.00,3090,3680.00,2560.00,5.00,30.00,224.00,1.50,******,37.00,******,22.50,
80.00,3095,3670.00,2560.00,5.00,30.00,224.00,1.50,******,37.00,******,22.50,
,,,,,,,,,,,,
Interval:,,,6.00,,,,,,,,,
Number of Data Points:,,,600.00,,,,,,,,,
,,,,,,,,,,,,
Time Setting:,,,600 Meas. Pts.,,,,,,,,,
,,,Meas. Pt. Duration 3 s,,,,,,,,,
Event Control:,,,Standard Mode,,,,,,,,,
"  Terminate test, ...",,,...if M > 200 mNm,,,,,,,,,
Measuring Profile:,,,,,,,,,,,,
#NAME?,,,Amplitude gamma = 5 %,,,,,,,,,
,,,Angular Frequency omega = 30 rad/s,,,,,,,,,
,,,,,,,,,,,,
Meas. Pts.,Time,Storage Modulus,Loss Modulus,Strain,Angular Frequency,Shear Stress,Shear Rate,Viscosity,Temperature,Speed,Torque,Status
,[s],[Pa],[Pa],[%],[rad/s],[Pa],[1/s],[Pa·s],[°C],[1/min],[µNm],[]
1.00,3098,3720.00,2560.00,5.00,30.00,226.00,1.50,******,37.00,******,22.70,WMa
2.00,3101,3730.00,2570.00,5.00,30.00,226.00,1.50,******,37.00,******,22.80,WMa
3.00,3104,3750.00,2560.00,5.00,30.00,227.00,1.50,******,37.00,******,22.80,WMa
4.00,3107,3760.00,2570.00,5.00,30.00,227.00,1.50,******,37.00,******,22.90,WMa
5.00,3110,3720.00,2570.00,5.00,30.00,226.00,1.50,******,37.00,******,22.70,WMa
6.00,3113,3700.00,2560.00,5.00,30.00,225.00,1.50,******,37.00,******,22.60,
7.00,3116,3730.00,2570.00,5.00,30.00,226.00,1.50,******,37.00,******,22.80,
8.00,3119,3740.00,2570.00,5.00,30.00,227.00,1.50,******,37.00,******,22.80,
9.00,3122,3730.00,2560.00,5.00,30.00,226.00,1.50,******,37.00,******,22.80,
10.00,3125,3730.00,2560.00,5.00,30.00,226.00,1.50,******,37.00,******,22.80,
11.00,3128,3730.00,2530.00,5.00,30.00,225.00,1.50,******,37.00,******,22.70,
12.00,3131,3740.00,2560.00,5.00,30.00,227.00,1.50,******,37.00,******,22.80,
13.00,3134,3740.00,2560.00,5.00,30.00,227.00,1.50,******,37.00,******,22.80,
14.00,3137,3740.00,2570.00,5.00,30.00,227.00,1.50,******,37.00,******,22.80,
15.00,3140,3730.00,2560.00,5.00,30.00,226.00,1.50,******,37.00,******,22.70,
16.00,3143,3740.00,2580.00,5.00,30.00,227.00,1.50,******,37.00,******,22.90,
17.00,3146,3730.00,2580.00,5.00,30.00,227.00,1.50,******,37.00,******,22.80,
18.00,3149,3740.00,2550.00,5.00,30.00,226.00,1.50,******,37.00,******,22.70,
19.00,3152,3730.00,2560.00,5.00,30.00,226.00,1.50,******,37.00,******,22.70,
20.00,3155,3740.00,2560.00,5.00,30.00,227.00,1.50,******,37.00,******,22.80,
21.00,3158,3750.00,2570.00,5.00,30.00,227.00,1.50,******,37.00,******,22.90,
22.00,3161,3720.00,2570.00,5.00,30.00,226.00,1.50,******,37.00,******,22.70,
23.00,3164,3760.00,2550.00,5.00,30.00,227.00,1.50,******,37.00,******,22.80,
24.00,3167,3730.00,2570.00,5.00,30.00,226.00,1.50,******,37.00,******,22.80,
25.00,3170,3730.00,2580.00,5.00,30.00,227.00,1.50,******,37.00,******,22.80,
26.00,3173,3740.00,2580.00,5.00,30.00,227.00,1.50,******,37.00,******,22.80,
27.00,3176,3720.00,2550.00,5.00,30.00,226.00,1.50,******,37.00,******,22.70,
28.00,3179,3700.00,2590.00,5.00,30.00,226.00,1.50,******,37.00,******,22.70,
29.00,3182,3720.00,2570.00,5.00,30.00,226.00,1.50,******,37.00,******,22.70,
30.00,3185,3730.00,2580.00,5.00,30.00,227.00,1.50,******,37.00,******,22.80,
31.00,3188,3730.00,2580.00,5.00,30.00,227.00,1.50,******,37.00,******,22.80,
32.00,3191,3730.00,2570.00,5.00,30.00,227.00,1.50,******,37.00,******,22.80,
33.00,3194,3730.00,2580.00,5.00,30.00,227.00,1.50,******,37.00,******,22.80,
34.00,3197,3750.00,2570.00,5.00,30.00,227.00,1.50,******,37.00,******,22.90,
35.00,3200,3750.00,2590.00,5.00,30.00,228.00,1.50,******,37.00,******,22.90,
36.00,3203,3720.00,2560.00,5.00,30.00,226.00,1.50,******,37.00,******,22.70,
37.00,3206,3740.00,2560.00,5.00,30.00,226.00,1.50,******,37.00,******,22.80,
38.00,3209,3750.00,2550.00,5.00,30.00,227.00,1.50,******,37.00,******,22.80,
39.00,3212,3720.00,2600.00,5.00,30.00,227.00,1.50,******,37.00,******,22.80,
40.00,3215,3740.00,2560.00,5.00,30.00,227.00,1.50,******,37.00,******,22.80,
41.00,3218,3720.00,2550.00,5.00,30.00,225.00,1.50,******,37.00,******,22.70,
42.00,3221,3730.00,2550.00,5.00,30.00,226.00,1.50,******,37.00,******,22.70,
43.00,3224,3740.00,2560.00,5.00,30.00,227.00,1.50,******,37.00,******,22.80,
44.00,3227,3740.00,2560.00,5.00,30.00,227.00,1.50,******,37.00,******,22.80,
45.00,3230,3750.00,2560.00,5.00,30.00,227.00,1.50,******,37.00,******,22.80,
46.00,3233,3710.00,2590.00,5.00,30.00,226.00,1.50,******,37.00,******,22.80,
47.00,3236,3750.00,2560.00,5.00,30.00,227.00,1.50,******,37.00,******,22.80,
48.00,3239,3740.00,2580.00,5.00,30.00,227.00,1.50,******,37.00,******,22.80,
49.00,3242,3730.00,2560.00,5.00,30.00,226.00,1.50,******,37.00,******,22.80,
50.00,3245,3730.00,2560.00,5.00,30.00,226.00,1.50,******,37.00,******,22.80,
51.00,3248,3740.00,2580.00,5.00,30.00,227.00,1.50,******,37.00,******,22.90,
52.00,3251,3760.00,2570.00,5.00,30.00,228.00,1.50,******,37.00,******,22.90,
53.00,3254,3740.00,2550.00,5.00,30.00,227.00,1.50,******,37.00,******,22.80,
54.00,3257,3740.00,2570.00,5.00,30.00,227.00,1.50,******,37.00,******,22.80,
55.00,3260,3740.00,2570.00,5.00,30.00,227.00,1.50,******,37.00,******,22.80,
56.00,3263,3740.00,2580.00,5.00,30.00,227.00,1.50,******,37.00,******,22.80,
57.00,3266,3740.00,2570.00,5.00,30.00,227.00,1.50,******,37.00,******,22.80,
58.00,3269,3730.00,2560.00,5.00,30.00,226.00,1.50,******,37.00,******,22.80,
59.00,3272,3740.00,2570.00,5.00,30.00,227.00,1.50,******,37.00,******,22.80,
60.00,3275,3750.00,2580.00,5.00,30.00,227.00,1.50,******,37.00,******,22.90,
61.00,3278,3740.00,2570.00,5.00,30.00,227.00,1.50,******,37.00,******,22.80,
62.00,3281,3730.00,2590.00,5.00,30.00,227.00,1.50,******,37.00,******,22.80,
63.00,3284,3740.00,2570.00,5.00,30.00,227.00,1.50,******,37.00,******,22.80,
64.00,3287,3750.00,2600.00,5.00,30.00,228.00,1.50,******,37.00,******,22.90,
65.00,3290,3730.00,2560.00,5.00,30.00,226.00,1.50,******,37.00,******,22.80,
66.00,3293,3740.00,2570.00,5.00,30.00,227.00,1.50,******,37.00,******,22.80,
67.00,3296,3740.00,2580.00,5.00,30.00,227.00,1.50,******,37.00,******,22.80,
68.00,3299,3740.00,2580.00,5.00,30.00,227.00,1.50,******,37.00,******,22.80,
69.00,3302,3730.00,2590.00,5.00,30.00,227.00,1.50,******,37.00,******,22.80,
70.00,3305,3750.00,2580.00,5.00,30.00,227.00,1.50,******,37.00,******,22.90,
71.00,3308,3750.00,2540.00,5.00,30.00,227.00,1.50,******,37.00,******,22.80,
72.00,3311,3740.00,2570.00,5.00,30.00,227.00,1.50,******,37.00,******,22.80,
73.00,3314,3760.00,2590.00,5.00,30.00,228.00,1.50,******,37.00,******,22.90,
74.00,3317,3740.00,2570.00,5.00,30.00,227.00,1.50,******,37.00,******,22.80,
75.00,3320,3750.00,2580.00,5.00,30.00,227.00,1.50,******,37.00,******,22.90,
76.00,3323,3740.00,2580.00,5.00,30.00,227.00,1.50,******,37.00,******,22.80,
77.00,3326,3710.00,2610.00,5.00,30.00,227.00,1.50,******,37.00,******,22.80,
78.00,3329,3760.00,2590.00,5.00,30.00,228.00,1.50,******,37.00,******,23.00,
79.00,3332,3740.00,2560.00,5.00,30.00,227.00,1.50,******,37.00,******,22.80,
80.00,3335,3750.00,2580.00,5.00,30.00,228.00,1.50,******,37.00,******,22.90,
81.00,3338,3750.00,2580.00,5.00,30.00,228.00,1.50,******,37.00,******,22.90,
82.00,3341,3740.00,2580.00,5.00,30.00,227.00,1.50,******,37.00,******,22.80,
83.00,3344,3760.00,2570.00,5.00,30.00,228.00,1.50,******,37.00,******,22.90,
84.00,3347,3740.00,2570.00,5.00,30.00,227.00,1.50,******,37.00,******,22.80,
85.00,3350,3740.00,2570.00,5.00,30.00,227.00,1.50,******,37.00,******,22.80,
86.00,3353,3760.00,2570.00,5.00,30.00,228.00,1.50,******,37.00,******,22.90,
87.00,3356,3740.00,2560.00,5.00,30.00,227.00,1.50,******,37.00,******,22.80,
88.00,3359,3760.00,2610.00,5.00,30.00,229.00,1.50,******,37.00,******,23.00,
89.00,3362,3740.00,2570.00,5.00,30.00,227.00,1.50,******,37.00,******,22.80,
90.00,3365,3730.00,2590.00,5.00,30.00,227.00,1.50,******,37.00,******,22.80,
91.00,3368,3750.00,2570.00,5.00,30.00,228.00,1.50,******,37.00,******,22.90,
92.00,3371,3750.00,2570.00,5.00,30.00,227.00,1.50,******,37.00,******,22.90,
93.00,3374,3750.00,2570.00,5.00,30.00,227.00,1.50,******,37.00,******,22.80,
94.00,3377,3740.00,2580.00,5.00,30.00,227.00,1.50,******,37.00,******,22.80,
95.00,3380,3710.00,2560.00,5.00,30.00,226.00,1.50,******,37.00,******,22.70,
96.00,3383,3760.00,2580.00,5.00,30.00,228.00,1.50,******,37.00,******,22.90,
97.00,3386,3730.00,2570.00,5.00,30.00,227.00,1.50,******,37.00,******,22.80,
98.00,3389,3800.00,2590.00,5.00,30.00,230.00,1.50,******,37.00,******,23.10,
99.00,3392,3760.00,2540.00,5.00,30.00,227.00,1.50,******,37.00,******,22.80,
100.00,3395,3750.00,2570.00,5.00,30.00,228.00,1.50,******,37.00,******,22.90,
101.00,3398,3730.00,2570.00,5.00,30.00,227.00,1.50,******,37.00,******,22.80,
102.00,3401,3740.00,2580.00,5.00,30.00,227.00,1.50,******,37.00,******,22.90,
103.00,3404,3770.00,2570.00,5.00,30.00,228.00,1.50,******,37.00,******,22.90,
104.00,3407,3730.00,2560.00,5.00,30.00,226.00,1.50,******,37.00,******,22.70,
105.00,3410,3730.00,2570.00,5.00,30.00,226.00,1.50,******,37.00,******,22.70,
106.00,3413,3770.00,2570.00,5.00,30.00,228.00,1.50,******,37.00,******,22.90,
107.00,3416,3750.00,2580.00,5.00,30.00,228.00,1.50,******,37.00,******,22.90,
108.00,3419,3760.00,2570.00,5.00,30.00,228.00,1.50,******,37.00,******,22.90,
109.00,3422,3730.00,2600.00,5.00,30.00,227.00,1.50,******,37.00,******,22.90,
[...]
388.00,11699,3590.00,2620.00,5.00,30.00,222.00,1.50,******,37.00,******,22.30,
389.00,11702,3610.00,2620.00,5.00,30.00,223.00,1.50,******,37.00,******,22.40,
390.00,11705,3620.00,2620.00,5.00,30.00,223.00,1.50,******,37.00,******,22.40,
391.00,11708,3620.00,2620.00,5.00,30.00,223.00,1.50,******,37.00,******,22.50,
392.00,11711,3630.00,2610.00,5.00,30.00,223.00,1.50,******,37.00,******,22.50,
393.00,11714,3620.00,2590.00,5.00,30.00,222.00,1.50,******,37.00,******,22.40,
394.00,11717,3630.00,2630.00,5.00,30.00,224.00,1.50,******,37.00,******,22.60,
395.00,11720,3610.00,2620.00,5.00,30.00,223.00,1.50,******,37.00,******,22.40,
396.00,11723,3610.00,2610.00,5.00,30.00,223.00,1.50,******,37.00,******,22.40,
397.00,11726,3580.00,2600.00,5.00,30.00,221.00,1.50,******,37.00,******,22.20,
398.00,11729,3600.00,2610.00,5.00,30.00,222.00,1.50,******,37.00,******,22.30,
399.00,11732,3620.00,2610.00,5.00,30.00,223.00,1.50,******,37.00,******,22.50,
400.00,11735,3610.00,2590.00,5.00,30.00,222.00,1.50,******,37.00,******,22.30,
401.00,11738,3620.00,2610.00,5.00,30.00,223.00,1.50,******,37.00,******,22.40,
402.00,11741,3610.00,2620.00,5.00,30.00,223.00,1.50,******,37.00,******,22.40,
403.00,11744,3610.00,2610.00,5.00,30.00,223.00,1.50,******,37.00,******,22.40,
404.00,11747,3610.00,2620.00,5.00,30.00,223.00,1.50,******,37.00,******,22.40,
405.00,11750,3620.00,2620.00,5.00,30.00,223.00,1.50,******,37.00,******,22.50,
406.00,11753,3620.00,2630.00,5.00,30.00,224.00,1.50,******,37.00,******,22.50,
407.00,11756,3600.00,2610.00,5.00,30.00,222.00,1.50,******,37.00,******,22.40,
408.00,11759,3600.00,2610.00,5.00,30.00,222.00,1.50,******,37.00,******,22.30,
409.00,11762,3610.00,2630.00,5.00,30.00,223.00,1.50,******,37.00,******,22.40,
410.00,11765,3620.00,2610.00,5.00,30.00,223.00,1.50,******,37.00,******,22.40,
411.00,11768,3620.00,2620.00,5.00,30.00,223.00,1.50,******,37.00,******,22.40,
412.00,11771,3620.00,2630.00,5.00,30.00,224.00,1.50,******,37.00,******,22.50,
413.00,11774,3600.00,2610.00,5.00,30.00,223.00,1.50,******,37.00,******,22.40,
414.00,11777,3620.00,2620.00,5.00,30.00,223.00,1.50,******,37.00,******,22.50,
415.00,11780,3610.00,2600.00,5.00,30.00,222.00,1.50,******,37.00,******,22.30,
416.00,11783,3620.00,2620.00,5.00,30.00,223.00,1.50,******,37.00,******,22.40,
417.00,11786,3630.00,2610.00,5.00,30.00,224.00,1.50,******,37.00,******,22.50,
418.00,11789,3620.00,2600.00,5.00,30.00,223.00,1.50,******,37.00,******,22.40,
419.00,11792,3620.00,2610.00,5.00,30.00,223.00,1.50,******,37.00,******,22.40,
420.00,11795,3600.00,2640.00,5.00,30.00,223.00,1.50,******,37.00,******,22.40,
421.00,11798,3610.00,2610.00,5.00,30.00,223.00,1.50,******,37.00,******,22.40,
422.00,11801,3630.00,2620.00,5.00,30.00,224.00,1.50,******,37.00,******,22.50,
423.00,11804,3610.00,2640.00,5.00,30.00,224.00,1.50,******,37.00,******,22.50,
424.00,11807,3620.00,2620.00,5.00,30.00,223.00,1.50,******,37.00,******,22.50,
425.00,11810,3620.00,2620.00,5.00,30.00,224.00,1.50,******,37.00,******,22.50,
426.00,11813,3610.00,2600.00,5.00,30.00,223.00,1.50,******,37.00,******,22.40,
427.00,11816,3600.00,2610.00,5.00,30.00,222.00,1.50,******,37.00,******,22.40,
428.00,11819,3630.00,2620.00,5.00,30.00,224.00,1.50,******,37.00,******,22.50,
429.00,11822,3620.00,2620.00,5.00,30.00,223.00,1.50,******,37.00,******,22.50,
430.00,11825,3620.00,2620.00,5.00,30.00,223.00,1.50,******,37.00,******,22.50,
431.00,11828,3620.00,2630.00,5.00,30.00,224.00,1.50,******,37.00,******,22.50,
432.00,11831,3610.00,2610.00,5.00,30.00,223.00,1.50,******,37.00,******,22.40,
433.00,11834,3620.00,2610.00,5.00,30.00,223.00,1.50,******,37.00,******,22.40,
434.00,11837,3620.00,2610.00,5.00,30.00,223.00,1.50,******,37.00,******,22.40,
435.00,11840,3570.00,2640.00,5.00,30.00,222.00,1.50,******,37.00,******,22.30,
436.00,11843,3620.00,2620.00,5.00,30.00,223.00,1.50,******,37.00,******,22.50,
437.00,11846,3650.00,2620.00,5.00,30.00,225.00,1.50,******,37.00,******,22.60,
438.00,11849,3620.00,2620.00,5.00,30.00,224.00,1.50,******,37.00,******,22.50,
439.00,11852,3610.00,2630.00,5.00,30.00,223.00,1.50,******,37.00,******,22.50,
440.00,11855,3620.00,2630.00,5.00,30.00,224.00,1.50,******,37.00,******,22.50,
441.00,11858,3610.00,2630.00,5.00,30.00,223.00,1.50,******,37.00,******,22.50,
442.00,11861,3620.00,2630.00,5.00,30.00,224.00,1.50,******,37.00,******,22.50,
443.00,11864,3620.00,2610.00,5.00,30.00,223.00,1.50,******,37.00,******,22.40,
444.00,11867,3640.00,2620.00,5.00,30.00,224.00,1.50,******,37.00,******,22.50,
445.00,11870,3610.00,2600.00,5.00,30.00,222.00,1.50,******,37.00,******,22.40,
446.00,11873,3620.00,2620.00,5.00,30.00,223.00,1.50,******,37.00,******,22.40,
447.00,11876,3630.00,2610.00,5.00,30.00,224.00,1.50,******,37.00,******,22.50,
448.00,11879,3630.00,2600.00,5.00,30.00,223.00,1.50,******,37.00,******,22.40,
449.00,11882,3630.00,2610.00,5.00,30.00,223.00,1.50,******,37.00,******,22.50,
450.00,11885,3640.00,2600.00,5.00,30.00,224.00,1.50,******,37.00,******,22.50,
451.00,11888,3620.00,2590.00,5.00,30.00,223.00,1.50,******,37.00,******,22.40,
452.00,11891,3610.00,2640.00,5.00,30.00,224.00,1.50,******,37.00,******,22.50,
453.00,11894,3620.00,2620.00,5.00,30.00,223.00,1.50,******,37.00,******,22.50,
454.00,11897,3620.00,2630.00,5.00,30.00,224.00,1.50,******,37.00,******,22.50,
455.00,11900,3640.00,2650.00,5.00,30.00,225.00,1.50,******,37.00,******,22.70,
456.00,11903,3600.00,2600.00,5.00,30.00,222.00,1.50,******,37.00,******,22.30,
457.00,11906,3610.00,2630.00,5.00,30.00,223.00,1.50,******,37.00,******,22.40,
458.00,11909,3650.00,2600.00,5.00,30.00,224.00,1.50,******,37.00,******,22.60,
459.00,11912,3610.00,2620.00,5.00,30.00,223.00,1.50,******,37.00,******,22.40,
460.00,11915,3610.00,2640.00,5.00,30.00,223.00,1.50,******,37.00,******,22.50,
461.00,11918,3610.00,2620.00,5.00,30.00,223.00,1.50,******,37.00,******,22.40,
462.00,11921,3630.00,2620.00,5.00,30.00,224.00,1.50,******,37.00,******,22.50,
463.00,11924,3620.00,2620.00,5.00,30.00,224.00,1.50,******,37.00,******,22.50,
464.00,11927,3620.00,2600.00,5.00,30.00,223.00,1.50,******,37.00,******,22.40,
465.00,11930,3630.00,2630.00,5.00,30.00,224.00,1.50,******,37.00,******,22.50,
466.00,11933,3620.00,2620.00,5.00,30.00,224.00,1.50,******,37.00,******,22.50,
467.00,11936,3600.00,2620.00,5.00,30.00,223.00,1.50,******,37.00,******,22.40,
468.00,11939,3610.00,2630.00,5.00,30.00,223.00,1.50,******,37.00,******,22.40,
469.00,11942,3630.00,2630.00,5.00,30.00,224.00,1.50,******,37.00,******,22.50,
470.00,11945,3630.00,2600.00,5.00,30.00,223.00,1.50,******,37.00,******,22.50,
471.00,11948,3610.00,2590.00,5.00,30.00,222.00,1.50,******,37.00,******,22.30,
472.00,11951,3620.00,2590.00,5.00,30.00,222.00,1.50,******,37.00,******,22.40,
473.00,11954,3620.00,2600.00,5.00,30.00,223.00,1.50,******,37.00,******,22.40,
474.00,11957,3610.00,2610.00,5.00,30.00,223.00,1.50,******,37.00,******,22.40,
475.00,11960,3610.00,2630.00,5.00,30.00,223.00,1.50,******,37.00,******,22.40,
476.00,11963,3600.00,2620.00,5.00,30.00,223.00,1.50,******,37.00,******,22.40,
477.00,11966,3580.00,2610.00,5.00,30.00,222.00,1.50,******,37.00,******,22.30,
478.00,11969,3640.00,2610.00,5.00,30.00,224.00,1.50,******,37.00,******,22.50,
479.00,11972,3610.00,2620.00,5.00,30.00,223.00,1.50,******,37.00,******,22.40,
480.00,11975,3630.00,2620.00,5.00,30.00,224.00,1.50,******,37.00,******,22.50,
481.00,11978,3610.00,2620.00,5.00,30.00,223.00,1.50,******,37.00,******,22.40,
482.00,11981,3610.00,2640.00,5.00,30.00,224.00,1.50,******,37.00,******,22.50,
483.00,11984,3620.00,2610.00,5.00,30.00,223.00,1.50,******,37.00,******,22.40,
484.00,11987,3610.00,2620.00,5.00,30.00,223.00,1.50,******,37.00,******,22.40,
485.00,11990,3620.00,2620.00,5.00,30.00,224.00,1.50,******,37.00,******,22.50,
486.00,11993,3650.00,2620.00,5.00,30.00,225.00,1.50,******,37.00,******,22.60,
487.00,11996,3620.00,2610.00,5.00,30.00,223.00,1.50,******,37.00,******,22.40,
488.00,11999,3620.00,2610.00,5.00,30.00,223.00,1.50,******,37.00,******,22.40,
489.00,12002,3600.00,2630.00,5.00,30.00,223.00,1.50,******,37.00,******,22.40,
490.00,12005,3620.00,2620.00,5.00,30.00,223.00,1.50,******,37.00,******,22.50,
491.00,12008,3650.00,2570.00,5.00,30.00,223.00,1.50,******,37.00,******,22.40,
492.00,12011,3630.00,2610.00,5.00,30.00,223.00,1.50,******,37.00,******,22.50,
493.00,12014,3620.00,2620.00,5.00,30.00,223.00,1.50,******,37.00,******,22.50,
494.00,12017,3620.00,2620.00,5.00,30.00,223.00,1.50,******,37.00,******,22.50,
495.00,12020,3620.00,2610.00,5.00,30.00,223.00,1.50,******,37.00,******,22.50,
496.00,12023,3610.00,2620.00,5.00,30.00,223.00,1.50,******,37.00,******,22.40,
497.00,12026,3610.00,2630.00,5.00,30.00,223.00,1.50,******,37.00,******,22.40,
498.00,12029,3630.00,2620.00,5.00,30.00,224.00,1.50,******,37.00,******,22.50,
499.00,12032,3610.00,2630.00,5.00,30.00,223.00,1.50,******,37.00,******,22.50,
500.00,12035,3630.00,2620.00,5.00,30.00,224.00,1.50,******,37.00,******,22.50,
501.00,12038,3600.00,2640.00,5.00,30.00,223.00,1.50,******,37.00,******,22.40,
502.00,12041,3620.00,2620.00,5.00,30.00,223.00,1.50,******,37.00,******,22.50,
503.00,12044,3620.00,2630.00,5.00,30.00,224.00,1.50,******,37.00,******,22.50,
504.00,12047,3620.00,2620.00,5.00,30.00,223.00,1.50,******,37.00,******,22.50,
505.00,12050,3610.00,2620.00,5.00,30.00,223.00,1.50,******,37.00,******,22.40,
506.00,12053,3620.00,2630.00,5.00,30.00,223.00,1.50,******,37.00,******,22.50,
507.00,12056,3620.00,2610.00,5.00,30.00,223.00,1.50,******,37.00,******,22.40,
508.00,12059,3620.00,2620.00,5.00,30.00,223.00,1.50,******,37.00,******,22.50,
509.00,12062,3630.00,2610.00,5.00,30.00,223.00,1.50,******,37.00,******,22.50,
510.00,12065,3620.00,2600.00,5.00,30.00,223.00,1.50,******,37.00,******,22.40,
511.00,12068,3610.00,2630.00,5.00,30.00,223.00,1.50,******,37.00,******,22.50,
512.00,12071,3620.00,2620.00,5.00,30.00,223.00,1.50,******,37.00,******,22.50,
513.00,12074,3630.00,2630.00,5.00,30.00,224.00,1.50,******,37.00,******,22.50,
514.00,12077,3620.00,2630.00,5.00,30.00,224.00,1.50,******,37.00,******,22.50,
515.00,12080,3630.00,2610.00,5.00,30.00,224.00,1.50,******,37.00,******,22.50,
516.00,12083,3620.00,2610.00,5.00,30.00,223.00,1.50,******,37.00,******,22.40,
517.00,12086,3620.00,2610.00,5.00,30.00,223.00,1.50,******,37.00,******,22.40,
518.00,12089,3630.00,2610.00,5.00,30.00,224.00,1.50,******,37.00,******,22.50,
519.00,12092,3610.00,2620.00,5.00,30.00,223.00,1.50,******,37.00,******,22.40,
520.00,12095,3590.00,2630.00,5.00,30.00,223.00,1.50,******,37.00,******,22.40,
521.00,12098,3600.00,2660.00,5.00,30.00,223.00,1.50,******,37.00,******,22.50,
522.00,12101,3610.00,2630.00,5.00,30.00,223.00,1.50,******,37.00,******,22.50,
523.00,12104,3620.00,2630.00,5.00,30.00,224.00,1.50,******,37.00,******,22.50,
524.00,12107,3590.00,2620.00,5.00,30.00,222.00,1.50,******,37.00,******,22.40,
525.00,12110,3610.00,2630.00,5.00,30.00,223.00,1.50,******,37.00,******,22.40,
526.00,12113,3590.00,2600.00,5.00,30.00,222.00,1.50,******,37.00,******,22.30,
527.00,12116,3570.00,2610.00,5.00,30.00,221.00,1.50,******,37.00,******,22.20,
528.00,12119,3620.00,2640.00,5.00,30.00,224.00,1.50,******,37.00,******,22.50,
529.00,12122,3580.00,2640.00,5.00,30.00,222.00,1.50,******,37.00,******,22.30,
530.00,12125,3630.00,2620.00,5.00,30.00,224.00,1.50,******,37.00,******,22.50,
531.00,12128,3610.00,2630.00,5.00,30.00,223.00,1.50,******,37.00,******,22.50,
532.00,12131,3610.00,2610.00,5.00,30.00,223.00,1.50,******,37.00,******,22.40,
533.00,12134,3630.00,2620.00,5.00,30.00,224.00,1.50,******,37.00,******,22.50,
534.00,12137,3600.00,2570.00,5.00,30.00,221.00,1.50,******,37.00,******,22.20,
535.00,12140,3630.00,2640.00,5.00,30.00,224.00,1.50,******,37.00,******,22.50,
536.00,12143,3650.00,2640.00,5.00,30.00,225.00,1.50,******,37.00,******,22.60,
537.00,12146,3630.00,2580.00,5.00,30.00,223.00,1.50,******,37.00,******,22.40,
538.00,12149,3620.00,2610.00,5.00,30.00,223.00,1.50,******,37.00,******,22.40,
539.00,12152,3630.00,2620.00,5.00,30.00,224.00,1.50,******,37.00,******,22.50,
540.00,12155,3630.00,2610.00,5.00,30.00,224.00,1.50,******,37.00,******,22.50,
541.00,12158,3620.00,2620.00,5.00,30.00,223.00,1.50,******,37.00,******,22.50,
542.00,12161,3610.00,2620.00,5.00,30.00,223.00,1.50,******,37.00,******,22.40,
543.00,12164,3620.00,2630.00,5.00,30.00,224.00,1.50,******,37.00,******,22.50,
544.00,12167,3610.00,2600.00,5.00,30.00,223.00,1.50,******,37.00,******,22.40,
545.00,12170,3650.00,2640.00,5.00,30.00,225.00,1.50,******,37.00,******,22.70,
546.00,12173,3630.00,2610.00,5.00,30.00,224.00,1.50,******,37.00,******,22.50,
547.00,12176,3620.00,2610.00,5.00,30.00,223.00,1.50,******,37.00,******,22.40,
548.00,12179,3580.00,2620.00,5.00,30.00,222.00,1.50,******,37.00,******,22.30,
549.00,12182,3620.00,2620.00,5.00,30.00,223.00,1.50,******,37.00,******,22.50,
550.00,12185,3620.00,2590.00,5.00,30.00,223.00,1.50,******,37.00,******,22.40,
551.00,12188,3620.00,2610.00,5.00,30.00,223.00,1.50,******,37.00,******,22.50,
552.00,12191,3620.00,2650.00,5.00,30.00,224.00,1.50,******,37.00,******,22.60,
553.00,12194,3630.00,2610.00,5.00,30.00,223.00,1.50,******,37.00,******,22.50,
554.00,12197,3610.00,2600.00,5.00,30.00,222.00,1.50,******,37.00,******,22.40,
555.00,12200,3610.00,2630.00,5.00,30.00,223.00,1.50,******,37.00,******,22.40,
556.00,12203,3620.00,2620.00,5.00,30.00,224.00,1.50,******,37.00,******,22.50,
557.00,12206,3600.00,2620.00,5.00,30.00,223.00,1.50,******,37.00,******,22.40,
558.00,12209,3610.00,2620.00,5.00,30.00,223.00,1.50,******,37.00,******,22.40,
559.00,12212,3630.00,2620.00,5.00,30.00,224.00,1.50,******,37.00,******,22.50,
560.00,12215,3630.00,2610.00,5.00,30.00,224.00,1.50,******,37.00,******,22.50,
561.00,12218,3620.00,2620.00,5.00,30.00,223.00,1.50,******,37.00,******,22.50,
562.00,12221,3620.00,2620.00,5.00,30.00,224.00,1.50,******,37.00,******,22.50,
563.00,12224,3650.00,2620.00,5.00,30.00,225.00,1.50,******,37.00,******,22.60,
564.00,12227,3630.00,2610.00,5.00,30.00,224.00,1.50,******,37.00,******,22.50,
565.00,12230,3600.00,2610.00,5.00,30.00,222.00,1.50,******,37.00,******,22.40,
566.00,12233,3620.00,2620.00,5.00,30.00,224.00,1.50,******,37.00,******,22.50,
567.00,12236,3620.00,2620.00,5.00,30.00,224.00,1.50,******,37.00,******,22.50,
568.00,12239,3620.00,2610.00,5.00,30.00,223.00,1.50,******,37.00,******,22.40,
569.00,12242,3640.00,2610.00,5.00,30.00,224.00,1.50,******,37.00,******,22.50,
570.00,12245,3620.00,2610.00,5.00,30.00,223.00,1.50,******,37.00,******,22.50,
571.00,12248,3630.00,2620.00,5.00,30.00,224.00,1.50,******,37.00,******,22.50,
572.00,12251,3620.00,2620.00,5.00,30.00,224.00,1.50,******,37.00,******,22.50,
573.00,12254,3620.00,2640.00,5.00,30.00,224.00,1.50,******,37.00,******,22.50,
574.00,12257,3620.00,2620.00,5.00,30.00,224.00,1.50,******,37.00,******,22.50,
575.00,12260,3610.00,2620.00,5.00,30.00,223.00,1.50,******,37.00,******,22.40,
576.00,12263,3630.00,2610.00,5.00,30.00,224.00,1.50,******,37.00,******,22.50,
577.00,12266,3630.00,2590.00,5.00,30.00,223.00,1.50,******,37.00,******,22.40,
578.00,12269,3640.00,2620.00,5.00,30.00,224.00,1.50,******,37.00,******,22.60,
579.00,12272,3620.00,2630.00,5.00,30.00,224.00,1.50,******,37.00,******,22.50,
580.00,12275,3620.00,2610.00,5.00,30.00,223.00,1.50,******,37.00,******,22.40,
581.00,12278,3590.00,2590.00,5.00,30.00,221.00,1.50,******,37.00,******,22.30,
582.00,12281,3620.00,2630.00,5.00,30.00,224.00,1.50,******,37.00,******,22.50,
583.00,12284,3620.00,2620.00,5.00,30.00,223.00,1.50,******,37.00,******,22.50,
584.00,12287,3600.00,2590.00,5.00,30.00,222.00,1.50,******,37.00,******,22.30,
585.00,12290,3650.00,2640.00,5.00,30.00,225.00,1.50,******,37.00,******,22.70,
586.00,12293,3630.00,2620.00,5.00,30.00,224.00,1.50,******,37.00,******,22.50,
587.00,12296,3640.00,2630.00,5.00,30.00,225.00,1.50,******,37.00,******,22.60,
588.00,12299,3630.00,2620.00,5.00,30.00,224.00,1.50,******,37.00,******,22.50,
589.00,12302,3630.00,2620.00,5.00,30.00,224.00,1.50,******,37.00,******,22.50,
590.00,12305,3630.00,2610.00,5.00,30.00,224.00,1.50,******,37.00,******,22.50,
591.00,12308,3620.00,2630.00,5.00,30.00,224.00,1.50,******,37.00,******,22.50,
592.00,12311,3630.00,2600.00,5.00,30.00,223.00,1.50,******,37.00,******,22.50,
593.00,12314,3620.00,2610.00,5.00,30.00,223.00,1.50,******,37.00,******,22.40,
594.00,12317,3610.00,2610.00,5.00,30.00,223.00,1.50,******,37.00,******,22.40,
595.00,12320,3620.00,2610.00,5.00,30.00,223.00,1.50,******,37.00,******,22.40,
596.00,12323,3620.00,2620.00,5.00,30.00,224.00,1.50,******,37.00,******,22.50,
597.00,12326,3610.00,2610.00,5.00,30.00,223.00,1.50,******,37.00,******,22.40,
598.00,12329,3610.00,2630.00,5.00,30.00,223.00,1.50,******,37.00,******,22.50,
599.00,12332,3630.00,2620.00,5.00,30.00,224.00,1.50,******,37.00,******,22.50,
600.00,12335,3600.00,2650.00,5.00,30.00,224.00,1.50,******,37.00,******,22.50,
,,,,,,,,,,,,
Interval:,,,15.00,,,,,,,,,
Number of Data Points:,,,28.00,,,,,,,,,
,,,,,,,,,,,,
Time Setting:,,,28 Meas. Pts.,,,,,,,,,
,,,Meas. Pt. Duration 6.4285714 s,,,,,,,,,
Event Control:,,,Standard Mode,,,,,,,,,
"  Terminate test, ...",,,...if d(gamma)/dt > 1000 1/s,,,,,,,,,
"  Terminate test, ...",,,...if M > 200 mNm,,,,,,,,,
"  Terminate test, ...",,,...if FN < -50 N or > 50 N,,,,,,,,,
Measuring Profile:,,,,,,,,,,,,
  Shear Rate,,,d(gamma)/dt = 0.1 ... 50 1/s log; |Slope| = 10.003816 Pt. / dec ,,,,,,,,,
,,,,,,,,,,,,
Meas. Pts.,Time,Storage Modulus,Loss Modulus,Strain,Angular Frequency,Shear Stress,Shear Rate,Viscosity,Temperature,Speed,Torque,Status
,[s],[Pa],[Pa],[%],[rad/s],[Pa],[1/s],[Pa·s],[°C],[1/min],[µNm],[]
1.00,12300,******,******,47.90,******,46.40,0.10,464.00,37.00,0.12,4.67,Dy_auto
2.00,12300,******,******,125.00,******,59.60,0.13,473.00,37.00,0.15,5.99,Dy_auto
3.00,12400,******,******,221.00,******,74.70,0.16,471.00,37.00,0.19,7.51,Dy_auto
4.00,12400,******,******,343.00,******,93.30,0.20,468.00,37.00,0.24,9.38,Dy_auto
5.00,12400,******,******,496.00,******,116.00,0.25,462.00,37.00,0.30,11.70,Dy_auto
6.00,12400,******,******,688.00,******,143.00,0.32,453.00,37.00,0.38,14.40,Dy_auto
7.00,12400,******,******,931.00,******,177.00,0.40,446.00,37.00,0.48,17.80,Dy_auto
8.00,12400,******,******,1240.00,******,219.00,0.50,437.00,37.00,0.60,22.00,Dy_auto
9.00,12400,******,******,1620.00,******,271.00,0.63,431.00,37.00,0.75,27.30,Dy_auto
10.00,12400,******,******,2100.00,******,338.00,0.79,426.00,37.00,0.95,34.00,Dy_auto
11.00,12400,******,******,2710.00,******,421.00,1.00,421.00,37.00,1.19,42.30,Dy_auto
12.00,12400,******,******,3480.00,******,525.00,1.26,417.00,37.00,1.50,52.80,Dy_auto
13.00,12400,******,******,4440.00,******,656.00,1.58,414.00,37.00,1.89,65.90,Dy_auto
14.00,12400,******,******,5660.00,******,818.00,1.99,411.00,37.00,2.38,82.30,Dy_auto
15.00,12400,******,******,7190.00,******,1020.00,2.51,406.00,37.00,2.99,103.00,Dy_auto
16.00,12400,******,******,9110.00,******,1270.00,3.16,403.00,37.00,3.77,128.00,Dy_auto
17.00,12400,******,******,11500.00,******,1590.00,3.98,399.00,37.00,4.75,160.00,Dy_auto
18.00,12500,******,******,14600.00,******,1970.00,5.00,394.00,37.00,5.97,198.00,Dy_auto
19.00,12500,******,******,18400.00,******,2450.00,6.30,388.00,37.00,7.52,246.00,Dy_auto
20.00,12500,******,******,23300.00,******,3000.00,7.93,378.00,37.00,9.47,302.00,Dy_auto
21.00,12500,******,******,29300.00,******,3640.00,9.98,365.00,37.00,11.90,366.00,Dy_auto
22.00,12500,******,******,37000.00,******,4330.00,12.60,345.00,37.00,15.00,436.00,Dy_auto
23.00,12500,******,******,46600.00,******,4830.00,15.80,305.00,37.00,18.90,485.00,Dy_auto
24.00,12500,******,******,58800.00,******,2230.00,19.90,112.00,37.00,23.80,224.00,Dy_auto
25.00,12500,******,******,74000.00,******,1510.00,25.10,60.30,37.00,29.90,152.00,Dy_auto
26.00,12500,******,******,93300.00,******,532.00,31.60,16.90,37.00,37.70,53.50,Dy_auto
27.00,12500,******,******,117000.00,******,688.00,39.70,17.30,37.00,47.40,69.20,Dy_auto
28.00,12500,******,******,148000.00,******,95.80,50.00,1.92,37.00,59.70,9.63,Dy_auto