File: exampledata/TXT_N4.csv
Meas. Pts.,Time,Storage Modulus,Loss Modulus,Strain,Angular Frequency,Shear Stress,Shear Rate,Viscosity,Temperature,Speed,Torque,Status
,[s],[Pa],[Pa],[%],[rad/s],[Pa],[1/s],[Pa·s],[°C],[1/min],[µNm],[]
1,5,2270,1320,4.99,30,131,1.5,******,36.9,******,13.2,WMa
2,10,2360,708,5,30,123,1.5,******,37,******,12.4,
3,15,2370,708,5,30,124,1.5,******,37,******,12.4,
4,20,2380,710,5,30,124,1.5,******,37,******,12.5,
5,25,2380,709,5,30,124,1.5,******,37,******,12.5,
6,30,2370,714,5,30,124,1.5,******,37,******,12.4,
7,35,2380,710,5,30,124,1.5,******,37,******,12.5,
8,40,2370,718,5,30,124,1.5,******,37,******,12.5,
9,45,2370,711,5,30,124,1.5,******,37,******,12.4,
10,50,2360,722,5,30,124,1.5,******,37,******,12.4,
11,55,2370,719,5,30,124,1.5,******,37,******,12.5,
12,60,2370,717,5,30,124,1.5,******,37,******,12.5,
13,65,2370,726,5,30,124,1.5,******,37,******,12.5,
14,70,2380,732,5,30,124,1.5,******,37,******,12.5,
15,75,2380,733,5,30,124,1.5,******,37,******,12.5,
16,80,2380,723,5,30,124,1.5,******,37,******,12.5,
17,85,2370,739,5,30,124,1.5,******,37,******,12.5,
18,90,2380,724,5,30,124,1.5,******,37,******,12.5,
19,95,2360,727,5,30,124,1.5,******,37,******,12.4,
20,100,2360,726,5,30,124,1.5,******,37,******,12.4,
21,105,2370,728,5,30,124,1.5,******,37,******,12.5,
22,110,2380,732,5,30,124,1.5,******,37,******,12.5,
23,115,2380,734,5,30,124,1.5,******,37,******,12.5,
24,120,2380,724,5,30,124,1.5,******,37,******,12.5,
25,125,2390,744,5,30,125,1.5,******,37,******,12.6,
26,130,2380,736,5,30,124,1.5,******,37,******,12.5,
27,135,2370,744,5,30,124,1.5,******,37,******,12.5,
28,140,2380,739,5,30,125,1.5,******,37,******,12.5,
29,145,2390,744,5,30,125,1.5,******,37,******,12.6,
30,150,2360,740,5,30,124,1.5,******,37,******,12.5,
31,155,2390,737,5,30,125,1.5,******,37,******,12.6,
32,160,2390,730,5,30,125,1.5,******,37,******,12.6,
33,165,2380,742,5,30,125,1.5,******,37,******,12.5,
34,170,2390,735,5,30,125,1.5,******,37,******,12.6,
35,175,2380,748,5,30,125,1.5,******,37,******,12.5,
36,180,2390,741,5,30,125,1.5,******,37,******,12.6,
37,185,2380,733,5,30,124,1.5,******,37,******,12.5,
38,190,2380,741,5,30,125,1.5,******,37,******,12.5,
39,195,2380,735,5,30,125,1.5,******,37,******,12.5,
40,200,2400,755,5,30,126,1.5,******,37,******,12.6,
41,205,2400,742,5,30,125,1.5,******,37,******,12.6,
42,210,2400,746,5,30,126,1.5,******,37,******,12.7,
43,215,2400,744,5,30,126,1.5,******,37,******,12.6,
44,220,2380,749,5,30,125,1.5,******,37,******,12.6,
45,225,2400,751,5,30,126,1.5,******,37,******,12.7,
46,230,2390,737,5,30,125,1.5,******,37,******,12.6,
47,235,2400,743,5,30,126,1.5,******,37,******,12.6,
48,240,2400,753,5,30,126,1.5,******,37,******,12.6,
49,245,2390,762,5,30,126,1.5,******,37,******,12.6,
50,250,2400,743,5,30,125,1.5,******,37,******,12.6,
51,255,2400,749,5,30,126,1.5,******,37,******,12.7,
52,260,2410,754,5,30,126,1.5,******,37,******,12.7,
53,265,2400,744,5,30,126,1.5,******,37,******,12.6,
54,270,2420,766,5,30,127,1.5,******,37,******,12.8,
55,275,2400,748,5,30,126,1.5,******,37,******,12.7,
56,280,2410,758,5,30,126,1.5,******,37,******,12.7,
57,285,2410,758,5,30,126,1.5,******,37,******,12.7,
58,290,2420,739,5,30,126,1.5,******,37,******,12.7,
59,295,2420,754,5,30,127,1.5,******,37,******,12.7,
60,300,2420,767,5,30,127,1.5,******,37,******,12.8,
61,305,2430,754,5,30,127,1.5,******,37,******,12.8,
62,310,2420,749,5,30,127,1.5,******,37,******,12.7,
63,315,2420,763,5,30,127,1.5,******,37,******,12.7,
64,320,2410,758,5,30,126,1.5,******,37,******,12.7,
65,325,2420,752,5,30,127,1.5,******,37,******,12.7,
66,330,2420,751,5,30,127,1.5,******,37,******,12.7,
67,335,2410,755,5,30,127,1.5,******,37,******,12.7,
68,340,2430,763,5,30,127,1.5,******,37,******,12.8,
69,345,2420,770,5,30,127,1.5,******,37,******,12.8,
70,350,2410,763,5,30,126,1.5,******,37,******,12.7,
71,355,2420,753,5,30,127,1.5,******,37,******,12.8,
72,360,2430,759,5,30,127,1.5,******,37,******,12.8,
73,365,2420,762,5,30,127,1.5,******,37,******,12.8,
74,370,2430,773,5,30,128,1.5,******,37,******,12.8,
75,375,2410,766,5,30,127,1.5,******,37,******,12.7,
76,380,2420,763,5,30,127,1.5,******,37,******,12.8,
77,385,2430,750,5,30,127,1.5,******,37,******,12.8,
78,390,2430,757,5,30,127,1.5,******,37,******,12.8,
79,395,2440,760,5,30,128,1.5,******,37,******,12.9,
80,400,2440,739,5,30,128,1.5,******,37,******,12.8,
,,,,,,,,,,,,
Interval:,,,2,,,,,,,,,
Number of Data Points:,,,31,,,,,,,,,
,,,,,,,,,,,,
Time Setting:,,,31 Meas. Pts.,,,,,,,,,
Measuring Profile:,,,,,,,,,,,,
#NAME?,,,Amplitude gamma = 5 %,,,,,,,,,
,,,Angular Frequency omega = 100 ... 0.1 rad/s log; |Slope| = 10 Pt. / dec ,,,,,,,,,
,,,,,,,,,,,,
Meas. Pts.,Time,Storage Modulus,Loss Modulus,Strain,Angular Frequency,Shear Stress,Shear Rate,Viscosity,Temperature,Speed,Torque,Status
,[s],[Pa],[Pa],[%],[rad/s],[Pa],[1/s],[Pa·s],[°C],[1/min],[µNm],[]
1,410,2550,993,5,100,137,5,******,37,******,13.7,
2,418,2690,653,5,79.4,138,3.97,******,37,******,13.9,
3,425,2630,687,5,63.1,136,3.15,******,37,******,13.6,
4,432,2610,646,5,50.1,134,2.51,******,37,******,13.5,
5,439,2530,692,5,39.8,131,1.99,******,37,******,13.2,
6,448,2430,755,5,31.6,127,1.58,******,37,******,12.8,
7,458,2330,813,5,25.1,123,1.26,******,37,******,12.4,
8,465,2190,868,5,20,118,1,******,37,******,11.9,
9,472,2060,920,5,15.8,113,0.79,******,37,******,11.3,
10,478,1900,961,5,12.6,106,0.63,******,37,******,10.7,
11,486,1730,1000,5,10,100,0.5,******,37,******,10.1,
12,493,1550,1020,5,7.94,92.8,0.4,******,37,******,9.33,
13,502,1370,1020,5,6.31,85.5,0.32,******,37,******,8.6,
14,509,1180,1000,5,5.01,77.4,0.25,******,37,******,7.78,
15,517,1000,963,5,3.98,69.6,0.2,******,37,******,6.99,
16,527,835,905,5,3.16,61.6,0.16,******,37,******,6.19,
17,540,687,833,5,2.51,54,0.13,******,37,******,5.43,
18,560,559,753,5,2,46.9,0.1,******,37,******,4.71,
19,586,450,668,5,1.58,40.3,0.08,******,37,******,4.05,
20,617,363,584,5,1.26,34.4,0.06,******,37,******,3.46,
21,656,294,505,5,1,29.3,0.05,******,37,******,2.94,
22,693,240,433,5.01,0.79,24.8,0.04,******,37,******,2.49,
23,739,199,369,5.01,0.63,21,0.03,******,37,******,2.11,
24,797,167,314,5.01,0.5,17.8,0.03,******,37,******,1.79,
25,869,142,266,5.01,0.4,15.1,0.02,******,37,******,1.52,
26,929,122,227,5,0.32,12.9,0.02,******,37,******,1.3,
27,1010,107,193,5,0.25,11.1,0.01,******,37,******,1.11,
28,1100,96,165,5,0.2,9.55,0.01,******,37,******,0.96,
29,1220,86.8,142,5,0.16,8.33,0.01,******,37,******,0.84,
30,1450,80.3,123,5,0.13,7.34,0.01,******,37,******,0.74,
31,1730,75.2,107,5,0.1,6.53,0.01,******,37,******,0.66,
,,,,,,,,,,,,
Interval:,,,3,,,,,,,,,
Number of Data Points:,,,80,,,,,,,,,
,,,,,,,,,,,,
Time Setting:,,,80 Meas. Pts.,,,,,,,,,
,,,Meas. Pt. Duration 5 s,,,,,,,,,
Event Control:,,,Standard Mode,,,,,,,,,
"  Terminate test, ...",,,...if M > 75 mNm,,,,,,,,,
Measuring Profile:,,,,,,,,,,,,
#NAME?,,,Amplitude gamma = 5 %,,,,,,,,,
,,,Angular Frequency omega = 30 rad/s,,,,,,,,,
,,,,,,,,,,,,
Meas. Pts.,Time,Storage Modulus,Loss Modulus,Strain,Angular Frequency,Shear Stress,Shear Rate,Viscosity,Temperature,Speed,Torque,Status
,[s],[Pa],[Pa],[%],[rad/s],[Pa],[1/s],[Pa·s],[°C],[1/min],[µNm],[]
1,invalid point,,,,,,,,,,,
2,1740,,,,,,,,,,,
3,1745,,,,,,,,,,,
4,1750,,,,,,,,,,,
5,1755,,,,,,,,,,,
6,1760,,,,,,,,,,,
7,1765,,,,,,,,,,,
8,1770,,,,,,,,,,,
9,1775,,,,,,,,,,,
10,1780,,,,,,,,,,,
11,1785,,,,,,,,,,,
12,1790,,,,,,,,,,,
13,1795,,,,,,,,,,,
14,1800,,,,,,,,,,,
15,1805,,,,,,,,,,,
16,1810,,,,,,,,,,,
17,1815,,,,,,,,,,,
18,1820,,,,,,,,,,,
19,1825,,,,,,,,,,,
20,1830,2640,1080,5.17,30,147,1.55,******,37,******,14.8,WMa
21,1835,2620,813,5,30,137,1.5,******,37,******,13.8,
22,1840,2630,825,5,30,138,1.5,******,37,******,13.8,
23,1845,2620,821,5,30,137,1.5,******,37,******,13.8,
24,1850,2620,825,5,30,137,1.5,******,37,******,13.8,
25,1855,2620,817,5,30,137,1.5,******,37,******,13.8,
26,1860,2630,813,5,30,137,1.5,******,37,******,13.8,
27,1865,2600,811,5,30,136,1.5,******,37,******,13.7,
28,1870,2610,813,5,30,137,1.5,******,37,******,13.8,
29,1875,2620,822,5,30,137,1.5,******,37,******,13.8,
30,1880,2630,808,5,30,138,1.5,******,37,******,13.8,
31,1885,2620,811,5,30,137,1.5,******,37,******,13.8,
32,1890,2610,827,5,30,137,1.5,******,37,******,13.8,
33,1895,2640,817,5,30,138,1.5,******,37,******,13.9,
34,1900,2620,810,5,30,137,1.5,******,37,******,13.8,
35,1905,2620,814,5,30,137,1.5,******,37,******,13.8,
36,1910,2630,819,5,30,138,1.5,******,37,******,13.8,
37,1915,2620,814,5,30,137,1.5,******,37,******,13.8,
38,1920,2630,816,5,30,138,1.5,******,37,******,13.9,
39,1925,2640,814,5,30,138,1.5,******,37,******,13.9,
40,1930,2620,819,5,30,137,1.5,******,37,******,13.8,
41,1935,2620,816,5,30,137,1.5,******,37,******,13.8,
42,1940,2620,816,5,30,137,1.5,******,37,******,13.8,
43,1945,2630,816,5,30,138,1.5,******,37,******,13.8,
44,1950,2610,827,5,30,137,1.5,******,37,******,13.8,
45,1955,2620,817,5,30,137,1.5,******,37,******,13.8,
46,1960,2630,821,5,30,138,1.5,******,37,******,13.9,
47,1965,2620,813,5,30,137,1.5,******,37,******,13.8,
48,1970,2630,822,5,30,138,1.5,******,37,******,13.8,
49,1975,2610,815,5,30,137,1.5,******,37,******,13.8,
50,1980,2620,811,5,30,137,1.5,******,37,******,13.8,
51,1985,2630,822,5,30,138,1.5,******,37,******,13.8,
52,1990,2620,815,5,30,137,1.5,******,37,******,13.8,
53,1995,2640,820,5,30,138,1.5,******,37,******,13.9,
54,2000,2630,826,5,30,138,1.5,******,37,******,13.8,
55,2005,2650,815,5,30,139,1.5,******,37,******,13.9,
56,2010,2620,815,5,30,137,1.5,******,37,******,13.8,
57,2015,2630,814,5,30,138,1.5,******,37,******,13.8,
58,2020,2640,824,5,30,138,1.5,******,37,******,13.9,
59,2025,2630,822,5,30,138,1.5,******,37,******,13.9,
60,2030,2620,827,5,30,137,1.5,******,37,******,13.8,
61,2035,2630,822,5,30,138,1.5,******,37,******,13.9,
62,2040,2620,823,5,30,137,1.5,******,37,******,13.8,
63,2045,2630,824,5,30,138,1.5,******,37,******,13.9,
64,2050,2620,816,5,30,137,1.5,******,37,******,13.8,
65,2055,2640,829,5,30,138,1.5,******,37,******,13.9,
66,2060,2620,817,5,30,137,1.5,******,37,******,13.8,
67,2065,2630,817,5,30,138,1.5,******,37,******,13.8,
68,2070,2630,829,5,30,138,1.5,******,37,******,13.9,
69,2075,2620,832,5,30,138,1.5,******,37,******,13.8,
70,2080,2640,823,5,30,138,1.5,******,37,******,13.9,
71,2085,2640,830,5,30,138,1.5,******,37,******,13.9,
72,2090,2650,826,5,30,139,1.5,******,37,******,14,
73,2095,2640,819,5,30,138,1.5,******,37,******,13.9,
74,2100,2630,828,5,30,138,1.5,******,37,******,13.9,
75,2105,2640,815,5,30,138,1.5,******,37,******,13.9,
76,2110,2630,817,5,30,138,1.5,******,37,******,13.8,
77,2115,2640,817,5,30,138,1.5,******,37,******,13.9,
78,2120,2640,821,5,30,138,1.5,******,37,******,13.9,
79,2125,2640,824,5,30,138,1.5,******,37,******,13.9,
80,2130,2630,834,5,30,138,1.5,******,37,******,13.9,
,,,,,,,,,,,,
Interval:,,,4,,,,,,,,,
Number of Data Points:,,,113,,,,,,,,,
,,,,,,,,,,,,
Time Setting:,,,113 Meas. Pts.,,,,,,,,,
,,,Meas. Pt. Duration 5 s,,,,,,,,,
Measuring Profile:,,,,,,,,,,,,
#NAME?,,,Amplitude gamma = 0.1 ... 500 % log; |Slope| = 30.278699 Pt. / dec ,,,,,,,,,
,,,Angular Frequency omega = 30 rad/s,,,,,,,,,
,,,,,,,,,,,,
Meas. Pts.,Time,Storage Modulus,Loss Modulus,Strain,Angular Frequency,Shear Stress,Shear Rate,Viscosity,Temperature,Speed,Torque,Status
,[s],[Pa],[Pa],[%],[rad/s],[Pa],[1/s],[Pa·s],[°C],[1/min],[µNm],[]
1,2135,0,19900,0.1,30,19.7,0.03,******,37,******,1.98,"ME-,WMa"
2,2140,55100,32300,0.11,30,68.4,0.03,******,37,******,6.88,"ME-,MV-"
3,2145,5810,27000,0.12,30,33.6,0.04,******,37,******,3.38,"ME-,MV-"
4,2150,191,342,0.13,30,0.49,0.04,******,37,******,0.05,"WMa,taD"
5,2155,497,703,0.14,30,1.17,0.04,******,37,******,0.12,
6,2160,566,793,0.15,30,1.42,0.04,******,37,******,0.14,
7,2165,455,700,0.16,30,1.32,0.05,******,37,******,0.13,
8,2170,1040,619,0.17,30,2.07,0.05,******,37,******,0.21,
9,2175,299,581,0.18,30,1.2,0.06,******,37,******,0.12,
10,2180,744,702,0.2,30,2.03,0.06,******,37,******,0.2,
11,2185,574,752,0.21,30,2.03,0.06,******,37,******,0.2,
12,2190,855,843,0.23,30,2.78,0.07,******,37,******,0.28,
13,2195,296,670,0.25,30,1.82,0.07,******,37,******,0.18,
14,2200,610,1130,0.27,30,3.44,0.08,******,37,******,0.35,
15,2205,542,953,0.29,30,3.18,0.09,******,37,******,0.32,
16,2210,243,899,0.31,30,2.91,0.09,******,37,******,0.29,
17,2215,607,913,0.34,30,3.7,0.1,******,37,******,0.37,
18,2220,723,1040,0.37,30,4.62,0.11,******,37,******,0.46,
19,2225,944,863,0.39,30,5.03,0.12,******,37,******,0.51,
20,2230,969,799,0.43,30,5.33,0.13,******,37,******,0.54,
21,2235,997,787,0.46,30,5.79,0.14,******,37,******,0.58,
22,2240,1270,761,0.49,30,7.29,0.15,******,37,******,0.73,
23,2245,1520,908,0.53,30,9.44,0.16,******,37,******,0.95,
24,2250,1710,877,0.58,30,11.1,0.17,******,37,******,1.11,
25,2255,1950,772,0.62,30,13,0.19,******,37,******,1.31,
26,2260,2140,797,0.67,30,15.3,0.2,******,37,******,1.54,
27,2265,2210,949,0.72,30,17.4,0.22,******,37,******,1.75,
28,2270,9630,0,0.78,30,75.5,0.24,******,37,******,7.59,"MV-,WMa"
29,2275,3730,968,0.85,30,32.6,0.25,******,37,******,3.28,WMa
30,2280,5750,5690,0.91,30,73.7,0.27,******,37,******,7.41,WMa
31,2285,2160,1870,0.98,30,28.1,0.3,******,37,******,2.82,WMa
32,2290,2640,869,1.06,30,29.4,0.32,******,37,******,2.96,
33,2295,3720,1250,1.14,30,44.6,0.34,******,37,******,4.49,WMa
34,2300,5640,5620,1.23,30,98,0.37,******,37,******,9.86,WMa
35,2305,3110,0,1.33,30,41.3,0.4,******,37,******,4.15,"MV-,WMa"
36,2310,1390,1590,1.43,30,30.3,0.43,******,37,******,3.05,WMa
37,2315,2900,864,1.55,30,46.8,0.46,******,37,******,4.7,
38,2320,2230,0,1.67,30,37.2,0.5,******,37,******,3.74,"MV-,WMa"
39,2325,5400,0,1.8,30,97.3,0.54,******,37,******,9.78,"MV-,WMa"
40,2330,5070,0,1.95,30,98.7,0.58,******,37,******,9.92,"MV-,WMa"
41,2335,2950,910,2.1,30,64.7,0.63,******,37,******,6.5,WMa
42,2340,2170,0,2.26,30,49.1,0.68,******,37,******,4.94,"MV-,WMa"
43,2345,1930,2200,2.44,30,71.4,0.73,******,37,******,7.18,WMa
44,2350,2610,827,2.63,30,72.1,0.79,******,37,******,7.25,
45,2355,2050,715,2.84,30,61.7,0.85,******,37,******,6.21,WMa
46,2360,2080,0,3.07,30,63.8,0.92,******,37,******,6.41,"MV-,WMa"
47,2365,2260,1680,3.31,30,93,0.99,******,37,******,9.36,WMa
48,2370,2730,821,3.57,30,102,1.07,******,37,******,10.2,
49,2375,4010,1380,3.85,30,163,1.15,******,37,******,16.4,WMa
50,2380,2660,700,4.16,30,114,1.25,******,37,******,11.5,WMa
51,2385,2680,687,4.48,30,124,1.35,******,37,******,12.5,WMa
52,2390,3230,585,4.84,30,159,1.45,******,37,******,16,WMa
53,2395,2170,575,5.22,30,117,1.57,******,37,******,11.8,WMa
54,2400,2890,1330,5.63,30,179,1.69,******,37,******,18,WMa
55,2405,2990,261,6.08,30,182,1.82,******,37,******,18.3,WMa
56,2410,2580,839,6.56,30,178,1.97,******,37,******,17.9,WMa
57,2415,2530,774,7.08,30,187,2.12,******,37,******,18.8,WMa
58,2420,2560,577,7.64,30,201,2.29,******,37,******,20.2,WMa
59,2425,2800,537,8.24,30,235,2.47,******,37,******,23.6,WMa
60,2430,2900,761,8.89,30,266,2.67,******,37,******,26.8,WMa
61,2435,2790,943,9.59,30,282,2.88,******,37,******,28.4,WMa
62,2440,2600,803,10.3,30,282,3.1,******,37,******,28.3,WMa
63,2445,2930,312,11.2,30,329,3.35,******,37,******,33,WMa
64,2450,3020,758,12.1,30,376,3.62,******,37,******,37.8,WMa
65,2455,2250,566,13,30,301,3.9,******,37,******,30.3,WMa
66,2460,2640,997,14,30,396,4.21,******,37,******,39.8,WMa
67,2465,2710,637,15.1,30,422,4.54,******,37,******,42.4,WMa
68,2470,3080,726,16.3,30,517,4.9,******,37,******,52,WMa
69,2475,2630,842,17.6,30,487,5.29,******,37,******,49,WMa
70,2480,2560,699,19,30,504,5.7,******,37,******,50.7,WMa
71,2485,2940,379,20.5,30,609,6.16,******,37,******,61.2,WMa
72,2490,2150,853,22.1,30,513,6.64,******,37,******,51.6,WMa
73,2495,3190,1300,23.9,30,823,7.17,******,37,******,82.8,WMa
74,2500,2540,776,25.8,30,685,7.73,******,37,******,68.9,WMa
75,2505,2310,1050,27.8,30,707,8.34,******,37,******,71.1,WMa
76,2510,2520,796,30,30,792,9,******,37,******,79.7,WMa
77,2515,3000,1210,32.4,30,1050,9.71,******,37,******,105,WMa
78,2520,2500,710,34.9,30,907,10.5,******,37,******,91.2,WMa
79,2525,2410,879,37.7,30,969,11.3,******,37,******,97.4,WMa
80,2530,2350,794,40.7,30,1010,12.2,******,37,******,101,WMa
81,2535,2640,950,43.9,30,1230,13.2,******,37,******,124,WMa
82,2540,2450,772,47.4,30,1220,14.2,******,37,******,122,WMa
83,2545,2170,986,51.1,30,1220,15.3,******,37,******,123,WMa
84,2550,2360,841,55.1,30,1380,16.5,******,37,******,139,
85,2555,2450,1010,59.5,30,1580,17.8,******,37,******,158,WMa
86,2560,2300,853,64.2,30,1570,19.3,******,37,******,158,WMa
87,2565,2210,934,69.2,30,1660,20.8,******,37,******,167,
88,2570,2130,982,74.7,30,1750,22.4,******,37,******,176,
89,2575,2030,1040,80.6,30,1840,24.2,******,37,******,185,
90,2580,1950,1080,87,30,1940,26.1,******,37,******,195,
91,2585,1880,1100,93.8,30,2040,28.2,******,37,******,206,
92,2590,1760,1110,101,30,2110,30.4,******,37,******,212,
93,2595,1590,1090,109,30,2110,32.8,******,37,******,212,
94,2600,1400,1030,118,30,2050,35.4,******,37,******,206,
95,2605,1130,959,127,30,1890,38.2,******,37,******,190,
96,2610,967,878,137,30,1790,41.2,******,37,******,180,
97,2615,785,770,148,30,1630,44.4,******,37,******,164,
98,2620,632,689,160,30,1490,47.9,******,37,******,150,
99,2625,472,600,172,30,1320,51.7,******,37,******,132,
100,2630,303,483,186,30,1060,55.8,******,37,******,107,
101,2635,153,374,201,30,811,60.2,******,37,******,81.6,
102,2640,0,269,217,30,583,65,******,37,******,58.6,"ME-,taD"
103,2645,0,260,234,30,609,70.1,******,37,******,61.2,"ME-,taD"
104,2650,0,278,252,30,701,75.7,******,37,******,70.5,"ME-,taD"
105,2655,0,276,272,30,752,81.6,******,37,******,75.6,"ME-,taD"
106,2660,0,256,294,30,752,88.1,******,37,******,75.6,"ME-,taD"
107,2665,0,241,317,30,764,95,******,37,******,76.8,"ME-,taD"
108,2670,0,236,342,30,808,103,******,37,******,81.2,"ME-,taD"
109,2675,0,217,369,30,802,111,******,37,******,80.6,"ME-,taD"
110,2680,0,182,398,30,726,119,******,37,******,73,"ME-,taD"
111,2685,0,163,429,30,701,129,******,37,******,70.5,"ME-,taD"
112,2690,0,165,463,30,763,139,******,37,******,76.7,"ME-,taD"
113,2695,0,153,500,30,763,150,******,37,******,76.7,"ME-,taD"
,,,,,,,,,,,,
Interval:,,,5,,,,,,,,,
Number of Data Points:,,,80,,,,,,,,,
,,,,,,,,,,,,
Time Setting:,,,80 Meas. Pts.,,,,,,,,,
,,,Meas. Pt. Duration 5 s,,,,,,,,,
Event Control:,,,Standard Mode,,,,,,,,,
"  Terminate test, ...",,,...if M > 75 mNm,,,,,,,,,
Measuring Profile:,,,,,,,,,,,,
#NAME?,,,Amplitude gamma = 5 %,,,,,,,,,
,,,Angular Frequency omega = 30 rad/s,,,,,,,,,
,,,,,,,,,,,,
Meas. Pts.,Time,Storage Modulus,Loss Modulus,Strain,Angular Frequency,Shear Stress,Shear Rate,Viscosity,Temperature,Speed,Torque,Status
,[s],[Pa],[Pa],[%],[rad/s],[Pa],[1/s],[Pa·s],[°C],[1/min],[µNm],[]
1,2700,392,1710,4.95,30,87,1.49,******,37,******,8.75,WMa
2,2705,855,335,5,30,45.9,1.5,******,37,******,4.62,
3,2710,1100,402,5,30,58.4,1.5,******,37,******,5.87,
4,2715,1240,456,5,30,66.2,1.5,******,37,******,6.66,
5,2720,1350,495,5,30,71.8,1.5,******,37,******,7.22,
6,2725,1480,526,5,30,78.5,1.5,******,37,******,7.9,
7,2730,1600,564,5,30,84.6,1.5,******,37,******,8.51,
8,2735,1720,598,5,30,91,1.5,******,37,******,9.15,
9,2740,1760,605,5,30,93.1,1.5,******,37,******,9.36,
10,2745,1810,623,5,30,95.8,1.5,******,37,******,9.63,
11,2750,1850,636,5,30,98.1,1.5,******,37,******,9.86,
12,2755,1890,643,5,30,99.9,1.5,******,37,******,10,
13,2760,1910,658,5,30,101,1.5,******,37,******,10.2,
14,2765,1950,667,5,30,103,1.5,******,37,******,10.4,
15,2770,1960,681,5,30,104,1.5,******,37,******,10.4,
16,2775,1970,676,5,30,104,1.5,******,37,******,10.5,
17,2780,2010,684,5,30,106,1.5,******,37,******,10.7,
18,2785,2010,688,5,30,106,1.5,******,37,******,10.7,
19,2790,2040,695,5,30,108,1.5,******,37,******,10.8,
20,2795,2040,701,5,30,108,1.5,******,37,******,10.9,
21,2800,2050,704,5,30,108,1.5,******,37,******,10.9,
22,2805,2060,697,5,30,109,1.5,******,37,******,10.9,
23,2810,2070,700,5,30,109,1.5,******,37,******,11,
24,2815,2080,714,5,30,110,1.5,******,37,******,11,
25,2820,2110,707,5,30,111,1.5,******,37,******,11.2,
26,2825,2110,702,5,30,111,1.5,******,37,******,11.2,
27,2830,2090,731,5,30,111,1.5,******,37,******,11.1,
28,2835,2120,717,5,30,112,1.5,******,37,******,11.3,
29,2840,2120,726,5,30,112,1.5,******,37,******,11.3,
30,2845,2100,729,5,30,111,1.5,******,37,******,11.2,
31,2850,2120,720,5,30,112,1.5,******,37,******,11.3,
32,2855,2140,718,5,30,113,1.5,******,37,******,11.3,
33,2860,2150,721,5,30,113,1.5,******,37,******,11.4,
34,2865,2150,734,5,30,114,1.5,******,37,******,11.4,
35,2870,2150,733,5,30,114,1.5,******,37,******,11.4,
36,2875,2150,734,5,30,114,1.5,******,37,******,11.4,
37,2880,2160,729,5,30,114,1.5,******,37,******,11.4,
38,2885,2160,709,5,30,114,1.5,******,37,******,11.5,
39,2890,2170,735,5,30,114,1.5,******,37,******,11.5,
40,2895,2180,743,5,30,115,1.5,******,37,******,11.6,
41,2900,2190,721,5,30,115,1.5,******,37,******,11.6,
42,2905,2170,743,5,30,115,1.5,******,37,******,11.5,
43,2910,2190,748,5,30,116,1.5,******,37,******,11.7,
44,2915,2200,737,5,30,116,1.5,******,37,******,11.7,
45,2920,2190,744,5,30,116,1.5,******,37,******,11.6,
46,2925,2190,744,5,30,116,1.5,******,37,******,11.6,
47,2930,2190,753,5,30,116,1.5,******,37,******,11.6,
48,2935,2210,754,5,30,117,1.5,******,37,******,11.7,
49,2940,2210,756,5,30,117,1.5,******,37,******,11.7,
50,2945,2210,753,5,30,117,1.5,******,37,******,11.7,
51,2950,2230,757,5,30,118,1.5,******,37,******,11.8,
52,2955,2210,737,5,30,117,1.5,******,37,******,11.7,
53,2960,2220,755,5,30,117,1.5,******,37,******,11.8,
54,2965,2210,752,5,30,117,1.5,******,37,******,11.8,
55,2970,2220,765,5,30,118,1.5,******,37,******,11.8,
56,2975,2220,754,5,30,117,1.5,******,37,******,11.8,
57,2980,2230,768,5,30,118,1.5,******,37,******,11.9,
58,2985,2230,752,5,30,118,1.5,******,37,******,11.8,
59,2990,2240,753,5,30,118,1.5,******,37,******,11.9,
60,2995,2240,757,5,30,118,1.5,******,37,******,11.9,
61,3000,2230,773,5,30,118,1.5,******,37,******,11.9,
62,3005,2240,748,5,30,118,1.5,******,37,******,11.9,
63,3010,2240,739,5,30,118,1.5,******,37,******,11.9,
64,3015,2270,748,5,30,119,1.5,******,37,******,12,
65,3020,2260,765,5,30,119,1.5,******,37,******,12,
66,3025,2260,769,5,30,119,1.5,******,37,******,12,
67,3030,2250,756,5,30,119,1.5,******,37,******,11.9,
68,3035,2260,764,5,30,119,1.5,******,37,******,12,
69,3040,2260,769,5,30,119,1.5,******,37,******,12,
70,3045,2260,768,5,30,119,1.5,******,37,******,12,
71,3050,2260,765,5,30,119,1.5,******,37,******,12,
72,3055,2270,764,5,30,120,1.5,******,37,******,12,
73,3060,2260,765,5,30,119,1.5,******,37,******,12,
74,3065,2270,775,5,30,120,1.5,******,37,******,12.1,
75,3070,2270,752,5,30,120,1.5,******,37,******,12,
76,3075,2260,758,5,30,119,1.5,******,37,******,12,
77,3080,2270,769,5,30,120,1.5,******,37,******,12.1,
78,3085,2280,766,5,30,120,1.5,******,37,******,12.1,
79,3090,2260,775,5,30,120,1.5,******,37,******,12,
80,3095,2270,776,5,30,120,1.5,******,37,******,12.1,
,,,,,,,,,,,,
Interval:,,,6,,,,,,,,,
Number of Data Points:,,,600,,,,,,,,,
,,,,,,,,,,,,
Time Setting:,,,600 Meas. Pts.,,,,,,,,,
,,,Meas. Pt. Duration 3 s,,,,,,,,,
Event Control:,,,Standard Mode,,,,,,,,,
"  Terminate test, ...",,,...if M > 200 mNm,,,,,,,,,
Measuring Profile:,,,,,,,,,,,,
#NAME?,,,Amplitude gamma = 5 %,,,,,,,,,
,,,Angular Frequency omega = 30 rad/s,,,,,,,,,
,,,,,,,,,,,,
Meas. Pts.,Time,Storage Modulus,Loss Modulus,Strain,Angular Frequency,Shear Stress,Shear Rate,Viscosity,Temperature,Speed,Torque,Status
,[s],[Pa],[Pa],[%],[rad/s],[Pa],[1/s],[Pa·s],[°C],[1/min],[µNm],[]
1,3098,2360,763,5.02,30,124,1.5,******,37,******,12.5,WMa
2,3101,2360,770,5,30,124,1.5,******,37,******,12.5,WMa
3,3104,2360,765,5,30,124,1.5,******,37,******,12.5,
4,3107,2380,760,5,30,125,1.5,******,37,******,12.6,
5,3110,2360,781,5,30,124,1.5,******,37,******,12.5,
6,3113,2370,767,5,30,125,1.5,******,37,******,12.5,
7,3116,2360,773,5,30,124,1.5,******,37,******,12.5,
8,3119,2360,778,5,30,124,1.5,******,37,******,12.5,
9,3122,2360,750,5,30,124,1.5,******,37,******,12.5,
10,3125,2370,797,5,30,125,1.5,******,37,******,12.6,
11,3128,2380,773,5,30,125,1.5,******,37,******,12.6,
12,3131,2380,790,5,30,126,1.5,******,37,******,12.6,
13,3134,2390,767,5,30,126,1.5,******,37,******,12.6,
14,3137,2370,763,5,30,124,1.5,******,37,******,12.5,
15,3140,2390,781,5,30,126,1.5,******,37,******,12.7,
16,3143,2370,770,5,30,125,1.5,******,37,******,12.5,
17,3146,2370,754,5,30,124,1.5,******,37,******,12.5,
18,3149,2380,777,5,30,125,1.5,******,37,******,12.6,
19,3152,2390,755,5,30,125,1.5,******,37,******,12.6,
20,3155,2380,766,5,30,125,1.5,******,37,******,12.6,
21,3158,2380,760,5,30,125,1.5,******,37,******,12.6,
22,3161,2420,762,5,30,127,1.5,******,37,******,12.7,
23,3164,2400,784,5,30,126,1.5,******,37,******,12.7,
24,3167,2400,778,5,30,126,1.5,******,37,******,12.7,
25,3170,2390,775,5,30,126,1.5,******,37,******,12.6,
26,3173,2390,766,5,30,125,1.5,******,37,******,12.6,
27,3176,2410,749,5,30,126,1.5,******,37,******,12.7,
28,3179,2380,802,5,30,126,1.5,******,37,******,12.6,
29,3182,2390,794,5,30,126,1.5,******,37,******,12.7,
30,3185,2400,773,5,30,126,1.5,******,37,******,12.7,
31,3188,2390,760,5,30,125,1.5,******,37,******,12.6,
32,3191,2410,782,5,30,127,1.5,******,37,******,12.8,
33,3194,2370,776,5,30,125,1.5,******,37,******,12.6,
34,3197,2420,767,5,30,127,1.5,******,37,******,12.8,
35,3200,2400,785,5,30,126,1.5,******,37,******,12.7,
36,3203,2390,794,5,30,126,1.5,******,37,******,12.7,
37,3206,2390,793,5,30,126,1.5,******,37,******,12.7,
38,3209,2390,775,5,30,126,1.5,******,37,******,12.6,
39,3212,2400,784,5,30,126,1.5,******,37,******,12.7,
40,3215,2410,782,5,30,126,1.5,******,37,******,12.7,
41,3218,2390,774,5,30,126,1.5,******,37,******,12.6,
42,3221,2410,784,5,30,127,1.5,******,37,******,12.7,
43,3224,2400,767,5,30,126,1.5,******,37,******,12.7,
44,3227,2400,773,5,30,126,1.5,******,37,******,12.7,
45,3230,2390,787,5,30,126,1.5,******,37,******,12.6,
46,3233,2400,787,5,30,126,1.5,******,37,******,12.7,
47,3236,2400,799,5,30,127,1.5,******,37,******,12.7,
48,3239,2410,770,5,30,127,1.5,******,37,******,12.7,
49,3242,2400,777,5,30,126,1.5,******,37,******,12.7,
50,3245,2440,785,5,30,128,1.5,******,37,******,12.9,
51,3248,2420,775,5,30,127,1.5,******,37,******,12.8,
52,3251,2400,798,5,30,127,1.5,******,37,******,12.7,
53,3254,2400,787,5,30,126,1.5,******,37,******,12.7,
54,3257,2410,766,5,30,127,1.5,******,37,******,12.7,
55,3260,2410,799,5,30,127,1.5,******,37,******,12.8,
56,3263,2420,777,5,30,127,1.5,******,37,******,12.8,
57,3266,2420,809,5,30,127,1.5,******,37,******,12.8,
58,3269,2430,793,5,30,128,1.5,******,37,******,12.9,
59,3272,2400,788,5,30,126,1.5,******,37,******,12.7,
60,3275,2400,805,5,30,127,1.5,******,37,******,12.7,
61,3278,2410,785,5,30,127,1.5,******,37,******,12.8,
62,3281,2390,792,5,30,126,1.5,******,37,******,12.7,
63,3284,2410,790,5,30,127,1.5,******,37,******,12.8,
64,3287,2420,796,5,30,127,1.5,******,37,******,12.8,
65,3290,2430,782,5,30,128,1.5,******,37,******,12.8,
66,3293,2420,802,5,30,127,1.5,******,37,******,12.8,
67,3296,2440,803,5,30,128,1.5,******,37,******,12.9,
68,3299,2380,775,5,30,125,1.5,******,37,******,12.6,
69,3302,2410,790,5,30,127,1.5,******,37,******,12.7,
70,3305,2440,767,5,30,128,1.5,******,37,******,12.9,
71,3308,2390,814,5,30,126,1.5,******,37,******,12.7,
72,3311,2420,787,5,30,127,1.5,******,37,******,12.8,
73,3314,2430,793,5,30,128,1.5,******,37,******,12.9,
74,3317,2420,792,5,30,127,1.5,******,37,******,12.8,
75,3320,2410,773,5,30,127,1.5,******,37,******,12.7,
76,3323,2430,791,5,30,128,1.5,******,37,******,12.8,
77,3326,2420,772,5,30,127,1.5,******,37,******,12.8,
78,3329,2410,780,5,30,127,1.5,******,37,******,12.8,
79,3332,2430,768,5,30,128,1.5,******,37,******,12.8,
80,3335,2430,782,5,30,128,1.5,******,37,******,12.8,
81,3338,2420,785,5,30,127,1.5,******,37,******,12.8,
82,3341,2440,797,5,30,128,1.5,******,37,******,12.9,
83,3344,2420,792,5,30,127,1.5,******,37,******,12.8,
84,3347,2430,802,5,30,128,1.5,******,37,******,12.9,
85,3350,2420,793,5,30,128,1.5,******,37,******,12.8,
86,3353,2430,772,5,30,127,1.5,******,37,******,12.8,
87,3356,2420,787,5,30,127,1.5,******,37,******,12.8,
88,3359,2440,779,5,30,128,1.5,******,37,******,12.9,
89,3362,2410,806,5,30,127,1.5,******,37,******,12.8,
90,3365,2420,796,5,30,127,1.5,******,37,******,12.8,
91,3368,2460,795,5,30,129,1.5,******,37,******,13,
92,3371,2430,798,5,30,128,1.5,******,37,******,12.9,
93,3374,2430,797,5,30,128,1.5,******,37,******,12.9,
94,3377,2450,792,5,30,129,1.5,******,37,******,12.9,
95,3380,2440,778,5,30,128,1.5,******,37,******,12.9,
96,3383,2470,777,5,30,130,1.5,******,37,******,13,
97,3386,2420,786,5,30,127,1.5,******,37,******,12.8,
98,3389,2430,782,5,30,128,1.5,******,37,******,12.8,
99,3392,2390,754,5,30,125,1.5,******,37,******,12.6,
100,3395,2430,765,5,30,127,1.5,******,37,******,12.8,
101,3398,2430,772,5,30,127,1.5,******,37,******,12.8,
102,3401,2450,799,5,30,129,1.5,******,37,******,12.9,
103,3404,2440,785,5,30,128,1.5,******,37,******,12.9,
104,3407,2430,796,5,30,128,1.5,******,37,******,12.9,
105,3410,2450,791,5,30,129,1.5,******,37,******,12.9,
106,3413,2420,801,5,30,127,1.5,******,37,******,12.8,
107,3416,2450,770,5,30,129,1.5,******,37,******,12.9,
108,3419,2430,783,5,30,128,1.5,******,37,******,12.8,
109,3422,2440,776,5,30,128,1.5,******,37,******,12.9,
110,3425,2440,773,5,30,128,1.5,******,37,******,12.9,
111,3428,2440,783,5,30,128,1.5,******,37,******,12.9,
112,3431,2450,784,5,30,129,1.5,******,37,******,12.9,
113,3434,2440,789,5,30,128,1.5,******,37,******,12.9,
114,3437,2450,779,5,30,129,1.5,******,37,******,12.9,
115,3440,2440,802,5,30,128,1.5,******,37,******,12.9,
116,3443,2450,789,5,30,128,1.5,******,37,******,12.9,
117,3446,2440,783,5,30,128,1.5,******,37,******,12.9,
118,3449,2440,817,5,30,128,1.5,******,37,******,12.9,
119,3452,2440,777,5,30,128,1.5,******,37,******,12.9,
120,3455,2420,767,5,30,127,1.5,******,37,******,12.8,
121,3458,2440,803,5,30,128,1.5,******,37,******,12.9,
122,3461,2430,790,5,30,128,1.5,******,37,******,12.9,
123,3464,2420,791,5,30,127,1.5,******,37,******,12.8,
124,3467,2460,782,5,30,129,1.5,******,37,******,13,
125,3470,2440,778,5,30,128,1.5,******,37,******,12.9,
126,3473,2450,780,5,30,129,1.5,******,37,******,12.9,
127,3476,2440,798,5,30,128,1.5,******,37,******,12.9,
128,3479,2460,811,5,30,129,1.5,******,37,******,13,
129,3482,2440,792,5,30,128,1.5,******,37,******,12.9,
130,3485,2430,783,5,30,128,1.5,******,37,******,12.8,
131,3488,2450,794,5,30,129,1.5,******,37,******,12.9,
132,3491,2450,794,5,30,129,1.5,******,37,******,12.9,
133,3494,2450,791,5,30,129,1.5,******,37,******,12.9,
134,3497,2440,760,5,30,128,1.5,******,37,******,12.8,
135,3500,2450,795,5,30,129,1.5,******,37,******,13,
136,3503,2440,766,5,30,128,1.5,******,37,******,12.9,
137,3506,2450,791,5,30,129,1.5,******,37,******,12.9,
138,3509,2430,809,5,30,128,1.5,******,37,******,12.9,
139,3512,2430,782,5,30,128,1.5,******,37,******,12.8,
140,3515,2470,793,5,30,130,1.5,******,37,******,13,
141,3518,2440,798,5,30,128,1.5,******,37,******,12.9,
142,3521,2460,821,5,30,130,1.5,******,37,******,13.1,
143,3524,2440,815,5,30,129,1.5,******,37,******,12.9,
144,3527,2450,815,5,30,129,1.5,******,37,******,13,
145,3530,2460,770,5,30,129,1.5,******,37,******,13,
146,3533,2450,796,5,30,129,1.5,******,37,******,13,
147,3536,2460,794,5,30,129,1.5,******,37,******,13,
148,3539,2430,785,5,30,128,1.5,******,37,******,12.8,
149,3542,2430,797,5,30,128,1.5,******,37,******,12.9,
150,3545,2450,790,5,30,129,1.5,******,37,******,12.9,
151,3548,2450,776,5,30,129,1.5,******,37,******,12.9,
152,3551,2440,816,5,30,129,1.5,******,37,******,13,
153,3554,2460,803,5,30,130,1.5,******,37,******,13,
154,3557,2460,786,5,30,129,1.5,******,37,******,13,
155,3560,2450,800,5,30,129,1.5,******,37,******,12.9,
156,3563,2450,781,5,30,128,1.5,******,37,******,12.9,
157,3566,2470,795,5,30,130,1.5,******,37,******,13.1,
158,3569,2430,792,5,30,128,1.5,******,37,******,12.9,
159,3572,2450,802,5,30,129,1.5,******,37,******,12.9,
160,3575,2450,770,5,30,128,1.5,******,37,******,12.9,
161,3578,2470,793,5,30,129,1.5,******,37,******,13,
162,3581,2450,826,5,30,129,1.5,******,37,******,13,
163,3584,2460,817,5,30,130,1.5,******,37,******,13,
164,3587,2460,789,5,30,129,1.5,******,37,******,13,
165,3590,2460,795,5,30,129,1.5,******,37,******,13,
166,3593,2480,802,5,30,130,1.5,******,37,******,13.1,
167,3596,2440,796,5,30,129,1.5,******,37,******,12.9,
168,3599,2470,797,5,30,130,1.5,******,37,******,13.1,
169,3602,2450,801,5,30,129,1.5,******,37,******,13,
170,3605,2440,823,5,30,129,1.5,******,37,******,12.9,
171,3608,2470,804,5,30,130,1.5,******,37,******,13.1,
172,3611,2460,806,5,30,130,1.5,******,37,******,13,
173,3614,2430,801,5,30,128,1.5,******,37,******,12.9,
174,3617,2450,788,5,30,129,1.5,******,37,******,13,
175,3620,2480,796,5,30,130,1.5,******,37,******,13.1,
176,3623,2440,792,5,30,128,1.5,******,37,******,12.9,
177,3626,2480,784,5,30,130,1.5,******,37,******,13.1,
178,3629,2480,796,5,30,130,1.5,******,37,******,13.1,
179,3632,2450,811,5,30,129,1.5,******,37,******,13,
180,3635,2480,793,5,30,130,1.5,******,37,******,13.1,
181,3638,2450,785,5,30,129,1.5,******,37,******,12.9,
182,3641,2470,799,5,30,130,1.5,******,37,******,13.1,
183,3644,2450,769,5,30,128,1.5,******,37,******,12.9,
184,3647,2460,794,5,30,129,1.5,******,37,******,13,
185,3650,2450,796,5,30,129,1.5,******,37,******,12.9,
186,3653,2470,809,5,30,130,1.5,******,37,******,13.1,
187,3656,2470,793,5,30,130,1.5,******,37,******,13,
188,3659,2460,820,5,30,130,1.5,******,37,******,13,
189,3662,2470,796,5,30,130,1.5,******,37,******,13,
190,3665,2460,801,5,30,130,1.5,******,37,******,13,
191,3668,2470,815,5,30,130,1.5,******,37,******,13.1,
192,3671,2480,806,5,30,130,1.5,******,37,******,13.1,
193,3674,2480,807,5,30,131,1.5,******,37,******,13.1,
194,3677,2470,824,5,30,130,1.5,******,37,******,13.1,
195,3680,2480,801,5,30,131,1.5,******,37,******,13.1,
196,3683,2460,816,5,30,129,1.5,******,37,******,13,
197,3686,2470,811,5,30,130,1.5,******,37,******,13.1,
198,3689,2480,792,5,30,130,1.5,******,37,******,13.1,
199,3692,2480,799,5,30,130,1.5,******,37,******,13.1,
200,3695,2490,828,5,30,131,1.5,******,37,******,13.2,
201,3698,2470,790,5,30,130,1.5,******,37,******,13,
202,3701,2520,816,5,30,132,1.5,******,37,******,13.3,
203,3704,2480,799,5,30,130,1.5,******,37,******,13.1,
204,3707,2480,802,5,30,130,1.5,******,37,******,13.1,
205,3710,2500,782,5,30,131,1.5,******,37,******,13.1,
206,3713,2470,810,5,30,130,1.5,******,37,******,13,
207,3716,2500,825,5,30,132,1.5,******,37,******,13.2,
208,3719,2480,821,5,30,131,1.5,******,37,******,13.1,
209,3722,2480,814,5,30,131,1.5,******,37,******,13.1,
210,3725,2480,807,5,30,130,1.5,******,37,******,13.1,
211,3728,2480,805,5,30,130,1.5,******,37,******,13.1,
212,3731,2450,805,5,30,129,1.5,******,37,******,13,
213,3734,2510,795,5,30,132,1.5,******,37,******,13.2,
214,3737,2470,801,5,30,130,1.5,******,37,******,13.1,
215,3740,2490,783,5,30,130,1.5,******,37,******,13.1,
216,3743,2470,788,5,30,130,1.5,******,37,******,13,
217,3746,2470,788,5,30,130,1.5,******,37,******,13,
218,3749,2500,837,5,30,132,1.5,******,37,******,13.3,
219,3752,2470,790,5,30,130,1.5,******,37,******,13,
220,3755,2460,811,5,30,130,1.5,******,37,******,13,
221,3758,2500,804,5,30,131,1.5,******,37,******,13.2,
222,3761,2460,808,5,30,130,1.5,******,37,******,13,
223,3764,2470,806,5,30,130,1.5,******,37,******,13.1,
224,3767,2490,799,5,30,131,1.5,******,37,******,13.1,
225,3770,2480,805,5,30,130,1.5,******,37,******,13.1,
226,3773,2490,809,5,30,131,1.5,******,37,******,13.1,
227,3776,2470,787,5,30,130,1.5,******,37,******,13.1,
228,3779,2480,794,5,30,130,1.5,******,37,******,13.1,
229,3782,2500,793,5,30,131,1.5,******,37,******,13.2,
230,3785,2500,800,5,30,131,1.5,******,37,******,13.2,
231,3788,2470,808,5,30,130,1.5,******,37,******,13.1,
232,3791,2500,787,5,30,131,1.5,******,37,******,13.2,
233,3794,2480,792,5,30,130,1.5,******,37,******,13.1,
234,3797,2490,751,5,30,130,1.5,******,37,******,13.1,
235,3800,2490,800,5,30,131,1.5,******,37,******,13.1,
236,3803,2480,783,5,30,130,1.5,******,37,******,13.1,
237,3806,2470,807,5,30,130,1.5,******,37,******,13,
238,3809,2490,807,5,30,131,1.5,******,37,******,13.2,
239,3812,2500,805,5,30,131,1.5,******,37,******,13.2,
240,3815,2490,800,5,30,131,1.5,******,37,******,13.2,
241,3818,2470,824,5,30,130,1.5,******,37,******,13.1,
242,3821,2500,821,5,30,132,1.5,******,37,******,13.2,
243,3824,2480,804,5,30,130,1.5,******,37,******,13.1,
244,3827,2490,819,5,30,131,1.5,******,37,******,13.2,
245,3830,2490,815,5,30,131,1.5,******,37,******,13.2,
246,3833,2500,789,5,30,131,1.5,******,37,******,13.2,
247,3836,2510,813,5,30,132,1.5,******,37,******,13.3,
248,3839,2480,807,5,30,131,1.5,******,37,******,13.1,
249,3842,2490,808,5,30,131,1.5,******,37,******,13.2,
250,3845,2490,806,5,30,131,1.5,******,37,******,13.1,
251,3848,2490,790,5,30,131,1.5,******,37,******,13.1,
252,3851,2490,805,5,30,131,1.5,******,37,******,13.2,
253,3854,2500,814,5,30,131,1.5,******,37,******,13.2,
254,3857,2490,798,5,30,131,1.5,******,37,******,13.1,
255,3860,2480,816,5,30,130,1.5,******,37,******,13.1,
256,3863,2490,810,5,30,131,1.5,******,37,******,13.1,
257,3866,2450,795,5,30,129,1.5,******,37,******,12.9,
258,3869,2520,794,5,30,132,1.5,******,37,******,13.3,
259,3872,2490,819,5,30,131,1.5,******,37,******,13.2,
260,3875,2490,817,5,30,131,1.5,******,37,******,13.2,
261,3878,2490,808,5,30,131,1.5,******,37,******,13.2,
262,3881,2500,847,5,30,132,1.5,******,37,******,13.3,
263,3884,2520,799,5,30,132,1.5,******,37,******,13.3,
264,3887,2500,813,5,30,131,1.5,******,37,******,13.2,
265,3890,2530,816,5,30,133,1.5,******,37,******,13.4,
266,3893,2480,803,5,30,131,1.5,******,37,******,13.1,
267,3896,2500,788,5,30,131,1.5,******,37,******,13.2,
268,3899,2480,815,5,30,131,1.5,******,37,******,13.1,
269,3902,2490,802,5,30,131,1.5,******,37,******,13.2,
270,3905,2490,826,5,30,131,1.5,******,37,******,13.2,
271,3908,2490,790,5,30,131,1.5,******,37,******,13.1,
272,3911,2510,806,5,30,132,1.5,******,37,******,13.2,
273,3914,2510,824,5,30,132,1.5,******,37,******,13.3,
274,3917,2510,808,5,30,132,1.5,******,37,******,13.3,
275,3920,2500,801,5,30,131,1.5,******,37,******,13.2,
276,3923,2500,826,5,30,132,1.5,******,37,******,13.2,
277,3926,2500,817,5,30,131,1.5,******,37,******,13.2,
278,3929,2510,794,5,30,131,1.5,******,37,******,13.2,
279,3932,2490,850,5,30,132,1.5,******,37,******,13.2,
280,3935,2510,812,5,30,132,1.5,******,37,******,13.3,
281,3938,2490,800,5,30,131,1.5,******,37,******,13.2,
282,3941,2480,804,5,30,131,1.5,******,37,******,13.1,
283,3944,2490,816,5,30,131,1.5,******,37,******,13.2,
284,3947,2520,809,5,30,132,1.5,******,37,******,13.3,
285,3950,2500,797,5,30,131,1.5,******,37,******,13.2,
286,3953,2500,802,5,30,131,1.5,******,37,******,13.2,
287,3956,2500,811,5,30,131,1.5,******,37,******,13.2,
288,3959,2500,817,5,30,132,1.5,******,37,******,13.2,
289,3962,2480,810,5,30,130,1.5,******,37,******,13.1,
290,3965,2490,802,5,30,131,1.5,******,37,******,13.1,
291,3968,2520,822,5,30,133,1.5,******,37,******,13.3,
292,3971,2500,802,5,30,131,1.5,******,37,******,13.2,
293,3974,2500,829,5,30,132,1.5,******,37,******,13.2,
294,3977,2510,802,5,30,132,1.5,******,37,******,13.2,
295,3980,2500,812,5,30,131,1.5,******,37,******,13.2,
296,3983,2500,803,5,30,131,1.5,******,37,******,13.2,
297,3986,2500,798,5,30,131,1.5,******,37,******,13.2,
298,3989,2530,807,5,30,133,1.5,******,37,******,13.3,
299,3992,2510,820,5,30,132,1.5,******,37,******,13.3,
300,3995,2510,816,5,30,132,1.5,******,37,******,13.3,
301,3998,2480,807,5,30,130,1.5,******,37,******,13.1,
302,4001,2500,828,5,30,132,1.5,******,37,******,13.3,
303,4004,2530,798,5,30,133,1.5,******,37,******,13.3,
304,4007,2500,804,5,30,131,1.5,******,37,******,13.2,
305,4010,2510,791,5,30,132,1.5,******,37,******,13.2,
306,4013,2460,793,5,30,129,1.5,******,37,******,13,
307,4016,2510,797,5,30,131,1.5,******,37,******,13.2,
308,4019,2500,801,5,30,131,1.5,******,37,******,13.2,
309,4022,2520,822,5,30,132,1.5,******,37,******,13.3,
310,4025,2500,808,5,30,131,1.5,******,37,******,13.2,
311,4028,2510,821,5,30,132,1.5,******,37,******,13.3,
[...]
309,11462,2330,787,5,30,123,1.5,******,37,******,12.4,WMa
310,11465,2320,788,5,30,122,1.5,******,37,******,12.3,WMa
311,11468,2330,789,5,30,123,1.5,******,37,******,12.4,WMa
312,11471,2330,786,5,30,123,1.5,******,37,******,12.4,WMa
313,11474,2330,773,5,30,123,1.5,******,37,******,12.4,WMa
314,11477,2330,757,5,30,123,1.5,******,37,******,12.3,WMa
315,11480,2330,783,5,30,123,1.5,******,37,******,12.4,"MV-,WMa"
316,11483,2340,796,5,30,123,1.5,******,37,******,12.4,"MV-,WMa"
317,11486,2320,792,5,30,123,1.5,******,37,******,12.3,WMa
318,11489,2320,781,5,30,122,1.5,******,37,******,12.3,WMa
319,11492,2330,790,5,30,123,1.5,******,37,******,12.4,"ME-,WMa"
320,11495,2340,776,5,30,123,1.5,******,37,******,12.4,"MV-,WMa"
321,11498,2320,806,5,30,123,1.5,******,37,******,12.4,WMa
322,11501,2320,780,5,30,123,1.5,******,37,******,12.3,WMa
323,11504,2330,775,5,30,123,1.5,******,37,******,12.3,WMa
324,11507,2330,780,5,30,123,1.5,******,37,******,12.4,WMa
325,11510,2320,787,5,30,122,1.5,******,37,******,12.3,WMa
326,11513,2350,771,5,30,124,1.5,******,37,******,12.4,"ME-,WMa"
327,11516,2330,777,5,30,123,1.5,******,37,******,12.4,WMa
328,11519,2330,801,5,30,123,1.5,******,37,******,12.4,WMa
329,11522,2330,786,5,30,123,1.5,******,37,******,12.4,WMa
330,11525,2350,791,5,30,124,1.5,******,37,******,12.4,WMa
331,11528,2340,788,5,30,123,1.5,******,37,******,12.4,WMa
332,11531,2350,785,5,30,124,1.5,******,37,******,12.4,"ME-,MV-"
333,11534,2310,781,5,30,122,1.5,******,37,******,12.3,WMa
334,11537,2360,752,5,30,124,1.5,******,37,******,12.4,WMa
335,11540,2340,827,5,30,124,1.5,******,37,******,12.5,WMa
336,11543,2330,771,5,30,123,1.5,******,37,******,12.4,"MV-,WMa"
337,11546,2340,787,5,30,123,1.5,******,37,******,12.4,WMa
338,11549,2360,820,5,30,125,1.5,******,37,******,12.6,WMa
339,11552,2340,791,5,30,124,1.5,******,37,******,12.4,WMa
340,11555,2320,788,5,30,122,1.5,******,37,******,12.3,WMa
341,11558,2350,775,5,30,124,1.5,******,37,******,12.5,"ME-,WMa"
342,11561,2330,788,5,30,123,1.5,******,37,******,12.4,"MV-,WMa"
343,11564,2330,761,5,30,122,1.5,******,37,******,12.3,"MV-,WMa"
344,11567,2340,796,5,30,124,1.5,******,37,******,12.4,WMa
345,11570,2330,780,5,30,123,1.5,******,37,******,12.3,WMa
346,11573,2330,782,5,30,123,1.5,******,37,******,12.4,WMa
347,11576,2360,788,5,30,125,1.5,******,37,******,12.5,WMa
348,11579,2340,780,5,30,123,1.5,******,37,******,12.4,"ME-,WMa"
349,11582,2330,794,5,30,123,1.5,******,37,******,12.4,"MV-,WMa"
350,11585,2330,784,5,30,123,1.5,******,37,******,12.3,"MV-,WMa"
351,11588,2340,784,5,30,123,1.5,******,37,******,12.4,WMa
352,11591,2330,780,5,30,123,1.5,******,37,******,12.4,WMa
353,11594,2340,794,5,30,123,1.5,******,37,******,12.4,WMa
354,11597,2330,789,5,30,123,1.5,******,37,******,12.4,"ME-,WMa"
355,11600,2360,778,5,30,124,1.5,******,37,******,12.5,"ME-,WMa"
356,11603,2340,779,5,30,123,1.5,******,37,******,12.4,"MV-,WMa"
357,11606,2340,768,5,30,123,1.5,******,37,******,12.4,WMa
358,11609,2340,777,5,30,123,1.5,******,37,******,12.4,"MV-,WMa"
359,11612,2360,802,5,30,125,1.5,******,37,******,12.5,WMa
360,11615,2330,791,5,30,123,1.5,******,37,******,12.4,WMa
361,11618,2300,790,5,30,122,1.5,******,37,******,12.2,WMa
362,11621,2350,780,5,30,124,1.5,******,37,******,12.5,"ME-,WMa"
363,11624,2340,802,5,30,124,1.5,******,37,******,12.5,WMa
364,11627,2340,787,5,30,124,1.5,******,37,******,12.4,"MV-,WMa"
365,11630,2330,748,5,30,122,1.5,******,37,******,12.3,WMa
366,11633,2350,784,5,30,124,1.5,******,37,******,12.4,WMa
367,11636,2320,784,5,30,123,1.5,******,37,******,12.3,WMa
368,11639,2320,789,5,30,123,1.5,******,37,******,12.3,WMa
369,11642,2340,782,5,30,124,1.5,******,37,******,12.4,WMa
370,11645,2340,795,5,30,124,1.5,******,37,******,12.4,WMa
371,11648,2340,791,5,30,124,1.5,******,37,******,12.4,WMa
372,11651,2340,802,5,30,124,1.5,******,37,******,12.5,WMa
373,11654,2330,769,5,30,123,1.5,******,37,******,12.3,WMa
374,11657,2350,795,5,30,124,1.5,******,37,******,12.5,WMa
375,11660,2350,808,5,30,124,1.5,******,37,******,12.5,WMa
376,11663,2320,786,5,30,122,1.5,******,37,******,12.3,WMa
377,11666,2320,798,5,30,123,1.5,******,37,******,12.3,WMa
378,11669,2340,786,5,30,123,1.5,******,37,******,12.4,"MV-,WMa"
379,11672,2340,828,5,30,124,1.5,******,37,******,12.5,WMa
380,11675,2320,771,5,30,122,1.5,******,37,******,12.3,WMa
381,11678,2360,803,5,30,125,1.5,******,37,******,12.5,WMa
382,11681,2360,800,5,30,125,1.5,******,37,******,12.5,WMa
383,11684,2330,792,5,30,123,1.5,******,37,******,12.3,WMa
384,11687,2360,776,5,30,124,1.5,******,37,******,12.5,"MV-,WMa"
385,11690,2330,811,5,30,123,1.5,******,37,******,12.4,WMa
386,11693,2340,785,5,30,123,1.5,******,37,******,12.4,"MV-,WMa"
387,11696,2340,778,5,30,123,1.5,******,37,******,12.4,"MV-,WMa"
388,11699,2350,786,5,30,124,1.5,******,37,******,12.4,WMa
389,11702,2340,792,5,30,124,1.5,******,37,******,12.4,WMa
390,11705,2360,789,5,30,124,1.5,******,37,******,12.5,WMa
391,11708,2350,776,5,30,124,1.5,******,37,******,12.5,WMa
392,11711,2350,794,5,30,124,1.5,******,37,******,12.5,WMa
393,11714,2340,773,5,30,123,1.5,******,37,******,12.4,"MV-,WMa"
394,11717,2350,767,5,30,123,1.5,******,37,******,12.4,WMa
395,11720,2360,808,5,30,125,1.5,******,37,******,12.6,WMa
396,11723,2320,782,5,30,122,1.5,******,37,******,12.3,WMa
397,11726,2380,786,5,30,125,1.5,******,37,******,12.6,WMa
398,11729,2350,784,5,30,124,1.5,******,37,******,12.4,WMa
399,11732,2330,809,5,30,123,1.5,******,37,******,12.4,WMa
400,11735,2340,806,5,30,124,1.5,******,37,******,12.4,"MV-,WMa"
401,11738,2350,811,5,30,124,1.5,******,37,******,12.5,WMa
402,11741,2340,771,5,30,123,1.5,******,37,******,12.4,WMa
403,11744,2320,770,5,30,122,1.5,******,37,******,12.3,WMa
404,11747,2350,791,5,30,124,1.5,******,37,******,12.5,WMa
405,11750,2320,804,5,30,123,1.5,******,37,******,12.4,WMa
406,11753,2340,784,5,30,124,1.5,******,37,******,12.4,WMa
407,11756,2340,791,5,30,123,1.5,******,37,******,12.4,"MV-,WMa"
408,11759,2340,781,5,30,123,1.5,******,37,******,12.4,WMa
409,11762,2350,792,5,30,124,1.5,******,37,******,12.5,"MV-,WMa"
410,11765,2350,793,5,30,124,1.5,******,37,******,12.5,WMa
411,11768,2360,788,5,30,124,1.5,******,37,******,12.5,"ME-,MV-"
412,11771,2340,796,5,30,124,1.5,******,37,******,12.4,WMa
413,11774,2350,781,5,30,124,1.5,******,37,******,12.5,"MV-,WMa"
414,11777,2350,808,5,30,124,1.5,******,37,******,12.5,WMa
415,11780,2350,806,5,30,124,1.5,******,37,******,12.5,WMa
416,11783,2340,787,5,30,124,1.5,******,37,******,12.4,WMa
417,11786,2400,818,5,30,127,1.5,******,37,******,12.7,WMa
418,11789,2320,786,5,30,122,1.5,******,37,******,12.3,WMa
419,11792,2340,783,5,30,123,1.5,******,37,******,12.4,WMa
420,11795,2340,792,5,30,124,1.5,******,37,******,12.4,WMa
421,11798,2340,790,5,30,124,1.5,******,37,******,12.4,"MV-,WMa"
422,11801,2340,772,5,30,123,1.5,******,37,******,12.4,WMa
423,11804,2350,797,5,30,124,1.5,******,37,******,12.5,WMa
424,11807,2370,807,5,30,125,1.5,******,37,******,12.6,WMa
425,11810,2360,785,5,30,124,1.5,******,37,******,12.5,WMa
426,11813,2330,803,5,30,123,1.5,******,37,******,12.4,WMa
427,11816,2350,794,5,30,124,1.5,******,37,******,12.5,"ME-,WMa"
428,11819,2340,807,5,30,124,1.5,******,37,******,12.4,WMa
429,11822,2350,765,5,30,124,1.5,******,37,******,12.4,WMa
430,11825,2340,779,5,30,124,1.5,******,37,******,12.4,WMa
431,11828,2340,784,5,30,123,1.5,******,37,******,12.4,WMa
432,11831,2350,827,5,30,125,1.5,******,37,******,12.5,WMa
433,11834,2350,788,5,30,124,1.5,******,37,******,12.5,WMa
434,11837,2360,773,5,30,124,1.5,******,37,******,12.5,WMa
435,11840,2360,775,5,30,124,1.5,******,37,******,12.5,"MV-,WMa"
436,11843,2360,791,5,30,124,1.5,******,37,******,12.5,WMa
437,11846,2350,787,5,30,124,1.5,******,37,******,12.4,WMa
438,11849,2330,783,5,30,123,1.5,******,37,******,12.4,WMa
439,11852,2330,793,5,30,123,1.5,******,37,******,12.4,WMa
440,11855,2350,790,5,30,124,1.5,******,37,******,12.5,WMa
441,11858,2370,781,5,30,125,1.5,******,37,******,12.5,WMa
442,11861,2370,769,5,30,124,1.5,******,37,******,12.5,"MV-,WMa"
443,11864,2350,816,5,30,124,1.5,******,37,******,12.5,WMa
444,11867,2350,783,5,30,124,1.5,******,37,******,12.4,WMa
445,11870,2370,817,5,30,125,1.5,******,37,******,12.6,WMa
446,11873,2360,797,5,30,125,1.5,******,37,******,12.5,WMa
447,11876,2330,798,5,30,123,1.5,******,37,******,12.4,"ME-,MV-"
448,11879,2340,791,5,30,124,1.5,******,37,******,12.4,WMa
449,11882,2350,788,5,30,124,1.5,******,37,******,12.5,WMa
450,11885,2350,769,5,30,124,1.5,******,37,******,12.4,"MV-,WMa"
451,11888,2350,747,5,30,123,1.5,******,37,******,12.4,WMa
452,11891,2340,783,5,30,124,1.5,******,37,******,12.4,WMa
453,11894,2370,804,5,30,125,1.5,******,37,******,12.6,WMa
454,11897,2350,790,5,30,124,1.5,******,37,******,12.4,WMa
455,11900,2370,796,5,30,125,1.5,******,37,******,12.6,WMa
456,11903,2330,810,5,30,123,1.5,******,37,******,12.4,WMa
457,11906,2340,802,5,30,124,1.5,******,37,******,12.4,WMa
458,11909,2350,762,5,30,124,1.5,******,37,******,12.4,WMa
459,11912,2360,807,5,30,125,1.5,******,37,******,12.5,WMa
460,11915,2350,778,5,30,124,1.5,******,37,******,12.4,"MV-,WMa"
461,11918,2360,786,5,30,124,1.5,******,37,******,12.5,"MV-,WMa"
462,11921,2380,790,5,30,125,1.5,******,37,******,12.6,WMa
463,11924,2310,818,5,30,123,1.5,******,37,******,12.3,WMa
464,11927,2350,772,5,30,124,1.5,******,37,******,12.5,WMa
465,11930,2360,774,5,30,124,1.5,******,37,******,12.5,WMa
466,11933,2360,805,5,30,125,1.5,******,37,******,12.5,WMa
467,11936,2360,793,5,30,124,1.5,******,37,******,12.5,"MV-,WMa"
468,11939,2350,788,5,30,124,1.5,******,37,******,12.5,WMa
469,11942,2340,794,5,30,123,1.5,******,37,******,12.4,WMa
470,11945,2340,792,5,30,124,1.5,******,37,******,12.4,WMa
471,11948,2360,786,5,30,124,1.5,******,37,******,12.5,WMa
472,11951,2360,767,5,30,124,1.5,******,37,******,12.5,WMa
473,11954,2350,795,5,30,124,1.5,******,37,******,12.5,WMa
474,11957,2380,823,5,30,126,1.5,******,37,******,12.7,WMa
475,11960,2330,784,5,30,123,1.5,******,37,******,12.3,WMa
476,11963,2370,781,5,30,125,1.5,******,37,******,12.5,WMa
477,11966,2370,798,5,30,125,1.5,******,37,******,12.6,WMa
478,11969,2360,793,5,30,124,1.5,******,37,******,12.5,WMa
479,11972,2360,795,5,30,125,1.5,******,37,******,12.5,"MV-,WMa"
480,11975,2350,795,5,30,124,1.5,******,37,******,12.5,WMa
481,11978,2330,773,5,30,123,1.5,******,37,******,12.3,WMa
482,11981,2360,792,5,30,124,1.5,******,37,******,12.5,WMa
483,11984,2380,787,5,30,125,1.5,******,37,******,12.6,WMa
484,11987,2370,787,5,30,125,1.5,******,37,******,12.6,WMa
485,11990,2360,794,5,30,124,1.5,******,37,******,12.5,"MV-,WMa"
486,11993,2360,790,5,30,124,1.5,******,37,******,12.5,WMa
487,11996,2350,807,5,30,124,1.5,******,37,******,12.5,"MV-,WMa"
488,11999,2350,797,5,30,124,1.5,******,37,******,12.5,"MV-,WMa"
489,12002,2350,767,5,30,124,1.5,******,37,******,12.4,WMa
490,12005,2370,792,5,30,125,1.5,******,37,******,12.5,WMa
491,12008,2350,791,5,30,124,1.5,******,37,******,12.4,WMa
492,12011,2340,803,5,30,124,1.5,******,37,******,12.5,WMa
493,12014,2350,793,5,30,124,1.5,******,37,******,12.5,"MV-,WMa"
494,12017,2350,780,5,30,124,1.5,******,37,******,12.4,"MV-,WMa"
495,12020,2340,786,5,30,124,1.5,******,37,******,12.4,WMa
496,12023,2350,792,5,30,124,1.5,******,37,******,12.5,WMa
497,12026,2350,786,5,30,124,1.5,******,37,******,12.4,WMa
498,12029,2340,788,5,30,123,1.5,******,37,******,12.4,WMa
499,12032,2370,781,5,30,125,1.5,******,37,******,12.5,"MV-,WMa"
500,12035,2340,817,5,30,124,1.5,******,37,******,12.4,WMa
501,12038,2370,794,5,30,125,1.5,******,37,******,12.5,WMa
502,12041,2360,801,5,30,124,1.5,******,37,******,12.5,WMa
503,12044,2370,805,5,30,125,1.5,******,37,******,12.6,"MV-,WMa"
504,12047,2340,783,5,30,123,1.5,******,37,******,12.4,WMa
505,12050,2370,779,5,30,125,1.5,******,37,******,12.6,WMa
506,12053,2350,809,5,30,124,1.5,******,37,******,12.5,WMa
507,12056,2350,796,5,30,124,1.5,******,37,******,12.5,WMa
508,12059,2360,771,5,30,124,1.5,******,37,******,12.5,"MV-,WMa"
509,12062,2370,817,5,30,125,1.5,******,37,******,12.6,WMa
510,12065,2330,762,5,30,122,1.5,******,37,******,12.3,"MV-,WMa"
511,12068,2370,792,5,30,125,1.5,******,37,******,12.6,WMa
512,12071,2340,792,5,30,124,1.5,******,37,******,12.4,WMa
513,12074,2340,787,5,30,124,1.5,******,37,******,12.4,WMa
514,12077,2350,779,5,30,124,1.5,******,37,******,12.5,"ME-,WMa"
515,12080,2350,782,5,30,124,1.5,******,37,******,12.5,"MV-,WMa"
516,12083,2370,811,5,30,125,1.5,******,37,******,12.6,"MV-,WMa"
517,12086,2360,796,5,30,124,1.5,******,37,******,12.5,WMa
518,12089,2360,790,5,30,124,1.5,******,37,******,12.5,WMa
519,12092,2380,795,5,30,126,1.5,******,37,******,12.6,WMa
520,12095,2350,791,5,30,124,1.5,******,37,******,12.4,WMa
521,12098,2370,775,5,30,125,1.5,******,37,******,12.5,WMa
522,12101,2380,786,5,30,125,1.5,******,37,******,12.6,WMa
523,12104,2350,783,5,30,124,1.5,******,37,******,12.5,"MV-,WMa"
524,12107,2370,809,5,30,125,1.5,******,37,******,12.6,WMa
525,12110,2350,785,5,30,124,1.5,******,37,******,12.5,WMa
526,12113,2340,789,5,30,124,1.5,******,37,******,12.4,"ME-,MV-"
527,12116,2380,771,5,30,125,1.5,******,37,******,12.6,WMa
528,12119,2360,783,5,30,124,1.5,******,37,******,12.5,WMa
529,12122,2360,789,5,30,124,1.5,******,37,******,12.5,WMa
530,12125,2360,794,5,30,125,1.5,******,37,******,12.5,WMa
531,12128,2360,783,5,30,124,1.5,******,37,******,12.5,WMa
532,12131,2370,811,5,30,125,1.5,******,37,******,12.6,WMa
533,12134,2340,783,5,30,123,1.5,******,37,******,12.4,WMa
534,12137,2340,784,5,30,124,1.5,******,37,******,12.4,WMa
535,12140,2360,791,5,30,125,1.5,******,37,******,12.5,WMa
536,12143,2350,800,5,30,124,1.5,******,37,******,12.5,WMa
537,12146,2370,788,5,30,125,1.5,******,37,******,12.5,"MV-,WMa"
538,12149,2350,787,5,30,124,1.5,******,37,******,12.4,WMa
539,12152,2340,770,5,30,123,1.5,******,37,******,12.4,WMa
540,12155,2400,790,5,30,126,1.5,******,37,******,12.7,WMa
541,12158,2350,789,5,30,124,1.5,******,37,******,12.4,WMa
542,12161,2390,762,5,30,125,1.5,******,37,******,12.6,WMa
543,12164,2370,791,5,30,125,1.5,******,37,******,12.5,WMa
544,12167,2360,800,5,30,124,1.5,******,37,******,12.5,WMa
545,12170,2350,782,5,30,124,1.5,******,37,******,12.5,WMa
546,12173,2350,797,5,30,124,1.5,******,37,******,12.5,WMa
547,12176,2330,785,5,30,123,1.5,******,37,******,12.4,WMa
548,12179,2390,794,5,30,126,1.5,******,37,******,12.7,WMa
549,12182,2360,799,5,30,125,1.5,******,37,******,12.5,"ME-,WMa"
550,12185,2360,788,5,30,125,1.5,******,37,******,12.5,"MV-,WMa"
551,12188,2360,807,5,30,125,1.5,******,37,******,12.5,"MV-,WMa"
552,12191,2340,769,5,30,123,1.5,******,37,******,12.4,WMa
553,12194,2350,788,5,30,124,1.5,******,37,******,12.5,WMa
554,12197,2370,793,5,30,125,1.5,******,37,******,12.6,"MV-,WMa"
555,12200,2350,795,5,30,124,1.5,******,37,******,12.5,WMa
556,12203,2360,795,5,30,125,1.5,******,37,******,12.5,WMa
557,12206,2360,789,5,30,124,1.5,******,37,******,12.5,"MV-,WMa"
558,12209,2350,821,5,30,124,1.5,******,37,******,12.5,WMa
559,12212,2360,802,5,30,124,1.5,******,37,******,12.5,WMa
560,12215,2340,786,5,30,124,1.5,******,37,******,12.4,"MV-,WMa"
561,12218,2340,779,5,30,123,1.5,******,37,******,12.4,"ME-,MV-"
562,12221,2380,796,5,30,125,1.5,******,37,******,12.6,WMa
563,12224,2360,795,5,30,125,1.5,******,37,******,12.5,WMa
564,12227,2370,776,5,30,125,1.5,******,37,******,12.6,WMa
565,12230,2360,800,5,30,124,1.5,******,37,******,12.5,"MV-,WMa"
566,12233,2350,780,5,30,124,1.5,******,37,******,12.5,WMa
567,12236,2370,808,5,30,125,1.5,******,37,******,12.6,WMa
568,12239,2360,791,5,30,124,1.5,******,37,******,12.5,WMa
569,12242,2350,794,5,30,124,1.5,******,37,******,12.5,WMa
570,12245,2350,799,5,30,124,1.5,******,37,******,12.5,WMa
571,12248,2370,776,5,30,125,1.5,******,37,******,12.5,WMa
572,12251,2370,780,5,30,125,1.5,******,37,******,12.5,"MV-,WMa"
573,12254,2360,787,5,30,125,1.5,******,37,******,12.5,WMa
574,12257,2360,787,5,30,124,1.5,******,37,******,12.5,WMa
575,12260,2370,805,5,30,125,1.5,******,37,******,12.6,WMa
576,12263,2330,793,5,30,123,1.5,******,37,******,12.4,WMa
577,12266,2350,792,5,30,124,1.5,******,37,******,12.5,WMa
578,12269,2380,782,5,30,125,1.5,******,37,******,12.6,"MV-,WMa"
579,12272,2350,792,5,30,124,1.5,******,37,******,12.5,WMa
580,12275,2360,802,5,30,125,1.5,******,37,******,12.5,WMa
581,12278,2360,796,5,30,125,1.5,******,37,******,12.5,WMa
582,12281,2350,786,5,30,124,1.5,******,37,******,12.4,"MV-,WMa"
583,12284,2360,796,5,30,125,1.5,******,37,******,12.5,WMa
584,12287,2360,789,5,30,124,1.5,******,37,******,12.5,WMa
585,12290,2360,795,5,30,125,1.5,******,37,******,12.5,WMa
586,12293,2350,815,5,30,124,1.5,******,37,******,12.5,WMa
587,12296,2360,792,5,30,124,1.5,******,37,******,12.5,"MV-,WMa"
588,12299,2360,807,5,30,125,1.5,******,37,******,12.5,WMa
589,12302,2380,811,5,30,126,1.5,******,37,******,12.6,WMa
590,12305,2340,791,5,30,124,1.5,******,37,******,12.4,WMa
591,12308,2370,797,5,30,125,1.5,******,37,******,12.6,WMa
592,12311,2370,786,5,30,125,1.5,******,37,******,12.6,WMa
593,12314,2360,809,5,30,125,1.5,******,37,******,12.5,WMa
594,12317,2350,781,5,30,124,1.5,******,37,******,12.5,WMa
595,12320,2360,793,5,30,124,1.5,******,37,******,12.5,"MV-,WMa"
596,12323,2360,790,5,30,124,1.5,******,37,******,12.5,WMa
597,12326,2350,791,5,30,124,1.5,******,37,******,12.5,WMa
598,12329,2340,792,5,30,124,1.5,******,37,******,12.4,WMa
599,12332,2370,787,5,30,125,1.5,******,37,******,12.5,"ME-,WMa"
600,12335,2380,780,5,30,125,1.5,******,37,******,12.6,WMa
,,,,,,,,,,,,
Interval:,,,15,,,,,,,,,
Number of Data Points:,,,28,,,,,,,,,
,,,,,,,,,,,,
Time Setting:,,,28 Meas. Pts.,,,,,,,,,
,,,Meas. Pt. Duration 6.4285714 s,,,,,,,,,
Event Control:,,,Standard Mode,,,,,,,,,
"  Terminate test, ...",,,...if d(gamma)/dt > 1000 1/s,,,,,,,,,
"  Terminate test, ...",,,...if M > 200 mNm,,,,,,,,,
"  Terminate test, ...",,,...if FN < -50 N or > 50 N,,,,,,,,,
Measuring Profile:,,,,,,,,,,,,
  Shear Rate,,,d(gamma)/dt = 0.1 ... 50 1/s log; |Slope| = 10.003816 Pt. / dec ,,,,,,,,,
,,,,,,,,,,,,
Meas. Pts.,Time,Storage Modulus,Loss Modulus,Strain,Angular Frequency,Shear Stress,Shear Rate,Viscosity,Temperature,Speed,Torque,Status
,[s],[Pa],[Pa],[%],[rad/s],[Pa],[1/s],[Pa·s],[°C],[1/min],[µNm],[]
1,12300,******,******,48.1,******,114,0.1,1140,37,0.12,11.4,Dy_auto
2,12300,******,******,125,******,175,0.13,1390,37,0.15,17.6,Dy_auto
3,12400,******,******,221,******,217,0.16,1370,37,0.19,21.8,Dy_auto
4,12400,******,******,343,******,255,0.2,1280,37,0.24,25.6,Dy_auto
5,12400,******,******,496,******,291,0.25,1160,37,0.3,29.3,Dy_auto
6,12400,******,******,688,******,325,0.32,1030,37,0.38,32.6,Dy_auto
7,12400,******,******,931,******,366,0.4,919,37,0.48,36.8,Dy_auto
8,12400,******,******,1240,******,417,0.5,833,37,0.6,41.9,Dy_auto
9,12400,******,******,1620,******,465,0.63,737,37,0.75,46.7,Dy_auto
10,12400,******,******,2100,******,527,0.79,664,37,0.95,53,Dy_auto
11,12400,******,******,2710,******,596,1,596,37,1.19,59.9,Dy_auto
12,12400,******,******,3480,******,667,1.26,530,37,1.5,67,Dy_auto
13,12400,******,******,4440,******,740,1.58,467,37,1.89,74.4,Dy_auto
14,12400,******,******,5660,******,884,1.99,443,37,2.38,88.9,Dy_auto
15,12400,******,******,7190,******,1050,2.51,417,37,2.99,105,Dy_auto
16,12400,******,******,9110,******,1100,3.16,349,37,3.77,111,Dy_auto
17,12400,******,******,11500,******,1210,3.98,306,37,4.75,122,Dy_auto
18,12500,******,******,14600,******,1130,5,226,37,5.97,114,Dy_auto
19,12500,******,******,18400,******,1240,6.3,197,37,7.52,125,Dy_auto
20,12500,******,******,23300,******,1310,7.93,165,37,9.47,132,Dy_auto
21,12500,******,******,29300,******,1340,9.98,135,37,11.9,135,Dy_auto
22,12500,******,******,37000,******,1230,12.6,97.9,37,15,124,Dy_auto
23,12500,******,******,46600,******,1300,15.8,82.4,37,18.9,131,Dy_auto
24,12500,******,******,58800,******,1330,19.9,66.6,37,23.8,133,Dy_auto
25,12500,******,******,74100,******,1490,25.1,59.6,37,29.9,150,Dy_auto
26,12500,******,******,93300,******,1560,31.6,49.4,37,37.7,157,Dy_auto
27,12500,******,******,117000,******,1580,39.7,39.8,37,47.4,159,Dy_auto
28,12500,******,******,148000,******,1580,50,31.6,37,59.7,159,Dy_auto