File: exampledata/TXT_N3.csv
Meas. Pts.,Time,Storage Modulus,Loss Modulus,Strain,Angular Frequency,Shear Stress,Shear Rate,Viscosity,Temperature,Speed,Torque,Status
,[s],[Pa],[Pa],[%],[rad/s],[Pa],[1/s],[Pa·s],[°C],[1/min],[µNm],[]
1,5,6160,0,4.99,30,307,1.5,******,37,******,30.9,"MV-,WMa"
2,10,6160,810,5,30,310,1.5,******,37,******,31.2,
3,15,6170,823,5,30,311,1.5,******,37,******,31.3,
4,20,6160,828,5,30,311,1.5,******,37,******,31.3,
5,25,6170,820,5,30,311,1.5,******,37,******,31.3,
6,30,6200,818,5,30,313,1.5,******,37,******,31.4,
7,35,6200,826,5,30,313,1.5,******,37,******,31.4,
8,40,6190,829,5,30,312,1.5,******,37,******,31.4,
9,45,6210,824,5,30,313,1.5,******,37,******,31.5,
10,50,6230,829,5,30,314,1.5,******,37,******,31.6,
11,55,6250,849,5,30,315,1.5,******,37,******,31.7,
12,60,6240,844,5,30,315,1.5,******,37,******,31.7,
13,65,6250,850,5,30,315,1.5,******,37,******,31.7,
14,70,6260,850,5,30,316,1.5,******,37,******,31.8,
15,75,6260,839,5,30,316,1.5,******,37,******,31.8,
16,80,6290,855,5,30,317,1.5,******,37,******,31.9,
17,85,6280,852,5,30,317,1.5,******,37,******,31.9,
18,90,6310,835,5,30,318,1.5,******,37,******,32,
19,95,6320,858,5,30,319,1.5,******,37,******,32,
20,100,6310,862,5,30,319,1.5,******,37,******,32,
21,105,6340,856,5,30,320,1.5,******,37,******,32.1,
22,110,6350,866,5,30,321,1.5,******,37,******,32.2,
23,115,6350,879,5,30,321,1.5,******,37,******,32.2,
24,120,6350,882,5,30,321,1.5,******,37,******,32.2,
25,125,6360,867,5,30,321,1.5,******,37,******,32.3,
26,130,6370,886,5,30,322,1.5,******,37,******,32.3,
27,135,6370,883,5,30,322,1.5,******,37,******,32.4,
28,140,6380,882,5,30,322,1.5,******,37,******,32.4,
29,145,6390,880,5,30,323,1.5,******,37,******,32.5,
30,150,6410,884,5,30,323,1.5,******,37,******,32.5,
31,155,6410,880,5,30,323,1.5,******,37,******,32.5,
32,160,6420,905,5,30,324,1.5,******,37,******,32.6,
33,165,6410,896,5,30,324,1.5,******,37,******,32.6,
34,170,6440,886,5,30,325,1.5,******,37,******,32.7,
35,175,6450,884,5,30,325,1.5,******,37,******,32.7,
36,180,6450,894,5,30,326,1.5,******,37,******,32.7,
37,185,6460,897,5,30,326,1.5,******,37,******,32.8,
38,190,6470,917,5,30,327,1.5,******,37,******,32.8,
39,195,6480,897,5,30,327,1.5,******,37,******,32.9,
40,200,6480,922,5,30,327,1.5,******,37,******,32.9,
41,205,6480,904,5,30,327,1.5,******,37,******,32.9,
42,210,6470,905,5,30,326,1.5,******,37,******,32.8,
43,215,6500,898,5,30,328,1.5,******,37,******,33,
44,220,6480,917,5,30,327,1.5,******,37,******,32.9,
45,225,6500,906,5,30,328,1.5,******,37,******,33,
46,230,6510,900,5,30,329,1.5,******,37,******,33.1,
47,235,6520,916,5,30,329,1.5,******,37,******,33.1,
48,240,6530,902,5,30,330,1.5,******,37,******,33.1,
49,245,6540,897,5,30,330,1.5,******,37,******,33.2,
50,250,6550,908,5,30,331,1.5,******,37,******,33.2,
51,255,6560,920,5,30,331,1.5,******,37,******,33.3,
52,260,6550,927,5,30,331,1.5,******,37,******,33.2,
53,265,6560,921,5,30,331,1.5,******,37,******,33.3,
54,270,6570,911,5,30,331,1.5,******,37,******,33.3,
55,275,6570,924,5,30,332,1.5,******,37,******,33.4,
56,280,6570,926,5,30,332,1.5,******,37,******,33.4,
57,285,6590,914,5,30,333,1.5,******,37,******,33.4,
58,290,6580,930,5,30,332,1.5,******,37,******,33.4,
59,295,6580,926,5,30,332,1.5,******,37,******,33.4,
60,300,6610,929,5,30,334,1.5,******,37,******,33.5,
61,305,6610,930,5,30,333,1.5,******,37,******,33.5,
62,310,6600,920,5,30,333,1.5,******,37,******,33.5,
63,315,6620,934,5,30,334,1.5,******,37,******,33.6,
64,320,6630,923,5,30,335,1.5,******,37,******,33.7,
65,325,6650,933,5,30,336,1.5,******,37,******,33.8,
66,330,6640,930,5,30,335,1.5,******,37,******,33.7,
67,335,6640,943,5,30,335,1.5,******,37,******,33.7,
68,340,6650,937,5,30,336,1.5,******,37,******,33.8,
69,345,6660,940,5,30,336,1.5,******,37,******,33.8,
70,350,6660,928,5,30,336,1.5,******,37,******,33.8,
71,355,6670,958,5,30,337,1.5,******,37,******,33.9,
72,360,6670,942,5,30,337,1.5,******,37,******,33.9,
73,365,6690,936,5,30,338,1.5,******,37,******,34,
74,370,6690,947,5,30,338,1.5,******,37,******,34,
75,375,6690,942,5,30,338,1.5,******,37,******,34,
76,380,6690,942,5,30,338,1.5,******,37,******,34,
77,385,6710,956,5,30,339,1.5,******,37,******,34.1,
78,390,6700,953,5,30,338,1.5,******,37,******,34,
79,395,6710,948,5,30,339,1.5,******,37,******,34.1,
80,400,6720,950,5,30,339,1.5,******,37,******,34.1,
,,,,,,,,,,,,
Interval:,,,2,,,,,,,,,
Number of Data Points:,,,31,,,,,,,,,
,,,,,,,,,,,,
Time Setting:,,,31 Meas. Pts.,,,,,,,,,
Measuring Profile:,,,,,,,,,,,,
#NAME?,,,Amplitude gamma = 5 %,,,,,,,,,
,,,Angular Frequency omega = 100 ... 0.1 rad/s log; |Slope| = 10 Pt. / dec ,,,,,,,,,
,,,,,,,,,,,,
Meas. Pts.,Time,Storage Modulus,Loss Modulus,Strain,Angular Frequency,Shear Stress,Shear Rate,Viscosity,Temperature,Speed,Torque,Status
,[s],[Pa],[Pa],[%],[rad/s],[Pa],[1/s],[Pa·s],[°C],[1/min],[µNm],[]
1,410,7040,831,5,100,354,5,******,37,******,35.6,
2,418,7090,492,5,79.4,356,3.97,******,37,******,35.7,
3,425,7020,577,5,63.1,352,3.16,******,37,******,35.4,
4,432,7010,691,5,50.1,352,2.51,******,37,******,35.4,
5,439,6970,799,5,39.8,351,1.99,******,37,******,35.3,
6,448,6890,925,5,31.6,347,1.58,******,37,******,34.9,
7,458,6790,1070,5,25.1,344,1.26,******,37,******,34.6,
8,465,6670,1230,5,20,339,1,******,37,******,34.1,
9,472,6510,1430,5,15.8,333,0.79,******,37,******,33.5,
10,478,6320,1640,5,12.6,326,0.63,******,37,******,32.8,
11,486,6080,1860,5,10,318,0.5,******,37,******,31.9,
12,493,5790,2080,4.99,7.94,307,0.4,******,37,******,30.9,
13,502,5440,2310,4.99,6.31,295,0.32,******,37,******,29.6,
14,509,5040,2510,4.99,5.01,281,0.25,******,37,******,28.2,
15,517,4570,2690,4.99,3.98,265,0.2,******,37,******,26.6,
16,527,4060,2810,4.99,3.16,247,0.16,******,37,******,24.8,
17,540,3510,2880,5,2.51,227,0.13,******,37,******,22.8,
18,560,2950,2860,5,2,206,0.1,******,37,******,20.7,
19,586,2400,2770,5,1.58,183,0.08,******,37,******,18.4,
20,617,1880,2590,5.01,1.26,161,0.06,******,37,******,16.1,
21,656,1430,2360,5.01,1,138,0.05,******,37,******,13.9,
22,693,1060,2090,5,0.79,117,0.04,******,37,******,11.8,
23,739,764,1810,5.01,0.63,98.2,0.03,******,37,******,9.87,
24,797,544,1530,5.01,0.5,81.5,0.03,******,37,******,8.2,
25,869,383,1280,5.01,0.4,67.1,0.02,******,37,******,6.75,
26,929,269,1070,5.01,0.32,55,0.02,******,37,******,5.53,
27,1010,190,878,5.01,0.25,45,0.01,******,37,******,4.52,
28,1100,136,721,5.01,0.2,36.8,0.01,******,37,******,3.7,
29,1220,98.3,592,5.01,0.16,30,0.01,******,37,******,3.02,
30,1450,73,485,5.01,0.13,24.5,0.01,******,37,******,2.47,
31,1730,55.1,398,5.01,0.1,20.1,0.01,******,37,******,2.02,
,,,,,,,,,,,,
Interval:,,,3,,,,,,,,,
Number of Data Points:,,,80,,,,,,,,,
,,,,,,,,,,,,
Time Setting:,,,80 Meas. Pts.,,,,,,,,,
,,,Meas. Pt. Duration 5 s,,,,,,,,,
Event Control:,,,Standard Mode,,,,,,,,,
"  Terminate test, ...",,,...if M > 75 mNm,,,,,,,,,
Measuring Profile:,,,,,,,,,,,,
#NAME?,,,Amplitude gamma = 5 %,,,,,,,,,
,,,Angular Frequency omega = 30 rad/s,,,,,,,,,
,,,,,,,,,,,,
Meas. Pts.,Time,Storage Modulus,Loss Modulus,Strain,Angular Frequency,Shear Stress,Shear Rate,Viscosity,Temperature,Speed,Torque,Status
,[s],[Pa],[Pa],[%],[rad/s],[Pa],[1/s],[Pa·s],[°C],[1/min],[µNm],[]
1,invalid point,,,,,,,,,,,
2,1740,,,,,,,,,,,
3,1745,,,,,,,,,,,
4,1750,,,,,,,,,,,
5,1755,,,,,,,,,,,
6,1760,,,,,,,,,,,
7,1765,,,,,,,,,,,
8,1770,,,,,,,,,,,
9,1775,,,,,,,,,,,
10,1780,,,,,,,,,,,
11,1785,,,,,,,,,,,
12,1790,,,,,,,,,,,
13,1795,,,,,,,,,,,
14,1800,,,,,,,,,,,
15,1805,,,,,,,,,,,
16,1810,,,,,,,,,,,
17,1815,,,,,,,,,,,
18,1820,,,,,,,,,,,
19,1825,,,,,,,,,,,
20,1830,7830,400,5.17,30,405,1.55,******,37,******,40.7,WMa
21,1835,7840,1100,5,30,396,1.5,******,37,******,39.8,
22,1840,7830,1080,5,30,395,1.5,******,37,******,39.8,
23,1845,7850,1070,5,30,396,1.5,******,37,******,39.8,
24,1850,7840,1090,5,30,396,1.5,******,37,******,39.8,
25,1855,7850,1090,5,30,396,1.5,******,37,******,39.8,
26,1860,7830,1100,5,30,395,1.5,******,37,******,39.7,
27,1865,7870,1090,5,30,397,1.5,******,37,******,39.9,
28,1870,7850,1090,5,30,396,1.5,******,37,******,39.8,
29,1875,7850,1090,5,30,396,1.5,******,37,******,39.9,
30,1880,7850,1090,5,30,396,1.5,******,37,******,39.8,
31,1885,7860,1090,5,30,397,1.5,******,37,******,39.9,
32,1890,7860,1090,5,30,397,1.5,******,37,******,39.9,
33,1895,7840,1090,5,30,396,1.5,******,37,******,39.8,
34,1900,7860,1090,5,30,397,1.5,******,37,******,39.9,
35,1905,7840,1090,5,30,396,1.5,******,37,******,39.8,
36,1910,7850,1080,5,30,396,1.5,******,37,******,39.9,
37,1915,7860,1110,5,30,397,1.5,******,37,******,39.9,
38,1920,7860,1100,5,30,397,1.5,******,37,******,39.9,
39,1925,7870,1100,5,30,398,1.5,******,37,******,40,
40,1930,7880,1100,5,30,398,1.5,******,37,******,40,
41,1935,7860,1090,5,30,397,1.5,******,37,******,39.9,
42,1940,7870,1090,5,30,397,1.5,******,37,******,39.9,
43,1945,7870,1110,5,30,398,1.5,******,37,******,40,
44,1950,7870,1100,5,30,397,1.5,******,37,******,39.9,
45,1955,7880,1080,5,30,398,1.5,******,37,******,40,
46,1960,7880,1100,5,30,398,1.5,******,37,******,40,
47,1965,7880,1100,5,30,398,1.5,******,37,******,40,
48,1970,7880,1090,5,30,398,1.5,******,37,******,40,
49,1975,7900,1100,5,30,399,1.5,******,37,******,40.1,
50,1980,7890,1090,5,30,398,1.5,******,37,******,40,
51,1985,7890,1100,5,30,398,1.5,******,37,******,40,
52,1990,7880,1100,5,30,398,1.5,******,37,******,40,
53,1995,7880,1100,5,30,398,1.5,******,37,******,40,
54,2000,7890,1100,5,30,398,1.5,******,37,******,40.1,
55,2005,7890,1100,5,30,398,1.5,******,37,******,40,
56,2010,7900,1100,5,30,399,1.5,******,37,******,40.1,
57,2015,7900,1100,5,30,399,1.5,******,37,******,40.1,
58,2020,7890,1100,5,30,398,1.5,******,37,******,40.1,
59,2025,7900,1090,5,30,399,1.5,******,37,******,40.1,
60,2030,7910,1090,5,30,399,1.5,******,37,******,40.1,
61,2035,7900,1100,5,30,399,1.5,******,37,******,40.1,
62,2040,7920,1100,5,30,400,1.5,******,37,******,40.2,
63,2045,7930,1090,5,30,400,1.5,******,37,******,40.2,
64,2050,7930,1100,5,30,400,1.5,******,37,******,40.2,
65,2055,7920,1110,5,30,400,1.5,******,37,******,40.2,
66,2060,7920,1090,5,30,400,1.5,******,37,******,40.2,
67,2065,7910,1100,5,30,399,1.5,******,37,******,40.1,
68,2070,7910,1110,5,30,400,1.5,******,37,******,40.2,
69,2075,7920,1100,5,30,400,1.5,******,37,******,40.2,
70,2080,7920,1100,5,30,400,1.5,******,37,******,40.2,
71,2085,7920,1090,5,30,400,1.5,******,37,******,40.2,
72,2090,7910,1100,5,30,399,1.5,******,37,******,40.2,
73,2095,7920,1090,5,30,400,1.5,******,37,******,40.2,
74,2100,7930,1090,5,30,400,1.5,******,37,******,40.2,
75,2105,7930,1100,5,30,400,1.5,******,37,******,40.2,
76,2110,7940,1090,5,30,401,1.5,******,37,******,40.3,
77,2115,7920,1110,5,30,400,1.5,******,37,******,40.2,
78,2120,7930,1100,5,30,401,1.5,******,37,******,40.3,
79,2125,7940,1100,5,30,401,1.5,******,37,******,40.3,
80,2130,7930,1100,5,30,401,1.5,******,37,******,40.3,
,,,,,,,,,,,,
Interval:,,,4,,,,,,,,,
Number of Data Points:,,,113,,,,,,,,,
,,,,,,,,,,,,
Time Setting:,,,113 Meas. Pts.,,,,,,,,,
,,,Meas. Pt. Duration 5 s,,,,,,,,,
Measuring Profile:,,,,,,,,,,,,
#NAME?,,,Amplitude gamma = 0.1 ... 500 % log; |Slope| = 30.278699 Pt. / dec ,,,,,,,,,
,,,Angular Frequency omega = 30 rad/s,,,,,,,,,
,,,,,,,,,,,,
Meas. Pts.,Time,Storage Modulus,Loss Modulus,Strain,Angular Frequency,Shear Stress,Shear Rate,Viscosity,Temperature,Speed,Torque,Status
,[s],[Pa],[Pa],[%],[rad/s],[Pa],[1/s],[Pa·s],[°C],[1/min],[µNm],[]
1,2135,4410,14100,0.1,30,14.8,0.03,******,37,******,1.49,"WMa,taD"
2,2140,5510,1400,0.11,30,6.14,0.03,******,37,******,0.62,
3,2145,12300,34800,0.12,30,43.3,0.04,******,37,******,4.36,WMa
4,2150,0,18000,0.13,30,22.7,0.04,******,37,******,2.28,"MV-,WMa"
5,2155,27300,0,0.13,30,36.7,0.04,******,37,******,3.69,"ME-,WMa"
6,2160,10800,3000,0.15,30,16.9,0.05,******,37,******,1.7,WMa
7,2165,6960,6100,0.16,30,14.8,0.05,******,37,******,1.48,WMa
8,2170,13900,0,0.17,30,23.9,0.05,******,37,******,2.4,"MV-,WMa"
9,2175,10700,0,0.19,30,20.1,0.06,******,37,******,2.02,"MV-,WMa"
10,2180,16700,8320,0.2,30,37.3,0.06,******,37,******,3.75,WMa
11,2185,0,7420,0.22,30,16.1,0.07,******,37,******,1.62,"MV-,WMa"
12,2190,6150,1160,0.23,30,14.4,0.07,******,37,******,1.45,
13,2195,13200,0,0.25,30,33.2,0.08,******,37,******,3.34,"ME-,WMa"
14,2200,0,2440,0.27,30,6.7,0.08,******,37,******,0.67,"MV-,WMa"
15,2205,6420,1120,0.29,30,18.9,0.09,******,37,******,1.9,
16,2210,6880,0,0.32,30,21.7,0.09,******,37,******,2.18,"MV-,WMa"
17,2215,11800,0,0.34,30,40.2,0.1,******,37,******,4.04,"MV-,WMa"
18,2220,20200,13000,0.37,30,88.8,0.11,******,37,******,8.92,WMa
19,2225,0,7840,0.4,30,31.3,0.12,******,37,******,3.14,"MV-,WMa"
20,2230,7160,921,0.43,30,30.7,0.13,******,37,******,3.09,
21,2235,6410,1150,0.46,30,30.1,0.14,******,37,******,3.03,WMa
22,2240,1130,4070,0.5,30,21.1,0.15,******,37,******,2.12,"ME-,MV-"
23,2245,7690,986,0.53,30,41.4,0.16,******,37,******,4.16,
24,2250,14700,0,0.58,30,85.2,0.17,******,37,******,8.57,"MV-,WMa"
25,2255,6750,1370,0.63,30,43.1,0.19,******,37,******,4.33,WMa
26,2260,6650,6.58,0.67,30,44.8,0.2,******,37,******,4.5,WMa
27,2265,7750,0,0.73,30,56.5,0.22,******,37,******,5.69,"MV-,WMa"
28,2270,7570,1610,0.78,30,60.5,0.24,******,37,******,6.09,WMa
29,2275,6190,1310,0.84,30,53.3,0.25,******,37,******,5.36,WMa
30,2280,11000,3690,0.91,30,105,0.27,******,37,******,10.6,WMa
31,2285,8290,3810,0.98,30,89.5,0.29,******,37,******,9,WMa
32,2290,10900,0,1.06,30,115,0.32,******,37,******,11.6,"MV-,WMa"
33,2295,7670,1170,1.14,30,88.7,0.34,******,37,******,8.92,WMa
34,2300,5180,0,1.23,30,63.9,0.37,******,37,******,6.42,"MV-,WMa"
35,2305,8080,0,1.33,30,107,0.4,******,37,******,10.8,"MV-,WMa"
36,2310,7690,1230,1.44,30,112,0.43,******,37,******,11.2,WMa
37,2315,7380,1180,1.55,30,116,0.46,******,37,******,11.6,WMa
38,2320,8020,1060,1.67,30,135,0.5,******,37,******,13.6,WMa
39,2325,8230,0,1.8,30,148,0.54,******,37,******,14.9,"MV-,WMa"
40,2330,7330,1770,1.95,30,147,0.58,******,37,******,14.8,WMa
41,2335,8150,1150,2.1,30,173,0.63,******,37,******,17.4,WMa
42,2340,8290,1500,2.26,30,191,0.68,******,37,******,19.2,WMa
43,2345,7930,1980,2.44,30,200,0.73,******,37,******,20.1,WMa
44,2350,8530,665,2.64,30,226,0.79,******,37,******,22.7,WMa
45,2355,6910,1070,2.85,30,199,0.85,******,37,******,20,WMa
46,2360,7900,1070,3.07,30,245,0.92,******,37,******,24.6,WMa
47,2365,7930,1840,3.31,30,270,0.99,******,37,******,27.1,WMa
48,2370,7020,1890,3.57,30,260,1.07,******,37,******,26.1,WMa
49,2375,9160,1220,3.86,30,356,1.16,******,37,******,35.8,WMa
50,2380,7660,766,4.16,30,320,1.25,******,37,******,32.2,WMa
51,2385,8000,1050,4.49,30,362,1.35,******,37,******,36.4,WMa
52,2390,7800,1280,4.85,30,383,1.45,******,37,******,38.5,WMa
53,2395,8420,1170,5.23,30,444,1.57,******,37,******,44.7,WMa
54,2400,9060,2620,5.64,30,532,1.69,******,37,******,53.5,WMa
55,2405,7980,1140,6.09,30,491,1.83,******,37,******,49.3,WMa
56,2410,6910,1740,6.57,30,468,1.97,******,37,******,47.1,WMa
57,2415,8490,1200,7.09,30,608,2.13,******,37,******,61.1,WMa
58,2420,8170,1460,7.65,30,635,2.29,******,37,******,63.8,WMa
59,2425,7880,1230,8.25,30,658,2.48,******,37,******,66.1,WMa
60,2430,7640,1270,8.9,30,689,2.67,******,37,******,69.3,WMa
61,2435,7390,994,9.61,30,716,2.88,******,37,******,72,WMa
62,2440,8080,1330,10.4,30,849,3.11,******,37,******,85.3,WMa
63,2445,7950,1140,11.2,30,898,3.36,******,37,******,90.3,WMa
64,2450,8100,1020,12.1,30,985,3.62,******,37,******,99.1,WMa
65,2455,8230,1190,13,30,1080,3.91,******,37,******,109,WMa
66,2460,8080,1350,14.1,30,1150,4.22,******,37,******,116,WMa
67,2465,7910,1250,15.2,30,1210,4.55,******,37,******,122,WMa
68,2470,8220,940,16.4,30,1350,4.91,******,37,******,136,WMa
69,2475,7620,1020,17.7,30,1360,5.3,******,37,******,136,WMa
70,2480,7910,1080,19,30,1520,5.71,******,37,******,153,WMa
71,2485,7900,1130,20.6,30,1640,6.17,******,37,******,165,WMa
72,2490,7560,1240,22.2,30,1700,6.65,******,37,******,171,WMa
73,2495,7250,867,23.9,30,1750,7.18,******,37,******,176,WMa
74,2500,7980,1320,25.8,30,2090,7.74,******,37,******,210,WMa
75,2505,7900,1040,27.9,30,2220,8.36,******,37,******,223,WMa
76,2510,8270,927,30.1,30,2500,9.02,******,37,******,251,WMa
77,2515,7940,1130,32.4,30,2600,9.73,******,37,******,262,WMa
78,2520,7780,878,35,30,2740,10.5,******,37,******,275,WMa
79,2525,7760,1210,37.8,30,2960,11.3,******,37,******,298,WMa
80,2530,8000,1030,40.7,30,3290,12.2,******,37,******,330,WMa
81,2535,8040,1220,44,30,3570,13.2,******,37,******,359,WMa
82,2540,7780,1270,47.4,30,3740,14.2,******,37,******,376,WMa
83,2545,7630,1290,51.2,30,3960,15.4,******,37,******,398,WMa
84,2550,7130,1300,55.2,30,4000,16.6,******,37,******,402,WMa
85,2555,7280,1400,59.5,30,4410,17.9,******,37,******,444,WMa
86,2560,7050,1420,64.3,30,4620,19.3,******,37,******,464,WMa
87,2565,6580,1960,69.3,30,4760,20.8,******,37,******,479,WMa
88,2570,6690,1710,74.8,30,5160,22.4,******,37,******,519,WMa
89,2575,5800,1630,80.7,30,4860,24.2,******,37,******,488,WMa
90,2580,5060,1670,87,30,4640,26.1,******,37,******,466,WMa
91,2585,3880,1560,93.8,30,3920,28.1,******,37,******,394,WMa
92,2590,2580,1340,101,30,2940,30.4,******,37,******,296,WMa
93,2595,1850,1080,109,30,2340,32.8,******,37,******,235,
94,2600,1280,922,118,30,1860,35.4,******,37,******,187,
95,2605,892,781,127,30,1510,38.2,******,37,******,152,
96,2610,661,678,137,30,1300,41.2,******,37,******,131,
97,2615,484,567,148,30,1100,44.4,******,37,******,111,
98,2620,313,409,160,30,823,48,******,37,******,82.8,
99,2625,220,369,172,30,741,51.7,******,37,******,74.5,
100,2630,153,359,186,30,726,55.8,******,37,******,73,
101,2635,39.6,232,201,30,472,60.2,******,37,******,47.5,
102,2640,0,193,217,30,418,65,******,37,******,42,"ME-,taD"
103,2645,0,172,234,30,401,70.1,******,37,******,40.3,"ME-,taD"
104,2650,0,161,252,30,407,75.7,******,37,******,40.9,"ME-,taD"
105,2655,0,163,272,30,444,81.6,******,37,******,44.7,"ME-,taD"
106,2660,0,147,294,30,432,88.1,******,37,******,43.4,"ME-,taD"
107,2665,0,136,317,30,431,95,******,37,******,43.3,"ME-,taD"
108,2670,0,118,342,30,403,103,******,37,******,40.5,"ME-,taD"
109,2675,0,106,369,30,391,111,******,37,******,39.3,"ME-,taD"
110,2680,0,93.8,398,30,373,119,******,37,******,37.5,"ME-,taD"
111,2685,0,97.1,429,30,417,129,******,37,******,41.9,"ME-,taD"
112,2690,0,93.8,463,30,435,139,******,37,******,43.7,"ME-,taD"
113,2695,0,104,500,30,520,150,******,37,******,52.3,"ME-,taD"
,,,,,,,,,,,,
Interval:,,,5,,,,,,,,,
Number of Data Points:,,,80,,,,,,,,,
,,,,,,,,,,,,
Time Setting:,,,80 Meas. Pts.,,,,,,,,,
,,,Meas. Pt. Duration 5 s,,,,,,,,,
Event Control:,,,Standard Mode,,,,,,,,,
"  Terminate test, ...",,,...if M > 75 mNm,,,,,,,,,
Measuring Profile:,,,,,,,,,,,,
#NAME?,,,Amplitude gamma = 5 %,,,,,,,,,
,,,Angular Frequency omega = 30 rad/s,,,,,,,,,
,,,,,,,,,,,,
Meas. Pts.,Time,Storage Modulus,Loss Modulus,Strain,Angular Frequency,Shear Stress,Shear Rate,Viscosity,Temperature,Speed,Torque,Status
,[s],[Pa],[Pa],[%],[rad/s],[Pa],[1/s],[Pa·s],[°C],[1/min],[µNm],[]
1,2700,0,469,4.94,30,23.2,1.48,******,37,******,2.33,"ME-,WMa"
2,2705,246,77.8,5,30,12.9,1.5,******,37,******,1.3,
3,2710,809,151,5.01,30,41.2,1.5,******,37,******,4.14,
4,2715,1130,201,5,30,57.5,1.5,******,37,******,5.78,
5,2720,1370,232,5,30,69.7,1.5,******,37,******,7.01,
6,2725,1560,256,5,30,79.2,1.5,******,37,******,7.96,
7,2730,1770,283,5,30,89.7,1.5,******,37,******,9.02,
8,2735,1900,305,5,30,96.5,1.5,******,37,******,9.7,
9,2740,2010,323,5,30,102,1.5,******,37,******,10.2,
10,2745,2110,333,5,30,107,1.5,******,37,******,10.8,
11,2750,2210,345,5,30,112,1.5,******,37,******,11.3,
12,2755,2390,373,5,30,121,1.5,******,37,******,12.2,
13,2760,2530,390,5,30,128,1.5,******,37,******,12.9,
14,2765,2640,399,5,30,134,1.5,******,37,******,13.4,
15,2770,2750,399,5,30,139,1.5,******,37,******,14,
16,2775,2850,434,5,30,144,1.5,******,37,******,14.5,
17,2780,2970,447,5,30,150,1.5,******,37,******,15.1,
18,2785,3100,468,5,30,157,1.5,******,37,******,15.8,
19,2790,3210,473,5,30,162,1.5,******,37,******,16.3,
20,2795,3310,495,5,30,167,1.5,******,37,******,16.8,
21,2800,3450,510,5,30,174,1.5,******,37,******,17.5,
22,2805,3560,533,5,30,180,1.5,******,37,******,18.1,
23,2810,3640,537,5,30,184,1.5,******,37,******,18.5,
24,2815,3730,546,5,30,189,1.5,******,37,******,19,
25,2820,3800,565,5,30,192,1.5,******,37,******,19.3,
26,2825,3920,590,5,30,198,1.5,******,37,******,19.9,
27,2830,4020,584,5,30,203,1.5,******,37,******,20.4,
28,2835,4090,597,5,30,207,1.5,******,37,******,20.8,
29,2840,4170,619,5,30,211,1.5,******,37,******,21.2,
30,2845,4270,624,5,30,216,1.5,******,37,******,21.7,
31,2850,4340,633,5,30,219,1.5,******,37,******,22,
32,2855,4410,652,5,30,223,1.5,******,37,******,22.4,
33,2860,4490,642,5,30,227,1.5,******,37,******,22.8,
34,2865,4560,661,5,30,230,1.5,******,37,******,23.1,
35,2870,4650,663,5,30,235,1.5,******,37,******,23.6,
36,2875,4750,691,5,30,240,1.5,******,37,******,24.1,
37,2880,4820,698,5,30,244,1.5,******,37,******,24.5,
38,2885,4910,716,5,30,248,1.5,******,37,******,24.9,
39,2890,5010,718,5,30,253,1.5,******,37,******,25.4,
40,2895,5090,734,5,30,257,1.5,******,37,******,25.9,
41,2900,5170,748,5,30,261,1.5,******,37,******,26.3,
42,2905,5260,750,5,30,266,1.5,******,37,******,26.7,
43,2910,5320,760,5,30,269,1.5,******,37,******,27,
44,2915,5410,770,5,30,273,1.5,******,37,******,27.5,
45,2920,5490,797,5,30,278,1.5,******,37,******,27.9,
46,2925,5540,790,5,30,280,1.5,******,37,******,28.1,
47,2930,5610,808,5,30,283,1.5,******,37,******,28.5,
48,2935,5680,801,5,30,287,1.5,******,37,******,28.8,
49,2940,5740,825,5,30,290,1.5,******,37,******,29.2,
50,2945,5780,828,5,30,292,1.5,******,37,******,29.3,
51,2950,5830,824,5,30,295,1.5,******,37,******,29.6,
52,2955,5890,835,5,30,298,1.5,******,37,******,29.9,
53,2960,5950,843,5,30,301,1.5,******,37,******,30.2,
54,2965,6020,863,5,30,304,1.5,******,37,******,30.6,
55,2970,6050,861,5,30,306,1.5,******,37,******,30.7,
56,2975,6100,868,5,30,308,1.5,******,37,******,31,
57,2980,6160,867,5,30,311,1.5,******,37,******,31.3,
58,2985,6200,876,5,30,313,1.5,******,37,******,31.5,
59,2990,6240,884,5,30,315,1.5,******,37,******,31.7,
60,2995,6280,886,5,30,317,1.5,******,37,******,31.9,
61,3000,6320,889,5,30,319,1.5,******,37,******,32.1,
62,3005,6360,883,5,30,321,1.5,******,37,******,32.3,
63,3010,6400,895,5,30,323,1.5,******,37,******,32.5,
64,3015,6430,908,5,30,325,1.5,******,37,******,32.7,
65,3020,6450,914,5,30,326,1.5,******,37,******,32.7,
66,3025,6500,893,5,30,328,1.5,******,37,******,33,
67,3030,6560,922,5,30,331,1.5,******,37,******,33.3,
68,3035,6580,922,5,30,332,1.5,******,37,******,33.4,
69,3040,6620,922,5,30,334,1.5,******,37,******,33.6,
70,3045,6650,931,5,30,336,1.5,******,37,******,33.7,
71,3050,6680,942,5,30,337,1.5,******,37,******,33.9,
72,3055,6720,938,5,30,339,1.5,******,37,******,34.1,
73,3060,6750,949,5,30,341,1.5,******,37,******,34.3,
74,3065,6770,960,5,30,342,1.5,******,37,******,34.4,
75,3070,6790,951,5,30,343,1.5,******,37,******,34.5,
76,3075,6820,961,5,30,344,1.5,******,37,******,34.6,
77,3080,6850,967,5,30,346,1.5,******,37,******,34.8,
78,3085,6870,965,5,30,347,1.5,******,37,******,34.9,
79,3090,6920,973,5,30,349,1.5,******,37,******,35.1,
80,3095,6930,986,5,30,350,1.5,******,37,******,35.2,
,,,,,,,,,,,,
Interval:,,,6,,,,,,,,,
Number of Data Points:,,,600,,,,,,,,,
,,,,,,,,,,,,
Time Setting:,,,600 Meas. Pts.,,,,,,,,,
,,,Meas. Pt. Duration 3 s,,,,,,,,,
Event Control:,,,Standard Mode,,,,,,,,,
"  Terminate test, ...",,,...if M > 200 mNm,,,,,,,,,
Measuring Profile:,,,,,,,,,,,,
#NAME?,,,Amplitude gamma = 5 %,,,,,,,,,
,,,Angular Frequency omega = 30 rad/s,,,,,,,,,
,,,,,,,,,,,,
Meas. Pts.,Time,Storage Modulus,Loss Modulus,Strain,Angular Frequency,Shear Stress,Shear Rate,Viscosity,Temperature,Speed,Torque,Status
,[s],[Pa],[Pa],[%],[rad/s],[Pa],[1/s],[Pa·s],[°C],[1/min],[µNm],[]
1,3098,6910,951,5.08,30,354,1.52,******,37,******,35.6,WMa
2,3101,6950,984,5,30,351,1.5,******,37,******,35.3,WMa
3,3104,6960,990,5,30,352,1.5,******,37,******,35.4,
4,3107,6980,977,5,30,352,1.5,******,37,******,35.4,
5,3110,7010,986,5,30,354,1.5,******,37,******,35.6,
6,3113,7010,993,5,30,354,1.5,******,37,******,35.6,
7,3116,7030,990,5,30,355,1.5,******,37,******,35.7,
8,3119,7020,1000,5,30,354,1.5,******,37,******,35.6,
9,3122,7040,998,5,30,356,1.5,******,37,******,35.8,
10,3125,7060,988,5,30,357,1.5,******,37,******,35.8,
11,3128,7070,967,5,30,357,1.5,******,37,******,35.9,
12,3131,7090,1010,5,30,358,1.5,******,37,******,36,
13,3134,7100,994,5,30,359,1.5,******,37,******,36.1,
14,3137,7130,1000,5,30,360,1.5,******,37,******,36.2,
15,3140,7110,1010,5,30,359,1.5,******,37,******,36.1,
16,3143,7140,1000,5,30,361,1.5,******,37,******,36.3,
17,3146,7150,1030,5,30,361,1.5,******,37,******,36.3,
18,3149,7160,1010,5,30,362,1.5,******,37,******,36.4,
19,3152,7170,1000,5,30,362,1.5,******,37,******,36.4,
20,3155,7190,1000,5,30,363,1.5,******,37,******,36.5,
21,3158,7180,992,5,30,363,1.5,******,37,******,36.4,
22,3161,7190,1020,5,30,363,1.5,******,37,******,36.5,
23,3164,7210,1010,5,30,364,1.5,******,37,******,36.6,
24,3167,7230,1020,5,30,365,1.5,******,37,******,36.7,
25,3170,7210,1030,5,30,364,1.5,******,37,******,36.6,
26,3173,7250,1040,5,30,366,1.5,******,37,******,36.8,
27,3176,7260,1030,5,30,367,1.5,******,37,******,36.9,
28,3179,7270,1010,5,30,367,1.5,******,37,******,36.9,
29,3182,7290,1030,5,30,368,1.5,******,37,******,37,
30,3185,7300,1020,5,30,369,1.5,******,37,******,37.1,
31,3188,7300,1030,5,30,369,1.5,******,37,******,37.1,
32,3191,7300,1030,5,30,369,1.5,******,37,******,37.1,
33,3194,7320,1040,5,30,370,1.5,******,37,******,37.2,
34,3197,7330,1030,5,30,370,1.5,******,37,******,37.2,
35,3200,7330,1020,5,30,370,1.5,******,37,******,37.2,
36,3203,7350,1030,5,30,371,1.5,******,37,******,37.3,
37,3206,7360,1040,5,30,372,1.5,******,37,******,37.4,
38,3209,7360,1020,5,30,372,1.5,******,37,******,37.4,
39,3212,7350,1040,5,30,371,1.5,******,37,******,37.3,
40,3215,7410,1050,5,30,374,1.5,******,37,******,37.6,
41,3218,7420,1050,5,30,375,1.5,******,37,******,37.7,
42,3221,7390,1040,5,30,373,1.5,******,37,******,37.5,
43,3224,7400,1050,5,30,374,1.5,******,37,******,37.6,
44,3227,7390,1060,5,30,373,1.5,******,37,******,37.5,
45,3230,7420,1040,5,30,375,1.5,******,37,******,37.7,
46,3233,7420,1040,5,30,375,1.5,******,37,******,37.7,
47,3236,7440,1050,5,30,375,1.5,******,37,******,37.8,
48,3239,7450,1050,5,30,376,1.5,******,37,******,37.8,
49,3242,7450,1050,5,30,376,1.5,******,37,******,37.8,
50,3245,7460,1060,5,30,377,1.5,******,37,******,37.9,
51,3248,7450,1050,5,30,376,1.5,******,37,******,37.8,
52,3251,7460,1050,5,30,377,1.5,******,37,******,37.9,
53,3254,7470,1050,5,30,377,1.5,******,37,******,37.9,
54,3257,7480,1060,5,30,378,1.5,******,37,******,38,
55,3260,7490,1060,5,30,378,1.5,******,37,******,38,
56,3263,7480,1060,5,30,378,1.5,******,37,******,38,
57,3266,7490,1050,5,30,378,1.5,******,37,******,38,
58,3269,7510,1060,5,30,379,1.5,******,37,******,38.1,
59,3272,7520,1060,5,30,379,1.5,******,37,******,38.2,
60,3275,7530,1060,5,30,380,1.5,******,37,******,38.2,
61,3278,7530,1070,5,30,380,1.5,******,37,******,38.2,
62,3281,7540,1040,5,30,380,1.5,******,37,******,38.3,
63,3284,7520,1070,5,30,380,1.5,******,37,******,38.2,
64,3287,7530,1090,5,30,381,1.5,******,37,******,38.3,
65,3290,7560,1060,5,30,382,1.5,******,37,******,38.4,
66,3293,7530,1050,5,30,380,1.5,******,37,******,38.2,
67,3296,7560,1070,5,30,382,1.5,******,37,******,38.4,
68,3299,7570,1070,5,30,382,1.5,******,37,******,38.4,
69,3302,7560,1050,5,30,382,1.5,******,37,******,38.4,
70,3305,7550,1070,5,30,381,1.5,******,37,******,38.3,
71,3308,7570,1070,5,30,382,1.5,******,37,******,38.4,
72,3311,7580,1050,5,30,383,1.5,******,37,******,38.5,
73,3314,7560,1060,5,30,381,1.5,******,37,******,38.4,
74,3317,7590,1090,5,30,383,1.5,******,37,******,38.5,
75,3320,7600,1080,5,30,384,1.5,******,37,******,38.6,
76,3323,7580,1060,5,30,383,1.5,******,37,******,38.5,
77,3326,7570,1060,5,30,382,1.5,******,37,******,38.4,
78,3329,7600,1090,5,30,384,1.5,******,37,******,38.6,
79,3332,7600,1080,5,30,384,1.5,******,37,******,38.6,
80,3335,7610,1070,5,30,384,1.5,******,37,******,38.7,
81,3338,7620,1060,5,30,385,1.5,******,37,******,38.7,
82,3341,7660,1080,5,30,387,1.5,******,37,******,38.9,
83,3344,7630,1090,5,30,385,1.5,******,37,******,38.7,
84,3347,7620,1070,5,30,385,1.5,******,37,******,38.7,
85,3350,7640,1080,5,30,386,1.5,******,37,******,38.8,
86,3353,7650,1060,5,30,386,1.5,******,37,******,38.8,
87,3356,7650,1070,5,30,386,1.5,******,37,******,38.8,
88,3359,7630,1080,5,30,385,1.5,******,37,******,38.7,
89,3362,7650,1070,5,30,386,1.5,******,37,******,38.8,
90,3365,7650,1100,5,30,386,1.5,******,37,******,38.8,
91,3368,7640,1080,5,30,386,1.5,******,37,******,38.8,
92,3371,7670,1120,5,30,388,1.5,******,37,******,39,
93,3374,7660,1070,5,30,387,1.5,******,37,******,38.9,
94,3377,7660,1080,5,30,387,1.5,******,37,******,38.9,
95,3380,7670,1090,5,30,387,1.5,******,37,******,38.9,
96,3383,7680,1070,5,30,388,1.5,******,37,******,39,
97,3386,7670,1080,5,30,387,1.5,******,37,******,39,
98,3389,7660,1110,5,30,387,1.5,******,37,******,38.9,
99,3392,7690,1080,5,30,388,1.5,******,37,******,39,
100,3395,7700,1100,5,30,389,1.5,******,37,******,39.1,
101,3398,7700,1100,5,30,389,1.5,******,37,******,39.1,
102,3401,7700,1080,5,30,389,1.5,******,37,******,39.1,
103,3404,7730,1090,5,30,390,1.5,******,37,******,39.3,
104,3407,7690,1080,5,30,388,1.5,******,37,******,39.1,
105,3410,7690,1070,5,30,388,1.5,******,37,******,39,
106,3413,7700,1090,5,30,389,1.5,******,37,******,39.1,
107,3416,7710,1100,5,30,389,1.5,******,37,******,39.1,
108,3419,7700,1080,5,30,389,1.5,******,37,******,39.1,
109,3422,7710,1090,5,30,389,1.5,******,37,******,39.2,
110,3425,7730,1100,5,30,390,1.5,******,37,******,39.3,
111,3428,7720,1080,5,30,390,1.5,******,37,******,39.2,
112,3431,7710,1090,5,30,389,1.5,******,37,******,39.2,
113,3434,7750,1090,5,30,391,1.5,******,37,******,39.3,
114,3437,7740,1080,5,30,391,1.5,******,37,******,39.3,
115,3440,7730,1100,5,30,390,1.5,******,37,******,39.3,
116,3443,7730,1060,5,30,390,1.5,******,37,******,39.2,
117,3446,7740,1080,5,30,391,1.5,******,37,******,39.3,
118,3449,7750,1090,5,30,391,1.5,******,37,******,39.4,
119,3452,7750,1080,5,30,391,1.5,******,37,******,39.3,
120,3455,7740,1080,5,30,391,1.5,******,37,******,39.3,
121,3458,7750,1090,5,30,391,1.5,******,37,******,39.3,
122,3461,7730,1080,5,30,390,1.5,******,37,******,39.2,
123,3464,7790,1090,5,30,394,1.5,******,37,******,39.6,
124,3467,7770,1080,5,30,392,1.5,******,37,******,39.4,
125,3470,7760,1090,5,30,392,1.5,******,37,******,39.4,
126,3473,7770,1080,5,30,393,1.5,******,37,******,39.5,
127,3476,7790,1120,5,30,393,1.5,******,37,******,39.5,
128,3479,7760,1060,5,30,392,1.5,******,37,******,39.4,
129,3482,7760,1110,5,30,392,1.5,******,37,******,39.4,
130,3485,7770,1090,5,30,392,1.5,******,37,******,39.5,
131,3488,7790,1090,5,30,393,1.5,******,37,******,39.6,
132,3491,7780,1100,5,30,393,1.5,******,37,******,39.5,
133,3494,7780,1110,5,30,393,1.5,******,37,******,39.5,
134,3497,7790,1090,5,30,393,1.5,******,37,******,39.5,
135,3500,7800,1110,5,30,394,1.5,******,37,******,39.6,
136,3503,7800,1080,5,30,394,1.5,******,37,******,39.6,
137,3506,7810,1110,5,30,395,1.5,******,37,******,39.7,
138,3509,7800,1090,5,30,394,1.5,******,37,******,39.6,
139,3512,7810,1090,5,30,395,1.5,******,37,******,39.7,
140,3515,7790,1090,5,30,393,1.5,******,37,******,39.5,
141,3518,7830,1090,5,30,396,1.5,******,37,******,39.8,
142,3521,7820,1090,5,30,395,1.5,******,37,******,39.7,
143,3524,7820,1100,5,30,395,1.5,******,37,******,39.7,
144,3527,7820,1100,5,30,395,1.5,******,37,******,39.7,
145,3530,7820,1070,5,30,395,1.5,******,37,******,39.7,
146,3533,7840,1110,5,30,396,1.5,******,37,******,39.8,
147,3536,7830,1100,5,30,396,1.5,******,37,******,39.8,
148,3539,7850,1110,5,30,396,1.5,******,37,******,39.9,
149,3542,7830,1100,5,30,396,1.5,******,37,******,39.8,
150,3545,7830,1110,5,30,395,1.5,******,37,******,39.7,
151,3548,7840,1110,5,30,396,1.5,******,37,******,39.8,
152,3551,7850,1090,5,30,396,1.5,******,37,******,39.8,
153,3554,7860,1060,5,30,397,1.5,******,37,******,39.9,
154,3557,7850,1090,5,30,396,1.5,******,37,******,39.8,
155,3560,7840,1100,5,30,396,1.5,******,37,******,39.8,
156,3563,7850,1090,5,30,397,1.5,******,37,******,39.9,
157,3566,7850,1110,5,30,397,1.5,******,37,******,39.9,
158,3569,7860,1110,5,30,397,1.5,******,37,******,39.9,
159,3572,7860,1100,5,30,397,1.5,******,37,******,39.9,
160,3575,7860,1100,5,30,397,1.5,******,37,******,39.9,
161,3578,7850,1120,5,30,397,1.5,******,37,******,39.9,
162,3581,7880,1100,5,30,398,1.5,******,37,******,40,
163,3584,7870,1100,5,30,397,1.5,******,37,******,39.9,
164,3587,7860,1110,5,30,397,1.5,******,37,******,39.9,
165,3590,7890,1100,5,30,398,1.5,******,37,******,40,
166,3593,7860,1090,5,30,397,1.5,******,37,******,39.9,
167,3596,7870,1120,5,30,397,1.5,******,37,******,39.9,
168,3599,7880,1110,5,30,398,1.5,******,37,******,40,
169,3602,7880,1100,5,30,398,1.5,******,37,******,40,
170,3605,7900,1080,5,30,399,1.5,******,37,******,40.1,
171,3608,7890,1110,5,30,398,1.5,******,37,******,40.1,
172,3611,7880,1100,5,30,398,1.5,******,37,******,40,
173,3614,7890,1100,5,30,398,1.5,******,37,******,40.1,
174,3617,7890,1110,5,30,398,1.5,******,37,******,40.1,
175,3620,7900,1110,5,30,399,1.5,******,37,******,40.1,
176,3623,7930,1100,5,30,400,1.5,******,37,******,40.2,
177,3626,7900,1100,5,30,399,1.5,******,37,******,40.1,
178,3629,7900,1100,5,30,399,1.5,******,37,******,40.1,
179,3632,7900,1120,5,30,399,1.5,******,37,******,40.1,
180,3635,7900,1100,5,30,399,1.5,******,37,******,40.1,
181,3638,7910,1110,5,30,399,1.5,******,37,******,40.1,
182,3641,7910,1120,5,30,400,1.5,******,37,******,40.2,
183,3644,7920,1100,5,30,400,1.5,******,37,******,40.2,
184,3647,7920,1110,5,30,400,1.5,******,37,******,40.2,
185,3650,7920,1100,5,30,400,1.5,******,37,******,40.2,
186,3653,7920,1110,5,30,400,1.5,******,37,******,40.2,
187,3656,7920,1110,5,30,400,1.5,******,37,******,40.2,
188,3659,7920,1110,5,30,400,1.5,******,37,******,40.2,
189,3662,7920,1100,5,30,400,1.5,******,37,******,40.2,
190,3665,7910,1120,5,30,399,1.5,******,37,******,40.2,
191,3668,7930,1110,5,30,400,1.5,******,37,******,40.2,
192,3671,7940,1120,5,30,401,1.5,******,37,******,40.3,
193,3674,7930,1110,5,30,400,1.5,******,37,******,40.2,
194,3677,7940,1110,5,30,401,1.5,******,37,******,40.3,
195,3680,7940,1110,5,30,401,1.5,******,37,******,40.3,
196,3683,7950,1110,5,30,401,1.5,******,37,******,40.4,
197,3686,7940,1140,5,30,401,1.5,******,37,******,40.3,
198,3689,7910,1110,5,30,399,1.5,******,37,******,40.2,
199,3692,7930,1100,5,30,400,1.5,******,37,******,40.3,
200,3695,7950,1120,5,30,402,1.5,******,37,******,40.4,
201,3698,7930,1100,5,30,400,1.5,******,37,******,40.2,
202,3701,7960,1120,5,30,402,1.5,******,37,******,40.4,
203,3704,7950,1120,5,30,402,1.5,******,37,******,40.4,
204,3707,7980,1110,5,30,403,1.5,******,37,******,40.5,
205,3710,7950,1130,5,30,401,1.5,******,37,******,40.3,
206,3713,7960,1120,5,30,402,1.5,******,37,******,40.4,
207,3716,7940,1110,5,30,401,1.5,******,37,******,40.3,
208,3719,7970,1130,5,30,402,1.5,******,37,******,40.5,
209,3722,7950,1100,5,30,401,1.5,******,37,******,40.3,
210,3725,7970,1120,5,30,402,1.5,******,37,******,40.4,
211,3728,7970,1100,5,30,403,1.5,******,37,******,40.5,
212,3731,7940,1130,5,30,401,1.5,******,37,******,40.3,
213,3734,7960,1120,5,30,402,1.5,******,37,******,40.4,
214,3737,7970,1110,5,30,402,1.5,******,37,******,40.4,
215,3740,7970,1130,5,30,403,1.5,******,37,******,40.5,
216,3743,7970,1120,5,30,402,1.5,******,37,******,40.4,
217,3746,7980,1120,5,30,403,1.5,******,37,******,40.5,
218,3749,7980,1110,5,30,403,1.5,******,37,******,40.5,
219,3752,8000,1130,5,30,404,1.5,******,37,******,40.6,
220,3755,8000,1090,5,30,404,1.5,******,37,******,40.6,
221,3758,7990,1120,5,30,403,1.5,******,37,******,40.5,
222,3761,7980,1130,5,30,403,1.5,******,37,******,40.5,
223,3764,7980,1120,5,30,403,1.5,******,37,******,40.5,
224,3767,8000,1130,5,30,404,1.5,******,37,******,40.6,
225,3770,7990,1080,5,30,403,1.5,******,37,******,40.5,
226,3773,7990,1120,5,30,403,1.5,******,37,******,40.6,
227,3776,8000,1110,5,30,404,1.5,******,37,******,40.6,
228,3779,8010,1120,5,30,404,1.5,******,37,******,40.7,
229,3782,8000,1120,5,30,404,1.5,******,37,******,40.6,
230,3785,8000,1120,5,30,404,1.5,******,37,******,40.6,
231,3788,7990,1120,5,30,403,1.5,******,37,******,40.6,
232,3791,7980,1150,5,30,403,1.5,******,37,******,40.5,
233,3794,8010,1120,5,30,404,1.5,******,37,******,40.6,
234,3797,8010,1110,5,30,404,1.5,******,37,******,40.6,
235,3800,8000,1120,5,30,404,1.5,******,37,******,40.6,
236,3803,8010,1130,5,30,405,1.5,******,37,******,40.7,
237,3806,8030,1110,5,30,406,1.5,******,37,******,40.8,
238,3809,8000,1120,5,30,404,1.5,******,37,******,40.6,
239,3812,8000,1130,5,30,404,1.5,******,37,******,40.6,
240,3815,8010,1120,5,30,405,1.5,******,37,******,40.7,
241,3818,8020,1110,5,30,405,1.5,******,37,******,40.7,
242,3821,8010,1120,5,30,404,1.5,******,37,******,40.6,
243,3824,8010,1110,5,30,404,1.5,******,37,******,40.7,
244,3827,8030,1130,5,30,405,1.5,******,37,******,40.7,
245,3830,8000,1100,5,30,404,1.5,******,37,******,40.6,
246,3833,8010,1130,5,30,405,1.5,******,37,******,40.7,
247,3836,8010,1120,5,30,405,1.5,******,37,******,40.7,
248,3839,8050,1110,5,30,407,1.5,******,37,******,40.9,
249,3842,8000,1140,5,30,404,1.5,******,37,******,40.6,
250,3845,8030,1130,5,30,405,1.5,******,37,******,40.8,
251,3848,8030,1130,5,30,406,1.5,******,37,******,40.8,
252,3851,8030,1170,5,30,406,1.5,******,37,******,40.8,
253,3854,8030,1150,5,30,406,1.5,******,37,******,40.8,
254,3857,8030,1130,5,30,406,1.5,******,37,******,40.8,
255,3860,8050,1110,5,30,406,1.5,******,37,******,40.8,
256,3863,8040,1130,5,30,406,1.5,******,37,******,40.8,
257,3866,8050,1130,5,30,407,1.5,******,37,******,40.9,
258,3869,8060,1120,5,30,407,1.5,******,37,******,40.9,
259,3872,8040,1120,5,30,406,1.5,******,37,******,40.8,
260,3875,8050,1110,5,30,406,1.5,******,37,******,40.8,
261,3878,8050,1120,5,30,406,1.5,******,37,******,40.9,
262,3881,8040,1110,5,30,406,1.5,******,37,******,40.8,
263,3884,8070,1130,5,30,407,1.5,******,37,******,41,
264,3887,8020,1120,5,30,405,1.5,******,37,******,40.7,
265,3890,8050,1120,5,30,406,1.5,******,37,******,40.8,
266,3893,8060,1130,5,30,407,1.5,******,37,******,40.9,
267,3896,8060,1110,5,30,407,1.5,******,37,******,40.9,
268,3899,8070,1110,5,30,407,1.5,******,37,******,41,
269,3902,8050,1160,5,30,407,1.5,******,37,******,40.9,
270,3905,8060,1120,5,30,407,1.5,******,37,******,40.9,
271,3908,8070,1130,5,30,407,1.5,******,37,******,41,
272,3911,8060,1130,5,30,407,1.5,******,37,******,40.9,
273,3914,8060,1120,5,30,407,1.5,******,37,******,40.9,
274,3917,8060,1130,5,30,407,1.5,******,37,******,40.9,
275,3920,8080,1120,5,30,408,1.5,******,37,******,41,
276,3923,8060,1120,5,30,407,1.5,******,37,******,40.9,
277,3926,8060,1140,5,30,407,1.5,******,37,******,40.9,
278,3929,8060,1150,5,30,407,1.5,******,37,******,40.9,
279,3932,8070,1110,5,30,408,1.5,******,37,******,41,
280,3935,8050,1140,5,30,407,1.5,******,37,******,40.9,
281,3938,8070,1130,5,30,407,1.5,******,37,******,41,
282,3941,8100,1150,5,30,409,1.5,******,37,******,41.2,
283,3944,8080,1130,5,30,408,1.5,******,37,******,41,
284,3947,8090,1130,5,30,409,1.5,******,37,******,41.1,
285,3950,8080,1130,5,30,408,1.5,******,37,******,41,
286,3953,8070,1140,5,30,407,1.5,******,37,******,41,
287,3956,8080,1150,5,30,408,1.5,******,37,******,41,
288,3959,8090,1120,5,30,408,1.5,******,37,******,41.1,
289,3962,8090,1130,5,30,409,1.5,******,37,******,41.1,
290,3965,8080,1130,5,30,408,1.5,******,37,******,41,
291,3968,8090,1130,5,30,408,1.5,******,37,******,41,
292,3971,8110,1130,5,30,410,1.5,******,37,******,41.2,
293,3974,8090,1120,5,30,408,1.5,******,37,******,41.1,
294,3977,8100,1120,5,30,409,1.5,******,37,******,41.1,
295,3980,8070,1160,5,30,408,1.5,******,37,******,41,
296,3983,8100,1110,5,30,409,1.5,******,37,******,41.1,
297,3986,8100,1110,5,30,409,1.5,******,37,******,41.1,
298,3989,8090,1140,5,30,409,1.5,******,37,******,41.1,
299,3992,8100,1140,5,30,409,1.5,******,37,******,41.1,
300,3995,8110,1140,5,30,410,1.5,******,37,******,41.2,
[...]
310,11465,9100,1290,5,30,459,1.5,******,37,******,46.2,WMa
311,11468,9110,1300,5,30,460,1.5,******,37,******,46.3,WMa
312,11471,9090,1290,5,30,459,1.5,******,37,******,46.2,WMa
313,11474,9090,1280,5,30,459,1.5,******,37,******,46.2,WMa
314,11477,9090,1300,5,30,459,1.5,******,37,******,46.2,WMa
315,11480,9100,1290,5,30,459,1.5,******,37,******,46.2,WMa
316,11483,9100,1290,5,30,460,1.5,******,37,******,46.2,WMa
317,11486,9110,1290,5,30,460,1.5,******,37,******,46.3,WMa
318,11489,9090,1290,5,30,459,1.5,******,37,******,46.2,WMa
319,11492,9080,1300,5,30,459,1.5,******,37,******,46.1,WMa
320,11495,9100,1290,5,30,459,1.5,******,37,******,46.2,WMa
321,11498,9100,1260,5,30,459,1.5,******,37,******,46.2,WMa
322,11501,9110,1310,5,30,460,1.5,******,37,******,46.3,WMa
323,11504,9080,1270,5,30,459,1.5,******,37,******,46.1,WMa
324,11507,9110,1290,5,30,460,1.5,******,37,******,46.3,WMa
325,11510,9100,1300,5,30,459,1.5,******,37,******,46.2,WMa
326,11513,9080,1290,5,30,459,1.5,******,37,******,46.1,WMa
327,11516,9100,1300,5,30,459,1.5,******,37,******,46.2,WMa
328,11519,9100,1300,5,30,460,1.5,******,37,******,46.2,WMa
329,11522,9110,1280,5,30,460,1.5,******,37,******,46.2,"MV-,WMa"
330,11525,9090,1260,5,30,459,1.5,******,37,******,46.1,WMa
331,11528,9100,1290,5,30,460,1.5,******,37,******,46.2,WMa
332,11531,9140,1290,5,30,461,1.5,******,37,******,46.4,WMa
333,11534,9090,1310,5,30,459,1.5,******,37,******,46.1,WMa
334,11537,9110,1290,5,30,460,1.5,******,37,******,46.2,WMa
335,11540,9100,1310,5,30,460,1.5,******,37,******,46.2,WMa
336,11543,9100,1280,5,30,460,1.5,******,37,******,46.2,"MV-,WMa"
337,11546,9100,1280,5,30,460,1.5,******,37,******,46.2,WMa
338,11549,9130,1300,5,30,461,1.5,******,37,******,46.4,WMa
339,11552,9120,1300,5,30,461,1.5,******,37,******,46.3,WMa
340,11555,9120,1280,5,30,460,1.5,******,37,******,46.3,WMa
341,11558,9130,1270,5,30,461,1.5,******,37,******,46.4,WMa
342,11561,9110,1290,5,30,460,1.5,******,37,******,46.3,WMa
343,11564,9110,1310,5,30,460,1.5,******,37,******,46.3,WMa
344,11567,9110,1300,5,30,460,1.5,******,37,******,46.2,WMa
345,11570,9080,1270,5,30,459,1.5,******,37,******,46.1,WMa
346,11573,9120,1280,5,30,460,1.5,******,37,******,46.3,WMa
347,11576,9100,1290,5,30,460,1.5,******,37,******,46.2,WMa
348,11579,9100,1290,5,30,460,1.5,******,37,******,46.2,WMa
349,11582,9110,1280,5,30,460,1.5,******,37,******,46.3,"MV-,WMa"
350,11585,9110,1320,5,30,460,1.5,******,37,******,46.3,WMa
351,11588,9120,1310,5,30,460,1.5,******,37,******,46.3,"MV-,WMa"
352,11591,9110,1300,5,30,460,1.5,******,37,******,46.3,"MV-,WMa"
353,11594,9090,1280,5,30,459,1.5,******,37,******,46.2,WMa
354,11597,9130,1290,5,30,461,1.5,******,37,******,46.4,WMa
355,11600,9120,1290,5,30,460,1.5,******,37,******,46.3,WMa
356,11603,9110,1300,5,30,460,1.5,******,37,******,46.3,WMa
357,11606,9120,1280,5,30,460,1.5,******,37,******,46.3,WMa
358,11609,9110,1270,5,30,460,1.5,******,37,******,46.3,WMa
359,11612,9140,1300,5,30,462,1.5,******,37,******,46.4,WMa
360,11615,9110,1290,5,30,460,1.5,******,37,******,46.2,"MV-,WMa"
361,11618,9120,1290,5,30,461,1.5,******,37,******,46.3,WMa
362,11621,9110,1290,5,30,460,1.5,******,37,******,46.3,WMa
363,11624,9120,1290,5,30,461,1.5,******,37,******,46.3,WMa
364,11627,9110,1310,5,30,460,1.5,******,37,******,46.3,WMa
365,11630,9120,1290,5,30,461,1.5,******,37,******,46.3,WMa
366,11633,9120,1290,5,30,461,1.5,******,37,******,46.3,WMa
367,11636,9130,1290,5,30,461,1.5,******,37,******,46.4,WMa
368,11639,9130,1300,5,30,461,1.5,******,37,******,46.3,WMa
369,11642,9140,1290,5,30,462,1.5,******,37,******,46.4,WMa
370,11645,9110,1290,5,30,460,1.5,******,37,******,46.2,WMa
371,11648,9130,1270,5,30,461,1.5,******,37,******,46.3,WMa
372,11651,9130,1290,5,30,461,1.5,******,37,******,46.4,"MV-,WMa"
373,11654,9130,1300,5,30,461,1.5,******,37,******,46.4,WMa
374,11657,9110,1290,5,30,460,1.5,******,37,******,46.2,WMa
375,11660,9150,1290,5,30,462,1.5,******,37,******,46.5,WMa
376,11663,9100,1300,5,30,459,1.5,******,37,******,46.2,WMa
377,11666,9120,1280,5,30,461,1.5,******,37,******,46.3,WMa
378,11669,9120,1300,5,30,460,1.5,******,37,******,46.3,WMa
379,11672,9130,1300,5,30,461,1.5,******,37,******,46.4,WMa
380,11675,9120,1290,5,30,460,1.5,******,37,******,46.3,WMa
381,11678,9120,1280,5,30,461,1.5,******,37,******,46.3,WMa
382,11681,9140,1290,5,30,462,1.5,******,37,******,46.4,WMa
383,11684,9110,1300,5,30,460,1.5,******,37,******,46.3,WMa
384,11687,9110,1320,5,30,460,1.5,******,37,******,46.2,WMa
385,11690,9120,1280,5,30,460,1.5,******,37,******,46.3,WMa
386,11693,9130,1310,5,30,461,1.5,******,37,******,46.4,WMa
387,11696,9120,1270,5,30,460,1.5,******,37,******,46.3,WMa
388,11699,9130,1290,5,30,461,1.5,******,37,******,46.4,WMa
389,11702,9140,1300,5,30,461,1.5,******,37,******,46.4,WMa
390,11705,9120,1310,5,30,460,1.5,******,37,******,46.3,WMa
391,11708,9120,1290,5,30,460,1.5,******,37,******,46.3,WMa
392,11711,9130,1280,5,30,461,1.5,******,37,******,46.4,WMa
393,11714,9120,1300,5,30,461,1.5,******,37,******,46.3,WMa
394,11717,9130,1320,5,30,461,1.5,******,37,******,46.4,WMa
395,11720,9130,1290,5,30,461,1.5,******,37,******,46.4,"MV-,WMa"
396,11723,9120,1290,5,30,461,1.5,******,37,******,46.3,WMa
397,11726,9110,1290,5,30,460,1.5,******,37,******,46.3,WMa
398,11729,9130,1290,5,30,461,1.5,******,37,******,46.4,WMa
399,11732,9120,1300,5,30,461,1.5,******,37,******,46.3,WMa
400,11735,9130,1290,5,30,461,1.5,******,37,******,46.4,WMa
401,11738,9120,1300,5,30,461,1.5,******,37,******,46.3,WMa
402,11741,9120,1280,5,30,461,1.5,******,37,******,46.3,WMa
403,11744,9140,1300,5,30,462,1.5,******,37,******,46.4,WMa
404,11747,9160,1290,5,30,463,1.5,******,37,******,46.5,WMa
405,11750,9140,1290,5,30,461,1.5,******,37,******,46.4,WMa
406,11753,9130,1310,5,30,461,1.5,******,37,******,46.3,WMa
407,11756,9140,1270,5,30,461,1.5,******,37,******,46.4,WMa
408,11759,9130,1310,5,30,461,1.5,******,37,******,46.4,WMa
409,11762,9120,1270,5,30,461,1.5,******,37,******,46.3,WMa
410,11765,9140,1300,5,30,462,1.5,******,37,******,46.4,WMa
411,11768,9130,1300,5,30,461,1.5,******,37,******,46.4,WMa
412,11771,9120,1300,5,30,461,1.5,******,37,******,46.3,WMa
413,11774,9150,1300,5,30,462,1.5,******,37,******,46.4,WMa
414,11777,9140,1280,5,30,462,1.5,******,37,******,46.4,WMa
415,11780,9140,1280,5,30,462,1.5,******,37,******,46.4,WMa
416,11783,9130,1280,5,30,461,1.5,******,37,******,46.4,"MV-,WMa"
417,11786,9150,1300,5,30,462,1.5,******,37,******,46.5,WMa
418,11789,9130,1300,5,30,461,1.5,******,37,******,46.4,WMa
419,11792,9140,1290,5,30,462,1.5,******,37,******,46.4,WMa
420,11795,9160,1290,5,30,463,1.5,******,37,******,46.5,WMa
421,11798,9120,1320,5,30,460,1.5,******,37,******,46.3,WMa
422,11801,9140,1300,5,30,461,1.5,******,37,******,46.4,WMa
423,11804,9140,1300,5,30,461,1.5,******,37,******,46.4,"MV-,WMa"
424,11807,9140,1300,5,30,462,1.5,******,37,******,46.4,WMa
425,11810,9140,1300,5,30,462,1.5,******,37,******,46.4,WMa
426,11813,9120,1300,5,30,461,1.5,******,37,******,46.3,WMa
427,11816,9140,1300,5,30,461,1.5,******,37,******,46.4,WMa
428,11819,9140,1300,5,30,462,1.5,******,37,******,46.4,WMa
429,11822,9150,1290,5,30,462,1.5,******,37,******,46.5,"MV-,WMa"
430,11825,9140,1280,5,30,462,1.5,******,37,******,46.4,"MV-,WMa"
431,11828,9150,1300,5,30,462,1.5,******,37,******,46.4,WMa
432,11831,9160,1300,5,30,463,1.5,******,37,******,46.5,WMa
433,11834,9160,1300,5,30,462,1.5,******,37,******,46.5,WMa
434,11837,9110,1320,5,30,460,1.5,******,37,******,46.3,WMa
435,11840,9150,1290,5,30,462,1.5,******,37,******,46.5,"MV-,WMa"
436,11843,9150,1280,5,30,462,1.5,******,37,******,46.5,WMa
437,11846,9150,1280,5,30,462,1.5,******,37,******,46.4,WMa
438,11849,9150,1290,5,30,462,1.5,******,37,******,46.5,WMa
439,11852,9150,1290,5,30,462,1.5,******,37,******,46.4,WMa
440,11855,9150,1300,5,30,462,1.5,******,37,******,46.4,WMa
441,11858,9160,1300,5,30,463,1.5,******,37,******,46.5,WMa
442,11861,9130,1310,5,30,461,1.5,******,37,******,46.4,WMa
443,11864,9130,1320,5,30,461,1.5,******,37,******,46.4,WMa
444,11867,9140,1290,5,30,462,1.5,******,37,******,46.4,WMa
445,11870,9140,1280,5,30,461,1.5,******,37,******,46.4,WMa
446,11873,9160,1300,5,30,462,1.5,******,37,******,46.5,WMa
447,11876,9150,1300,5,30,462,1.5,******,37,******,46.5,WMa
448,11879,9160,1290,5,30,463,1.5,******,37,******,46.5,WMa
449,11882,9150,1290,5,30,462,1.5,******,37,******,46.5,WMa
450,11885,9160,1290,5,30,462,1.5,******,37,******,46.5,WMa
451,11888,9150,1280,5,30,462,1.5,******,37,******,46.4,WMa
452,11891,9150,1300,5,30,462,1.5,******,37,******,46.5,WMa
453,11894,9170,1320,5,30,463,1.5,******,37,******,46.6,WMa
454,11897,9130,1290,5,30,461,1.5,******,37,******,46.3,WMa
455,11900,9150,1290,5,30,462,1.5,******,37,******,46.5,WMa
456,11903,9170,1280,5,30,463,1.5,******,37,******,46.6,WMa
457,11906,9140,1310,5,30,462,1.5,******,37,******,46.4,WMa
458,11909,9140,1300,5,30,461,1.5,******,37,******,46.4,WMa
459,11912,9150,1280,5,30,462,1.5,******,37,******,46.4,WMa
460,11915,9150,1300,5,30,462,1.5,******,37,******,46.4,"MV-,WMa"
461,11918,9160,1300,5,30,463,1.5,******,37,******,46.5,WMa
462,11921,9140,1300,5,30,462,1.5,******,37,******,46.4,WMa
463,11924,9140,1310,5,30,462,1.5,******,37,******,46.4,WMa
464,11927,9170,1260,5,30,463,1.5,******,37,******,46.6,WMa
465,11930,9160,1300,5,30,463,1.5,******,37,******,46.5,WMa
466,11933,9160,1300,5,30,462,1.5,******,37,******,46.5,WMa
467,11936,9140,1280,5,30,462,1.5,******,37,******,46.4,WMa
468,11939,9140,1290,5,30,462,1.5,******,37,******,46.4,WMa
469,11942,9170,1290,5,30,463,1.5,******,37,******,46.6,WMa
470,11945,9170,1310,5,30,463,1.5,******,37,******,46.6,WMa
471,11948,9160,1300,5,30,463,1.5,******,37,******,46.5,WMa
472,11951,9150,1290,5,30,462,1.5,******,37,******,46.5,WMa
473,11954,9150,1290,5,30,462,1.5,******,37,******,46.5,WMa
474,11957,9160,1290,5,30,462,1.5,******,37,******,46.5,WMa
475,11960,9150,1300,5,30,462,1.5,******,37,******,46.4,WMa
476,11963,9170,1300,5,30,463,1.5,******,37,******,46.5,WMa
477,11966,9170,1300,5,30,463,1.5,******,37,******,46.6,WMa
478,11969,9160,1290,5,30,463,1.5,******,37,******,46.5,WMa
479,11972,9150,1310,5,30,462,1.5,******,37,******,46.5,WMa
480,11975,9160,1300,5,30,463,1.5,******,37,******,46.5,WMa
481,11978,9160,1290,5,30,462,1.5,******,37,******,46.5,WMa
482,11981,9170,1280,5,30,463,1.5,******,37,******,46.5,WMa
483,11984,9150,1290,5,30,462,1.5,******,37,******,46.5,WMa
484,11987,9130,1300,5,30,461,1.5,******,37,******,46.4,WMa
485,11990,9170,1280,5,30,463,1.5,******,37,******,46.5,WMa
486,11993,9170,1280,5,30,463,1.5,******,37,******,46.5,WMa
487,11996,9160,1310,5,30,463,1.5,******,37,******,46.5,WMa
488,11999,9160,1290,5,30,463,1.5,******,37,******,46.5,WMa
489,12002,9160,1290,5,30,462,1.5,******,37,******,46.5,WMa
490,12005,9190,1310,5,30,464,1.5,******,37,******,46.7,WMa
491,12008,9150,1300,5,30,462,1.5,******,37,******,46.5,WMa
492,12011,9160,1300,5,30,463,1.5,******,37,******,46.5,WMa
493,12014,9170,1280,5,30,463,1.5,******,37,******,46.5,WMa
494,12017,9160,1290,5,30,463,1.5,******,37,******,46.5,WMa
495,12020,9160,1280,5,30,463,1.5,******,37,******,46.5,WMa
496,12023,9190,1320,5,30,464,1.5,******,37,******,46.7,WMa
497,12026,9160,1290,5,30,462,1.5,******,37,******,46.5,WMa
498,12029,9160,1300,5,30,463,1.5,******,37,******,46.5,WMa
499,12032,9170,1280,5,30,463,1.5,******,37,******,46.6,WMa
500,12035,9160,1300,5,30,462,1.5,******,37,******,46.5,WMa
501,12038,9160,1310,5,30,463,1.5,******,37,******,46.5,WMa
502,12041,9170,1280,5,30,463,1.5,******,37,******,46.5,"MV-,WMa"
503,12044,9140,1270,5,30,461,1.5,******,37,******,46.4,WMa
504,12047,9170,1310,5,30,463,1.5,******,37,******,46.6,WMa
505,12050,9170,1300,5,30,463,1.5,******,37,******,46.6,WMa
506,12053,9160,1300,5,30,462,1.5,******,37,******,46.5,WMa
507,12056,9150,1320,5,30,462,1.5,******,37,******,46.5,WMa
508,12059,9170,1270,5,30,463,1.5,******,37,******,46.6,WMa
509,12062,9170,1300,5,30,463,1.5,******,37,******,46.6,WMa
510,12065,9170,1300,5,30,463,1.5,******,37,******,46.5,WMa
511,12068,9160,1300,5,30,463,1.5,******,37,******,46.5,WMa
512,12071,9170,1290,5,30,463,1.5,******,37,******,46.6,WMa
513,12074,9190,1290,5,30,464,1.5,******,37,******,46.6,WMa
514,12077,9160,1310,5,30,462,1.5,******,37,******,46.5,WMa
515,12080,9130,1300,5,30,461,1.5,******,37,******,46.4,WMa
516,12083,9170,1270,5,30,463,1.5,******,37,******,46.5,WMa
517,12086,9170,1290,5,30,463,1.5,******,37,******,46.5,WMa
518,12089,9170,1300,5,30,463,1.5,******,37,******,46.6,WMa
519,12092,9180,1310,5,30,463,1.5,******,37,******,46.6,WMa
520,12095,9180,1290,5,30,464,1.5,******,37,******,46.6,WMa
521,12098,9180,1280,5,30,464,1.5,******,37,******,46.6,WMa
522,12101,9160,1310,5,30,463,1.5,******,37,******,46.5,WMa
523,12104,9170,1290,5,30,463,1.5,******,37,******,46.5,WMa
524,12107,9170,1300,5,30,463,1.5,******,37,******,46.6,WMa
525,12110,9190,1310,5,30,464,1.5,******,37,******,46.7,WMa
526,12113,9150,1290,5,30,462,1.5,******,37,******,46.4,WMa
527,12116,9160,1290,5,30,463,1.5,******,37,******,46.5,WMa
528,12119,9180,1290,5,30,464,1.5,******,37,******,46.6,WMa
529,12122,9170,1300,5,30,463,1.5,******,37,******,46.6,"MV-,WMa"
530,12125,9170,1270,5,30,463,1.5,******,37,******,46.5,"MV-,WMa"
531,12128,9170,1300,5,30,463,1.5,******,37,******,46.6,WMa
532,12131,9180,1310,5,30,464,1.5,******,37,******,46.6,"MV-,WMa"
533,12134,9150,1300,5,30,462,1.5,******,37,******,46.5,WMa
534,12137,9150,1300,5,30,462,1.5,******,37,******,46.5,WMa
535,12140,9160,1310,5,30,463,1.5,******,37,******,46.5,WMa
536,12143,9180,1290,5,30,464,1.5,******,37,******,46.6,WMa
537,12146,9180,1310,5,30,463,1.5,******,37,******,46.6,WMa
538,12149,9170,1310,5,30,463,1.5,******,37,******,46.6,WMa
539,12152,9180,1280,5,30,463,1.5,******,37,******,46.6,WMa
540,12155,9190,1310,5,30,464,1.5,******,37,******,46.7,WMa
541,12158,9150,1300,5,30,462,1.5,******,37,******,46.5,WMa
542,12161,9220,1270,5,30,465,1.5,******,37,******,46.8,WMa
543,12164,9180,1300,5,30,463,1.5,******,37,******,46.6,WMa
544,12167,9170,1300,5,30,463,1.5,******,37,******,46.6,WMa
545,12170,9160,1290,5,30,462,1.5,******,37,******,46.5,WMa
546,12173,9160,1280,5,30,462,1.5,******,37,******,46.5,WMa
547,12176,9200,1320,5,30,465,1.5,******,37,******,46.7,WMa
548,12179,9170,1300,5,30,463,1.5,******,37,******,46.5,WMa
549,12182,9160,1310,5,30,463,1.5,******,37,******,46.5,WMa
550,12185,9170,1300,5,30,463,1.5,******,37,******,46.6,WMa
551,12188,9170,1310,5,30,463,1.5,******,37,******,46.6,WMa
552,12191,9180,1300,5,30,464,1.5,******,37,******,46.6,WMa
553,12194,9180,1300,5,30,464,1.5,******,37,******,46.6,WMa
554,12197,9180,1300,5,30,463,1.5,******,37,******,46.6,WMa
555,12200,9190,1290,5,30,464,1.5,******,37,******,46.7,WMa
556,12203,9190,1290,5,30,464,1.5,******,37,******,46.6,WMa
557,12206,9170,1310,5,30,463,1.5,******,37,******,46.6,WMa
558,12209,9180,1310,5,30,463,1.5,******,37,******,46.6,WMa
559,12212,9180,1280,5,30,463,1.5,******,37,******,46.6,WMa
560,12215,9180,1290,5,30,463,1.5,******,37,******,46.6,WMa
561,12218,9180,1300,5,30,464,1.5,******,37,******,46.6,WMa
562,12221,9190,1290,5,30,464,1.5,******,37,******,46.7,WMa
563,12224,9190,1290,5,30,464,1.5,******,37,******,46.7,WMa
564,12227,9180,1300,5,30,463,1.5,******,37,******,46.6,WMa
565,12230,9180,1310,5,30,463,1.5,******,37,******,46.6,WMa
566,12233,9190,1320,5,30,464,1.5,******,37,******,46.7,WMa
567,12236,9180,1310,5,30,464,1.5,******,37,******,46.6,WMa
568,12239,9170,1290,5,30,463,1.5,******,37,******,46.5,WMa
569,12242,9190,1300,5,30,464,1.5,******,37,******,46.7,WMa
570,12245,9210,1290,5,30,465,1.5,******,37,******,46.8,WMa
571,12248,9170,1320,5,30,463,1.5,******,37,******,46.6,WMa
572,12251,9170,1300,5,30,463,1.5,******,37,******,46.5,WMa
573,12254,9190,1280,5,30,464,1.5,******,37,******,46.6,WMa
574,12257,9190,1300,5,30,464,1.5,******,37,******,46.7,"MV-,WMa"
575,12260,9180,1300,5,30,464,1.5,******,37,******,46.6,WMa
576,12263,9180,1300,5,30,464,1.5,******,37,******,46.6,WMa
577,12266,9200,1290,5,30,464,1.5,******,37,******,46.7,WMa
578,12269,9180,1300,5,30,464,1.5,******,37,******,46.6,WMa
579,12272,9180,1310,5,30,464,1.5,******,37,******,46.6,WMa
580,12275,9190,1300,5,30,464,1.5,******,37,******,46.7,WMa
581,12278,9180,1290,5,30,464,1.5,******,37,******,46.6,WMa
582,12281,9190,1300,5,30,464,1.5,******,37,******,46.7,WMa
583,12284,9180,1300,5,30,464,1.5,******,37,******,46.6,WMa
584,12287,9190,1300,5,30,464,1.5,******,37,******,46.6,WMa
585,12290,9180,1300,5,30,464,1.5,******,37,******,46.6,WMa
586,12293,9180,1320,5,30,463,1.5,******,37,******,46.6,WMa
587,12296,9190,1290,5,30,464,1.5,******,37,******,46.6,WMa
588,12299,9200,1310,5,30,465,1.5,******,37,******,46.7,WMa
589,12302,9190,1310,5,30,464,1.5,******,37,******,46.7,WMa
590,12305,9180,1290,5,30,463,1.5,******,37,******,46.6,WMa
591,12308,9180,1300,5,30,463,1.5,******,37,******,46.6,WMa
592,12311,9180,1300,5,30,464,1.5,******,37,******,46.6,WMa
593,12314,9190,1300,5,30,464,1.5,******,37,******,46.7,"MV-,WMa"
594,12317,9190,1300,5,30,464,1.5,******,37,******,46.7,WMa
595,12320,9190,1290,5,30,464,1.5,******,37,******,46.7,WMa
596,12323,9190,1310,5,30,464,1.5,******,37,******,46.7,WMa
597,12326,9200,1310,5,30,465,1.5,******,37,******,46.7,WMa
598,12329,9170,1300,5,30,463,1.5,******,37,******,46.6,WMa
599,12332,9200,1300,5,30,464,1.5,******,37,******,46.7,WMa
600,12335,9190,1310,5,30,464,1.5,******,37,******,46.6,"MV-,WMa"
,,,,,,,,,,,,
Interval:,,,15,,,,,,,,,
Number of Data Points:,,,28,,,,,,,,,
,,,,,,,,,,,,
Time Setting:,,,28 Meas. Pts.,,,,,,,,,
,,,Meas. Pt. Duration 6.4285714 s,,,,,,,,,
Event Control:,,,Standard Mode,,,,,,,,,
"  Terminate test, ...",,,...if d(gamma)/dt > 1000 1/s,,,,,,,,,
"  Terminate test, ...",,,...if M > 200 mNm,,,,,,,,,
"  Terminate test, ...",,,...if FN < -50 N or > 50 N,,,,,,,,,
Measuring Profile:,,,,,,,,,,,,
  Shear Rate,,,d(gamma)/dt = 0.1 ... 50 1/s log; |Slope| = 10.003816 Pt. / dec ,,,,,,,,,
,,,,,,,,,,,,
Meas. Pts.,Time,Storage Modulus,Loss Modulus,Strain,Angular Frequency,Shear Stress,Shear Rate,Viscosity,Temperature,Speed,Torque,Status
,[s],[Pa],[Pa],[%],[rad/s],[Pa],[1/s],[Pa·s],[°C],[1/min],[µNm],[]
1,12300,******,******,48.5,******,477,0.1,4780,37,0.12,48,Dy_auto
2,12300,******,******,125,******,615,0.13,4890,37,0.15,61.9,Dy_auto
3,12400,******,******,222,******,771,0.16,4860,37,0.19,77.5,Dy_auto
4,12400,******,******,343,******,956,0.2,4790,37,0.24,96.1,Dy_auto
5,12400,******,******,496,******,1170,0.25,4660,37,0.3,118,Dy_auto
6,12400,******,******,689,******,1430,0.32,4510,37,0.38,143,Dy_auto
7,12400,******,******,931,******,1730,0.4,4340,37,0.48,174,Dy_auto
8,12400,******,******,1240,******,2100,0.5,4190,37,0.6,211,Dy_auto
9,12400,******,******,1620,******,2550,0.63,4050,37,0.75,257,Dy_auto
10,12400,******,******,2100,******,3130,0.79,3950,37,0.95,315,Dy_auto
11,12400,******,******,2710,******,3880,1,3890,37,1.19,390,Dy_auto
12,12400,******,******,3480,******,4730,1.26,3760,37,1.5,476,Dy_auto
13,12400,******,******,4440,******,4780,1.58,3020,37,1.89,480,Dy_auto
14,12400,******,******,5660,******,4380,1.99,2200,37,2.38,440,Dy_auto
15,12400,******,******,7190,******,3330,2.51,1330,37,3,335,Dy_auto
16,12400,******,******,9110,******,2680,3.16,848,37,3.77,269,Dy_auto
17,12400,******,******,11500,******,1850,3.98,464,37,4.75,186,Dy_auto
18,12500,******,******,14600,******,1190,5.01,237,37,5.98,119,Dy_auto
19,12500,******,******,18400,******,783,6.3,124,37,7.52,78.7,Dy_auto
20,12500,******,******,23300,******,703,7.93,88.7,37,9.47,70.7,Dy_auto
21,12500,******,******,29300,******,566,9.98,56.7,37,11.9,56.9,Dy_auto
22,12500,******,******,37000,******,626,12.6,49.8,37,15,62.9,Dy_auto
23,12500,******,******,46600,******,647,15.8,40.9,37,18.9,65.1,Dy_auto
24,12500,******,******,58800,******,735,19.9,36.9,37,23.8,73.9,Dy_auto
25,12500,******,******,74100,******,692,25.1,27.6,37,29.9,69.6,Dy_auto
26,12500,******,******,93300,******,308,31.6,9.77,37,37.7,31,Dy_auto
27,12500,******,******,117000,******,210,39.7,5.29,37,47.4,21.1,Dy_auto
28,12500,******,******,148000,******,127,50,2.55,37,59.7,12.8,Dy_auto