File: exampledata/TXT_N1.csv
Meas. Pts.,Time,Storage Modulus,Loss Modulus,Strain,Angular Frequency,Shear Stress,Shear Rate,Viscosity,Temperature,Speed,Torque,Status
,[s],[Pa],[Pa],[%],[rad/s],[Pa],[1/s],[Pa·s],[°C],[1/min],[µNm],[]
1,5,6430,1100,4.99,30,325,1.5,******,37,******,32.7,WMa
2,10,6440,1640,5,30,332,1.5,******,37,******,33.4,
3,15,6460,1680,5,30,334,1.5,******,37,******,33.5,
4,20,6450,1650,5,30,333,1.5,******,37,******,33.4,
5,25,6480,1640,5,30,334,1.5,******,37,******,33.6,
6,30,6460,1660,5,30,333,1.5,******,37,******,33.5,
7,35,6450,1680,5,30,333,1.5,******,37,******,33.5,
8,40,6480,1660,5,30,334,1.5,******,37,******,33.6,
9,45,6470,1670,5,30,334,1.5,******,37,******,33.6,
10,50,6490,1700,5,30,336,1.5,******,37,******,33.7,
11,55,6450,1700,5,30,333,1.5,******,37,******,33.5,
12,60,6480,1660,5,30,334,1.5,******,37,******,33.6,
13,65,6490,1690,5,30,335,1.5,******,37,******,33.7,
14,70,6490,1700,5,30,335,1.5,******,37,******,33.7,
15,75,6480,1700,5,30,335,1.5,******,37,******,33.7,
16,80,6490,1700,5,30,335,1.5,******,37,******,33.7,
17,85,6500,1710,5,30,336,1.5,******,37,******,33.8,
18,90,6490,1700,5,30,336,1.5,******,37,******,33.7,
19,95,6500,1700,5,30,336,1.5,******,37,******,33.8,
20,100,6510,1710,5,30,337,1.5,******,37,******,33.8,
21,105,6500,1710,5,30,336,1.5,******,37,******,33.8,
22,110,6510,1710,5,30,336,1.5,******,37,******,33.8,
23,115,6510,1720,5,30,337,1.5,******,37,******,33.8,
24,120,6510,1720,5,30,336,1.5,******,37,******,33.8,
25,125,6520,1720,5,30,337,1.5,******,37,******,33.9,
26,130,6520,1730,5,30,337,1.5,******,37,******,33.9,
27,135,6520,1720,5,30,337,1.5,******,37,******,33.9,
28,140,6550,1730,5,30,339,1.5,******,37,******,34.1,
29,145,6540,1740,5,30,338,1.5,******,37,******,34,
30,150,6540,1730,5,30,338,1.5,******,37,******,34,
31,155,6520,1720,5,30,337,1.5,******,37,******,33.9,
32,160,6540,1750,5,30,339,1.5,******,37,******,34,
33,165,6530,1740,5,30,338,1.5,******,37,******,34,
34,170,6550,1740,5,30,339,1.5,******,37,******,34.1,
35,175,6550,1750,5,30,339,1.5,******,37,******,34.1,
36,180,6550,1740,5,30,339,1.5,******,37,******,34.1,
37,185,6570,1740,5,30,340,1.5,******,37,******,34.2,
38,190,6550,1740,5,30,339,1.5,******,37,******,34.1,
39,195,6540,1740,5,30,339,1.5,******,37,******,34,
40,200,6570,1750,5,30,340,1.5,******,37,******,34.2,
41,205,6560,1750,5,30,339,1.5,******,37,******,34.1,
42,210,6550,1750,5,30,339,1.5,******,37,******,34.1,
43,215,6570,1770,5,30,340,1.5,******,37,******,34.2,
44,220,6550,1760,5,30,339,1.5,******,37,******,34.1,
45,225,6580,1760,5,30,340,1.5,******,37,******,34.2,
46,230,6580,1750,5,30,340,1.5,******,37,******,34.2,
47,235,6580,1760,5,30,340,1.5,******,37,******,34.2,
48,240,6580,1760,5,30,341,1.5,******,37,******,34.2,
49,245,6590,1760,5,30,341,1.5,******,37,******,34.3,
50,250,6580,1760,5,30,341,1.5,******,37,******,34.2,
51,255,6580,1750,5,30,340,1.5,******,37,******,34.2,
52,260,6590,1760,5,30,341,1.5,******,37,******,34.3,
53,265,6620,1760,5,30,342,1.5,******,37,******,34.4,
54,270,6590,1770,5,30,341,1.5,******,37,******,34.3,
55,275,6600,1770,5,30,342,1.5,******,37,******,34.4,
56,280,6610,1770,5,30,342,1.5,******,37,******,34.4,
57,285,6610,1780,5,30,342,1.5,******,37,******,34.4,
58,290,6610,1770,5,30,342,1.5,******,37,******,34.4,
59,295,6610,1770,5,30,342,1.5,******,37,******,34.4,
60,300,6620,1780,5,30,343,1.5,******,37,******,34.4,
61,305,6620,1780,5,30,343,1.5,******,37,******,34.4,
62,310,6610,1780,5,30,342,1.5,******,37,******,34.4,
63,315,6610,1780,5,30,343,1.5,******,37,******,34.4,
64,320,6610,1790,5,30,342,1.5,******,37,******,34.4,
65,325,6620,1780,5,30,343,1.5,******,37,******,34.5,
66,330,6620,1780,5,30,343,1.5,******,37,******,34.5,
67,335,6650,1770,5,30,344,1.5,******,37,******,34.6,
68,340,6640,1780,5,30,344,1.5,******,37,******,34.6,
69,345,6630,1780,5,30,343,1.5,******,37,******,34.5,
70,350,6630,1770,5,30,343,1.5,******,37,******,34.5,
71,355,6640,1770,5,30,344,1.5,******,37,******,34.5,
72,360,6630,1800,5,30,343,1.5,******,37,******,34.5,
73,365,6630,1790,5,30,343,1.5,******,37,******,34.5,
74,370,6640,1790,5,30,344,1.5,******,37,******,34.6,
75,375,6650,1780,5,30,344,1.5,******,37,******,34.6,
76,380,6650,1790,5,30,344,1.5,******,37,******,34.6,
77,385,6650,1780,5,30,344,1.5,******,37,******,34.6,
78,390,6650,1790,5,30,344,1.5,******,37,******,34.6,
79,395,6650,1790,5,30,344,1.5,******,37,******,34.6,
80,400,6660,1790,5,30,345,1.5,******,37,******,34.7,
,,,,,,,,,,,,
Interval:,,,2,,,,,,,,,
Number of Data Points:,,,31,,,,,,,,,
,,,,,,,,,,,,
Time Setting:,,,31 Meas. Pts.,,,,,,,,,
Measuring Profile:,,,,,,,,,,,,
#NAME?,,,Amplitude gamma = 5 %,,,,,,,,,
,,,Angular Frequency omega = 100 ... 0.1 rad/s log; |Slope| = 10 Pt. / dec ,,,,,,,,,
,,,,,,,,,,,,
Meas. Pts.,Time,Storage Modulus,Loss Modulus,Strain,Angular Frequency,Shear Stress,Shear Rate,Viscosity,Temperature,Speed,Torque,Status
,[s],[Pa],[Pa],[%],[rad/s],[Pa],[1/s],[Pa·s],[°C],[1/min],[µNm],[]
1,410,4270,1200,5,100,222,5,******,37,******,22.3,
2,418,5610,1020,5,79.4,285,3.97,******,37,******,28.7,
3,425,6220,1140,5,63.1,316,3.16,******,37,******,31.8,
4,432,6600,1370,5,50.1,337,2.51,******,37,******,33.9,
5,439,6710,1550,5,39.8,344,1.99,******,37,******,34.6,
6,448,6660,1750,5,31.6,345,1.58,******,37,******,34.6,
7,458,6520,1960,5,25.1,340,1.26,******,37,******,34.2,
8,465,6290,2170,5,20,332,1,******,37,******,33.4,
9,472,5980,2350,5,15.8,321,0.79,******,37,******,32.3,
10,478,5610,2540,5,12.6,308,0.63,******,37,******,31,
11,486,5190,2680,5,10,292,0.5,******,37,******,29.4,
12,493,4720,2810,5,7.94,274,0.4,******,37,******,27.6,
13,502,4210,2890,5,6.31,255,0.32,******,37,******,25.7,
14,509,3690,2920,5,5.01,235,0.25,******,37,******,23.6,
15,517,3140,2900,5,3.98,213,0.2,******,37,******,21.5,
16,527,2600,2810,5,3.16,191,0.16,******,37,******,19.2,
17,540,2090,2650,5,2.51,169,0.13,******,37,******,17,
18,560,1630,2430,5.01,2,147,0.1,******,37,******,14.8,
19,586,1240,2180,5.01,1.58,126,0.08,******,37,******,12.6,
20,617,911,1910,5.01,1.26,106,0.06,******,37,******,10.7,
21,656,657,1640,5.02,1,88.4,0.05,******,37,******,8.89,
22,693,466,1380,5.01,0.79,72.8,0.04,******,37,******,7.32,
23,739,327,1150,5,0.63,59.7,0.03,******,37,******,6,
24,797,230,944,5,0.5,48.6,0.03,******,37,******,4.89,
25,869,162,773,5.01,0.4,39.5,0.02,******,37,******,3.97,
26,929,117,630,5,0.32,32,0.02,******,37,******,3.22,
27,1010,84.5,511,5.03,0.25,26,0.01,******,37,******,2.62,
28,1100,62.7,414,5.02,0.2,21,0.01,******,37,******,2.12,
29,1220,47.6,336,5.02,0.16,17,0.01,******,37,******,1.71,
30,1450,36.9,273,5.02,0.13,13.8,0.01,******,37,******,1.39,
31,1730,29.8,222,5.02,0.1,11.2,0.01,******,37,******,1.13,
,,,,,,,,,,,,
Interval:,,,3,,,,,,,,,
Number of Data Points:,,,80,,,,,,,,,
,,,,,,,,,,,,
Time Setting:,,,80 Meas. Pts.,,,,,,,,,
,,,Meas. Pt. Duration 5 s,,,,,,,,,
Event Control:,,,Standard Mode,,,,,,,,,
"  Terminate test, ...",,,...if M > 75 mNm,,,,,,,,,
Measuring Profile:,,,,,,,,,,,,
#NAME?,,,Amplitude gamma = 5 %,,,,,,,,,
,,,Angular Frequency omega = 30 rad/s,,,,,,,,,
,,,,,,,,,,,,
Meas. Pts.,Time,Storage Modulus,Loss Modulus,Strain,Angular Frequency,Shear Stress,Shear Rate,Viscosity,Temperature,Speed,Torque,Status
,[s],[Pa],[Pa],[%],[rad/s],[Pa],[1/s],[Pa·s],[°C],[1/min],[µNm],[]
1,invalid point,,,,,,,,,,,
2,1740,,,,,,,,,,,
3,1745,,,,,,,,,,,
4,1750,,,,,,,,,,,
5,1755,,,,,,,,,,,
6,1760,,,,,,,,,,,
7,1765,,,,,,,,,,,
8,1770,,,,,,,,,,,
9,1775,,,,,,,,,,,
10,1780,,,,,,,,,,,
11,1785,,,,,,,,,,,
12,1790,,,,,,,,,,,
13,1795,,,,,,,,,,,
14,1800,,,,,,,,,,,
15,1805,,,,,,,,,,,
16,1810,,,,,,,,,,,
17,1815,,,,,,,,,,,
18,1820,,,,,,,,,,,
19,1825,,,,,,,,,,,
20,1830,7060,2270,5.17,30,384,1.55,******,37,******,38.6,WMa
21,1835,7040,1900,5,30,365,1.5,******,37,******,36.7,
22,1840,7050,1900,5,30,365,1.5,******,37,******,36.7,
23,1845,7050,1900,5,30,365,1.5,******,37,******,36.7,
24,1850,7050,1900,5,30,365,1.5,******,37,******,36.7,
25,1855,7060,1900,5,30,365,1.5,******,37,******,36.7,
26,1860,7040,1910,5,30,365,1.5,******,37,******,36.7,
27,1865,7050,1890,5,30,365,1.5,******,37,******,36.7,
28,1870,7060,1900,5,30,365,1.5,******,37,******,36.7,
29,1875,7060,1890,5,30,365,1.5,******,37,******,36.7,
30,1880,7070,1900,5,30,366,1.5,******,37,******,36.8,
31,1885,7060,1890,5,30,365,1.5,******,37,******,36.7,
32,1890,7050,1910,5,30,365,1.5,******,37,******,36.7,
33,1895,7070,1900,5,30,366,1.5,******,37,******,36.8,
34,1900,7060,1890,5,30,365,1.5,******,37,******,36.7,
35,1905,7060,1900,5,30,365,1.5,******,37,******,36.7,
36,1910,7070,1900,5,30,366,1.5,******,37,******,36.8,
37,1915,7060,1900,5,30,366,1.5,******,37,******,36.8,
38,1920,7070,1900,5,30,366,1.5,******,37,******,36.8,
39,1925,7050,1900,5,30,365,1.5,******,37,******,36.7,
40,1930,7060,1910,5,30,366,1.5,******,37,******,36.8,
41,1935,7070,1900,5,30,366,1.5,******,37,******,36.8,
42,1940,7060,1900,5,30,366,1.5,******,37,******,36.8,
43,1945,7070,1890,5,30,366,1.5,******,37,******,36.8,
44,1950,7070,1910,5,30,366,1.5,******,37,******,36.8,
45,1955,7070,1900,5,30,366,1.5,******,37,******,36.8,
46,1960,7070,1910,5,30,366,1.5,******,37,******,36.8,
47,1965,7070,1900,5,30,366,1.5,******,37,******,36.8,
48,1970,7080,1910,5,30,367,1.5,******,37,******,36.9,
49,1975,7070,1910,5,30,366,1.5,******,37,******,36.8,
50,1980,7100,1920,5,30,368,1.5,******,37,******,37,
51,1985,7080,1920,5,30,367,1.5,******,37,******,36.9,
52,1990,7070,1910,5,30,366,1.5,******,37,******,36.8,
53,1995,7090,1900,5,30,367,1.5,******,37,******,36.9,
54,2000,7080,1900,5,30,367,1.5,******,37,******,36.9,
55,2005,7080,1910,5,30,366,1.5,******,37,******,36.8,
56,2010,7090,1900,5,30,367,1.5,******,37,******,36.9,
57,2015,7080,1900,5,30,367,1.5,******,37,******,36.9,
58,2020,7090,1900,5,30,367,1.5,******,37,******,36.9,
59,2025,7080,1900,5,30,367,1.5,******,37,******,36.9,
60,2030,7090,1890,5,30,367,1.5,******,37,******,36.9,
61,2035,7090,1910,5,30,367,1.5,******,37,******,36.9,
62,2040,7090,1910,5,30,367,1.5,******,37,******,36.9,
63,2045,7080,1910,5,30,367,1.5,******,37,******,36.9,
64,2050,7090,1910,5,30,367,1.5,******,37,******,36.9,
65,2055,7110,1930,5,30,368,1.5,******,37,******,37,
66,2060,7090,1910,5,30,367,1.5,******,37,******,36.9,
67,2065,7100,1910,5,30,368,1.5,******,37,******,37,
68,2070,7090,1910,5,30,367,1.5,******,37,******,36.9,
69,2075,7090,1910,5,30,367,1.5,******,37,******,36.9,
70,2080,7100,1900,5,30,368,1.5,******,37,******,37,
71,2085,7110,1930,5,30,368,1.5,******,37,******,37,
72,2090,7110,1900,5,30,368,1.5,******,37,******,37,
73,2095,7090,1910,5,30,367,1.5,******,37,******,36.9,
74,2100,7100,1900,5,30,368,1.5,******,37,******,37,
75,2105,7090,1920,5,30,367,1.5,******,37,******,36.9,
76,2110,7100,1900,5,30,367,1.5,******,37,******,36.9,
77,2115,7090,1920,5,30,367,1.5,******,37,******,36.9,
78,2120,7110,1910,5,30,368,1.5,******,37,******,37,
79,2125,7110,1910,5,30,368,1.5,******,37,******,37,
80,2130,7110,1900,5,30,368,1.5,******,37,******,37,
,,,,,,,,,,,,
Interval:,,,4,,,,,,,,,
Number of Data Points:,,,113,,,,,,,,,
,,,,,,,,,,,,
Time Setting:,,,113 Meas. Pts.,,,,,,,,,
,,,Meas. Pt. Duration 5 s,,,,,,,,,
Measuring Profile:,,,,,,,,,,,,
#NAME?,,,Amplitude gamma = 0.1 ... 500 % log; |Slope| = 30.278699 Pt. / dec ,,,,,,,,,
,,,Angular Frequency omega = 30 rad/s,,,,,,,,,
,,,,,,,,,,,,
Meas. Pts.,Time,Storage Modulus,Loss Modulus,Strain,Angular Frequency,Shear Stress,Shear Rate,Viscosity,Temperature,Speed,Torque,Status
,[s],[Pa],[Pa],[%],[rad/s],[Pa],[1/s],[Pa·s],[°C],[1/min],[µNm],[]
1,2135,0,15800,0.1,30,15.8,0.03,******,37,******,1.59,"MV-,WMa"
2,2140,6510,2290,0.11,30,7.36,0.03,******,37,******,0.74,WMa
3,2145,257,21000,0.12,30,24.7,0.04,******,37,******,2.48,"ME-,MV-"
4,2150,12100,0,0.13,30,15.1,0.04,******,37,******,1.52,"MV-,WMa"
5,2155,17200,0,0.14,30,23.5,0.04,******,37,******,2.37,"ME-,WMa"
6,2160,21000,15600,0.15,30,38.6,0.04,******,37,******,3.88,"ME-,MV-"
7,2165,8540,15300,0.16,30,28.2,0.05,******,37,******,2.83,WMa
8,2170,670,9190,0.17,30,15.8,0.05,******,37,******,1.58,WMa
9,2175,6970,1820,0.18,30,13.2,0.06,******,37,******,1.33,
10,2180,3620,6100,0.2,30,14.2,0.06,******,37,******,1.43,"ME-,MV-"
11,2185,6580,0,0.22,30,14.2,0.06,******,37,******,1.42,"MV-,WMa"
12,2190,4810,4120,0.23,30,14.8,0.07,******,37,******,1.48,WMa
13,2195,14600,1800,0.25,30,36.6,0.07,******,37,******,3.68,WMa
14,2200,14900,9390,0.27,30,47.8,0.08,******,37,******,4.81,WMa
15,2205,7570,2750,0.29,30,23.6,0.09,******,37,******,2.37,WMa
16,2210,17600,0,0.32,30,55.6,0.09,******,37,******,5.59,"MV-,WMa"
17,2215,14800,1500,0.35,30,51.3,0.1,******,37,******,5.16,WMa
18,2220,4420,0,0.37,30,16.4,0.11,******,37,******,1.65,"MV-,WMa"
19,2225,6280,11700,0.4,30,52.6,0.12,******,37,******,5.29,WMa
20,2230,10300,0,0.43,30,43.7,0.13,******,37,******,4.39,"MV-,WMa"
21,2235,11200,2500,0.46,30,52.7,0.14,******,37,******,5.3,WMa
22,2240,4030,0,0.5,30,20.1,0.15,******,37,******,2.02,"MV-,WMa"
23,2245,0,15000,0.53,30,80.1,0.16,******,37,******,8.05,"MV-,WMa"
24,2250,7760,2550,0.57,30,46.6,0.17,******,37,******,4.69,WMa
25,2255,11700,2170,0.62,30,74.1,0.19,******,37,******,7.45,WMa
26,2260,10300,5310,0.67,30,77.8,0.2,******,37,******,7.82,WMa
27,2265,8050,2290,0.72,30,60.5,0.22,******,37,******,6.09,WMa
28,2270,13300,0,0.78,30,104,0.24,******,37,******,10.4,"MV-,WMa"
29,2275,6800,1690,0.85,30,59.4,0.25,******,37,******,5.97,WMa
30,2280,8610,3250,0.91,30,83.9,0.27,******,37,******,8.44,WMa
31,2285,6740,4480,0.98,30,79.6,0.3,******,37,******,8.01,WMa
32,2290,8570,1090,1.06,30,91.2,0.32,******,37,******,9.17,WMa
33,2295,4040,1610,1.14,30,49.5,0.34,******,37,******,4.98,WMa
34,2300,8120,3220,1.23,30,107,0.37,******,37,******,10.8,WMa
35,2305,7260,995,1.33,30,97.4,0.4,******,37,******,9.8,WMa
36,2310,12400,0,1.43,30,177,0.43,******,37,******,17.8,"MV-,WMa"
37,2315,7940,2070,1.55,30,127,0.47,******,37,******,12.8,WMa
38,2320,5860,211,1.67,30,97.9,0.5,******,37,******,9.84,WMa
39,2325,6720,3590,1.8,30,137,0.54,******,37,******,13.8,WMa
40,2330,6670,2140,1.95,30,136,0.58,******,37,******,13.7,WMa
41,2335,7640,2140,2.1,30,166,0.63,******,37,******,16.7,WMa
42,2340,7240,2050,2.26,30,170,0.68,******,37,******,17.1,WMa
43,2345,7250,1510,2.44,30,181,0.73,******,37,******,18.2,WMa
44,2350,4820,3250,2.63,30,153,0.79,******,37,******,15.4,WMa
45,2355,5560,1460,2.84,30,163,0.85,******,37,******,16.4,WMa
46,2360,8610,4530,3.07,30,299,0.92,******,37,******,30,WMa
47,2365,6730,3150,3.31,30,246,0.99,******,37,******,24.7,WMa
48,2370,6690,2180,3.57,30,251,1.07,******,37,******,25.3,WMa
49,2375,7380,1950,3.86,30,294,1.16,******,37,******,29.6,WMa
50,2380,7250,2040,4.16,30,313,1.25,******,37,******,31.5,WMa
51,2385,7530,1070,4.49,30,342,1.35,******,37,******,34.3,WMa
52,2390,9130,1110,4.84,30,445,1.45,******,37,******,44.8,WMa
53,2395,6340,1570,5.23,30,341,1.57,******,37,******,34.3,WMa
54,2400,7010,1600,5.64,30,405,1.69,******,37,******,40.7,WMa
55,2405,7190,1960,6.08,30,454,1.83,******,37,******,45.6,WMa
56,2410,8150,1590,6.56,30,545,1.97,******,37,******,54.8,WMa
57,2415,6250,1460,7.09,30,455,2.13,******,37,******,45.8,WMa
58,2420,7390,2450,7.64,30,595,2.29,******,37,******,59.8,WMa
59,2425,6850,2640,8.25,30,605,2.47,******,37,******,60.9,WMa
60,2430,7790,1740,8.9,30,710,2.67,******,37,******,71.4,WMa
61,2435,6740,1670,9.61,30,667,2.88,******,37,******,67,WMa
62,2440,7120,1690,10.4,30,759,3.11,******,37,******,76.3,WMa
63,2445,6990,2340,11.2,30,823,3.35,******,37,******,82.8,WMa
64,2450,7980,1690,12.1,30,984,3.62,******,37,******,99,WMa
65,2455,7590,2140,13,30,1030,3.91,******,37,******,103,WMa
66,2460,7140,1810,14,30,1030,4.21,******,37,******,104,WMa
67,2465,7210,1900,15.2,30,1130,4.55,******,37,******,114,WMa
68,2470,7320,1880,16.4,30,1240,4.91,******,37,******,124,WMa
69,2475,7080,1850,17.6,30,1290,5.29,******,37,******,130,WMa
70,2480,7130,1640,19,30,1390,5.71,******,37,******,140,WMa
71,2485,7230,1860,20.5,30,1530,6.16,******,37,******,154,WMa
72,2490,6970,1950,22.2,30,1600,6.65,******,37,******,161,WMa
73,2495,7750,2330,23.9,30,1940,7.17,******,37,******,195,WMa
74,2500,7140,1740,25.8,30,1900,7.74,******,37,******,191,WMa
75,2505,7160,1940,27.8,30,2070,8.35,******,37,******,208,WMa
76,2510,7620,1840,30,30,2350,9.01,******,37,******,237,WMa
77,2515,7390,2090,32.4,30,2490,9.73,******,37,******,250,WMa
78,2520,7160,1810,35,30,2580,10.5,******,37,******,260,WMa
79,2525,7300,1710,37.7,30,2830,11.3,******,37,******,285,WMa
80,2530,6820,1930,40.7,30,2890,12.2,******,37,******,290,WMa
81,2535,7360,2080,43.9,30,3360,13.2,******,37,******,338,WMa
82,2540,7120,1890,47.4,30,3490,14.2,******,37,******,351,WMa
83,2545,6620,2300,51.2,30,3580,15.3,******,37,******,360,WMa
84,2550,5900,1870,55.2,30,3410,16.6,******,37,******,343,WMa
85,2555,7350,2310,59.5,30,4590,17.9,******,37,******,461,WMa
86,2560,6850,1990,64.2,30,4590,19.3,******,37,******,461,WMa
87,2565,7060,1750,69.3,30,5040,20.8,******,37,******,507,WMa
88,2570,7060,2270,74.8,30,5550,22.4,******,37,******,558,WMa
89,2575,6660,2880,80.7,30,5850,24.2,******,37,******,589,WMa
90,2580,5850,2310,87.1,30,5480,26.1,******,37,******,551,WMa
91,2585,4870,2470,93.9,30,5130,28.2,******,37,******,516,WMa
92,2590,4360,1950,101,30,4840,30.4,******,37,******,486,WMa
93,2595,3160,1380,109,30,3770,32.8,******,37,******,379,WMa
94,2600,1950,1070,118,30,2630,35.4,******,37,******,264,WMa
95,2605,885,516,127,30,1300,38.2,******,37,******,131,
96,2610,498,374,137,30,855,41.2,******,37,******,85.9,
97,2615,317,319,148,30,666,44.4,******,37,******,66.9,
98,2620,241,277,160,30,587,47.9,******,37,******,59,
99,2625,158,218,172,30,464,51.7,******,37,******,46.6,
100,2630,105,190,186,30,404,55.8,******,37,******,40.6,
101,2635,68.9,170,201,30,368,60.2,******,37,******,37,
102,2640,38.1,152,217,30,340,65,******,37,******,34.2,
103,2645,17.4,128,234,30,302,70.1,******,37,******,30.4,
104,2650,10.5,101,252,30,257,75.7,******,37,******,25.8,
105,2655,0,94.7,272,30,258,81.6,******,37,******,25.9,"ME-,taD"
106,2660,0,100,294,30,294,88.1,******,37,******,29.6,"ME-,taD"
107,2665,0,121,317,30,382,95,******,37,******,38.5,"ME-,taD"
108,2670,0,139,342,30,474,103,******,37,******,47.6,"ME-,taD"
109,2675,0,167,369,30,617,111,******,37,******,62,"ME-,taD"
110,2680,0,197,398,30,783,119,******,37,******,78.7,"ME-,taD"
111,2685,0,223,429,30,957,129,******,37,******,96.2,"ME-,taD"
112,2690,0,220,463,30,1020,139,******,37,******,102,"ME-,taD"
113,2695,0,203,500,30,1020,150,******,37,******,102,"ME-,taD"
,,,,,,,,,,,,
Interval:,,,5,,,,,,,,,
Number of Data Points:,,,80,,,,,,,,,
,,,,,,,,,,,,
Time Setting:,,,80 Meas. Pts.,,,,,,,,,
,,,Meas. Pt. Duration 5 s,,,,,,,,,
Event Control:,,,Standard Mode,,,,,,,,,
"  Terminate test, ...",,,...if M > 75 mNm,,,,,,,,,
Measuring Profile:,,,,,,,,,,,,
#NAME?,,,Amplitude gamma = 5 %,,,,,,,,,
,,,Angular Frequency omega = 30 rad/s,,,,,,,,,
,,,,,,,,,,,,
Meas. Pts.,Time,Storage Modulus,Loss Modulus,Strain,Angular Frequency,Shear Stress,Shear Rate,Viscosity,Temperature,Speed,Torque,Status
,[s],[Pa],[Pa],[%],[rad/s],[Pa],[1/s],[Pa·s],[°C],[1/min],[µNm],[]
1,2700,456,777,4.95,30,44.6,1.49,******,37,******,4.49,WMa
2,2705,959,271,5,30,49.9,1.5,******,37,******,5.01,
3,2710,1350,374,5,30,69.8,1.5,******,37,******,7.02,
4,2715,1590,414,5,30,82.3,1.5,******,37,******,8.28,
5,2720,1810,482,5,30,93.6,1.5,******,37,******,9.41,
6,2725,1990,527,5,30,103,1.5,******,37,******,10.4,
7,2730,2170,570,5,30,112,1.5,******,37,******,11.3,
8,2735,2370,627,5,30,122,1.5,******,37,******,12.3,
9,2740,2530,654,5,30,131,1.5,******,37,******,13.2,
10,2745,2710,718,5,30,140,1.5,******,37,******,14.1,
11,2750,2870,766,5,30,148,1.5,******,37,******,14.9,
12,2755,3160,833,5,30,163,1.5,******,37,******,16.4,
13,2760,3350,877,5,30,173,1.5,******,37,******,17.4,
14,2765,3530,935,5,30,183,1.5,******,37,******,18.4,
15,2770,3690,960,5,30,191,1.5,******,37,******,19.2,
16,2775,3870,1000,5,30,200,1.5,******,37,******,20.1,
17,2780,4060,1050,5,30,210,1.5,******,37,******,21.1,
18,2785,4220,1100,5,30,218,1.5,******,37,******,21.9,
19,2790,4350,1150,5,30,225,1.5,******,37,******,22.6,
20,2795,4490,1170,5,30,232,1.5,******,37,******,23.3,
21,2800,4640,1220,5,30,240,1.5,******,37,******,24.1,
22,2805,4750,1250,5,30,245,1.5,******,37,******,24.7,
23,2810,4890,1280,5,30,253,1.5,******,37,******,25.4,
24,2815,5020,1320,5,30,259,1.5,******,37,******,26.1,
25,2820,5130,1350,5,30,265,1.5,******,37,******,26.7,
26,2825,5270,1380,5,30,272,1.5,******,37,******,27.4,
27,2830,5380,1400,5,30,278,1.5,******,37,******,28,
28,2835,5460,1420,5,30,282,1.5,******,37,******,28.4,
29,2840,5540,1450,5,30,286,1.5,******,37,******,28.8,
30,2845,5660,1480,5,30,292,1.5,******,37,******,29.4,
31,2850,5740,1490,5,30,297,1.5,******,37,******,29.8,
32,2855,5810,1530,5,30,301,1.5,******,37,******,30.2,
33,2860,5890,1530,5,30,304,1.5,******,37,******,30.6,
34,2865,5970,1550,5,30,308,1.5,******,37,******,31,
35,2870,6050,1560,5,30,313,1.5,******,37,******,31.4,
36,2875,6130,1590,5,30,316,1.5,******,37,******,31.8,
37,2880,6160,1600,5,30,318,1.5,******,37,******,32,
38,2885,6210,1610,5,30,321,1.5,******,37,******,32.3,
39,2890,6280,1630,5,30,324,1.5,******,37,******,32.6,
40,2895,6320,1640,5,30,326,1.5,******,37,******,32.8,
41,2900,6360,1670,5,30,329,1.5,******,37,******,33,
42,2905,6400,1660,5,30,331,1.5,******,37,******,33.2,
43,2910,6460,1680,5,30,334,1.5,******,37,******,33.6,
44,2915,6510,1670,5,30,336,1.5,******,37,******,33.8,
45,2920,6520,1690,5,30,337,1.5,******,37,******,33.9,
46,2925,6570,1700,5,30,339,1.5,******,37,******,34.1,
47,2930,6590,1720,5,30,341,1.5,******,37,******,34.3,
48,2935,6630,1720,5,30,343,1.5,******,37,******,34.4,
49,2940,6650,1720,5,30,344,1.5,******,37,******,34.6,
50,2945,6690,1730,5,30,346,1.5,******,37,******,34.7,
51,2950,6700,1740,5,30,346,1.5,******,37,******,34.8,
52,2955,6720,1730,5,30,347,1.5,******,37,******,34.9,
53,2960,6740,1750,5,30,348,1.5,******,37,******,35,
54,2965,6770,1750,5,30,350,1.5,******,37,******,35.1,
55,2970,6790,1740,5,30,351,1.5,******,37,******,35.3,
56,2975,6820,1750,5,30,352,1.5,******,37,******,35.4,
57,2980,6830,1760,5,30,353,1.5,******,37,******,35.5,
58,2985,6850,1770,5,30,354,1.5,******,37,******,35.6,
59,2990,6850,1770,5,30,354,1.5,******,37,******,35.6,
60,2995,6860,1770,5,30,354,1.5,******,37,******,35.6,
61,3000,6890,1800,5,30,356,1.5,******,37,******,35.8,
62,3005,6910,1790,5,30,357,1.5,******,37,******,35.9,
63,3010,6920,1800,5,30,358,1.5,******,37,******,36,
64,3015,6940,1790,5,30,358,1.5,******,37,******,36,
65,3020,6940,1800,5,30,359,1.5,******,37,******,36.1,
66,3025,6940,1790,5,30,358,1.5,******,37,******,36,
67,3030,6970,1800,5,30,360,1.5,******,37,******,36.2,
68,3035,6990,1810,5,30,361,1.5,******,37,******,36.3,
69,3040,7000,1820,5,30,361,1.5,******,37,******,36.3,
70,3045,7020,1790,5,30,363,1.5,******,37,******,36.5,
71,3050,7020,1820,5,30,363,1.5,******,37,******,36.5,
72,3055,7030,1810,5,30,363,1.5,******,37,******,36.5,
73,3060,7030,1820,5,30,363,1.5,******,37,******,36.5,
74,3065,7050,1830,5,30,364,1.5,******,37,******,36.6,
75,3070,7060,1810,5,30,364,1.5,******,37,******,36.6,
76,3075,7060,1820,5,30,365,1.5,******,37,******,36.7,
77,3080,7070,1820,5,30,365,1.5,******,37,******,36.7,
78,3085,7080,1830,5,30,366,1.5,******,37,******,36.8,
79,3090,7110,1830,5,30,367,1.5,******,37,******,36.9,
80,3095,7110,1840,5,30,367,1.5,******,37,******,36.9,
,,,,,,,,,,,,
Interval:,,,6,,,,,,,,,
Number of Data Points:,,,600,,,,,,,,,
,,,,,,,,,,,,
Time Setting:,,,600 Meas. Pts.,,,,,,,,,
,,,Meas. Pt. Duration 3 s,,,,,,,,,
Event Control:,,,Standard Mode,,,,,,,,,
"  Terminate test, ...",,,...if M > 200 mNm,,,,,,,,,
Measuring Profile:,,,,,,,,,,,,
#NAME?,,,Amplitude gamma = 5 %,,,,,,,,,
,,,Angular Frequency omega = 30 rad/s,,,,,,,,,
,,,,,,,,,,,,
Meas. Pts.,Time,Storage Modulus,Loss Modulus,Strain,Angular Frequency,Shear Stress,Shear Rate,Viscosity,Temperature,Speed,Torque,Status
,[s],[Pa],[Pa],[%],[rad/s],[Pa],[1/s],[Pa·s],[°C],[1/min],[µNm],[]
1,3098,7130,1840,5.07,30,374,1.52,******,37,******,37.6,WMa
2,3101,7150,1840,5,30,369,1.5,******,37,******,37.1,WMa
3,3104,7140,1840,5,30,369,1.5,******,37,******,37.1,
4,3107,7140,1840,5,30,368,1.5,******,37,******,37,
5,3110,7170,1830,5,30,370,1.5,******,37,******,37.2,
6,3113,7130,1840,5,30,368,1.5,******,37,******,37,
7,3116,7170,1840,5,30,370,1.5,******,37,******,37.2,
8,3119,7150,1860,5,30,369,1.5,******,37,******,37.1,
9,3122,7170,1840,5,30,370,1.5,******,37,******,37.2,
10,3125,7170,1870,5,30,370,1.5,******,37,******,37.3,
11,3128,7170,1820,5,30,370,1.5,******,37,******,37.2,
12,3131,7180,1860,5,30,371,1.5,******,37,******,37.3,
13,3134,7170,1860,5,30,371,1.5,******,37,******,37.3,
14,3137,7190,1850,5,30,371,1.5,******,37,******,37.3,
15,3140,7170,1860,5,30,370,1.5,******,37,******,37.2,
16,3143,7230,1850,5,30,373,1.5,******,37,******,37.5,
17,3146,7200,1840,5,30,371,1.5,******,37,******,37.3,
18,3149,7210,1850,5,30,372,1.5,******,37,******,37.4,
19,3152,7220,1840,5,30,373,1.5,******,37,******,37.5,
20,3155,7210,1850,5,30,372,1.5,******,37,******,37.4,
21,3158,7220,1850,5,30,373,1.5,******,37,******,37.5,
22,3161,7210,1860,5,30,373,1.5,******,37,******,37.5,
23,3164,7190,1850,5,30,371,1.5,******,37,******,37.3,
24,3167,7230,1860,5,30,373,1.5,******,37,******,37.5,
25,3170,7230,1860,5,30,373,1.5,******,37,******,37.6,
26,3173,7240,1860,5,30,374,1.5,******,37,******,37.6,
27,3176,7230,1890,5,30,374,1.5,******,37,******,37.6,
28,3179,7250,1840,5,30,374,1.5,******,37,******,37.6,
29,3182,7240,1860,5,30,374,1.5,******,37,******,37.6,
30,3185,7260,1860,5,30,375,1.5,******,37,******,37.7,
31,3188,7250,1860,5,30,374,1.5,******,37,******,37.6,
32,3191,7250,1860,5,30,374,1.5,******,37,******,37.6,
33,3194,7260,1870,5,30,375,1.5,******,37,******,37.7,
34,3197,7290,1860,5,30,376,1.5,******,37,******,37.9,
35,3200,7270,1850,5,30,375,1.5,******,37,******,37.7,
36,3203,7270,1880,5,30,376,1.5,******,37,******,37.8,
37,3206,7280,1870,5,30,376,1.5,******,37,******,37.8,
38,3209,7280,1870,5,30,376,1.5,******,37,******,37.8,
39,3212,7270,1870,5,30,375,1.5,******,37,******,37.7,
40,3215,7320,1890,5,30,378,1.5,******,37,******,38,
41,3218,7290,1880,5,30,376,1.5,******,37,******,37.8,
42,3221,7280,1870,5,30,376,1.5,******,37,******,37.8,
43,3224,7300,1890,5,30,377,1.5,******,37,******,37.9,
44,3227,7310,1870,5,30,377,1.5,******,37,******,37.9,
45,3230,7310,1880,5,30,378,1.5,******,37,******,38,
46,3233,7300,1880,5,30,377,1.5,******,37,******,37.9,
47,3236,7300,1860,5,30,377,1.5,******,37,******,37.9,
48,3239,7300,1870,5,30,377,1.5,******,37,******,37.9,
49,3242,7330,1880,5,30,378,1.5,******,37,******,38,
50,3245,7330,1880,5,30,378,1.5,******,37,******,38,
51,3248,7310,1880,5,30,377,1.5,******,37,******,37.9,
52,3251,7320,1890,5,30,378,1.5,******,37,******,38,
53,3254,7340,1860,5,30,379,1.5,******,37,******,38.1,
54,3257,7330,1880,5,30,379,1.5,******,37,******,38.1,
55,3260,7330,1900,5,30,379,1.5,******,37,******,38.1,
56,3263,7340,1890,5,30,379,1.5,******,37,******,38.1,
57,3266,7330,1870,5,30,379,1.5,******,37,******,38.1,
58,3269,7320,1870,5,30,378,1.5,******,37,******,38,
59,3272,7370,1890,5,30,381,1.5,******,37,******,38.3,
60,3275,7330,1890,5,30,378,1.5,******,37,******,38.1,
61,3278,7350,1900,5,30,380,1.5,******,37,******,38.2,
62,3281,7340,1900,5,30,379,1.5,******,37,******,38.1,
63,3284,7360,1890,5,30,380,1.5,******,37,******,38.2,
64,3287,7360,1900,5,30,380,1.5,******,37,******,38.2,
65,3290,7380,1900,5,30,381,1.5,******,37,******,38.3,
66,3293,7370,1890,5,30,380,1.5,******,37,******,38.2,
67,3296,7360,1880,5,30,380,1.5,******,37,******,38.2,
68,3299,7360,1900,5,30,380,1.5,******,37,******,38.2,
69,3302,7370,1890,5,30,381,1.5,******,37,******,38.3,
70,3305,7380,1890,5,30,381,1.5,******,37,******,38.3,
71,3308,7390,1890,5,30,381,1.5,******,37,******,38.4,
72,3311,7400,1870,5,30,382,1.5,******,37,******,38.4,
73,3314,7380,1910,5,30,381,1.5,******,37,******,38.3,
74,3317,7410,1900,5,30,382,1.5,******,37,******,38.4,
75,3320,7370,1870,5,30,380,1.5,******,37,******,38.3,
76,3323,7400,1890,5,30,382,1.5,******,37,******,38.4,
77,3326,7390,1900,5,30,381,1.5,******,37,******,38.3,
78,3329,7400,1910,5,30,382,1.5,******,37,******,38.4,
79,3332,7390,1910,5,30,381,1.5,******,37,******,38.3,
80,3335,7430,1880,5,30,383,1.5,******,37,******,38.5,
81,3338,7390,1920,5,30,382,1.5,******,37,******,38.4,
82,3341,7420,1900,5,30,383,1.5,******,37,******,38.5,
83,3344,7400,1880,5,30,382,1.5,******,37,******,38.4,
84,3347,7400,1880,5,30,382,1.5,******,37,******,38.4,
85,3350,7430,1920,5,30,384,1.5,******,37,******,38.6,
86,3353,7440,1880,5,30,384,1.5,******,37,******,38.6,
87,3356,7420,1920,5,30,383,1.5,******,37,******,38.5,
88,3359,7410,1900,5,30,383,1.5,******,37,******,38.5,
89,3362,7430,1890,5,30,384,1.5,******,37,******,38.6,
90,3365,7420,1910,5,30,383,1.5,******,37,******,38.5,
91,3368,7420,1910,5,30,383,1.5,******,37,******,38.5,
92,3371,7420,1870,5,30,383,1.5,******,37,******,38.5,
93,3374,7430,1900,5,30,383,1.5,******,37,******,38.6,
94,3377,7450,1910,5,30,384,1.5,******,37,******,38.7,
95,3380,7440,1900,5,30,384,1.5,******,37,******,38.6,
96,3383,7420,1910,5,30,383,1.5,******,37,******,38.5,
97,3386,7430,1920,5,30,384,1.5,******,37,******,38.6,
98,3389,7440,1920,5,30,384,1.5,******,37,******,38.6,
99,3392,7450,1930,5,30,385,1.5,******,37,******,38.7,
100,3395,7430,1900,5,30,384,1.5,******,37,******,38.6,
101,3398,7460,1910,5,30,385,1.5,******,37,******,38.7,
102,3401,7450,1920,5,30,385,1.5,******,37,******,38.7,
103,3404,7450,1900,5,30,385,1.5,******,37,******,38.7,
104,3407,7430,1930,5,30,384,1.5,******,37,******,38.6,
105,3410,7470,1910,5,30,385,1.5,******,37,******,38.8,
106,3413,7460,1910,5,30,385,1.5,******,37,******,38.7,
107,3416,7470,1910,5,30,385,1.5,******,37,******,38.7,
108,3419,7470,1920,5,30,386,1.5,******,37,******,38.8,
109,3422,7470,1910,5,30,386,1.5,******,37,******,38.8,
110,3425,7470,1920,5,30,386,1.5,******,37,******,38.8,
111,3428,7470,1910,5,30,385,1.5,******,37,******,38.7,
112,3431,7460,1920,5,30,385,1.5,******,37,******,38.7,
113,3434,7480,1920,5,30,386,1.5,******,37,******,38.8,
114,3437,7480,1920,5,30,386,1.5,******,37,******,38.8,
115,3440,7460,1920,5,30,385,1.5,******,37,******,38.7,
116,3443,7490,1910,5,30,387,1.5,******,37,******,38.9,
117,3446,7480,1910,5,30,386,1.5,******,37,******,38.8,
118,3449,7490,1900,5,30,386,1.5,******,37,******,38.8,
119,3452,7490,1930,5,30,387,1.5,******,37,******,38.9,
120,3455,7490,1920,5,30,387,1.5,******,37,******,38.9,
121,3458,7480,1930,5,30,386,1.5,******,37,******,38.8,
122,3461,7480,1910,5,30,386,1.5,******,37,******,38.8,
123,3464,7500,1920,5,30,387,1.5,******,37,******,38.9,
124,3467,7490,1920,5,30,387,1.5,******,37,******,38.9,
125,3470,7480,1910,5,30,386,1.5,******,37,******,38.8,
126,3473,7490,1940,5,30,387,1.5,******,37,******,38.9,
127,3476,7500,1930,5,30,387,1.5,******,37,******,38.9,
128,3479,7500,1900,5,30,387,1.5,******,37,******,38.9,
129,3482,7510,1940,5,30,388,1.5,******,37,******,39,
130,3485,7510,1920,5,30,388,1.5,******,37,******,39,
131,3488,7510,1930,5,30,388,1.5,******,37,******,39,
132,3491,7500,1930,5,30,387,1.5,******,37,******,38.9,
133,3494,7530,1930,5,30,389,1.5,******,37,******,39.1,
134,3497,7520,1940,5,30,388,1.5,******,37,******,39,
135,3500,7520,1930,5,30,388,1.5,******,37,******,39,
136,3503,7510,1940,5,30,388,1.5,******,37,******,39,
137,3506,7520,1910,5,30,388,1.5,******,37,******,39,
138,3509,7500,1930,5,30,387,1.5,******,37,******,38.9,
139,3512,7500,1910,5,30,387,1.5,******,37,******,38.9,
140,3515,7540,1940,5,30,389,1.5,******,37,******,39.2,
141,3518,7510,1920,5,30,388,1.5,******,37,******,39,
142,3521,7510,1940,5,30,388,1.5,******,37,******,39,
143,3524,7530,1940,5,30,389,1.5,******,37,******,39.1,
144,3527,7520,1960,5,30,388,1.5,******,37,******,39,
145,3530,7530,1940,5,30,389,1.5,******,37,******,39.1,
146,3533,7540,1930,5,30,389,1.5,******,37,******,39.1,
147,3536,7530,1940,5,30,389,1.5,******,37,******,39.1,
148,3539,7540,1930,5,30,389,1.5,******,37,******,39.1,
149,3542,7560,1940,5,30,390,1.5,******,37,******,39.3,
150,3545,7540,1940,5,30,389,1.5,******,37,******,39.1,
151,3548,7540,1960,5,30,389,1.5,******,37,******,39.1,
152,3551,7560,1930,5,30,390,1.5,******,37,******,39.2,
153,3554,7540,1940,5,30,389,1.5,******,37,******,39.1,
154,3557,7550,1930,5,30,390,1.5,******,37,******,39.2,
155,3560,7550,1910,5,30,389,1.5,******,37,******,39.1,
156,3563,7530,1940,5,30,389,1.5,******,37,******,39.1,
157,3566,7560,1940,5,30,390,1.5,******,37,******,39.2,
158,3569,7580,1950,5,30,391,1.5,******,37,******,39.4,
159,3572,7540,1930,5,30,389,1.5,******,37,******,39.1,
160,3575,7560,1950,5,30,390,1.5,******,37,******,39.2,
161,3578,7560,1940,5,30,390,1.5,******,37,******,39.3,
162,3581,7580,1920,5,30,391,1.5,******,37,******,39.3,
163,3584,7560,1960,5,30,390,1.5,******,37,******,39.3,
164,3587,7610,1950,5,30,393,1.5,******,37,******,39.5,
165,3590,7570,1920,5,30,390,1.5,******,37,******,39.2,
166,3593,7570,1930,5,30,391,1.5,******,37,******,39.3,
167,3596,7570,1940,5,30,391,1.5,******,37,******,39.3,
168,3599,7540,1930,5,30,389,1.5,******,37,******,39.1,
169,3602,7580,1950,5,30,391,1.5,******,37,******,39.3,
170,3605,7600,1920,5,30,392,1.5,******,37,******,39.4,
171,3608,7580,1930,5,30,391,1.5,******,37,******,39.3,
172,3611,7580,1940,5,30,391,1.5,******,37,******,39.3,
173,3614,7590,1940,5,30,392,1.5,******,37,******,39.4,
174,3617,7580,1930,5,30,391,1.5,******,37,******,39.3,
175,3620,7600,1960,5,30,392,1.5,******,37,******,39.5,
176,3623,7570,1930,5,30,390,1.5,******,37,******,39.3,
177,3626,7580,1950,5,30,391,1.5,******,37,******,39.3,
178,3629,7580,1950,5,30,391,1.5,******,37,******,39.3,
179,3632,7580,1950,5,30,391,1.5,******,37,******,39.3,
180,3635,7570,1960,5,30,391,1.5,******,37,******,39.3,
181,3638,7600,1940,5,30,392,1.5,******,37,******,39.4,
182,3641,7570,1940,5,30,391,1.5,******,37,******,39.3,
183,3644,7590,1940,5,30,392,1.5,******,37,******,39.4,
184,3647,7590,1940,5,30,392,1.5,******,37,******,39.4,
185,3650,7600,1940,5,30,392,1.5,******,37,******,39.4,
186,3653,7580,1960,5,30,392,1.5,******,37,******,39.4,
187,3656,7620,1930,5,30,393,1.5,******,37,******,39.5,
188,3659,7570,1960,5,30,391,1.5,******,37,******,39.3,
189,3662,7610,1950,5,30,393,1.5,******,37,******,39.5,
190,3665,7610,1940,5,30,392,1.5,******,37,******,39.5,
191,3668,7610,1960,5,30,393,1.5,******,37,******,39.5,
192,3671,7610,1950,5,30,393,1.5,******,37,******,39.5,
193,3674,7610,1940,5,30,393,1.5,******,37,******,39.5,
194,3677,7580,1960,5,30,391,1.5,******,37,******,39.3,
195,3680,7620,1950,5,30,393,1.5,******,37,******,39.5,
196,3683,7610,1940,5,30,393,1.5,******,37,******,39.5,
197,3686,7600,1950,5,30,392,1.5,******,37,******,39.4,
198,3689,7620,1950,5,30,393,1.5,******,37,******,39.5,
199,3692,7610,1940,5,30,393,1.5,******,37,******,39.5,
200,3695,7620,1960,5,30,393,1.5,******,37,******,39.5,
201,3698,7620,1950,5,30,393,1.5,******,37,******,39.6,
202,3701,7630,1960,5,30,394,1.5,******,37,******,39.6,
203,3704,7610,1960,5,30,393,1.5,******,37,******,39.5,
204,3707,7630,1950,5,30,394,1.5,******,37,******,39.6,
205,3710,7620,1940,5,30,393,1.5,******,37,******,39.5,
206,3713,7630,1940,5,30,394,1.5,******,37,******,39.6,
207,3716,7620,1940,5,30,393,1.5,******,37,******,39.5,
208,3719,7630,1950,5,30,394,1.5,******,37,******,39.6,
209,3722,7630,1960,5,30,394,1.5,******,37,******,39.6,
210,3725,7630,1950,5,30,394,1.5,******,37,******,39.6,
211,3728,7650,1960,5,30,395,1.5,******,37,******,39.7,
212,3731,7620,1950,5,30,394,1.5,******,37,******,39.6,
213,3734,7630,1950,5,30,394,1.5,******,37,******,39.6,
214,3737,7640,1950,5,30,394,1.5,******,37,******,39.6,
215,3740,7630,1950,5,30,394,1.5,******,37,******,39.6,
216,3743,7630,1960,5,30,394,1.5,******,37,******,39.6,
217,3746,7630,2000,5,30,394,1.5,******,37,******,39.7,
218,3749,7640,1950,5,30,394,1.5,******,37,******,39.6,
219,3752,7640,1950,5,30,394,1.5,******,37,******,39.6,
220,3755,7640,1950,5,30,394,1.5,******,37,******,39.7,
221,3758,7650,1960,5,30,395,1.5,******,37,******,39.7,
222,3761,7620,1960,5,30,393,1.5,******,37,******,39.6,
223,3764,7680,1950,5,30,396,1.5,******,37,******,39.9,
224,3767,7660,1950,5,30,395,1.5,******,37,******,39.7,
225,3770,7670,1980,5,30,396,1.5,******,37,******,39.8,
226,3773,7650,1960,5,30,395,1.5,******,37,******,39.7,
227,3776,7640,1960,5,30,394,1.5,******,37,******,39.7,
228,3779,7660,1970,5,30,396,1.5,******,37,******,39.8,
229,3782,7660,1950,5,30,395,1.5,******,37,******,39.8,
230,3785,7650,1950,5,30,395,1.5,******,37,******,39.7,
231,3788,7650,1960,5,30,395,1.5,******,37,******,39.7,
232,3791,7660,1950,5,30,395,1.5,******,37,******,39.7,
233,3794,7660,1950,5,30,395,1.5,******,37,******,39.7,
234,3797,7670,1940,5,30,396,1.5,******,37,******,39.8,
235,3800,7660,1950,5,30,395,1.5,******,37,******,39.8,
236,3803,7660,1950,5,30,395,1.5,******,37,******,39.7,
237,3806,7680,1970,5,30,396,1.5,******,37,******,39.8,
238,3809,7650,1970,5,30,395,1.5,******,37,******,39.7,
239,3812,7670,1960,5,30,396,1.5,******,37,******,39.8,
240,3815,7640,1960,5,30,394,1.5,******,37,******,39.6,
241,3818,7680,1950,5,30,396,1.5,******,37,******,39.8,
242,3821,7670,1960,5,30,396,1.5,******,37,******,39.8,
243,3824,7670,1960,5,30,396,1.5,******,37,******,39.8,
244,3827,7680,1960,5,30,396,1.5,******,37,******,39.8,
245,3830,7670,1920,5,30,395,1.5,******,37,******,39.7,
246,3833,7660,1960,5,30,395,1.5,******,37,******,39.8,
247,3836,7690,1970,5,30,397,1.5,******,37,******,39.9,
248,3839,7680,1960,5,30,396,1.5,******,37,******,39.9,
249,3842,7660,1960,5,30,395,1.5,******,37,******,39.8,
250,3845,7660,1970,5,30,395,1.5,******,37,******,39.8,
251,3848,7680,1970,5,30,397,1.5,******,37,******,39.9,
252,3851,7680,1960,5,30,397,1.5,******,37,******,39.9,
253,3854,7680,1990,5,30,397,1.5,******,37,******,39.9,
254,3857,7680,1960,5,30,396,1.5,******,37,******,39.9,
255,3860,7680,1960,5,30,396,1.5,******,37,******,39.9,
256,3863,7700,1970,5,30,397,1.5,******,37,******,39.9,
257,3866,7700,1960,5,30,398,1.5,******,37,******,40,
258,3869,7700,1960,5,30,397,1.5,******,37,******,39.9,
259,3872,7690,1980,5,30,397,1.5,******,37,******,39.9,
260,3875,7670,1970,5,30,396,1.5,******,37,******,39.8,
261,3878,7700,1960,5,30,397,1.5,******,37,******,39.9,
262,3881,7690,1960,5,30,397,1.5,******,37,******,39.9,
263,3884,7660,1960,5,30,395,1.5,******,37,******,39.8,
264,3887,7700,1980,5,30,397,1.5,******,37,******,40,
265,3890,7700,1960,5,30,398,1.5,******,37,******,40,
266,3893,7700,1960,5,30,397,1.5,******,37,******,39.9,
267,3896,7710,1960,5,30,398,1.5,******,37,******,40,
268,3899,7700,1980,5,30,398,1.5,******,37,******,40,
269,3902,7700,1960,5,30,397,1.5,******,37,******,40,
270,3905,7700,1980,5,30,397,1.5,******,37,******,40,
271,3908,7700,1970,5,30,398,1.5,******,37,******,40,
272,3911,7700,1960,5,30,397,1.5,******,37,******,39.9,
273,3914,7710,1970,5,30,398,1.5,******,37,******,40,
274,3917,7710,1960,5,30,398,1.5,******,37,******,40,
275,3920,7690,1960,5,30,396,1.5,******,37,******,39.9,
276,3923,7700,1980,5,30,398,1.5,******,37,******,40,
277,3926,7730,1950,5,30,399,1.5,******,37,******,40.1,
278,3929,7710,1970,5,30,398,1.5,******,37,******,40,
279,3932,7700,1980,5,30,398,1.5,******,37,******,40,
280,3935,7710,1990,5,30,398,1.5,******,37,******,40,
281,3938,7710,1970,5,30,398,1.5,******,37,******,40,
282,3941,7720,1980,5,30,398,1.5,******,37,******,40,
283,3944,7730,1970,5,30,399,1.5,******,37,******,40.1,
284,3947,7730,1980,5,30,399,1.5,******,37,******,40.1,
285,3950,7720,1960,5,30,398,1.5,******,37,******,40.1,
286,3953,7710,1980,5,30,398,1.5,******,37,******,40,
287,3956,7710,1980,5,30,398,1.5,******,37,******,40,
288,3959,7730,1970,5,30,399,1.5,******,37,******,40.1,
289,3962,7710,1960,5,30,398,1.5,******,37,******,40,
290,3965,7730,1960,5,30,399,1.5,******,37,******,40.1,
291,3968,7720,1970,5,30,398,1.5,******,37,******,40.1,
292,3971,7760,1980,5,30,400,1.5,******,37,******,40.3,
293,3974,7700,1960,5,30,397,1.5,******,37,******,40,
294,3977,7720,2000,5,30,399,1.5,******,37,******,40.1,
295,3980,7740,1960,5,30,399,1.5,******,37,******,40.2,
296,3983,7750,1960,5,30,400,1.5,******,37,******,40.2,
297,3986,7730,1990,5,30,399,1.5,******,37,******,40.1,
298,3989,7730,1970,5,30,399,1.5,******,37,******,40.1,
[...]
308,11459,8630,2220,5,30,446,1.5,******,37,******,44.8,WMa
309,11462,8610,2170,5,30,444,1.5,******,37,******,44.6,WMa
310,11465,8610,2180,5,30,444,1.5,******,37,******,44.7,WMa
311,11468,8600,2190,5,30,444,1.5,******,37,******,44.6,WMa
312,11471,8660,2170,5,30,447,1.5,******,37,******,44.9,WMa
313,11474,8610,2200,5,30,444,1.5,******,37,******,44.7,WMa
314,11477,8620,2180,5,30,445,1.5,******,37,******,44.7,WMa
315,11480,8600,2200,5,30,444,1.5,******,37,******,44.6,WMa
316,11483,8640,2210,5,30,446,1.5,******,37,******,44.9,"MV-,WMa"
317,11486,8650,2200,5,30,446,1.5,******,37,******,44.9,WMa
318,11489,8640,2190,5,30,446,1.5,******,37,******,44.8,WMa
319,11492,8630,2180,5,30,445,1.5,******,37,******,44.8,WMa
320,11495,8630,2190,5,30,445,1.5,******,37,******,44.8,WMa
321,11498,8630,2190,5,30,445,1.5,******,37,******,44.8,WMa
322,11501,8630,2200,5,30,446,1.5,******,37,******,44.8,WMa
323,11504,8620,2170,5,30,444,1.5,******,37,******,44.7,"MV-,WMa"
324,11507,8620,2180,5,30,445,1.5,******,37,******,44.7,WMa
325,11510,8630,2190,5,30,445,1.5,******,37,******,44.8,WMa
326,11513,8660,2190,5,30,446,1.5,******,37,******,44.9,WMa
327,11516,8670,2200,5,30,447,1.5,******,37,******,44.9,WMa
328,11519,8610,2220,5,30,445,1.5,******,37,******,44.7,WMa
329,11522,8640,2160,5,30,445,1.5,******,37,******,44.8,WMa
330,11525,8640,2200,5,30,446,1.5,******,37,******,44.8,WMa
331,11528,8640,2190,5,30,446,1.5,******,37,******,44.8,WMa
332,11531,8600,2180,5,30,444,1.5,******,37,******,44.6,WMa
333,11534,8670,2180,5,30,447,1.5,******,37,******,45,WMa
334,11537,8650,2190,5,30,446,1.5,******,37,******,44.8,WMa
335,11540,8630,2200,5,30,445,1.5,******,37,******,44.8,WMa
336,11543,8630,2200,5,30,445,1.5,******,37,******,44.8,WMa
337,11546,8640,2180,5,30,446,1.5,******,37,******,44.8,WMa
338,11549,8660,2210,5,30,447,1.5,******,37,******,44.9,WMa
339,11552,8630,2180,5,30,445,1.5,******,37,******,44.8,WMa
340,11555,8620,2200,5,30,444,1.5,******,37,******,44.7,WMa
341,11558,8640,2190,5,30,446,1.5,******,37,******,44.8,WMa
342,11561,8650,2170,5,30,446,1.5,******,37,******,44.8,WMa
343,11564,8640,2220,5,30,446,1.5,******,37,******,44.8,WMa
344,11567,8650,2190,5,30,446,1.5,******,37,******,44.8,WMa
345,11570,8650,2200,5,30,446,1.5,******,37,******,44.9,WMa
346,11573,8630,2180,5,30,445,1.5,******,37,******,44.8,WMa
347,11576,8640,2190,5,30,446,1.5,******,37,******,44.8,WMa
348,11579,8640,2190,5,30,446,1.5,******,37,******,44.8,WMa
349,11582,8640,2210,5,30,446,1.5,******,37,******,44.8,WMa
350,11585,8640,2180,5,30,446,1.5,******,37,******,44.8,WMa
351,11588,8640,2190,5,30,446,1.5,******,37,******,44.8,WMa
352,11591,8630,2180,5,30,445,1.5,******,37,******,44.8,WMa
353,11594,8650,2190,5,30,446,1.5,******,37,******,44.9,WMa
354,11597,8640,2200,5,30,446,1.5,******,37,******,44.8,WMa
355,11600,8630,2200,5,30,445,1.5,******,37,******,44.8,WMa
356,11603,8650,2200,5,30,446,1.5,******,37,******,44.9,WMa
357,11606,8650,2210,5,30,446,1.5,******,37,******,44.9,WMa
358,11609,8650,2220,5,30,447,1.5,******,37,******,44.9,WMa
359,11612,8640,2170,5,30,445,1.5,******,37,******,44.8,WMa
360,11615,8670,2200,5,30,447,1.5,******,37,******,45,WMa
361,11618,8630,2200,5,30,445,1.5,******,37,******,44.7,WMa
362,11621,8670,2190,5,30,447,1.5,******,37,******,45,WMa
363,11624,8650,2200,5,30,446,1.5,******,37,******,44.9,WMa
364,11627,8640,2210,5,30,446,1.5,******,37,******,44.8,WMa
365,11630,8650,2150,5,30,446,1.5,******,37,******,44.8,WMa
366,11633,8660,2210,5,30,447,1.5,******,37,******,44.9,WMa
367,11636,8630,2180,5,30,445,1.5,******,37,******,44.7,WMa
368,11639,8650,2200,5,30,446,1.5,******,37,******,44.8,"MV-,WMa"
369,11642,8660,2190,5,30,447,1.5,******,37,******,44.9,WMa
370,11645,8630,2220,5,30,445,1.5,******,37,******,44.8,WMa
371,11648,8660,2180,5,30,446,1.5,******,37,******,44.9,WMa
372,11651,8640,2200,5,30,446,1.5,******,37,******,44.8,WMa
373,11654,8660,2200,5,30,447,1.5,******,37,******,44.9,"MV-,WMa"
374,11657,8670,2210,5,30,447,1.5,******,37,******,45,WMa
375,11660,8640,2190,5,30,446,1.5,******,37,******,44.8,WMa
376,11663,8660,2200,5,30,447,1.5,******,37,******,44.9,WMa
377,11666,8650,2200,5,30,446,1.5,******,37,******,44.9,WMa
378,11669,8640,2230,5,30,446,1.5,******,37,******,44.8,WMa
379,11672,8660,2210,5,30,447,1.5,******,37,******,44.9,WMa
380,11675,8660,2180,5,30,446,1.5,******,37,******,44.9,WMa
381,11678,8660,2190,5,30,447,1.5,******,37,******,44.9,WMa
382,11681,8650,2190,5,30,446,1.5,******,37,******,44.9,WMa
383,11684,8660,2190,5,30,447,1.5,******,37,******,44.9,WMa
384,11687,8650,2190,5,30,446,1.5,******,37,******,44.8,WMa
385,11690,8650,2210,5,30,446,1.5,******,37,******,44.9,WMa
386,11693,8670,2190,5,30,447,1.5,******,37,******,45,WMa
387,11696,8660,2190,5,30,447,1.5,******,37,******,44.9,WMa
388,11699,8690,2220,5,30,448,1.5,******,37,******,45.1,WMa
389,11702,8650,2190,5,30,446,1.5,******,37,******,44.9,WMa
390,11705,8640,2200,5,30,446,1.5,******,37,******,44.8,WMa
391,11708,8660,2200,5,30,446,1.5,******,37,******,44.9,WMa
392,11711,8650,2200,5,30,446,1.5,******,37,******,44.9,WMa
393,11714,8660,2200,5,30,447,1.5,******,37,******,44.9,WMa
394,11717,8680,2200,5,30,447,1.5,******,37,******,45,WMa
395,11720,8680,2210,5,30,448,1.5,******,37,******,45,WMa
396,11723,8660,2200,5,30,447,1.5,******,37,******,44.9,WMa
397,11726,8670,2200,5,30,447,1.5,******,37,******,44.9,WMa
398,11729,8660,2200,5,30,447,1.5,******,37,******,44.9,WMa
399,11732,8660,2210,5,30,447,1.5,******,37,******,44.9,WMa
400,11735,8670,2200,5,30,447,1.5,******,37,******,45,WMa
401,11738,8670,2200,5,30,447,1.5,******,37,******,45,WMa
402,11741,8660,2190,5,30,447,1.5,******,37,******,44.9,WMa
403,11744,8670,2200,5,30,447,1.5,******,37,******,44.9,WMa
404,11747,8650,2190,5,30,446,1.5,******,37,******,44.9,WMa
405,11750,8690,2180,5,30,448,1.5,******,37,******,45.1,WMa
406,11753,8690,2190,5,30,448,1.5,******,37,******,45,WMa
407,11756,8670,2220,5,30,447,1.5,******,37,******,45,WMa
408,11759,8670,2220,5,30,448,1.5,******,37,******,45,WMa
409,11762,8670,2200,5,30,447,1.5,******,37,******,45,WMa
410,11765,8680,2200,5,30,448,1.5,******,37,******,45,WMa
411,11768,8660,2200,5,30,447,1.5,******,37,******,44.9,WMa
412,11771,8670,2190,5,30,447,1.5,******,37,******,44.9,WMa
413,11774,8650,2220,5,30,447,1.5,******,37,******,44.9,WMa
414,11777,8670,2210,5,30,447,1.5,******,37,******,45,WMa
415,11780,8680,2200,5,30,448,1.5,******,37,******,45,WMa
416,11783,8680,2210,5,30,448,1.5,******,37,******,45.1,WMa
417,11786,8700,2220,5,30,449,1.5,******,37,******,45.2,WMa
418,11789,8650,2190,5,30,446,1.5,******,37,******,44.9,WMa
419,11792,8670,2200,5,30,447,1.5,******,37,******,45,WMa
420,11795,8670,2210,5,30,447,1.5,******,37,******,45,WMa
421,11798,8700,2170,5,30,448,1.5,******,37,******,45.1,WMa
422,11801,8680,2180,5,30,448,1.5,******,37,******,45,WMa
423,11804,8690,2220,5,30,448,1.5,******,37,******,45.1,WMa
424,11807,8680,2200,5,30,448,1.5,******,37,******,45,WMa
425,11810,8690,2210,5,30,448,1.5,******,37,******,45.1,WMa
426,11813,8700,2200,5,30,449,1.5,******,37,******,45.1,WMa
427,11816,8670,2200,5,30,447,1.5,******,37,******,45,WMa
428,11819,8670,2210,5,30,447,1.5,******,37,******,45,WMa
429,11822,8690,2200,5,30,448,1.5,******,37,******,45.1,WMa
430,11825,8680,2200,5,30,448,1.5,******,37,******,45,WMa
431,11828,8670,2190,5,30,447,1.5,******,37,******,45,WMa
432,11831,8680,2200,5,30,448,1.5,******,37,******,45,WMa
433,11834,8690,2200,5,30,448,1.5,******,37,******,45.1,WMa
434,11837,8670,2200,5,30,447,1.5,******,37,******,45,WMa
435,11840,8680,2200,5,30,448,1.5,******,37,******,45,WMa
436,11843,8680,2220,5,30,448,1.5,******,37,******,45,WMa
437,11846,8690,2200,5,30,448,1.5,******,37,******,45.1,WMa
438,11849,8700,2240,5,30,449,1.5,******,37,******,45.2,WMa
439,11852,8680,2210,5,30,448,1.5,******,37,******,45,WMa
440,11855,8670,2200,5,30,447,1.5,******,37,******,45,WMa
441,11858,8680,2190,5,30,448,1.5,******,37,******,45,WMa
442,11861,8680,2210,5,30,448,1.5,******,37,******,45,WMa
443,11864,8670,2210,5,30,447,1.5,******,37,******,45,WMa
444,11867,8690,2200,5,30,448,1.5,******,37,******,45.1,WMa
445,11870,8680,2180,5,30,447,1.5,******,37,******,45,WMa
446,11873,8690,2210,5,30,449,1.5,******,37,******,45.1,WMa
447,11876,8690,2200,5,30,448,1.5,******,37,******,45.1,WMa
448,11879,8710,2210,5,30,449,1.5,******,37,******,45.2,WMa
449,11882,8680,2210,5,30,448,1.5,******,37,******,45,WMa
450,11885,8680,2210,5,30,448,1.5,******,37,******,45,WMa
451,11888,8700,2180,5,30,448,1.5,******,37,******,45.1,WMa
452,11891,8690,2210,5,30,448,1.5,******,37,******,45.1,"MV-,WMa"
453,11894,8690,2210,5,30,448,1.5,******,37,******,45.1,WMa
454,11897,8700,2210,5,30,449,1.5,******,37,******,45.1,WMa
455,11900,8680,2200,5,30,448,1.5,******,37,******,45,WMa
456,11903,8690,2200,5,30,448,1.5,******,37,******,45,WMa
457,11906,8710,2190,5,30,449,1.5,******,37,******,45.2,WMa
458,11909,8690,2200,5,30,448,1.5,******,37,******,45.1,WMa
459,11912,8700,2220,5,30,449,1.5,******,37,******,45.1,WMa
460,11915,8700,2210,5,30,449,1.5,******,37,******,45.1,WMa
461,11918,8710,2220,5,30,449,1.5,******,37,******,45.2,WMa
462,11921,8700,2200,5,30,449,1.5,******,37,******,45.1,WMa
463,11924,8700,2210,5,30,449,1.5,******,37,******,45.1,WMa
464,11927,8690,2220,5,30,449,1.5,******,37,******,45.1,WMa
465,11930,8690,2220,5,30,448,1.5,******,37,******,45.1,WMa
466,11933,8690,2170,5,30,448,1.5,******,37,******,45.1,WMa
467,11936,8700,2210,5,30,449,1.5,******,37,******,45.1,WMa
468,11939,8710,2210,5,30,449,1.5,******,37,******,45.2,WMa
469,11942,8690,2200,5,30,448,1.5,******,37,******,45.1,WMa
470,11945,8700,2210,5,30,449,1.5,******,37,******,45.1,WMa
471,11948,8670,2230,5,30,447,1.5,******,37,******,45,WMa
472,11951,8700,2200,5,30,449,1.5,******,37,******,45.1,WMa
473,11954,8700,2190,5,30,449,1.5,******,37,******,45.1,WMa
474,11957,8710,2220,5,30,450,1.5,******,37,******,45.2,"MV-,WMa"
475,11960,8690,2200,5,30,448,1.5,******,37,******,45.1,WMa
476,11963,8710,2210,5,30,450,1.5,******,37,******,45.2,WMa
477,11966,8700,2200,5,30,449,1.5,******,37,******,45.1,WMa
478,11969,8710,2200,5,30,449,1.5,******,37,******,45.2,WMa
479,11972,8700,2200,5,30,449,1.5,******,37,******,45.1,WMa
480,11975,8700,2220,5,30,449,1.5,******,37,******,45.1,WMa
481,11978,8700,2200,5,30,449,1.5,******,37,******,45.1,WMa
482,11981,8710,2200,5,30,449,1.5,******,37,******,45.2,WMa
483,11984,8710,2200,5,30,449,1.5,******,37,******,45.2,WMa
484,11987,8710,2210,5,30,449,1.5,******,37,******,45.2,WMa
485,11990,8710,2200,5,30,449,1.5,******,37,******,45.2,WMa
486,11993,8710,2210,5,30,449,1.5,******,37,******,45.2,WMa
487,11996,8700,2230,5,30,449,1.5,******,37,******,45.2,"MV-,WMa"
488,11999,8700,2170,5,30,448,1.5,******,37,******,45.1,WMa
489,12002,8710,2210,5,30,449,1.5,******,37,******,45.2,WMa
490,12005,8720,2220,5,30,450,1.5,******,37,******,45.2,WMa
491,12008,8720,2210,5,30,450,1.5,******,37,******,45.2,WMa
492,12011,8710,2200,5,30,449,1.5,******,37,******,45.2,WMa
493,12014,8700,2220,5,30,449,1.5,******,37,******,45.1,WMa
494,12017,8710,2210,5,30,449,1.5,******,37,******,45.2,WMa
495,12020,8700,2180,5,30,448,1.5,******,37,******,45.1,"MV-,WMa"
496,12023,8710,2220,5,30,450,1.5,******,37,******,45.2,WMa
497,12026,8700,2210,5,30,449,1.5,******,37,******,45.1,WMa
498,12029,8720,2210,5,30,450,1.5,******,37,******,45.2,WMa
499,12032,8670,2230,5,30,447,1.5,******,37,******,44.9,WMa
500,12035,8720,2200,5,30,449,1.5,******,37,******,45.2,WMa
501,12038,8720,2180,5,30,450,1.5,******,37,******,45.2,WMa
502,12041,8710,2220,5,30,449,1.5,******,37,******,45.2,WMa
503,12044,8700,2200,5,30,449,1.5,******,37,******,45.1,WMa
504,12047,8690,2190,5,30,448,1.5,******,37,******,45.1,WMa
505,12050,8720,2210,5,30,450,1.5,******,37,******,45.2,WMa
506,12053,8710,2210,5,30,449,1.5,******,37,******,45.2,WMa
507,12056,8730,2190,5,30,450,1.5,******,37,******,45.2,WMa
508,12059,8710,2220,5,30,449,1.5,******,37,******,45.2,WMa
509,12062,8720,2230,5,30,450,1.5,******,37,******,45.2,WMa
510,12065,8710,2220,5,30,449,1.5,******,37,******,45.2,WMa
511,12068,8700,2200,5,30,449,1.5,******,37,******,45.1,WMa
512,12071,8720,2210,5,30,450,1.5,******,37,******,45.2,WMa
513,12074,8710,2200,5,30,449,1.5,******,37,******,45.2,WMa
514,12077,8710,2210,5,30,449,1.5,******,37,******,45.2,WMa
515,12080,8710,2240,5,30,449,1.5,******,37,******,45.2,"MV-,WMa"
516,12083,8710,2190,5,30,449,1.5,******,37,******,45.2,WMa
517,12086,8710,2200,5,30,449,1.5,******,37,******,45.2,WMa
518,12089,8710,2200,5,30,449,1.5,******,37,******,45.2,WMa
519,12092,8720,2210,5,30,450,1.5,******,37,******,45.2,WMa
520,12095,8710,2220,5,30,449,1.5,******,37,******,45.2,WMa
521,12098,8710,2210,5,30,449,1.5,******,37,******,45.2,WMa
522,12101,8700,2220,5,30,449,1.5,******,37,******,45.2,WMa
523,12104,8720,2220,5,30,450,1.5,******,37,******,45.2,WMa
524,12107,8710,2200,5,30,449,1.5,******,37,******,45.2,WMa
525,12110,8730,2210,5,30,450,1.5,******,37,******,45.3,WMa
526,12113,8730,2210,5,30,450,1.5,******,37,******,45.3,WMa
527,12116,8710,2210,5,30,449,1.5,******,37,******,45.2,WMa
528,12119,8720,2220,5,30,450,1.5,******,37,******,45.2,WMa
529,12122,8720,2220,5,30,450,1.5,******,37,******,45.2,WMa
530,12125,8720,2190,5,30,450,1.5,******,37,******,45.2,WMa
531,12128,8720,2200,5,30,450,1.5,******,37,******,45.2,WMa
532,12131,8720,2210,5,30,450,1.5,******,37,******,45.2,WMa
533,12134,8730,2220,5,30,450,1.5,******,37,******,45.3,WMa
534,12137,8730,2200,5,30,450,1.5,******,37,******,45.3,WMa
535,12140,8700,2220,5,30,449,1.5,******,37,******,45.1,WMa
536,12143,8700,2230,5,30,449,1.5,******,37,******,45.1,"MV-,WMa"
537,12146,8730,2200,5,30,450,1.5,******,37,******,45.3,WMa
538,12149,8710,2200,5,30,449,1.5,******,37,******,45.2,WMa
539,12152,8710,2170,5,30,449,1.5,******,37,******,45.1,WMa
540,12155,8730,2220,5,30,450,1.5,******,37,******,45.3,WMa
541,12158,8750,2220,5,30,452,1.5,******,37,******,45.4,WMa
542,12161,8710,2210,5,30,449,1.5,******,37,******,45.2,WMa
543,12164,8750,2220,5,30,451,1.5,******,37,******,45.4,WMa
544,12167,8720,2220,5,30,450,1.5,******,37,******,45.2,WMa
545,12170,8720,2210,5,30,450,1.5,******,37,******,45.2,WMa
546,12173,8730,2210,5,30,450,1.5,******,37,******,45.3,WMa
547,12176,8740,2220,5,30,451,1.5,******,37,******,45.3,WMa
548,12179,8710,2210,5,30,449,1.5,******,37,******,45.2,WMa
549,12182,8730,2200,5,30,450,1.5,******,37,******,45.3,WMa
550,12185,8720,2220,5,30,450,1.5,******,37,******,45.2,WMa
551,12188,8740,2180,5,30,451,1.5,******,37,******,45.3,"MV-,WMa"
552,12191,8730,2220,5,30,450,1.5,******,37,******,45.3,WMa
553,12194,8720,2220,5,30,450,1.5,******,37,******,45.3,WMa
554,12197,8730,2210,5,30,450,1.5,******,37,******,45.2,WMa
555,12200,8730,2200,5,30,450,1.5,******,37,******,45.3,WMa
556,12203,8740,2210,5,30,451,1.5,******,37,******,45.3,WMa
557,12206,8720,2220,5,30,450,1.5,******,37,******,45.2,WMa
558,12209,8730,2210,5,30,450,1.5,******,37,******,45.3,WMa
559,12212,8730,2210,5,30,450,1.5,******,37,******,45.3,WMa
560,12215,8730,2210,5,30,450,1.5,******,37,******,45.3,WMa
561,12218,8720,2210,5,30,450,1.5,******,37,******,45.2,WMa
562,12221,8730,2220,5,30,450,1.5,******,37,******,45.3,WMa
563,12224,8700,2220,5,30,449,1.5,******,37,******,45.2,WMa
564,12227,8740,2200,5,30,451,1.5,******,37,******,45.3,WMa
565,12230,8740,2220,5,30,451,1.5,******,37,******,45.3,WMa
566,12233,8720,2250,5,30,450,1.5,******,37,******,45.3,WMa
567,12236,8730,2210,5,30,450,1.5,******,37,******,45.3,WMa
568,12239,8730,2200,5,30,450,1.5,******,37,******,45.2,WMa
569,12242,8740,2220,5,30,451,1.5,******,37,******,45.3,WMa
570,12245,8710,2210,5,30,449,1.5,******,37,******,45.2,WMa
571,12248,8740,2210,5,30,451,1.5,******,37,******,45.3,WMa
572,12251,8740,2210,5,30,451,1.5,******,37,******,45.3,"MV-,WMa"
573,12254,8730,2210,5,30,450,1.5,******,37,******,45.3,WMa
574,12257,8730,2200,5,30,450,1.5,******,37,******,45.3,WMa
575,12260,8740,2220,5,30,451,1.5,******,37,******,45.3,WMa
576,12263,8730,2210,5,30,450,1.5,******,37,******,45.2,WMa
577,12266,8730,2210,5,30,450,1.5,******,37,******,45.2,WMa
578,12269,8760,2200,5,30,452,1.5,******,37,******,45.4,WMa
579,12272,8750,2200,5,30,451,1.5,******,37,******,45.3,WMa
580,12275,8740,2200,5,30,451,1.5,******,37,******,45.3,WMa
581,12278,8740,2200,5,30,451,1.5,******,37,******,45.3,WMa
582,12281,8730,2200,5,30,450,1.5,******,37,******,45.2,WMa
583,12284,8740,2210,5,30,451,1.5,******,37,******,45.3,WMa
584,12287,8750,2220,5,30,452,1.5,******,37,******,45.4,WMa
585,12290,8760,2210,5,30,452,1.5,******,37,******,45.4,WMa
586,12293,8740,2210,5,30,451,1.5,******,37,******,45.3,WMa
587,12296,8740,2220,5,30,451,1.5,******,37,******,45.3,WMa
588,12299,8740,2210,5,30,451,1.5,******,37,******,45.3,WMa
589,12302,8740,2220,5,30,451,1.5,******,37,******,45.3,WMa
590,12305,8740,2210,5,30,451,1.5,******,37,******,45.3,WMa
591,12308,8740,2210,5,30,451,1.5,******,37,******,45.3,WMa
592,12311,8780,2210,5,30,453,1.5,******,37,******,45.5,WMa
593,12314,8750,2220,5,30,451,1.5,******,37,******,45.3,WMa
594,12317,8740,2200,5,30,451,1.5,******,37,******,45.3,WMa
595,12320,8740,2210,5,30,451,1.5,******,37,******,45.3,WMa
596,12323,8740,2200,5,30,450,1.5,******,37,******,45.3,WMa
597,12326,8760,2220,5,30,452,1.5,******,37,******,45.4,WMa
598,12329,8740,2220,5,30,451,1.5,******,37,******,45.3,"MV-,WMa"
599,12332,8750,2210,5,30,451,1.5,******,37,******,45.4,WMa
600,12335,8720,2210,5,30,450,1.5,******,37,******,45.2,WMa
,,,,,,,,,,,,
Interval:,,,15,,,,,,,,,
Number of Data Points:,,,28,,,,,,,,,
,,,,,,,,,,,,
Time Setting:,,,28 Meas. Pts.,,,,,,,,,
,,,Meas. Pt. Duration 6.4285714 s,,,,,,,,,
Event Control:,,,Standard Mode,,,,,,,,,
"  Terminate test, ...",,,...if d(gamma)/dt > 1000 1/s,,,,,,,,,
"  Terminate test, ...",,,...if M > 200 mNm,,,,,,,,,
"  Terminate test, ...",,,...if FN < -50 N or > 50 N,,,,,,,,,
Measuring Profile:,,,,,,,,,,,,
  Shear Rate,,,d(gamma)/dt = 0.1 ... 50 1/s log; |Slope| = 10.003816 Pt. / dec ,,,,,,,,,
,,,,,,,,,,,,
Meas. Pts.,Time,Storage Modulus,Loss Modulus,Strain,Angular Frequency,Shear Stress,Shear Rate,Viscosity,Temperature,Speed,Torque,Status
,[s],[Pa],[Pa],[%],[rad/s],[Pa],[1/s],[Pa·s],[°C],[1/min],[µNm],[]
1,12300,******,******,47.7,******,282,0.1,2820,37,0.12,28.3,Dy_auto
2,12300,******,******,124,******,372,0.13,2950,37,0.15,37.4,Dy_auto
3,12400,******,******,221,******,472,0.16,2980,37,0.19,47.5,Dy_auto
4,12400,******,******,342,******,583,0.2,2920,37,0.24,58.6,Dy_auto
5,12400,******,******,495,******,711,0.25,2830,37,0.3,71.5,Dy_auto
6,12400,******,******,688,******,868,0.32,2740,37,0.38,87.2,Dy_auto
7,12400,******,******,930,******,1050,0.4,2640,37,0.48,106,Dy_auto
8,12400,******,******,1240,******,1280,0.5,2560,37,0.6,129,Dy_auto
9,12400,******,******,1620,******,1560,0.63,2480,37,0.75,157,Dy_auto
10,12400,******,******,2100,******,1900,0.79,2400,37,0.95,191,Dy_auto
11,12400,******,******,2710,******,2340,1,2340,37,1.19,235,Dy_auto
12,12400,******,******,3480,******,2900,1.26,2310,37,1.5,292,Dy_auto
13,12400,******,******,4440,******,3620,1.58,2290,37,1.89,364,Dy_auto
14,12400,******,******,5660,******,4450,1.99,2230,37,2.38,447,Dy_auto
15,12400,******,******,7180,******,5260,2.51,2100,37,2.99,529,Dy_auto
16,12400,******,******,9110,******,5450,3.16,1720,37,3.77,548,Dy_auto
17,12400,******,******,11500,******,4490,3.98,1130,37,4.75,451,Dy_auto
18,12500,******,******,14600,******,2520,5.01,504,37,5.97,254,Dy_auto
19,12500,******,******,18400,******,2090,6.3,332,37,7.52,210,Dy_auto
20,12500,******,******,23300,******,1840,7.93,232,37,9.46,185,Dy_auto
21,12500,******,******,29300,******,1570,9.98,158,37,11.9,158,Dy_auto
22,12500,******,******,37000,******,1340,12.6,106,37,15,134,Dy_auto
23,12500,******,******,46600,******,1160,15.8,73.2,37,18.9,116,Dy_auto
24,12500,******,******,58800,******,932,19.9,46.8,37,23.8,93.8,Dy_auto
25,12500,******,******,74100,******,723,25.1,28.9,37,29.9,72.7,Dy_auto
26,12500,******,******,93300,******,532,31.6,16.9,37,37.7,53.5,Dy_auto
27,12500,******,******,117000,******,474,39.7,11.9,37,47.4,47.6,Dy_auto
28,12500,******,******,148000,******,364,50,7.27,37,59.7,36.6,Dy_auto