File: exampledata/TXT_N2.csv
Meas. Pts.,Time,Storage Modulus,Loss Modulus,Strain,Angular Frequency,Shear Stress,Shear Rate,Viscosity,Temperature,Speed,Torque,Status
,[s],[Pa],[Pa],[%],[rad/s],[Pa],[1/s],[Pa·s],[°C],[1/min],[µNm],[]
1,5,9500,929,4.99,30,476,1.5,******,36.9,******,47.9,WMa
2,10,9570,1130,5,30,482,1.5,******,36.9,******,48.5,
3,15,9610,1130,5,30,484,1.5,******,36.9,******,48.6,
4,20,9640,1140,5,30,485,1.5,******,36.9,******,48.8,
5,25,9670,1150,5,30,487,1.5,******,37,******,49,
6,30,9700,1150,5,30,488,1.5,******,37,******,49.1,
7,35,9730,1150,5,30,490,1.5,******,37,******,49.3,
8,40,9780,1150,5,30,492,1.5,******,37,******,49.5,
9,45,9780,1170,5,30,493,1.5,******,37,******,49.5,
10,50,9810,1180,5,30,494,1.5,******,37,******,49.7,
11,55,9830,1170,5,30,495,1.5,******,37,******,49.8,
12,60,9850,1190,5,30,496,1.5,******,37,******,49.9,
13,65,9880,1190,5,30,497,1.5,******,37,******,50,
14,70,9900,1200,5,30,498,1.5,******,37,******,50.1,
15,75,9930,1200,5,30,500,1.5,******,37,******,50.3,
16,80,9920,1150,5,30,499,1.5,******,37,******,50.2,
17,85,9930,1260,5,30,500,1.5,******,37,******,50.3,
18,90,9970,1210,5,30,503,1.5,******,37,******,50.5,
19,95,9990,1200,5,30,503,1.5,******,36.9,******,50.6,
20,100,9930,1090,5,30,500,1.5,******,37,******,50.2,
21,105,10000,1210,5,30,505,1.5,******,37,******,50.8,
22,110,10000,1210,5,30,506,1.5,******,37,******,50.9,
23,115,10100,1220,5,30,506,1.5,******,37,******,50.9,
24,120,10100,1240,5,30,506,1.5,******,37,******,50.9,
25,125,10100,1230,5,30,507,1.5,******,37,******,51,
26,130,10100,1240,5,30,508,1.5,******,37,******,51.1,
27,135,10100,1240,5,30,508,1.5,******,37,******,51.1,
28,140,10100,1240,5,30,510,1.5,******,37,******,51.3,
29,145,10100,1240,5,30,510,1.5,******,37,******,51.3,
30,150,10100,1240,5,30,510,1.5,******,37,******,51.2,
31,155,10100,1250,5,30,511,1.5,******,37,******,51.4,
32,160,10200,1260,5,30,512,1.5,******,37,******,51.5,
33,165,10200,1250,5,30,512,1.5,******,37,******,51.5,
34,170,10200,1240,5,30,512,1.5,******,37,******,51.5,
35,175,10200,1250,5,30,513,1.5,******,37,******,51.6,
36,180,10200,1240,5,30,513,1.5,******,37,******,51.5,
37,185,10200,1260,5,30,513,1.5,******,37,******,51.6,
38,190,10200,1260,5,30,513,1.5,******,37,******,51.6,
39,195,10200,1250,5,30,513,1.5,******,37,******,51.6,
40,200,10200,1260,5,30,515,1.5,******,37,******,51.8,
41,205,10200,1270,5,30,514,1.5,******,37,******,51.7,
42,210,10200,1270,5,30,516,1.5,******,37,******,51.8,
43,215,10200,1280,5,30,515,1.5,******,37,******,51.8,
44,220,10200,1270,5,30,516,1.5,******,37,******,51.9,
45,225,10200,1250,5,30,516,1.5,******,37,******,51.9,
46,230,10300,1280,5,30,517,1.5,******,37,******,52,
47,235,10300,1270,5,30,517,1.5,******,37,******,52,
48,240,10300,1280,5,30,517,1.5,******,37,******,52,
49,245,10300,1280,5,30,518,1.5,******,37,******,52,
50,250,10300,1280,5,30,518,1.5,******,37,******,52.1,
51,255,10300,1280,5,30,519,1.5,******,37,******,52.2,
52,260,10300,1280,5,30,518,1.5,******,37,******,52.1,
53,265,10300,1270,5,30,519,1.5,******,37,******,52.2,
54,270,10300,1280,5,30,519,1.5,******,37,******,52.2,
55,275,10300,1280,5,30,520,1.5,******,37,******,52.2,
56,280,10300,1280,5,30,520,1.5,******,37,******,52.2,
57,285,10300,1290,5,30,520,1.5,******,37,******,52.3,
58,290,10300,1290,5,30,520,1.5,******,37,******,52.2,
59,295,10300,1300,5,30,520,1.5,******,37,******,52.3,
60,300,10300,1290,5,30,520,1.5,******,37,******,52.3,
61,305,10300,1280,5,30,520,1.5,******,37,******,52.3,
62,310,10300,1290,5,30,521,1.5,******,37,******,52.4,
63,315,10400,1290,5,30,522,1.5,******,37,******,52.5,
64,320,10400,1300,5,30,522,1.5,******,37,******,52.5,
65,325,10400,1280,5,30,522,1.5,******,37,******,52.5,
66,330,10400,1300,5,30,522,1.5,******,37,******,52.5,
67,335,10400,1290,5,30,524,1.5,******,37,******,52.6,
68,340,10400,1300,5,30,523,1.5,******,37,******,52.6,
69,345,10400,1310,5,30,523,1.5,******,37,******,52.6,
70,350,10400,1310,5,30,523,1.5,******,37,******,52.6,
71,355,10400,1310,5,30,524,1.5,******,37,******,52.6,
72,360,10400,1310,5,30,524,1.5,******,37,******,52.7,
73,365,10400,1300,5,30,524,1.5,******,37,******,52.7,
74,370,10400,1300,5,30,524,1.5,******,37,******,52.7,
75,375,10400,1290,5,30,524,1.5,******,37,******,52.7,
76,380,10400,1300,5,30,525,1.5,******,37,******,52.8,
77,385,10400,1320,5,30,525,1.5,******,37,******,52.8,
78,390,10400,1300,5,30,526,1.5,******,37,******,52.8,
79,395,10400,1300,5,30,526,1.5,******,37,******,52.9,
80,400,10400,1310,5,30,526,1.5,******,37,******,52.9,
,,,,,,,,,,,,
Interval:,,,2,,,,,,,,,
Number of Data Points:,,,31,,,,,,,,,
,,,,,,,,,,,,
Time Setting:,,,31 Meas. Pts.,,,,,,,,,
Measuring Profile:,,,,,,,,,,,,
#NAME?,,,Amplitude gamma = 5 %,,,,,,,,,
,,,Angular Frequency omega = 100 ... 0.1 rad/s log; |Slope| = 10 Pt. / dec ,,,,,,,,,
,,,,,,,,,,,,
Meas. Pts.,Time,Storage Modulus,Loss Modulus,Strain,Angular Frequency,Shear Stress,Shear Rate,Viscosity,Temperature,Speed,Torque,Status
,[s],[Pa],[Pa],[%],[rad/s],[Pa],[1/s],[Pa·s],[°C],[1/min],[µNm],[]
1,410,11400,1140,5,100,573,5,******,37,******,57.6,
2,418,11100,798,5,79.4,557,3.97,******,37,******,56,
3,425,11000,851,5,63.1,549,3.16,******,37,******,55.2,
4,432,10700,968,5,50.1,540,2.51,******,37,******,54.3,
5,439,10700,1110,5,39.8,536,1.99,******,37,******,53.9,
6,448,10500,1270,5,31.6,530,1.58,******,37,******,53.3,
7,458,10400,1470,5,25.1,523,1.26,******,37,******,52.6,
8,465,10200,1710,5,20,517,1,******,37,******,51.9,
9,472,9960,1970,5,15.8,508,0.79,******,37,******,51.1,
10,478,9700,2260,5,12.6,498,0.63,******,37,******,50.1,
11,486,9370,2570,5,10,486,0.5,******,37,******,48.8,
12,493,8990,2910,4.99,7.94,471,0.4,******,37,******,47.4,
13,502,8510,3250,4.99,6.31,454,0.32,******,37,******,45.6,
14,509,7950,3570,4.99,5.01,435,0.25,******,37,******,43.7,
15,517,7320,3860,4.99,3.98,412,0.2,******,37,******,41.5,
16,527,6590,4090,4.99,3.16,387,0.16,******,37,******,38.9,
17,540,5800,4240,4.99,2.51,359,0.13,******,37,******,36.1,
18,560,4970,4290,5,2,328,0.1,******,37,******,33,
19,586,4130,4230,5,1.58,296,0.08,******,37,******,29.7,
20,617,3320,4040,5.01,1.26,262,0.06,******,37,******,26.3,
21,656,2580,3740,5,1,227,0.05,******,37,******,22.9,
22,693,1940,3370,5.01,0.79,195,0.04,******,37,******,19.6,
23,739,1430,2950,5.01,0.63,164,0.03,******,37,******,16.5,
24,797,1030,2530,5.01,0.5,137,0.03,******,37,******,13.8,
25,869,728,2140,5.01,0.4,113,0.02,******,37,******,11.4,
26,929,513,1780,5.01,0.32,92.7,0.02,******,37,******,9.32,
27,1010,363,1470,5.01,0.25,75.7,0.01,******,37,******,7.61,
28,1100,257,1200,5.01,0.2,61.5,0.01,******,37,******,6.19,
29,1220,185,982,5.01,0.16,50.1,0.01,******,37,******,5.03,
30,1450,136,802,5.01,0.13,40.8,0.01,******,37,******,4.1,
31,1730,102,655,5.01,0.1,33.2,0.01,******,37,******,3.34,
,,,,,,,,,,,,
Interval:,,,3,,,,,,,,,
Number of Data Points:,,,80,,,,,,,,,
,,,,,,,,,,,,
Time Setting:,,,80 Meas. Pts.,,,,,,,,,
,,,Meas. Pt. Duration 5 s,,,,,,,,,
Event Control:,,,Standard Mode,,,,,,,,,
"  Terminate test, ...",,,...if M > 75 mNm,,,,,,,,,
Measuring Profile:,,,,,,,,,,,,
#NAME?,,,Amplitude gamma = 5 %,,,,,,,,,
,,,Angular Frequency omega = 30 rad/s,,,,,,,,,
,,,,,,,,,,,,
Meas. Pts.,Time,Storage Modulus,Loss Modulus,Strain,Angular Frequency,Shear Stress,Shear Rate,Viscosity,Temperature,Speed,Torque,Status
,[s],[Pa],[Pa],[%],[rad/s],[Pa],[1/s],[Pa·s],[°C],[1/min],[µNm],[]
1,invalid point,,,,,,,,,,,
2,1740,,,,,,,,,,,
3,1745,,,,,,,,,,,
4,1750,,,,,,,,,,,
5,1755,,,,,,,,,,,
6,1760,,,,,,,,,,,
7,1765,,,,,,,,,,,
8,1770,,,,,,,,,,,
9,1775,,,,,,,,,,,
10,1780,,,,,,,,,,,
11,1785,,,,,,,,,,,
12,1790,,,,,,,,,,,
13,1795,,,,,,,,,,,
14,1800,,,,,,,,,,,
15,1805,,,,,,,,,,,
16,1810,,,,,,,,,,,
17,1815,,,,,,,,,,,
18,1820,,,,,,,,,,,
19,1825,,,,,,,,,,,
20,1830,11200,1320,5.17,30,583,1.55,******,37,******,58.6,WMa
21,1835,11200,1420,5,30,565,1.5,******,37,******,56.8,
22,1840,11200,1410,5,30,565,1.5,******,37,******,56.8,
23,1845,11200,1420,5,30,565,1.5,******,37,******,56.8,
24,1850,11200,1420,5,30,565,1.5,******,37,******,56.8,
25,1855,11200,1420,5,30,564,1.5,******,37,******,56.7,
26,1860,11200,1420,5,30,565,1.5,******,37,******,56.8,
27,1865,11200,1440,5,30,564,1.5,******,37,******,56.7,
28,1870,11200,1420,5,30,566,1.5,******,37,******,56.9,
29,1875,11200,1420,5,30,565,1.5,******,37,******,56.8,
30,1880,11200,1420,5,30,565,1.5,******,37,******,56.8,
31,1885,11200,1420,5,30,565,1.5,******,37,******,56.9,
32,1890,11200,1430,5,30,566,1.5,******,37,******,56.9,
33,1895,11200,1430,5,30,566,1.5,******,37,******,56.9,
34,1900,11200,1430,5,30,565,1.5,******,37,******,56.8,
35,1905,11200,1420,5,30,565,1.5,******,37,******,56.9,
36,1910,11200,1430,5,30,566,1.5,******,37,******,56.9,
37,1915,11200,1420,5,30,566,1.5,******,37,******,56.9,
38,1920,11200,1420,5,30,566,1.5,******,37,******,56.9,
39,1925,11200,1420,5,30,566,1.5,******,37,******,56.9,
40,1930,11200,1420,5,30,566,1.5,******,37,******,56.9,
41,1935,11200,1420,5,30,566,1.5,******,37,******,56.9,
42,1940,11200,1420,5,30,566,1.5,******,37,******,56.9,
43,1945,11200,1420,5,30,566,1.5,******,37,******,56.9,
44,1950,11200,1420,5,30,566,1.5,******,37,******,56.9,
45,1955,11200,1410,5,30,566,1.5,******,37,******,56.9,
46,1960,11200,1430,5,30,566,1.5,******,37,******,56.9,
47,1965,11200,1420,5,30,566,1.5,******,37,******,56.9,
48,1970,11200,1410,5,30,565,1.5,******,37,******,56.8,
49,1975,11200,1420,5,30,566,1.5,******,37,******,56.9,
50,1980,11200,1420,5,30,566,1.5,******,37,******,56.9,
51,1985,11200,1410,5,30,566,1.5,******,37,******,56.9,
52,1990,11200,1430,5,30,567,1.5,******,37,******,57,
53,1995,11200,1410,5,30,567,1.5,******,37,******,57,
54,2000,11200,1420,5,30,566,1.5,******,37,******,57,
55,2005,11200,1420,5,30,567,1.5,******,37,******,57,
56,2010,11200,1420,5,30,567,1.5,******,37,******,57,
57,2015,11200,1420,5,30,566,1.5,******,37,******,56.9,
58,2020,11300,1430,5,30,567,1.5,******,37,******,57,
59,2025,11300,1410,5,30,567,1.5,******,37,******,57,
60,2030,11200,1430,5,30,567,1.5,******,37,******,57,
61,2035,11200,1430,5,30,567,1.5,******,37,******,57,
62,2040,11300,1400,5,30,567,1.5,******,37,******,57,
63,2045,11300,1430,5,30,567,1.5,******,37,******,57,
64,2050,11200,1420,5,30,567,1.5,******,37,******,57,
65,2055,11300,1430,5,30,567,1.5,******,37,******,57,
66,2060,11200,1430,5,30,567,1.5,******,37,******,57,
67,2065,11300,1420,5,30,567,1.5,******,37,******,57.1,
68,2070,11300,1430,5,30,568,1.5,******,37,******,57.1,
69,2075,11300,1420,5,30,568,1.5,******,37,******,57.1,
70,2080,11300,1420,5,30,567,1.5,******,37,******,57,
71,2085,11300,1440,5,30,568,1.5,******,37,******,57.1,
72,2090,11300,1420,5,30,568,1.5,******,37,******,57.1,
73,2095,11300,1420,5,30,568,1.5,******,37,******,57.1,
74,2100,11300,1440,5,30,568,1.5,******,37,******,57.1,
75,2105,11300,1430,5,30,568,1.5,******,37,******,57.1,
76,2110,11300,1420,5,30,568,1.5,******,37,******,57.1,
77,2115,11300,1440,5,30,568,1.5,******,37,******,57.1,
78,2120,11300,1410,5,30,568,1.5,******,37,******,57.1,
79,2125,11300,1430,5,30,568,1.5,******,37,******,57.1,
80,2130,11300,1420,5,30,568,1.5,******,37,******,57.1,
,,,,,,,,,,,,
Interval:,,,4,,,,,,,,,
Number of Data Points:,,,113,,,,,,,,,
,,,,,,,,,,,,
Time Setting:,,,113 Meas. Pts.,,,,,,,,,
,,,Meas. Pt. Duration 5 s,,,,,,,,,
Measuring Profile:,,,,,,,,,,,,
#NAME?,,,Amplitude gamma = 0.1 ... 500 % log; |Slope| = 30.278699 Pt. / dec ,,,,,,,,,
,,,Angular Frequency omega = 30 rad/s,,,,,,,,,
,,,,,,,,,,,,
Meas. Pts.,Time,Storage Modulus,Loss Modulus,Strain,Angular Frequency,Shear Stress,Shear Rate,Viscosity,Temperature,Speed,Torque,Status
,[s],[Pa],[Pa],[%],[rad/s],[Pa],[1/s],[Pa·s],[°C],[1/min],[µNm],[]
1,2135,0,21300,0.1,30,21.6,0.03,******,37,******,2.17,"MV-,WMa"
2,2140,11600,183,0.11,30,12.4,0.03,******,37,******,1.25,WMa
3,2145,21700,0,0.12,30,25.7,0.04,******,37,******,2.58,"MV-,WMa"
4,2150,24500,0,0.13,30,31.6,0.04,******,37,******,3.18,"ME-,WMa"
5,2155,0,4720,0.14,30,6.57,0.04,******,37,******,0.66,"MV-,WMa"
6,2160,12100,1330,0.15,30,17.8,0.04,******,37,******,1.79,
7,2165,5430,14200,0.16,30,24.4,0.05,******,37,******,2.45,WMa
8,2170,35600,0,0.17,30,60.8,0.05,******,37,******,6.12,"MV-,WMa"
9,2175,12000,996,0.19,30,22.9,0.06,******,37,******,2.3,WMa
10,2180,11400,1420,0.2,30,23.1,0.06,******,37,******,2.32,WMa
11,2185,11900,633,0.22,30,25.9,0.07,******,37,******,2.6,WMa
12,2190,8150,2580,0.23,30,19.9,0.07,******,37,******,2,WMa
13,2195,11700,2060,0.25,30,29.7,0.07,******,37,******,2.98,WMa
14,2200,14200,11600,0.27,30,49.8,0.08,******,37,******,5.01,WMa
15,2205,11000,3680,0.29,30,33.9,0.09,******,37,******,3.41,WMa
16,2210,11300,0,0.32,30,36,0.1,******,37,******,3.62,"ME-,WMa"
17,2215,15300,3240,0.34,30,53.8,0.1,******,37,******,5.41,WMa
18,2220,10600,0,0.37,30,39.2,0.11,******,37,******,3.94,"MV-,WMa"
19,2225,10800,1910,0.4,30,43.5,0.12,******,37,******,4.37,WMa
20,2230,14200,1360,0.43,30,60.6,0.13,******,37,******,6.09,WMa
21,2235,15800,5260,0.46,30,76.1,0.14,******,37,******,7.65,WMa
22,2240,11800,3510,0.5,30,61.8,0.15,******,37,******,6.22,WMa
23,2245,7700,6700,0.54,30,54.6,0.16,******,37,******,5.49,WMa
24,2250,8000,1690,0.58,30,47.5,0.17,******,37,******,4.77,WMa
25,2255,17100,6720,0.63,30,115,0.19,******,37,******,11.6,WMa
26,2260,11400,0,0.68,30,76.6,0.2,******,37,******,7.7,"MV-,WMa"
27,2265,12100,715,0.73,30,88.2,0.22,******,37,******,8.87,WMa
28,2270,15400,1070,0.78,30,121,0.24,******,37,******,12.2,WMa
29,2275,10900,602,0.85,30,93.1,0.26,******,37,******,9.36,WMa
30,2280,11200,6240,0.91,30,117,0.27,******,37,******,11.8,WMa
31,2285,13600,0,0.98,30,133,0.3,******,37,******,13.4,"MV-,WMa"
32,2290,14200,1410,1.06,30,151,0.32,******,37,******,15.2,WMa
33,2295,12600,2830,1.14,30,147,0.34,******,37,******,14.8,WMa
34,2300,11400,1370,1.23,30,142,0.37,******,37,******,14.3,WMa
35,2305,11900,1180,1.33,30,158,0.4,******,37,******,15.9,WMa
36,2310,7650,1480,1.44,30,112,0.43,******,37,******,11.3,WMa
37,2315,10100,475,1.55,30,156,0.46,******,37,******,15.7,WMa
38,2320,11400,1170,1.67,30,192,0.5,******,37,******,19.3,WMa
39,2325,10800,1730,1.81,30,198,0.54,******,37,******,19.9,WMa
40,2330,8710,1310,1.95,30,172,0.59,******,37,******,17.3,WMa
41,2335,11900,2230,2.1,30,255,0.63,******,37,******,25.6,WMa
42,2340,11300,1670,2.27,30,259,0.68,******,37,******,26.1,WMa
43,2345,12000,805,2.45,30,293,0.73,******,37,******,29.5,WMa
44,2350,12100,1470,2.64,30,321,0.79,******,37,******,32.3,WMa
45,2355,11900,2010,2.85,30,344,0.86,******,37,******,34.6,WMa
46,2360,11500,0,3.07,30,355,0.92,******,37,******,35.7,"MV-,WMa"
47,2365,12200,713,3.32,30,405,1,******,37,******,40.7,WMa
48,2370,11800,1530,3.58,30,425,1.07,******,37,******,42.8,WMa
49,2375,11100,1000,3.86,30,430,1.16,******,37,******,43.2,WMa
50,2380,11300,1960,4.17,30,476,1.25,******,37,******,47.8,WMa
51,2385,11300,1460,4.49,30,512,1.35,******,37,******,51.5,WMa
52,2390,10400,1320,4.85,30,507,1.45,******,37,******,51,WMa
53,2395,11400,1420,5.24,30,600,1.57,******,37,******,60.3,WMa
54,2400,11400,1410,5.65,30,647,1.69,******,37,******,65,WMa
55,2405,12700,467,6.09,30,777,1.83,******,37,******,78.1,WMa
56,2410,11500,1490,6.58,30,766,1.97,******,37,******,77,WMa
57,2415,11500,1750,7.09,30,827,2.13,******,37,******,83.1,WMa
58,2420,11300,1410,7.65,30,873,2.3,******,37,******,87.7,WMa
59,2425,10800,1760,8.26,30,902,2.48,******,37,******,90.7,WMa
60,2430,11400,1420,8.91,30,1020,2.67,******,37,******,103,WMa
61,2435,11500,1660,9.62,30,1110,2.89,******,37,******,112,WMa
62,2440,11200,1680,10.4,30,1180,3.11,******,37,******,119,WMa
63,2445,12000,1050,11.2,30,1350,3.36,******,37,******,136,WMa
64,2450,11500,1510,12.1,30,1400,3.62,******,37,******,141,WMa
65,2455,11300,1460,13,30,1480,3.91,******,37,******,149,WMa
66,2460,11000,2170,14.1,30,1580,4.22,******,37,******,159,WMa
67,2465,11200,1440,15.2,30,1720,4.55,******,37,******,173,WMa
68,2470,10600,1180,16.4,30,1750,4.91,******,37,******,176,WMa
69,2475,11300,1580,17.7,30,2020,5.3,******,37,******,203,WMa
70,2480,11300,1230,19.1,30,2180,5.72,******,37,******,219,WMa
71,2485,10800,1620,20.6,30,2250,6.17,******,37,******,226,WMa
72,2490,12100,1800,22.2,30,2720,6.66,******,37,******,273,WMa
73,2495,11000,936,24,30,2650,7.19,******,37,******,266,WMa
74,2500,11100,1680,25.8,30,2900,7.75,******,37,******,292,WMa
75,2505,12000,1120,27.9,30,3350,8.37,******,37,******,337,WMa
76,2510,10200,967,30.1,30,3080,9.03,******,37,******,309,WMa
77,2515,11200,1690,32.5,30,3680,9.74,******,37,******,370,WMa
78,2520,11400,971,35,30,4010,10.5,******,37,******,404,WMa
79,2525,11800,1180,37.8,30,4480,11.3,******,37,******,451,WMa
80,2530,10200,962,40.8,30,4180,12.2,******,37,******,421,WMa
81,2535,11000,1230,44,30,4880,13.2,******,37,******,490,WMa
82,2540,10800,1700,47.5,30,5200,14.2,******,37,******,523,WMa
83,2545,10300,1590,51.2,30,5330,15.4,******,37,******,536,WMa
84,2550,10600,1940,55.2,30,5950,16.6,******,37,******,599,WMa
85,2555,9910,1950,59.6,30,6020,17.9,******,37,******,605,WMa
86,2560,9260,2550,64.2,30,6170,19.3,******,37,******,620,WMa
87,2565,7080,2700,69.3,30,5250,20.8,******,37,******,528,WMa
88,2570,6370,2270,74.8,30,5050,22.4,******,37,******,508,WMa
89,2575,4490,1940,80.6,30,3940,24.2,******,37,******,396,WMa
90,2580,3090,973,87,30,2820,26.1,******,37,******,283,WMa
91,2585,2370,1050,93.9,30,2440,28.2,******,37,******,245,WMa
92,2590,980,747,101,30,1250,30.4,******,37,******,125,
93,2595,679,578,109,30,974,32.8,******,37,******,97.9,
94,2600,487,489,118,30,814,35.4,******,37,******,81.9,
95,2605,355,387,127,30,668,38.2,******,37,******,67.2,
96,2610,264,341,137,30,591,41.2,******,37,******,59.4,
97,2615,185,312,148,30,537,44.4,******,37,******,54,
98,2620,126,272,160,30,478,47.9,******,37,******,48.1,
99,2625,58.5,247,172,30,437,51.7,******,37,******,43.9,
100,2630,11.3,225,186,30,420,55.8,******,37,******,42.2,
101,2635,0,190,201,30,381,60.2,******,37,******,38.3,"ME-,taD"
102,2640,0,185,217,30,400,65,******,37,******,40.2,"ME-,taD"
103,2645,0,186,234,30,434,70.1,******,37,******,43.6,"ME-,taD"
104,2650,0,175,252,30,442,75.7,******,37,******,44.4,"ME-,taD"
105,2655,0,172,272,30,468,81.6,******,37,******,47,"ME-,taD"
106,2660,0,167,294,30,491,88.1,******,37,******,49.4,"ME-,taD"
107,2665,0,141,317,30,448,95,******,37,******,45.1,"ME-,taD"
108,2670,0,120,342,30,411,103,******,37,******,41.4,"ME-,taD"
109,2675,0,91.6,369,30,338,111,******,37,******,34,"ME-,taD"
110,2680,0,72,398,30,286,119,******,37,******,28.8,"ME-,taD"
111,2685,0,59.4,429,30,255,129,******,37,******,25.7,"ME-,taD"
112,2690,0,53.3,463,30,247,139,******,37,******,24.8,"ME-,taD"
113,2695,0,67,500,30,335,150,******,37,******,33.7,"ME-,taD"
,,,,,,,,,,,,
Interval:,,,5,,,,,,,,,
Number of Data Points:,,,80,,,,,,,,,
,,,,,,,,,,,,
Time Setting:,,,80 Meas. Pts.,,,,,,,,,
,,,Meas. Pt. Duration 5 s,,,,,,,,,
Event Control:,,,Standard Mode,,,,,,,,,
"  Terminate test, ...",,,...if M > 75 mNm,,,,,,,,,
Measuring Profile:,,,,,,,,,,,,
#NAME?,,,Amplitude gamma = 5 %,,,,,,,,,
,,,Angular Frequency omega = 30 rad/s,,,,,,,,,
,,,,,,,,,,,,
Meas. Pts.,Time,Storage Modulus,Loss Modulus,Strain,Angular Frequency,Shear Stress,Shear Rate,Viscosity,Temperature,Speed,Torque,Status
,[s],[Pa],[Pa],[%],[rad/s],[Pa],[1/s],[Pa·s],[°C],[1/min],[µNm],[]
1,2700,0,222,4.97,30,11,1.49,******,37,******,1.11,"MV-,WMa"
2,2705,315,88.5,5,30,16.4,1.5,******,37,******,1.64,
3,2710,533,150,5,30,27.7,1.5,******,37,******,2.79,
4,2715,929,177,5,30,47.3,1.5,******,37,******,4.76,
5,2720,1190,212,5,30,60.6,1.5,******,37,******,6.09,
6,2725,1430,236,5,30,72.3,1.5,******,37,******,7.27,
7,2730,1650,253,5,30,83.5,1.5,******,37,******,8.4,
8,2735,1890,283,5,30,95.6,1.5,******,37,******,9.61,
9,2740,2110,325,5,30,107,1.5,******,37,******,10.7,
10,2745,2310,332,5,30,117,1.5,******,37,******,11.7,
11,2750,2490,340,5,30,126,1.5,******,37,******,12.7,
12,2755,2660,379,5,30,134,1.5,******,37,******,13.5,
13,2760,2880,394,5,30,145,1.5,******,37,******,14.6,
14,2765,3060,399,5,30,154,1.5,******,37,******,15.5,
15,2770,3230,438,5,30,163,1.5,******,37,******,16.4,
16,2775,3360,458,5,30,170,1.5,******,37,******,17.1,
17,2780,3560,477,5,30,180,1.5,******,37,******,18.1,
18,2785,3710,495,5,30,187,1.5,******,37,******,18.8,
19,2790,3820,519,5,30,193,1.5,******,37,******,19.4,
20,2795,3970,532,5,30,200,1.5,******,37,******,20.1,
21,2800,4100,539,5,30,207,1.5,******,37,******,20.8,
22,2805,4250,561,5,30,214,1.5,******,37,******,21.5,
23,2810,4380,575,5,30,221,1.5,******,37,******,22.2,
24,2815,4510,610,5,30,228,1.5,******,37,******,22.9,
25,2820,4630,611,5,30,234,1.5,******,37,******,23.5,
26,2825,4760,631,5,30,240,1.5,******,37,******,24.1,
27,2830,4900,639,5,30,247,1.5,******,37,******,24.8,
28,2835,5010,657,5,30,253,1.5,******,37,******,25.4,
29,2840,5150,683,5,30,260,1.5,******,37,******,26.1,
30,2845,5280,717,5,30,266,1.5,******,37,******,26.8,
31,2850,5440,725,5,30,274,1.5,******,37,******,27.6,
32,2855,5580,730,5,30,281,1.5,******,37,******,28.3,
33,2860,5690,749,5,30,287,1.5,******,37,******,28.9,
34,2865,5790,737,5,30,292,1.5,******,37,******,29.3,
35,2870,5900,757,5,30,297,1.5,******,37,******,29.9,
36,2875,6020,794,5,30,304,1.5,******,37,******,30.5,
37,2880,6120,785,5,30,309,1.5,******,37,******,31,
38,2885,6200,810,5,30,313,1.5,******,37,******,31.4,
39,2890,6290,818,5,30,317,1.5,******,37,******,31.9,
40,2895,6380,818,5,30,322,1.5,******,37,******,32.4,
41,2900,6570,877,5,30,332,1.5,******,37,******,33.3,
42,2905,6670,857,5,30,336,1.5,******,37,******,33.8,
43,2910,6770,880,5,30,342,1.5,******,37,******,34.4,
44,2915,6860,896,5,30,346,1.5,******,37,******,34.8,
45,2920,6940,899,5,30,350,1.5,******,37,******,35.2,
46,2925,7070,916,5,30,357,1.5,******,37,******,35.9,
47,2930,7160,923,5,30,361,1.5,******,37,******,36.3,
48,2935,7230,934,5,30,365,1.5,******,37,******,36.7,
49,2940,7320,943,5,30,369,1.5,******,37,******,37.1,
50,2945,7440,960,5,30,375,1.5,******,37,******,37.7,
51,2950,7530,973,5,30,380,1.5,******,37,******,38.2,
52,2955,7600,979,5,30,383,1.5,******,37,******,38.5,
53,2960,7670,987,5,30,387,1.5,******,37,******,38.9,
54,2965,7760,992,5,30,391,1.5,******,37,******,39.3,
55,2970,7840,1010,5,30,395,1.5,******,37,******,39.8,
56,2975,7910,1030,5,30,399,1.5,******,37,******,40.1,
57,2980,7980,1020,5,30,402,1.5,******,37,******,40.5,
58,2985,8030,1030,5,30,405,1.5,******,37,******,40.7,
59,2990,8090,1030,5,30,408,1.5,******,37,******,41,
60,2995,8190,1050,5,30,413,1.5,******,37,******,41.5,
61,3000,8240,1060,5,30,416,1.5,******,37,******,41.8,
62,3005,8290,1060,5,30,418,1.5,******,37,******,42,
63,3010,8360,1060,5,30,421,1.5,******,37,******,42.4,
64,3015,8400,1080,5,30,423,1.5,******,37,******,42.6,
65,3020,8470,1070,5,30,427,1.5,******,37,******,43,
66,3025,8530,1100,5,30,430,1.5,******,37,******,43.2,
67,3030,8600,1090,5,30,433,1.5,******,37,******,43.6,
68,3035,8640,1100,5,30,435,1.5,******,37,******,43.8,
69,3040,8700,1120,5,30,438,1.5,******,37,******,44.1,
70,3045,8750,1120,5,30,441,1.5,******,37,******,44.4,
71,3050,8780,1120,5,30,443,1.5,******,37,******,44.5,
72,3055,8840,1140,5,30,445,1.5,******,37,******,44.8,
73,3060,8890,1130,5,30,448,1.5,******,37,******,45.1,
74,3065,8940,1140,5,30,451,1.5,******,37,******,45.3,
75,3070,8990,1140,5,30,453,1.5,******,37,******,45.6,
76,3075,9030,1150,5,30,455,1.5,******,37,******,45.8,
77,3080,9090,1150,5,30,458,1.5,******,37,******,46.1,
78,3085,9110,1160,5,30,459,1.5,******,37,******,46.2,
79,3090,9180,1180,5,30,463,1.5,******,37,******,46.6,
80,3095,9260,1180,5,30,467,1.5,******,37,******,46.9,
,,,,,,,,,,,,
Interval:,,,6,,,,,,,,,
Number of Data Points:,,,600,,,,,,,,,
,,,,,,,,,,,,
Time Setting:,,,600 Meas. Pts.,,,,,,,,,
,,,Meas. Pt. Duration 3 s,,,,,,,,,
Event Control:,,,Standard Mode,,,,,,,,,
"  Terminate test, ...",,,...if M > 200 mNm,,,,,,,,,
Measuring Profile:,,,,,,,,,,,,
#NAME?,,,Amplitude gamma = 5 %,,,,,,,,,
,,,Angular Frequency omega = 30 rad/s,,,,,,,,,
,,,,,,,,,,,,
Meas. Pts.,Time,Storage Modulus,Loss Modulus,Strain,Angular Frequency,Shear Stress,Shear Rate,Viscosity,Temperature,Speed,Torque,Status
,[s],[Pa],[Pa],[%],[rad/s],[Pa],[1/s],[Pa·s],[°C],[1/min],[µNm],[]
1,3098,9280,1220,5.11,30,479,1.53,******,37,******,48.1,WMa
2,3101,9330,1180,5,30,470,1.5,******,37,******,47.3,
3,3104,9340,1190,5,30,471,1.5,******,37,******,47.3,
4,3107,9380,1200,5,30,473,1.5,******,37,******,47.6,
5,3110,9400,1200,5,30,474,1.5,******,37,******,47.6,
6,3113,9420,1210,5,30,475,1.5,******,37,******,47.7,
7,3116,9460,1200,5,30,477,1.5,******,37,******,48,
8,3119,9490,1210,5,30,478,1.5,******,37,******,48.1,
9,3122,9500,1210,5,30,479,1.5,******,37,******,48.1,
10,3125,9540,1210,5,30,481,1.5,******,37,******,48.3,
11,3128,9580,1220,5,30,483,1.5,******,37,******,48.6,
12,3131,9600,1220,5,30,484,1.5,******,37,******,48.6,
13,3134,9610,1210,5,30,484,1.5,******,37,******,48.7,
14,3137,9660,1210,5,30,487,1.5,******,37,******,48.9,
15,3140,9670,1230,5,30,487,1.5,******,37,******,49,
16,3143,9700,1240,5,30,489,1.5,******,37,******,49.2,
17,3146,9720,1230,5,30,490,1.5,******,37,******,49.3,
18,3149,9760,1240,5,30,492,1.5,******,37,******,49.5,
19,3152,9730,1250,5,30,490,1.5,******,37,******,49.3,
20,3155,9800,1240,5,30,494,1.5,******,37,******,49.6,
21,3158,9800,1240,5,30,494,1.5,******,37,******,49.7,
22,3161,9840,1230,5,30,496,1.5,******,37,******,49.8,
23,3164,9850,1250,5,30,497,1.5,******,37,******,49.9,
24,3167,9890,1260,5,30,498,1.5,******,37,******,50.1,
25,3170,9920,1240,5,30,500,1.5,******,37,******,50.3,
26,3173,9920,1240,5,30,500,1.5,******,37,******,50.3,
27,3176,9940,1270,5,30,501,1.5,******,37,******,50.4,
28,3179,9970,1260,5,30,503,1.5,******,37,******,50.5,
29,3182,9990,1260,5,30,504,1.5,******,37,******,50.6,
30,3185,9990,1270,5,30,504,1.5,******,37,******,50.6,
31,3188,10000,1270,5,30,505,1.5,******,37,******,50.8,
32,3191,10000,1280,5,30,506,1.5,******,37,******,50.9,
33,3194,10100,1270,5,30,507,1.5,******,37,******,51,
34,3197,10100,1290,5,30,508,1.5,******,37,******,51.1,
35,3200,10100,1280,5,30,510,1.5,******,37,******,51.3,
36,3203,10100,1300,5,30,510,1.5,******,37,******,51.3,
37,3206,10100,1280,5,30,511,1.5,******,37,******,51.4,
38,3209,10200,1290,5,30,512,1.5,******,37,******,51.5,
39,3212,10200,1310,5,30,515,1.5,******,37,******,51.8,
40,3215,10200,1290,5,30,514,1.5,******,37,******,51.7,
41,3218,10200,1290,5,30,516,1.5,******,37,******,51.9,
42,3221,10200,1300,5,30,516,1.5,******,37,******,51.9,
43,3224,10300,1300,5,30,517,1.5,******,37,******,52,
44,3227,10300,1310,5,30,518,1.5,******,37,******,52.1,
45,3230,10300,1300,5,30,519,1.5,******,37,******,52.2,
46,3233,10300,1310,5,30,520,1.5,******,37,******,52.2,
47,3236,10300,1300,5,30,519,1.5,******,37,******,52.2,
48,3239,10400,1300,5,30,523,1.5,******,37,******,52.6,
49,3242,10300,1330,5,30,522,1.5,******,37,******,52.4,
50,3245,10400,1320,5,30,523,1.5,******,37,******,52.6,
51,3248,10400,1330,5,30,524,1.5,******,37,******,52.7,
52,3251,10400,1310,5,30,525,1.5,******,37,******,52.8,
53,3254,10400,1340,5,30,526,1.5,******,37,******,52.9,
54,3257,10500,1310,5,30,527,1.5,******,37,******,53,
55,3260,10500,1330,5,30,527,1.5,******,37,******,53,
56,3263,10500,1300,5,30,529,1.5,******,37,******,53.2,
57,3266,10500,1340,5,30,529,1.5,******,37,******,53.2,
58,3269,10500,1350,5,30,530,1.5,******,37,******,53.3,
59,3272,10500,1330,5,30,530,1.5,******,37,******,53.3,
60,3275,10500,1310,5,30,530,1.5,******,37,******,53.3,
61,3278,10600,1340,5,30,532,1.5,******,37,******,53.5,
62,3281,10600,1350,5,30,532,1.5,******,37,******,53.5,
63,3284,10500,1350,5,30,531,1.5,******,37,******,53.4,
64,3287,10600,1340,5,30,533,1.5,******,37,******,53.6,
65,3290,10600,1350,5,30,534,1.5,******,37,******,53.7,
66,3293,10600,1350,5,30,536,1.5,******,37,******,53.9,
67,3296,10600,1360,5,30,536,1.5,******,37,******,53.9,
68,3299,10600,1340,5,30,534,1.5,******,37,******,53.7,
69,3302,10700,1340,5,30,538,1.5,******,37,******,54.1,
70,3305,10700,1340,5,30,537,1.5,******,37,******,54,
71,3308,10700,1350,5,30,538,1.5,******,37,******,54.1,
72,3311,10700,1350,5,30,538,1.5,******,37,******,54.1,
73,3314,10700,1350,5,30,538,1.5,******,37,******,54.1,
74,3317,10700,1350,5,30,538,1.5,******,37,******,54.1,
75,3320,10700,1370,5,30,541,1.5,******,37,******,54.4,
76,3323,10700,1350,5,30,539,1.5,******,37,******,54.2,
77,3326,10700,1350,5,30,541,1.5,******,37,******,54.4,
78,3329,10700,1340,5,30,541,1.5,******,37,******,54.3,
79,3332,10800,1350,5,30,542,1.5,******,37,******,54.5,
80,3335,10800,1370,5,30,542,1.5,******,37,******,54.5,
81,3338,10800,1360,5,30,543,1.5,******,37,******,54.6,
82,3341,10800,1360,5,30,543,1.5,******,37,******,54.6,
83,3344,10800,1360,5,30,542,1.5,******,37,******,54.5,
84,3347,10800,1360,5,30,545,1.5,******,37,******,54.8,
85,3350,10800,1360,5,30,545,1.5,******,37,******,54.8,
86,3353,10800,1370,5,30,546,1.5,******,37,******,54.9,
87,3356,10800,1390,5,30,546,1.5,******,37,******,54.9,
88,3359,10800,1360,5,30,546,1.5,******,37,******,54.9,
89,3362,10900,1380,5,30,548,1.5,******,37,******,55.1,
90,3365,10800,1370,5,30,546,1.5,******,37,******,54.9,
91,3368,10900,1370,5,30,548,1.5,******,37,******,55.1,
92,3371,10900,1360,5,30,548,1.5,******,37,******,55,
93,3374,10900,1360,5,30,548,1.5,******,37,******,55.1,
94,3377,10900,1360,5,30,548,1.5,******,37,******,55.1,
95,3380,10900,1380,5,30,548,1.5,******,37,******,55.1,
96,3383,10900,1380,5,30,549,1.5,******,37,******,55.2,
97,3386,10900,1380,5,30,549,1.5,******,37,******,55.2,
98,3389,10900,1380,5,30,550,1.5,******,37,******,55.3,
99,3392,10900,1350,5,30,550,1.5,******,37,******,55.3,
100,3395,10900,1410,5,30,551,1.5,******,37,******,55.4,
101,3398,10900,1370,5,30,551,1.5,******,37,******,55.4,
102,3401,10900,1380,5,30,552,1.5,******,37,******,55.5,
103,3404,11000,1380,5,30,553,1.5,******,37,******,55.6,
104,3407,11000,1390,5,30,553,1.5,******,37,******,55.6,
105,3410,11000,1390,5,30,553,1.5,******,37,******,55.6,
106,3413,11000,1390,5,30,553,1.5,******,37,******,55.6,
107,3416,11000,1400,5,30,554,1.5,******,37,******,55.7,
108,3419,11000,1410,5,30,554,1.5,******,37,******,55.7,
109,3422,11000,1390,5,30,555,1.5,******,37,******,55.8,
110,3425,11000,1370,5,30,553,1.5,******,37,******,55.6,
111,3428,11000,1390,5,30,555,1.5,******,37,******,55.8,
112,3431,11000,1390,5,30,556,1.5,******,37,******,55.9,
113,3434,11000,1390,5,30,557,1.5,******,37,******,56,
114,3437,11000,1410,5,30,556,1.5,******,37,******,55.9,
115,3440,11100,1400,5,30,557,1.5,******,37,******,56,
116,3443,11100,1400,5,30,557,1.5,******,37,******,56,
117,3446,11000,1380,5,30,557,1.5,******,37,******,56,
118,3449,11100,1400,5,30,558,1.5,******,37,******,56.1,
119,3452,11100,1390,5,30,559,1.5,******,37,******,56.2,
120,3455,11100,1400,5,30,558,1.5,******,37,******,56.2,
121,3458,11100,1400,5,30,559,1.5,******,37,******,56.2,
122,3461,11100,1390,5,30,559,1.5,******,37,******,56.3,
123,3464,11100,1400,5,30,559,1.5,******,37,******,56.2,
124,3467,11100,1410,5,30,561,1.5,******,37,******,56.4,
125,3470,11100,1400,5,30,560,1.5,******,37,******,56.4,
126,3473,11100,1400,5,30,561,1.5,******,37,******,56.4,
127,3476,11100,1420,5,30,561,1.5,******,37,******,56.4,
128,3479,11200,1400,5,30,562,1.5,******,37,******,56.5,
129,3482,11100,1400,5,30,562,1.5,******,37,******,56.5,
130,3485,11200,1430,5,30,562,1.5,******,37,******,56.5,
131,3488,11200,1400,5,30,564,1.5,******,37,******,56.7,
132,3491,11200,1430,5,30,565,1.5,******,37,******,56.8,
133,3494,11200,1410,5,30,562,1.5,******,37,******,56.6,
134,3497,11200,1420,5,30,563,1.5,******,37,******,56.6,
135,3500,11200,1380,5,30,563,1.5,******,37,******,56.6,
136,3503,11200,1400,5,30,565,1.5,******,37,******,56.8,
137,3506,11200,1420,5,30,564,1.5,******,37,******,56.8,
138,3509,11200,1420,5,30,565,1.5,******,37,******,56.8,
139,3512,11200,1410,5,30,565,1.5,******,37,******,56.8,
140,3515,11200,1410,5,30,567,1.5,******,37,******,57,
141,3518,11200,1420,5,30,565,1.5,******,37,******,56.8,
142,3521,11200,1420,5,30,566,1.5,******,37,******,56.9,
143,3524,11200,1410,5,30,566,1.5,******,37,******,56.9,
144,3527,11200,1430,5,30,567,1.5,******,37,******,57,
145,3530,11200,1400,5,30,567,1.5,******,37,******,57,
146,3533,11300,1440,5,30,568,1.5,******,37,******,57.1,
147,3536,11300,1410,5,30,568,1.5,******,37,******,57.1,
148,3539,11300,1420,5,30,568,1.5,******,37,******,57.2,
149,3542,11300,1440,5,30,567,1.5,******,37,******,57,
150,3545,11300,1400,5,30,569,1.5,******,37,******,57.3,
151,3548,11300,1410,5,30,568,1.5,******,37,******,57.1,
152,3551,11300,1430,5,30,570,1.5,******,37,******,57.3,
153,3554,11300,1430,5,30,570,1.5,******,37,******,57.3,
154,3557,11300,1420,5,30,570,1.5,******,37,******,57.3,
155,3560,11300,1430,5,30,570,1.5,******,37,******,57.3,
156,3563,11300,1440,5,30,570,1.5,******,37,******,57.3,
157,3566,11300,1430,5,30,570,1.5,******,37,******,57.3,
158,3569,11300,1420,5,30,571,1.5,******,37,******,57.4,
159,3572,11300,1410,5,30,570,1.5,******,37,******,57.4,
160,3575,11300,1440,5,30,569,1.5,******,37,******,57.3,
161,3578,11300,1440,5,30,572,1.5,******,37,******,57.5,
162,3581,11300,1430,5,30,572,1.5,******,37,******,57.5,
163,3584,11300,1440,5,30,572,1.5,******,37,******,57.5,
164,3587,11400,1430,5,30,572,1.5,******,37,******,57.6,
165,3590,11400,1450,5,30,573,1.5,******,37,******,57.6,
166,3593,11400,1440,5,30,573,1.5,******,37,******,57.6,
167,3596,11400,1440,5,30,573,1.5,******,37,******,57.6,
168,3599,11400,1420,5,30,575,1.5,******,37,******,57.8,
169,3602,11400,1430,5,30,573,1.5,******,37,******,57.6,
170,3605,11400,1430,5,30,575,1.5,******,37,******,57.8,
171,3608,11400,1460,5,30,573,1.5,******,37,******,57.6,
172,3611,11400,1450,5,30,575,1.5,******,37,******,57.8,
173,3614,11400,1470,5,30,575,1.5,******,37,******,57.8,
174,3617,11400,1420,5,30,575,1.5,******,37,******,57.8,
175,3620,11400,1460,5,30,577,1.5,******,37,******,58,
176,3623,11400,1440,5,30,576,1.5,******,37,******,57.9,
177,3626,11400,1440,5,30,576,1.5,******,37,******,57.9,
178,3629,11400,1440,5,30,576,1.5,******,37,******,57.9,
179,3632,11400,1430,5,30,577,1.5,******,37,******,58,
180,3635,11400,1450,5,30,577,1.5,******,37,******,58,
181,3638,11500,1450,5,30,577,1.5,******,37,******,58,
182,3641,11400,1430,5,30,577,1.5,******,37,******,58,
183,3644,11400,1440,5,30,577,1.5,******,37,******,58,
184,3647,11500,1430,5,30,578,1.5,******,37,******,58.1,
185,3650,11500,1440,5,30,578,1.5,******,37,******,58.1,
186,3653,11500,1440,5,30,578,1.5,******,37,******,58.1,
187,3656,11500,1450,5,30,578,1.5,******,37,******,58.2,
188,3659,11500,1450,5,30,579,1.5,******,37,******,58.3,
189,3662,11500,1440,5,30,579,1.5,******,37,******,58.2,
190,3665,11500,1440,5,30,578,1.5,******,37,******,58.2,
191,3668,11500,1450,5,30,581,1.5,******,37,******,58.4,
192,3671,11500,1410,5,30,580,1.5,******,37,******,58.3,
193,3674,11500,1450,5,30,581,1.5,******,37,******,58.4,
194,3677,11500,1460,5,30,580,1.5,******,37,******,58.3,
195,3680,11500,1440,5,30,581,1.5,******,37,******,58.4,
196,3683,11500,1450,5,30,581,1.5,******,37,******,58.4,
197,3686,11500,1460,5,30,582,1.5,******,37,******,58.5,
198,3689,11500,1450,5,30,581,1.5,******,37,******,58.4,
199,3692,11500,1450,5,30,582,1.5,******,37,******,58.5,
200,3695,11500,1450,5,30,581,1.5,******,37,******,58.4,
201,3698,11500,1450,5,30,582,1.5,******,37,******,58.5,
202,3701,11500,1440,5,30,582,1.5,******,37,******,58.5,
203,3704,11600,1450,5,30,583,1.5,******,37,******,58.6,
204,3707,11600,1440,5,30,583,1.5,******,37,******,58.7,
205,3710,11600,1450,5,30,583,1.5,******,37,******,58.6,
206,3713,11600,1470,5,30,583,1.5,******,37,******,58.6,
207,3716,11600,1470,5,30,583,1.5,******,37,******,58.6,
208,3719,11600,1460,5,30,584,1.5,******,37,******,58.7,
209,3722,11600,1460,5,30,583,1.5,******,37,******,58.7,
210,3725,11600,1460,5,30,584,1.5,******,37,******,58.7,
211,3728,11600,1450,5,30,584,1.5,******,37,******,58.8,
212,3731,11600,1450,5,30,584,1.5,******,37,******,58.7,
213,3734,11600,1470,5,30,585,1.5,******,37,******,58.8,
214,3737,11600,1470,5,30,585,1.5,******,37,******,58.8,
215,3740,11600,1450,5,30,585,1.5,******,37,******,58.8,
216,3743,11600,1460,5,30,585,1.5,******,37,******,58.9,
217,3746,11600,1460,5,30,586,1.5,******,37,******,58.9,
218,3749,11700,1490,5,30,588,1.5,******,37,******,59.1,
219,3752,11600,1470,5,30,587,1.5,******,37,******,59,
220,3755,11600,1470,5,30,586,1.5,******,37,******,58.9,
221,3758,11600,1470,5,30,587,1.5,******,37,******,59,
222,3761,11600,1460,5,30,587,1.5,******,37,******,59,
223,3764,11700,1470,5,30,587,1.5,******,37,******,59,
224,3767,11600,1460,5,30,587,1.5,******,37,******,59,
225,3770,11700,1470,5,30,588,1.5,******,37,******,59.1,
226,3773,11700,1470,5,30,588,1.5,******,37,******,59.1,
227,3776,11700,1470,5,30,588,1.5,******,37,******,59.2,
228,3779,11600,1490,5,30,587,1.5,******,37,******,59,
229,3782,11700,1480,5,30,589,1.5,******,37,******,59.2,
230,3785,11700,1500,5,30,589,1.5,******,37,******,59.2,
231,3788,11700,1460,5,30,589,1.5,******,37,******,59.2,
232,3791,11700,1490,5,30,590,1.5,******,37,******,59.3,
233,3794,11700,1470,5,30,590,1.5,******,37,******,59.3,
234,3797,11700,1480,5,30,591,1.5,******,37,******,59.4,
235,3800,11700,1470,5,30,589,1.5,******,37,******,59.2,
236,3803,11700,1490,5,30,589,1.5,******,37,******,59.2,
237,3806,11700,1490,5,30,591,1.5,******,37,******,59.5,
238,3809,11700,1490,5,30,591,1.5,******,37,******,59.4,
239,3812,11700,1480,5,30,590,1.5,******,37,******,59.4,
240,3815,11700,1480,5,30,591,1.5,******,37,******,59.4,
241,3818,11700,1480,5,30,591,1.5,******,37,******,59.4,
242,3821,11700,1470,5,30,592,1.5,******,37,******,59.5,
243,3824,11700,1470,5,30,591,1.5,******,37,******,59.5,
244,3827,11700,1480,5,30,592,1.5,******,37,******,59.5,
245,3830,11800,1490,5,30,592,1.5,******,37,******,59.6,
246,3833,11700,1480,5,30,592,1.5,******,37,******,59.5,
247,3836,11800,1480,5,30,592,1.5,******,37,******,59.6,
248,3839,11800,1480,5,30,594,1.5,******,37,******,59.7,
249,3842,11800,1460,5,30,593,1.5,******,37,******,59.6,
250,3845,11700,1490,5,30,592,1.5,******,37,******,59.5,
251,3848,11800,1470,5,30,593,1.5,******,37,******,59.6,
252,3851,11800,1490,5,30,593,1.5,******,37,******,59.7,
253,3854,11800,1480,5,30,593,1.5,******,37,******,59.6,
254,3857,11800,1480,5,30,594,1.5,******,37,******,59.7,
255,3860,11800,1490,5,30,594,1.5,******,37,******,59.7,
256,3863,11800,1480,5,30,595,1.5,******,37,******,59.8,
257,3866,11800,1490,5,30,594,1.5,******,37,******,59.8,
258,3869,11800,1500,5,30,594,1.5,******,37,******,59.7,
259,3872,11800,1470,5,30,594,1.5,******,37,******,59.8,
260,3875,11800,1480,5,30,594,1.5,******,37,******,59.7,
261,3878,11800,1470,5,30,595,1.5,******,37,******,59.8,
262,3881,11800,1480,5,30,595,1.5,******,37,******,59.8,
263,3884,11800,1490,5,30,595,1.5,******,37,******,59.8,
264,3887,11800,1500,5,30,595,1.5,******,37,******,59.8,
265,3890,11800,1490,5,30,596,1.5,******,37,******,59.9,
266,3893,11800,1490,5,30,595,1.5,******,37,******,59.9,
267,3896,11800,1480,5,30,595,1.5,******,37,******,59.8,
268,3899,11800,1490,5,30,596,1.5,******,37,******,59.9,
269,3902,11800,1470,5,30,596,1.5,******,37,******,59.9,
270,3905,11800,1490,5,30,597,1.5,******,37,******,60,
271,3908,11800,1470,5,30,596,1.5,******,37,******,60,
272,3911,11800,1460,5,30,597,1.5,******,37,******,60,
273,3914,11800,1500,5,30,596,1.5,******,37,******,60,
274,3917,11800,1490,5,30,596,1.5,******,37,******,59.9,
275,3920,11800,1490,5,30,596,1.5,******,37,******,59.9,
276,3923,11800,1490,5,30,597,1.5,******,37,******,60,
277,3926,11800,1500,5,30,596,1.5,******,37,******,59.9,
278,3929,11800,1490,5,30,597,1.5,******,37,******,60,
279,3932,11800,1500,5,30,597,1.5,******,37,******,60,
280,3935,11800,1480,5,30,597,1.5,******,37,******,60,
281,3938,11900,1490,5,30,597,1.5,******,37,******,60.1,
282,3941,11900,1500,5,30,597,1.5,******,37,******,60.1,
283,3944,11900,1500,5,30,598,1.5,******,37,******,60.2,
284,3947,11900,1490,5,30,597,1.5,******,37,******,60.1,
285,3950,11800,1500,5,30,597,1.5,******,37,******,60,
286,3953,11900,1510,5,30,599,1.5,******,37,******,60.2,
287,3956,11900,1500,5,30,598,1.5,******,37,******,60.2,
288,3959,11900,1480,5,30,598,1.5,******,37,******,60.1,
289,3962,11900,1500,5,30,599,1.5,******,37,******,60.2,
290,3965,11900,1480,5,30,599,1.5,******,37,******,60.2,
291,3968,11900,1500,5,30,599,1.5,******,37,******,60.2,
[...]
297,11426,12800,1650,5,30,647,1.5,******,37,******,65,
298,11429,12800,1640,5,30,646,1.5,******,37,******,64.9,
299,11432,12800,1650,5,30,647,1.5,******,37,******,65,
300,11435,12800,1660,5,30,646,1.5,******,37,******,64.9,
301,11438,12800,1650,5,30,647,1.5,******,37,******,65,
302,11441,12800,1660,5,30,647,1.5,******,37,******,65.1,
303,11444,12800,1640,5,30,647,1.5,******,37,******,65.1,
304,11447,12800,1640,5,30,647,1.5,******,37,******,65,
305,11450,12800,1640,5,30,648,1.5,******,37,******,65.1,
306,11453,12800,1640,5,30,647,1.5,******,37,******,65,
307,11456,12800,1660,5,30,647,1.5,******,37,******,65.1,
308,11459,12800,1650,5,30,647,1.5,******,37,******,65.1,
309,11462,12800,1650,5,30,647,1.5,******,37,******,65.1,
310,11465,12800,1650,5,30,647,1.5,******,37,******,65.1,
311,11468,12800,1650,5,30,647,1.5,******,37,******,65.1,
312,11471,12900,1660,5,30,648,1.5,******,37,******,65.2,
313,11474,12800,1630,5,30,648,1.5,******,37,******,65.1,
314,11477,12800,1660,5,30,647,1.5,******,37,******,65,
315,11480,12800,1650,5,30,647,1.5,******,37,******,65.1,
316,11483,12800,1660,5,30,647,1.5,******,37,******,65.1,
317,11486,12800,1650,5,30,648,1.5,******,37,******,65.1,
318,11489,12900,1660,5,30,648,1.5,******,37,******,65.2,
319,11492,12800,1660,5,30,648,1.5,******,37,******,65.1,
320,11495,12900,1650,5,30,649,1.5,******,37,******,65.2,
321,11498,12800,1640,5,30,647,1.5,******,37,******,65,
322,11501,12800,1660,5,30,647,1.5,******,37,******,65.1,
323,11504,12800,1660,5,30,647,1.5,******,37,******,65.1,
324,11507,12800,1630,5,30,647,1.5,******,37,******,65.1,
325,11510,12800,1660,5,30,647,1.5,******,37,******,65,
326,11513,12800,1650,5,30,648,1.5,******,37,******,65.1,
327,11516,12800,1660,5,30,647,1.5,******,37,******,65,
328,11519,12800,1650,5,30,648,1.5,******,37,******,65.1,
329,11522,12800,1650,5,30,647,1.5,******,37,******,65.1,
330,11525,12800,1640,5,30,647,1.5,******,37,******,65.1,
331,11528,12900,1680,5,30,648,1.5,******,37,******,65.2,
332,11531,12800,1660,5,30,648,1.5,******,37,******,65.1,
333,11534,12900,1660,5,30,648,1.5,******,37,******,65.2,
334,11537,12900,1650,5,30,649,1.5,******,37,******,65.2,
335,11540,12900,1660,5,30,648,1.5,******,37,******,65.2,
336,11543,12900,1660,5,30,648,1.5,******,37,******,65.2,
337,11546,12800,1660,5,30,648,1.5,******,37,******,65.1,
338,11549,12800,1660,5,30,648,1.5,******,37,******,65.1,
339,11552,12900,1660,5,30,649,1.5,******,37,******,65.3,
340,11555,12800,1650,5,30,647,1.5,******,37,******,65,
341,11558,12800,1680,5,30,648,1.5,******,37,******,65.1,
342,11561,12900,1640,5,30,648,1.5,******,37,******,65.2,
343,11564,12900,1650,5,30,648,1.5,******,37,******,65.2,
344,11567,12900,1640,5,30,648,1.5,******,37,******,65.1,
345,11570,12800,1660,5,30,647,1.5,******,37,******,65,
346,11573,12900,1660,5,30,649,1.5,******,37,******,65.2,
347,11576,12900,1650,5,30,649,1.5,******,37,******,65.3,
348,11579,12800,1660,5,30,647,1.5,******,37,******,65.1,
349,11582,12900,1650,5,30,648,1.5,******,37,******,65.1,
350,11585,12900,1660,5,30,648,1.5,******,37,******,65.1,
351,11588,12900,1660,5,30,649,1.5,******,37,******,65.2,
352,11591,12900,1660,5,30,648,1.5,******,37,******,65.2,
353,11594,12900,1650,5,30,648,1.5,******,37,******,65.2,
354,11597,12900,1650,5,30,648,1.5,******,37,******,65.2,
355,11600,12900,1660,5,30,648,1.5,******,37,******,65.2,
356,11603,12900,1650,5,30,648,1.5,******,37,******,65.2,
357,11606,12900,1650,5,30,648,1.5,******,37,******,65.2,
358,11609,12900,1670,5,30,649,1.5,******,37,******,65.2,
359,11612,12800,1640,5,30,648,1.5,******,37,******,65.1,
360,11615,12900,1650,5,30,649,1.5,******,37,******,65.2,
361,11618,12900,1660,5,30,648,1.5,******,37,******,65.2,
362,11621,12900,1630,5,30,649,1.5,******,37,******,65.3,
363,11624,12900,1680,5,30,648,1.5,******,37,******,65.2,
364,11627,12900,1660,5,30,649,1.5,******,37,******,65.2,
365,11630,12900,1660,5,30,648,1.5,******,37,******,65.1,
366,11633,12900,1680,5,30,650,1.5,******,37,******,65.3,
367,11636,12900,1660,5,30,649,1.5,******,37,******,65.3,
368,11639,12900,1660,5,30,648,1.5,******,37,******,65.1,
369,11642,12900,1680,5,30,649,1.5,******,37,******,65.2,
370,11645,12900,1660,5,30,648,1.5,******,37,******,65.2,
371,11648,12900,1640,5,30,648,1.5,******,37,******,65.2,
372,11651,12900,1660,5,30,649,1.5,******,37,******,65.2,
373,11654,12900,1660,5,30,649,1.5,******,37,******,65.2,
374,11657,12900,1650,5,30,648,1.5,******,37,******,65.2,
375,11660,12900,1650,5,30,649,1.5,******,37,******,65.2,
376,11663,12900,1640,5,30,649,1.5,******,37,******,65.3,
377,11666,12900,1660,5,30,649,1.5,******,37,******,65.2,
378,11669,12900,1660,5,30,649,1.5,******,37,******,65.3,
379,11672,12900,1660,5,30,649,1.5,******,37,******,65.2,
380,11675,12900,1660,5,30,650,1.5,******,37,******,65.3,
381,11678,12900,1650,5,30,649,1.5,******,37,******,65.2,
382,11681,12900,1640,5,30,650,1.5,******,37,******,65.3,
383,11684,12900,1660,5,30,649,1.5,******,37,******,65.2,
384,11687,12900,1680,5,30,649,1.5,******,37,******,65.2,
385,11690,12900,1660,5,30,649,1.5,******,37,******,65.2,
386,11693,12900,1660,5,30,649,1.5,******,37,******,65.2,
387,11696,12900,1650,5,30,648,1.5,******,37,******,65.1,
388,11699,12900,1650,5,30,649,1.5,******,37,******,65.3,
389,11702,12900,1660,5,30,649,1.5,******,37,******,65.2,
390,11705,12900,1640,5,30,649,1.5,******,37,******,65.3,
391,11708,12900,1650,5,30,649,1.5,******,37,******,65.3,
392,11711,12900,1660,5,30,648,1.5,******,37,******,65.2,
393,11714,12900,1660,5,30,649,1.5,******,37,******,65.2,
394,11717,12900,1660,5,30,649,1.5,******,37,******,65.3,
395,11720,12900,1650,5,30,650,1.5,******,37,******,65.3,
396,11723,12900,1660,5,30,649,1.5,******,37,******,65.2,
397,11726,12900,1640,5,30,649,1.5,******,37,******,65.2,
398,11729,12900,1670,5,30,649,1.5,******,37,******,65.3,
399,11732,12900,1670,5,30,650,1.5,******,37,******,65.3,
400,11735,12900,1640,5,30,648,1.5,******,37,******,65.2,
401,11738,12900,1650,5,30,649,1.5,******,37,******,65.2,
402,11741,12900,1660,5,30,649,1.5,******,37,******,65.2,
403,11744,12900,1660,5,30,649,1.5,******,37,******,65.2,
404,11747,12900,1680,5,30,649,1.5,******,37,******,65.3,
405,11750,12900,1650,5,30,650,1.5,******,37,******,65.3,
406,11753,12900,1670,5,30,650,1.5,******,37,******,65.3,
407,11756,12900,1650,5,30,650,1.5,******,37,******,65.4,
408,11759,12900,1650,5,30,649,1.5,******,37,******,65.3,
409,11762,12900,1680,5,30,650,1.5,******,37,******,65.3,
410,11765,12900,1670,5,30,649,1.5,******,37,******,65.3,
411,11768,12900,1630,5,30,649,1.5,******,37,******,65.3,
412,11771,12900,1680,5,30,650,1.5,******,37,******,65.3,
413,11774,12900,1660,5,30,649,1.5,******,37,******,65.2,
414,11777,12900,1660,5,30,651,1.5,******,37,******,65.4,
415,11780,12900,1650,5,30,648,1.5,******,37,******,65.2,
416,11783,12900,1670,5,30,649,1.5,******,37,******,65.3,
417,11786,12900,1650,5,30,649,1.5,******,37,******,65.3,
418,11789,12900,1640,5,30,649,1.5,******,37,******,65.3,
419,11792,12900,1680,5,30,650,1.5,******,37,******,65.4,
420,11795,12900,1660,5,30,649,1.5,******,37,******,65.3,
421,11798,12900,1660,5,30,649,1.5,******,37,******,65.3,
422,11801,12900,1660,5,30,649,1.5,******,37,******,65.3,
423,11804,12900,1640,5,30,650,1.5,******,37,******,65.4,
424,11807,12900,1650,5,30,650,1.5,******,37,******,65.3,
425,11810,12900,1660,5,30,649,1.5,******,37,******,65.3,
426,11813,12900,1660,5,30,650,1.5,******,37,******,65.3,
427,11816,12900,1650,5,30,649,1.5,******,37,******,65.2,
428,11819,12900,1660,5,30,650,1.5,******,37,******,65.4,
429,11822,12900,1660,5,30,649,1.5,******,37,******,65.3,
430,11825,12900,1680,5,30,649,1.5,******,37,******,65.3,
431,11828,12900,1650,5,30,650,1.5,******,37,******,65.3,
432,11831,12900,1660,5,30,650,1.5,******,37,******,65.3,
433,11834,12900,1660,5,30,649,1.5,******,37,******,65.3,
434,11837,12900,1660,5,30,650,1.5,******,37,******,65.3,
435,11840,12900,1650,5,30,650,1.5,******,37,******,65.3,
436,11843,12900,1650,5,30,651,1.5,******,37,******,65.4,
437,11846,12900,1650,5,30,650,1.5,******,37,******,65.3,
438,11849,12900,1640,5,30,650,1.5,******,37,******,65.3,
439,11852,12900,1650,5,30,650,1.5,******,37,******,65.3,
440,11855,12900,1660,5,30,650,1.5,******,37,******,65.3,
441,11858,12900,1650,5,30,650,1.5,******,37,******,65.3,
442,11861,12900,1660,5,30,649,1.5,******,37,******,65.3,
443,11864,12900,1670,5,30,649,1.5,******,37,******,65.3,
444,11867,12900,1670,5,30,650,1.5,******,37,******,65.3,
445,11870,12900,1660,5,30,650,1.5,******,37,******,65.3,
446,11873,12900,1670,5,30,651,1.5,******,37,******,65.4,
447,11876,12900,1660,5,30,652,1.5,******,37,******,65.5,
448,11879,12900,1660,5,30,649,1.5,******,37,******,65.2,
449,11882,12900,1670,5,30,650,1.5,******,37,******,65.4,
450,11885,12900,1660,5,30,650,1.5,******,37,******,65.3,
451,11888,12900,1620,5,30,650,1.5,******,37,******,65.3,
452,11891,12900,1670,5,30,650,1.5,******,37,******,65.3,
453,11894,12900,1640,5,30,651,1.5,******,37,******,65.5,
454,11897,12900,1660,5,30,652,1.5,******,37,******,65.5,
455,11900,12900,1660,5,30,649,1.5,******,37,******,65.3,
456,11903,12900,1660,5,30,650,1.5,******,37,******,65.3,
457,11906,12900,1660,5,30,651,1.5,******,37,******,65.4,
458,11909,12900,1650,5,30,650,1.5,******,37,******,65.3,
459,11912,12900,1630,5,30,649,1.5,******,37,******,65.3,
460,11915,12900,1660,5,30,650,1.5,******,37,******,65.3,
461,11918,12900,1660,5,30,650,1.5,******,37,******,65.3,
462,11921,12900,1650,5,30,650,1.5,******,37,******,65.4,
463,11924,12900,1660,5,30,650,1.5,******,37,******,65.3,
464,11927,12900,1670,5,30,650,1.5,******,37,******,65.4,
465,11930,12900,1660,5,30,650,1.5,******,37,******,65.4,
466,11933,12900,1670,5,30,651,1.5,******,37,******,65.5,
467,11936,12900,1650,5,30,650,1.5,******,37,******,65.3,
468,11939,12900,1660,5,30,649,1.5,******,37,******,65.3,
469,11942,12900,1640,5,30,650,1.5,******,37,******,65.3,
470,11945,12900,1690,5,30,649,1.5,******,37,******,65.3,
471,11948,12900,1640,5,30,650,1.5,******,37,******,65.3,
472,11951,12900,1670,5,30,651,1.5,******,37,******,65.4,
473,11954,12900,1650,5,30,651,1.5,******,37,******,65.4,
474,11957,12900,1650,5,30,650,1.5,******,37,******,65.3,
475,11960,12900,1650,5,30,651,1.5,******,37,******,65.5,
476,11963,12900,1670,5,30,649,1.5,******,37,******,65.3,
477,11966,12900,1670,5,30,651,1.5,******,37,******,65.4,
478,11969,12900,1640,5,30,650,1.5,******,37,******,65.4,
479,11972,12900,1620,5,30,649,1.5,******,37,******,65.2,
480,11975,12900,1650,5,30,650,1.5,******,37,******,65.3,
481,11978,12900,1660,5,30,650,1.5,******,37,******,65.4,
482,11981,12900,1670,5,30,649,1.5,******,37,******,65.3,
483,11984,12900,1650,5,30,650,1.5,******,37,******,65.4,
484,11987,12900,1660,5,30,650,1.5,******,37,******,65.4,
485,11990,12900,1650,5,30,650,1.5,******,37,******,65.3,
486,11993,12900,1670,5,30,651,1.5,******,37,******,65.4,
487,11996,12900,1660,5,30,650,1.5,******,37,******,65.4,
488,11999,12900,1660,5,30,652,1.5,******,37,******,65.5,
489,12002,12900,1650,5,30,650,1.5,******,37,******,65.4,
490,12005,12900,1560,5.01,30,651,1.5,******,37,******,65.4,
491,12008,12900,1670,5,30,648,1.5,******,37,******,65.2,
492,12011,12900,1630,5,30,650,1.5,******,37,******,65.4,
493,12014,12900,1660,5,30,650,1.5,******,37,******,65.4,
494,12017,12900,1650,5,30,652,1.5,******,37,******,65.5,
495,12020,12900,1660,5,30,650,1.5,******,37,******,65.3,
496,12023,12900,1640,5,30,649,1.5,******,37,******,65.2,
497,12026,12900,1670,5,30,650,1.5,******,37,******,65.3,
498,12029,12900,1650,5,30,650,1.5,******,37,******,65.4,
499,12032,12900,1660,5,30,653,1.5,******,37,******,65.6,
500,12035,12900,1650,5,30,650,1.5,******,37,******,65.4,
501,12038,12900,1700,5,30,648,1.5,******,37,******,65.2,
502,12041,12900,1690,5,30,649,1.5,******,37,******,65.3,
503,12044,12900,1680,5,30,650,1.5,******,37,******,65.3,
504,12047,12900,1660,5,30,650,1.5,******,37,******,65.4,
505,12050,12900,1650,5,30,650,1.5,******,37,******,65.4,
506,12053,12900,1650,5,30,651,1.5,******,37,******,65.5,
507,12056,12900,1610,5,30,650,1.5,******,37,******,65.4,
508,12059,12900,1650,5,30,651,1.5,******,37,******,65.4,
509,12062,12900,1640,5,30,650,1.5,******,37,******,65.4,
510,12065,12900,1650,5,30,651,1.5,******,37,******,65.4,
511,12068,12900,1620,5,30,651,1.5,******,37,******,65.5,
512,12071,12900,1680,5,30,651,1.5,******,37,******,65.5,
513,12074,12900,1650,5,30,651,1.5,******,37,******,65.5,
514,12077,12900,1650,5,30,650,1.5,******,37,******,65.4,
515,12080,12900,1630,5,30,650,1.5,******,37,******,65.4,
516,12083,12900,1660,5,30,651,1.5,******,37,******,65.4,
517,12086,12900,1680,5,30,652,1.5,******,37,******,65.5,
518,12089,12900,1660,5,30,651,1.5,******,37,******,65.4,
519,12092,12900,1640,5,30,650,1.5,******,37,******,65.4,
520,12095,12900,1650,5,30,652,1.5,******,37,******,65.5,
521,12098,12900,1630,5,30,651,1.5,******,37,******,65.5,
522,12101,12900,1660,5,30,649,1.5,******,37,******,65.3,
523,12104,12900,1670,5,30,651,1.5,******,37,******,65.5,
524,12107,12900,1640,5,30,651,1.5,******,37,******,65.4,
525,12110,12900,1660,5,30,652,1.5,******,37,******,65.6,
526,12113,12900,1620,5,30,652,1.5,******,37,******,65.5,
527,12116,12900,1650,5,30,650,1.5,******,37,******,65.3,
528,12119,12900,1650,5,30,651,1.5,******,37,******,65.5,
529,12122,12900,1660,5,30,650,1.5,******,37,******,65.4,
530,12125,12900,1660,5,30,650,1.5,******,37,******,65.4,
531,12128,12900,1670,5,30,651,1.5,******,37,******,65.5,
532,12131,12900,1700,5,30,650,1.5,******,37,******,65.3,
533,12134,12900,1680,5,30,650,1.5,******,37,******,65.3,
534,12137,12900,1650,5,30,651,1.5,******,37,******,65.5,
535,12140,12900,1670,5,30,650,1.5,******,37,******,65.4,
536,12143,12900,1660,5,30,652,1.5,******,37,******,65.6,
537,12146,12900,1640,5,30,651,1.5,******,37,******,65.5,
538,12149,12900,1650,5,30,652,1.5,******,37,******,65.6,
539,12152,12900,1630,5,30,650,1.5,******,37,******,65.3,
540,12155,12900,1660,5,30,652,1.5,******,37,******,65.5,
541,12158,12900,1640,5,30,652,1.5,******,37,******,65.5,
542,12161,12900,1660,5,30,648,1.5,******,37,******,65.2,
543,12164,13000,1610,5,30,654,1.5,******,37,******,65.7,
544,12167,12900,1650,5,30,652,1.5,******,37,******,65.5,
545,12170,12900,1650,5,30,650,1.5,******,37,******,65.3,
546,12173,12900,1660,5,30,650,1.5,******,37,******,65.4,
547,12176,12900,1650,5,30,650,1.5,******,37,******,65.3,
548,12179,12900,1640,5,30,651,1.5,******,37,******,65.5,
549,12182,12900,1650,5,30,651,1.5,******,37,******,65.4,
550,12185,12900,1640,5,30,651,1.5,******,37,******,65.5,
551,12188,12900,1680,5,30,652,1.5,******,37,******,65.5,
552,12191,12900,1650,5,30,651,1.5,******,37,******,65.4,
553,12194,12900,1650,5,30,652,1.5,******,37,******,65.6,
554,12197,12900,1660,5,30,652,1.5,******,37,******,65.6,
555,12200,12900,1650,5,30,651,1.5,******,37,******,65.4,
556,12203,12900,1650,5,30,653,1.5,******,37,******,65.6,
557,12206,12900,1630,5,30,651,1.5,******,37,******,65.4,
558,12209,12900,1670,5,30,650,1.5,******,37,******,65.3,
559,12212,12900,1590,5.01,30,652,1.5,******,37,******,65.6,
560,12215,12900,1650,5,30,648,1.5,******,37,******,65.2,
561,12218,12900,1670,5,30,651,1.5,******,37,******,65.5,
562,12221,12900,1670,5,30,652,1.5,******,37,******,65.5,
563,12224,12900,1660,5,30,651,1.5,******,37,******,65.5,
564,12227,12900,1640,5,30,652,1.5,******,37,******,65.6,
565,12230,12900,1660,5,30,651,1.5,******,37,******,65.4,
566,12233,12900,1650,5,30,651,1.5,******,37,******,65.4,
567,12236,12900,1670,5,30,652,1.5,******,37,******,65.5,
568,12239,12900,1650,5,30,651,1.5,******,37,******,65.4,
569,12242,12900,1650,5,30,651,1.5,******,37,******,65.5,
570,12245,12900,1640,5,30,652,1.5,******,37,******,65.5,
571,12248,12900,1680,5,30,651,1.5,******,37,******,65.4,
572,12251,12900,1640,5,30,651,1.5,******,37,******,65.5,
573,12254,12900,1670,5,30,649,1.5,******,37,******,65.2,
574,12257,12900,1650,5,30,651,1.5,******,37,******,65.4,
575,12260,12900,1660,5,30,651,1.5,******,37,******,65.5,
576,12263,12900,1660,5,30,651,1.5,******,37,******,65.4,
577,12266,13200,1810,5,30,668,1.5,******,37,******,67.1,
578,12269,12900,1650,5,30,650,1.5,******,37,******,65.4,
579,12272,12900,1660,5,30,652,1.5,******,37,******,65.5,
580,12275,12900,1670,5,30,651,1.5,******,37,******,65.5,
581,12278,12900,1650,5,30,651,1.5,******,37,******,65.4,
582,12281,12900,1650,5,30,652,1.5,******,37,******,65.5,
583,12284,12900,1660,5,30,651,1.5,******,37,******,65.5,
584,12287,12900,1650,5,30,651,1.5,******,37,******,65.5,
585,12290,12900,1660,5,30,651,1.5,******,37,******,65.4,
586,12293,12900,1660,5,30,651,1.5,******,37,******,65.5,
587,12296,12900,1660,5,30,652,1.5,******,37,******,65.5,
588,12299,12900,1660,5,30,650,1.5,******,37,******,65.4,
589,12302,12900,1680,5,30,651,1.5,******,37,******,65.4,
590,12305,12900,1650,5,30,652,1.5,******,37,******,65.6,
591,12308,12900,1690,5,30,650,1.5,******,37,******,65.4,
592,12311,12900,1680,5,30,650,1.5,******,37,******,65.4,
593,12314,12900,1670,5,30,650,1.5,******,37,******,65.4,
594,12317,12900,1680,5,30,652,1.5,******,37,******,65.5,
595,12320,12900,1580,5.01,30,651,1.5,******,37,******,65.4,
596,12323,12900,1680,5,30,651,1.5,******,37,******,65.5,
597,12326,12900,1650,5,30,650,1.5,******,37,******,65.3,
598,12329,12900,1690,5,30,648,1.5,******,37,******,65.2,
599,12332,13000,1570,5.01,30,654,1.5,******,37,******,65.8,
600,12335,12900,1660,5,30,649,1.5,******,37,******,65.2,
,,,,,,,,,,,,
Interval:,,,15,,,,,,,,,
Number of Data Points:,,,28,,,,,,,,,
,,,,,,,,,,,,
Time Setting:,,,28 Meas. Pts.,,,,,,,,,
,,,Meas. Pt. Duration 6.4285714 s,,,,,,,,,
Event Control:,,,Standard Mode,,,,,,,,,
"  Terminate test, ...",,,...if d(gamma)/dt > 1000 1/s,,,,,,,,,
"  Terminate test, ...",,,...if M > 200 mNm,,,,,,,,,
"  Terminate test, ...",,,...if FN < -50 N or > 50 N,,,,,,,,,
Measuring Profile:,,,,,,,,,,,,
  Shear Rate,,,d(gamma)/dt = 0.1 ... 50 1/s log; |Slope| = 10.003816 Pt. / dec ,,,,,,,,,
,,,,,,,,,,,,
Meas. Pts.,Time,Storage Modulus,Loss Modulus,Strain,Angular Frequency,Shear Stress,Shear Rate,Viscosity,Temperature,Speed,Torque,Status
,[s],[Pa],[Pa],[%],[rad/s],[Pa],[1/s],[Pa·s],[°C],[1/min],[µNm],[]
1,12300,******,******,47.7,******,774,0.1,7750,37,0.12,77.9,Dy_auto
2,12300,******,******,124,******,1000,0.13,7980,37,0.15,101,Dy_auto
3,12400,******,******,221,******,1260,0.16,7940,37,0.19,126,Dy_auto
4,12400,******,******,342,******,1550,0.2,7800,37,0.24,156,Dy_auto
5,12400,******,******,495,******,1910,0.25,7600,37,0.3,192,Dy_auto
6,12400,******,******,688,******,2330,0.32,7380,37,0.38,234,Dy_auto
7,12400,******,******,930,******,2860,0.4,7180,37,0.48,287,Dy_auto
8,12400,******,******,1240,******,3500,0.5,6980,37,0.6,352,Dy_auto
9,12400,******,******,1620,******,4280,0.63,6780,37,0.75,430,Dy_auto
10,12400,******,******,2100,******,5190,0.79,6540,37,0.95,522,Dy_auto
11,12400,******,******,2710,******,6210,1,6210,37,1.19,624,Dy_auto
12,12400,******,******,3480,******,6000,1.26,4770,37,1.5,604,Dy_auto
13,12400,******,******,4440,******,5000,1.58,3160,37,1.89,503,Dy_auto
14,12400,******,******,5660,******,3910,1.99,1960,37,2.38,393,Dy_auto
15,12400,******,******,7190,******,3670,2.51,1460,37,2.99,369,Dy_auto
16,12400,******,******,9110,******,3380,3.16,1070,37,3.77,339,Dy_auto
17,12400,******,******,11500,******,2520,3.98,635,37,4.75,254,Dy_auto
18,12500,******,******,14600,******,2300,5,460,37,5.97,231,Dy_auto
19,12500,******,******,18400,******,2350,6.3,372,37,7.52,236,Dy_auto
20,12500,******,******,23300,******,2400,7.93,303,37,9.46,241,Dy_auto
21,12500,******,******,29300,******,2300,9.98,231,37,11.9,232,Dy_auto
22,12500,******,******,37000,******,1710,12.6,136,37,15,172,Dy_auto
23,12500,******,******,46600,******,1310,15.8,82.8,37,18.9,132,Dy_auto
24,12500,******,******,58800,******,1480,19.9,74.5,37,23.8,149,Dy_auto
25,12500,******,******,74100,******,1340,25.1,53.6,37,29.9,135,Dy_auto
26,12500,******,******,93300,******,1370,31.6,43.6,37,37.7,138,Dy_auto
27,12500,******,******,117000,******,1520,39.7,38.2,37,47.4,153,Dy_auto
28,12500,******,******,148000,******,1580,50,31.6,37,59.7,159,Dy_auto